



local T = lib_towns.schems.T


return {
	size = {x = 5,y = 14,z = 10},
	data = {
		T["_____"], T["C0pw0"], T["C0S00"], T["C0pw0"], T["_____"],
		T["_____"], T["C0pw0"], T["_____"], T["C0pw0"], T["_____"],
		T["_____"], T["TrN00"], T["_____"], T["TrN00"], T["_____"],
		T["_____"], T["_____"], T["_____"], T["_____"], T["_____"],
		T["_____"], T["_____"], T["_____"], T["_____"], T["_____"],
		T["_____"], T["_____"], T["_____"], T["_____"], T["_____"],
		T["_____"], T["_____"], T["_____"], T["_____"], T["_____"],
		T["_____"], T["_____"], T["_____"], T["_____"], T["_____"],
		T["_____"], T["_____"], T["_____"], T["_____"], T["_____"],
		T["_____"], T["_____"], T["_____"], T["_____"], T["_____"],
		T["_____"], T["_____"], T["_____"], T["_____"], T["_____"],
		T["_____"], T["_____"], T["_____"], T["_____"], T["_____"],
		T["_____"], T["_____"], T["_____"], T["_____"], T["_____"],
		T["_____"], T["_____"], T["_____"], T["_____"], T["_____"],

		T["_____"], T["S0m00"], T["S0m00"], T["S0m00"], T["_____"],
		T["_____"], T["S0m00"], T["W0dS0"], T["S0m00"], T["_____"],
		T["_____"], T["C0m00"], T["_____"], T["C0m00"], T["_____"],
		T["_____"], T["C0m00"], T["S0m00"], T["C0m00"], T["_____"],
		T["C0m00"], T["S0m00"], T["X0m00"], T["S0m00"], T["C0m00"],
		T["C0pw0"], T["C0m00"], T["S0m00"], T["C0m00"], T["C0pw0"],
		T["_____"], T["C0m00"], T["Xp0N0"], T["C0m00"], T["_____"],
		T["_____"], T["C0m00"], T["Xp0N0"], T["C0m00"], T["_____"],
		T["_____"], T["C0m00"], T["S0m00"], T["C0m00"], T["_____"],
		T["C0m00"], T["S0m00"], T["X0m00"], T["S0m00"], T["C0m00"],
		T["_____"], T["C0m00"], T["S0m00"], T["C0m00"], T["_____"],
		T["_____"], T["_____"], T["C0m00"], T["_____"], T["_____"],
		T["_____"], T["_____"], T["_____"], T["_____"], T["_____"],
		T["_____"], T["_____"], T["_____"], T["_____"], T["_____"],

		T["C0pw0"], T["S0m00"], T["WlvN0"], T["S0m00"], T["C0pw0"],
		T["C0m00"], T["_____"], T["_____"], T["_____"], T["C0m00"],
		T["C0m00"], T["_____"], T["_____"], T["_____"], T["C0m00"],
		T["C0m00"], T["_____"], T["_____"], T["_____"], T["C0m00"],
		T["C0m00"], T["C0m00"], T["C0m00"], T["C0m00"], T["C0m00"],
		T["C0m00"], T["_____"], T["_____"], T["_____"], T["C0m00"],
		T["C0m00"], T["_____"], T["_____"], T["_____"], T["C0m00"],
		T["C0m00"], T["_____"], T["_____"], T["_____"], T["C0m00"],
		T["C0m00"], T["_____"], T["_____"], T["_____"], T["C0m00"],
		T["S0m00"], T["C0m00"], T["C0m00"], T["C0m00"], T["S0m00"],
		T["C0m00"], T["_____"], T["_____"], T["_____"], T["C0m00"],
		T["_____"], T["_____"], T["_____"], T["_____"], T["_____"],
		T["_____"], T["_____"], T["_____"], T["_____"], T["_____"],
		T["_____"], T["_____"], T["_____"], T["_____"], T["_____"],

		T["_____"], T["S0m00"], T["WlvN0"], T["S0m00"], T["_____"],
		T["S0m00"], T["W0S02"], T["_____"], T["W0S02"], T["S0m00"],
		T["Xp0W0"], T["_____"], T["_____"], T["_____"], T["Xp0W0"],
		T["Xp0W0"], T["_____"], T["_____"], T["_____"], T["Xp0W0"],
		T["S0m00"], T["C0m00"], T["C0m00"], T["C0m00"], T["S0m00"],
		T["S0m00"], T["_____"], T["_____"], T["_____"], T["S0m00"],
		T["Xp0W0"], T["_____"], T["_____"], T["_____"], T["Xp0W0"],
		T["Xp0W0"], T["_____"], T["_____"], T["_____"], T["Xp0W0"],
		T["S0m00"], T["_____"], T["_____"], T["_____"], T["S0m00"],
		T["X0m00"], T["C0m00"], T["C0m00"], T["C0m00"], T["X0m00"],
		T["S0m00"], T["_____"], T["_____"], T["_____"], T["S0m00"],
		T["C0m00"], T["_____"], T["_____"], T["_____"], T["C0m00"],
		T["_____"], T["_____"], T["_____"], T["_____"], T["_____"],
		T["_____"], T["_____"], T["_____"], T["_____"], T["_____"],

		T["_____"], T["S0m00"], T["WlvN0"], T["S0m00"], T["_____"],
		T["C0m00"], T["_____"], T["_____"], T["Ld0N0"], T["C0m00"],
		T["C0m00"], T["_____"], T["_____"], T["Ld0N0"], T["C0m00"],
		T["C0m00"], T["_____"], T["_____"], T["Ld0N0"], T["C0m00"],
		T["C0m00"], T["C0m00"], T["C0m00"], T["Ld0N0"], T["C0m00"],
		T["C0m00"], T["_____"], T["_____"], T["Ld0N0"], T["C0m00"],
		T["C0m00"], T["_____"], T["_____"], T["Ld0N0"], T["C0m00"],
		T["C0m00"], T["_____"], T["_____"], T["Ld0N0"], T["C0m00"],
		T["C0m00"], T["_____"], T["_____"], T["Ld0N0"], T["C0m00"],
		T["S0m00"], T["C0m00"], T["C0m00"], T["Ld0N0"], T["S0m00"],
		T["C0m00"], T["_____"], T["_____"], T["_____"], T["C0m00"],
		T["_____"], T["_____"], T["_____"], T["_____"], T["_____"],
		T["_____"], T["_____"], T["_____"], T["_____"], T["_____"],
		T["_____"], T["_____"], T["_____"], T["_____"], T["_____"],

		T["S0m00"], T["C0m00"], T["WlvN0"], T["C0m00"], T["S0m00"],
		T["C0m00"], T["W0S02"], T["_____"], T["W0S02"], T["C0m00"],
		T["C0m00"], T["_____"], T["_____"], T["_____"], T["C0m00"],
		T["C0m00"], T["_____"], T["_____"], T["_____"], T["C0m00"],
		T["C0m00"], T["_____"], T["_____"], T["_____"], T["C0m00"],
		T["C0pw0"], T["C0m00"], T["C0m00"], T["C0m00"], T["C0pw0"],
		T["_____"], T["C0m00"], T["Xp0N0"], T["C0m00"], T["_____"],
		T["_____"], T["C0m00"], T["Xp0N0"], T["C0m00"], T["_____"],
		T["_____"], T["C0m00"], T["S0m00"], T["C0m00"], T["_____"],
		T["C0m00"], T["S0m00"], T["X0m00"], T["S0m00"], T["C0m00"],
		T["_____"], T["C0m00"], T["S0m00"], T["C0m00"], T["_____"],
		T["_____"], T["_____"], T["C0m00"], T["_____"], T["_____"],
		T["_____"], T["_____"], T["_____"], T["_____"], T["_____"],
		T["_____"], T["_____"], T["_____"], T["_____"], T["_____"],

		T["S0m00"], T["S0m00"], T["WlvN0"], T["S0m00"], T["S0m00"],
		T["C0m00"], T["_____"], T["_____"], T["_____"], T["C0m00"],
		T["C0m00"], T["_____"], T["_____"], T["_____"], T["C0m00"],
		T["C0m00"], T["_____"], T["_____"], T["_____"], T["C0m00"],
		T["C0m00"], T["_____"], T["_____"], T["_____"], T["C0m00"],
		T["_____"], T["C0m00"], T["S0m00"], T["C0m00"], T["_____"],
		T["_____"], T["_____"], T["_____"], T["_____"], T["_____"],
		T["_____"], T["_____"], T["_____"], T["_____"], T["_____"],
		T["_____"], T["_____"], T["_____"], T["_____"], T["_____"],
		T["_____"], T["_____"], T["_____"], T["_____"], T["_____"],
		T["_____"], T["_____"], T["_____"], T["_____"], T["_____"],
		T["_____"], T["_____"], T["_____"], T["_____"], T["_____"],
		T["_____"], T["_____"], T["_____"], T["_____"], T["_____"],
		T["_____"], T["_____"], T["_____"], T["_____"], T["_____"],

		T["S0m00"], T["S0m00"], T["C0m00"], T["S0m00"], T["S0m00"],
		T["S0m00"], T["C0S20"], T["C0S00"], T["C0S20"], T["S0m00"],
		T["S0m00"], T["_____"], T["_____"], T["_____"], T["S0m00"],
		T["Xp0W0"], T["_____"], T["_____"], T["_____"], T["Xp0W0"],
		T["S0m00"], T["_____"], T["_____"], T["_____"], T["S0m00"],
		T["_____"], T["S0m00"], T["X0m00"], T["S0m00"], T["_____"],
		T["_____"], T["_____"], T["_____"], T["_____"], T["_____"],
		T["_____"], T["_____"], T["_____"], T["_____"], T["_____"],
		T["_____"], T["_____"], T["_____"], T["_____"], T["_____"],
		T["_____"], T["_____"], T["_____"], T["_____"], T["_____"],
		T["_____"], T["_____"], T["_____"], T["_____"], T["_____"],
		T["_____"], T["_____"], T["_____"], T["_____"], T["_____"],
		T["_____"], T["_____"], T["_____"], T["_____"], T["_____"],
		T["_____"], T["_____"], T["_____"], T["_____"], T["_____"],

		T["S0m00"], T["C0m00"], T["C0m00"], T["C0m00"], T["S0m00"],
		T["C0m00"], T["C0m00"], T["C0m00"], T["C0m00"], T["C0m00"],
		T["C0m00"], T["C0S03"], T["_____"], T["C0S01"], T["C0m00"],
		T["C0m00"], T["TwS00"], T["_____"], T["TwS00"], T["C0m00"],
		T["C0m00"], T["_____"], T["_____"], T["_____"], T["C0m00"],
		T["_____"], T["C0m00"], T["S0m00"], T["C0m00"], T["_____"],
		T["_____"], T["_____"], T["_____"], T["_____"], T["_____"],
		T["_____"], T["_____"], T["_____"], T["_____"], T["_____"],
		T["_____"], T["_____"], T["_____"], T["_____"], T["_____"],
		T["_____"], T["_____"], T["_____"], T["_____"], T["_____"],
		T["_____"], T["_____"], T["_____"], T["_____"], T["_____"],
		T["_____"], T["_____"], T["_____"], T["_____"], T["_____"],
		T["_____"], T["_____"], T["_____"], T["_____"], T["_____"],
		T["_____"], T["_____"], T["_____"], T["_____"], T["_____"],

		T["_____"], T["S0m00"], T["S0m00"], T["S0m00"], T["_____"],
		T["C0pw0"], T["C0m00"], T["S0m00"], T["C0m00"], T["C0pw0"],
		T["_____"], T["C0m00"], T["S0m00"], T["C0m00"], T["_____"],
		T["_____"], T["C0m00"], T["Xp0N0"], T["C0m00"], T["_____"],
		T["C0m00"], T["C0m00"], T["S0m00"], T["C0m00"], T["C0m00"],
		T["_____"], T["_____"], T["_____"], T["_____"], T["_____"],
		T["_____"], T["_____"], T["_____"], T["_____"], T["_____"],
		T["_____"], T["_____"], T["_____"], T["_____"], T["_____"],
		T["_____"], T["_____"], T["_____"], T["_____"], T["_____"],
		T["_____"], T["_____"], T["_____"], T["_____"], T["_____"],
		T["_____"], T["_____"], T["_____"], T["_____"], T["_____"],
		T["_____"], T["_____"], T["_____"], T["_____"], T["_____"],
		T["_____"], T["_____"], T["_____"], T["_____"], T["_____"],
		T["_____"], T["_____"], T["_____"], T["_____"], T["_____"],
	},
	yslice_prob = {
		{prob = 254,ypos = 0},
		{prob = 254,ypos = 1},
		{prob = 254,ypos = 2},
		{prob = 254,ypos = 3},
		{prob = 254,ypos = 4},
		{prob = 254,ypos = 5},
		{prob = 254,ypos = 6},
		{prob = 254,ypos = 7},
		{prob = 254,ypos = 8},
		{prob = 254,ypos = 9},
		{prob = 254,ypos = 10},
		{prob = 254,ypos = 11},
		{prob = 254,ypos = 12},
		{prob = 254,ypos = 13}
	}
}