


local T = lib_towns.schems.T

return {
	size = {x = 5,y = 19,z = 5},
	data = {
		T["K0m00"], T["K0m00"], T["K0m00"], T["K0m00"], T["K0m00"],
		T["K0m00"], T["K0m00"], T["K0m00"], T["K0m00"], T["K0m00"],
		T["K0m00"], T["K0m00"], T["K0m00"], T["K0m00"], T["K0m00"],
		T["K0m00"], T["K0m00"], T["K0m00"], T["K0m00"], T["K0m00"],
		T["K0m00"], T["K0m00"], T["K0m00"], T["K0m00"], T["K0m00"],
		T["K0m00"], T["K0m00"], T["K0m00"], T["K0m00"], T["K0m00"],
		T["K0m00"], T["K0m00"], T["K0m00"], T["K0m00"], T["K0m00"],
		T["K0m00"], T["K0m00"], T["K0m00"], T["K0m00"], T["K0m00"],
		T["K0m00"], T["K0m00"], T["K0m00"], T["K0m00"], T["K0m00"],
		T["K0m00"], T["K0m00"], T["K0m00"], T["K0m00"], T["K0m00"],
		T["K0m00"], T["K0m00"], T["K0m00"], T["K0m00"], T["K0m00"],
		T["K0m00"], T["K0m00"], T["K0m00"], T["K0m00"], T["K0m00"],
		T["K0m00"], T["K0m00"], T["K0m00"], T["K0m00"], T["K0m00"],
		T["K0m00"], T["K0m00"], T["K0m00"], T["K0m00"], T["K0m00"],
		T["K0m00"], T["_____"], T["K0m00"], T["_____"], T["K0m00"],
		T["TrN00"], T["_____"], T["_____"], T["_____"], T["TrN00"],
		T["_____"], T["_____"], T["_____"], T["_____"], T["_____"],
		T["_____"], T["_____"], T["_____"], T["_____"], T["_____"],
		T["_____"], T["_____"], T["_____"], T["_____"], T["_____"],

		T["K0m00"], T["K0m00"], T["K0m00"], T["K0m00"], T["K0m00"],
		T["K0m00"], T["K0L00"], T["K0S01"], T["_____"], T["K0m00"],
		T["K0m00"], T["_____"], T["_____"], T["K0L00"], T["K0m00"],
		T["K0m00"], T["_____"], T["_____"], T["_____"], T["K0m00"],
		T["K0m00"], T["_____"], T["_____"], T["_____"], T["K0m00"],
		T["K0m00"], T["K0L00"], T["K0S01"], T["_____"], T["K0m00"],
		T["K0m00"], T["_____"], T["_____"], T["K0L00"], T["K0m00"],
		T["K0m00"], T["_____"], T["_____"], T["_____"], T["K0m00"],
		T["K0m00"], T["_____"], T["_____"], T["_____"], T["K0m00"],
		T["K0m00"], T["K0L00"], T["K0S01"], T["_____"], T["K0m00"],
		T["K0m00"], T["_____"], T["_____"], T["K0L00"], T["K0m00"],
		T["K0m00"], T["_____"], T["_____"], T["_____"], T["K0m00"],
		T["K0m00"], T["_____"], T["_____"], T["_____"], T["K0m00"],
		T["K0m00"], T["K0L00"], T["K0L00"], T["K0L00"], T["K0m00"],
		T["_____"], T["_____"], T["_____"], T["_____"], T["_____"],
		T["_____"], T["_____"], T["_____"], T["_____"], T["_____"],
		T["_____"], T["_____"], T["_____"], T["_____"], T["_____"],
		T["_____"], T["_____"], T["_____"], T["_____"], T["_____"],
		T["_____"], T["_____"], T["_____"], T["_____"], T["_____"],

		T["K0m00"], T["K0m00"], T["K0m00"], T["K0m00"], T["K0m00"],
		T["W0DW0"], T["_____"], T["W0n00"], T["Cs0E0"], T["K0m00"],
		T["_____"], T["_____"], T["W0n00"], T["K0S00"], T["K0m00"],
		T["K0m00"], T["_____"], T["W0n00"], T["_____"], T["K0m00"],
		T["K0m00"], T["K0S02"], T["W0n00"], T["_____"], T["K0m00"],
		T["K0m00"], T["_____"], T["W0n00"], T["_____"], T["K0m00"],
		T["K0m00"], T["_____"], T["W0n00"], T["K0S00"], T["K0m00"],
		T["K0m00"], T["_____"], T["W0n00"], T["_____"], T["K0m00"],
		T["K0m00"], T["K0S02"], T["W0n00"], T["_____"], T["K0m00"],
		T["K0m00"], T["_____"], T["W0n00"], T["_____"], T["K0m00"],
		T["K0m00"], T["_____"], T["W0n00"], T["K0S00"], T["K0m00"],
		T["K0m00"], T["_____"], T["W0n00"], T["_____"], T["K0m00"],
		T["K0m00"], T["K0L20"], T["W0n00"], T["_____"], T["K0m00"],
		T["K0m00"], T["_____"], T["K0L00"], T["K0L20"], T["K0m00"],
		T["K0m00"], T["_____"], T["_____"], T["_____"], T["K0m00"],
		T["_____"], T["_____"], T["_____"], T["_____"], T["_____"],
		T["_____"], T["_____"], T["_____"], T["_____"], T["_____"],
		T["_____"], T["_____"], T["_____"], T["_____"], T["_____"],
		T["_____"], T["_____"], T["_____"], T["_____"], T["_____"],

		T["K0m00"], T["K0m00"], T["K0m00"], T["K0m00"], T["K0m00"],
		T["K0m00"], T["Wm0N0"], T["Bb0E0"], T["Bt0E0"], T["K0m00"],
		T["K0m00"], T["_____"], T["_____"], T["_____"], T["K0m00"],
		T["K0m00"], T["TrN00"], T["K0S03"], T["K0L00"], T["K0m00"],
		T["K0m00"], T["K0L00"], T["_____"], T["_____"], T["K0m00"],
		T["K0m00"], T["_____"], T["_____"], T["_____"], T["K0m00"],
		T["K0m00"], T["_____"], T["_____"], T["_____"], T["K0m00"],
		T["K0m00"], T["_____"], T["K0S03"], T["K0L00"], T["K0m00"],
		T["K0m00"], T["K0L00"], T["_____"], T["_____"], T["K0m00"],
		T["K0m00"], T["_____"], T["_____"], T["_____"], T["K0m00"],
		T["K0m00"], T["_____"], T["_____"], T["_____"], T["K0m00"],
		T["K0m00"], T["_____"], T["K0S03"], T["K0L00"], T["K0m00"],
		T["K0m00"], T["K0L00"], T["_____"], T["_____"], T["K0m00"],
		T["K0m00"], T["_____"], T["_____"], T["_____"], T["K0m00"],
		T["_____"], T["_____"], T["_____"], T["_____"], T["_____"],
		T["_____"], T["_____"], T["_____"], T["_____"], T["_____"],
		T["_____"], T["_____"], T["_____"], T["_____"], T["_____"],
		T["_____"], T["_____"], T["_____"], T["_____"], T["_____"],
		T["_____"], T["_____"], T["_____"], T["_____"], T["_____"],

		T["K0m00"], T["K0m00"], T["K0m00"], T["K0m00"], T["K0m00"],
		T["K0m00"], T["K0m00"], T["K0m00"], T["K0m00"], T["K0m00"],
		T["K0m00"], T["K0m00"], T["K0m00"], T["K0m00"], T["K0m00"],
		T["K0m00"], T["K0m00"], T["K0m00"], T["K0m00"], T["K0m00"],
		T["K0m00"], T["K0m00"], T["K0m00"], T["K0m00"], T["K0m00"],
		T["K0m00"], T["K0m00"], T["K0m00"], T["K0m00"], T["K0m00"],
		T["K0m00"], T["K0m00"], T["K0m00"], T["K0m00"], T["K0m00"],
		T["K0m00"], T["K0m00"], T["K0m00"], T["K0m00"], T["K0m00"],
		T["K0m00"], T["K0m00"], T["K0m00"], T["K0m00"], T["K0m00"],
		T["K0m00"], T["K0m00"], T["K0m00"], T["K0m00"], T["K0m00"],
		T["K0m00"], T["K0m00"], T["K0m00"], T["K0m00"], T["K0m00"],
		T["K0m00"], T["K0m00"], T["K0m00"], T["K0m00"], T["K0m00"],
		T["K0m00"], T["K0m00"], T["K0m00"], T["K0m00"], T["K0m00"],
		T["K0m00"], T["K0m00"], T["K0m00"], T["K0m00"], T["K0m00"],
		T["K0m00"], T["_____"], T["K0m00"], T["_____"], T["K0m00"],
		T["TrN00"], T["_____"], T["_____"], T["_____"], T["TrN00"],
		T["_____"], T["_____"], T["_____"], T["_____"], T["_____"],
		T["_____"], T["_____"], T["_____"], T["_____"], T["_____"],
		T["_____"], T["_____"], T["_____"], T["_____"], T["_____"],
	},
	yslice_prob = {
		{ypos = 0,prob = 254},
		{ypos = 1,prob = 254},
		{ypos = 2,prob = 254},
		{ypos = 3,prob = 254},
		{ypos = 4,prob = 254},
		{ypos = 5,prob = 254},
		{ypos = 6,prob = 254},
		{ypos = 7,prob = 254},
		{ypos = 8,prob = 254},
		{ypos = 9,prob = 254},
		{ypos = 10,prob = 254},
		{ypos = 11,prob = 254},
		{ypos = 12,prob = 254},
		{ypos = 13,prob = 254},
		{ypos = 14,prob = 254},
		{ypos = 15,prob = 254},
		{ypos = 16,prob = 254},
		{ypos = 17,prob = 254},
		{ypos = 18,prob = 254}
	}
}