


local T = lib_towns.schems.T

--Air, Lava, and Water constants used throughout schematics
		local __ = T["_____"] or {name = "air", param2 = 0, prob = 0}

		local N9 = T["W0m00"] or {name = "lib_ecology:tree_default_wood", param2 = 0, prob = 254}

		local DD = T["ddddd"] or {name = "lib_materials:dirt", param2 = 0, prob = 254}
		local DG = T["ggggg"] or {name = "lib_materials:dirt_with_grass", param2 = 0, prob = 254}

		local TT = T["TrN00"] or {name = "torch:torch", param2 = 1, prob = 254}
		local T1 = T["TwF00"] or {name = "torch:torch_wall", param2 = 1, prob = 254}
		local T2 = T["TwN00"] or {name = "torch:torch_wall", param2 = 2, prob = 254}
		local T3 = T["TwE00"] or {name = "torch:torch_wall", param2 = 3, prob = 254}
		local T4 = T["TwS00"] or {name = "torch:torch_wall", param2 = 4, prob = 254}
		local T5 = T["TwW00"] or {name = "torch:torch_wall", param2 = 5, prob = 254}

		local R0 = T["Rf0N0"] or {name = "cottages:roof_wood", param2 = 0, prob = 254}
		local R1 = T["Rf0E0"] or {name = "cottages:roof_wood", param2 = 1, prob = 254}
		local R2 = T["Rf0S0"] or {name = "cottages:roof_wood", param2 = 2, prob = 254}
		local R3 = T["Rf0W0"] or {name = "cottages:roof_wood", param2 = 3, prob = 254}
		local R5 = T["Rc0N0"] or {name = "cottages:roof_connector_wood", param2 = 0, prob = 254}
		local R6 = T["Rc0E0"] or {name = "cottages:roof_connector_wood", param2 = 1, prob = 254}
		local R7 = T["Rc0S0"] or {name = "cottages:roof_connector_wood", param2 = 2, prob = 254}
		local R8 = T["Rc0W0"] or {name = "cottages:roof_connector_wood", param2 = 3, prob = 254}

		local II = {name = "lib_ecology:tree_default_wood_fence",param2 = 0,prob = 254}

return {
	yslice_prob = {
		{prob = 254, ypos = 0},
		{prob = 254, ypos = 1},
		{prob = 254, ypos = 2},
		{prob = 254, ypos = 3},
		{prob = 254, ypos = 4},
		{prob = 254, ypos = 5},
		{prob = 254, ypos = 6},
		{prob = 254, ypos = 7},
		{prob = 254, ypos = 8},
		{prob = 254, ypos = 9},
		{prob = 254, ypos = 10},
		{prob = 254, ypos = 11},
		{prob = 254, ypos = 12},
		{prob = 254, ypos = 13},
		{prob = 254, ypos = 14},
		{prob = 254, ypos = 15},
		{prob = 254, ypos = 16},
		{prob = 254, ypos = 17},
		{prob = 254, ypos = 18}
	},
	data = {
		T["ddddd"], T["ddddd"], T["ddddd"], T["ddddd"], T["ddddd"], T["ddddd"], T["ddddd"], T["ddddd"], T["ddddd"], T["ddddd"], T["ddddd"], T["ddddd"], T["ddddd"], T["ddddd"], T["ddddd"], T["ddddd"], T["ddddd"], T["ddddd"], T["ddddd"], T["ddddd"], T["ddddd"], T["ddddd"], T["ddddd"], T["ddddd"], T["ddddd"], T["ddddd"], T["ddddd"], T["ddddd"], T["ddddd"], T["ddddd"], T["ddddd"], T["ddddd"], T["ddddd"], T["ddddd"], T["ddddd"], T["ddddd"], T["ddddd"], T["ddddd"], T["ddddd"], T["ddddd"], T["ddddd"], T["ddddd"], T["ddddd"], T["ddddd"], T["ddddd"], T["ddddd"], T["ddddd"], T["ddddd"], T["ddddd"], T["ddddd"], T["ddddd"], T["ddddd"], T["ddddd"], T["ddddd"], T["ddddd"], T["ddddd"], T["ddddd"], T["ddddd"], T["ddddd"], T["ddddd"], T["ddddd"], T["ddddd"], T["ddddd"], T["ddddd"], T["ddddd"], T["ddddd"], T["ddddd"], T["ddddd"], T["ddddd"], T["ddddd"], T["ddddd"], T["ddddd"], T["ddddd"], T["ddddd"], T["ddddd"], T["ddddd"], T["ddddd"], T["ddddd"], T["ddddd"], T["ddddd"], T["ddddd"], T["ddddd"], T["ddddd"], T["ddddd"], T["ddddd"], T["ddddd"], T["ddddd"], T["ddddd"], T["ddddd"], T["ddddd"], T["ddddd"], T["ddddd"], T["ddddd"], T["ddddd"], T["ddddd"], T["_____"], T["_____"], T["_____"], T["_____"], T["_____"], T["_____"], T["_____"], T["_____"], T["_____"], T["_____"], T["_____"], T["_____"], T["_____"], T["_____"], T["_____"], T["_____"], T["_____"], T["_____"], T["_____"], T["_____"], T["_____"], T["_____"], T["_____"], T["_____"], T["_____"], T["_____"], T["_____"], T["_____"], T["_____"], T["_____"], T["_____"], T["_____"], T["_____"], T["_____"], T["_____"], T["_____"], T["_____"], T["_____"], T["_____"], T["_____"], T["_____"], T["_____"], T["_____"], T["_____"], T["_____"], T["_____"], T["_____"], T["_____"], T["_____"], T["_____"], T["_____"], T["_____"], T["_____"], T["_____"], T["_____"], T["_____"], T["_____"], T["_____"], T["_____"], T["_____"], T["_____"], T["_____"], T["_____"], T["_____"], T["_____"], T["_____"], T["_____"], T["_____"], T["_____"], T["_____"], T["_____"], T["_____"], T["_____"], T["_____"], T["_____"], T["_____"], T["_____"], T["_____"], T["_____"], T["_____"], T["_____"], T["_____"], T["_____"], T["_____"], T["_____"], {param2 = 0, name = "cottages:window_shutter_open", prob = 254},
		T["_____"], T["_____"], T["_____"], T["_____"], T["_____"], T["_____"], T["_____"], T["_____"], T["_____"], T["_____"], T["_____"], T["_____"], T["_____"], T["_____"], T["_____"], {param2 = 1, name = "cottages:roof_black", prob = 254},
		T["W0S20"], T["W0S20"], T["W0S20"], T["W0S20"], T["W0S20"], T["W0S20"], {param2 = 3, name = "cottages:roof_black", prob = 254},
		T["_____"], T["_____"], T["_____"], T["_____"], T["_____"], T["_____"], T["_____"], T["_____"], T["_____"], T["_____"], T["_____"], T["_____"], {param2 = 1, name = "cottages:roof_black", prob = 254},
		T["_____"], T["_____"], T["_____"], T["_____"], {param2 = 3, name = "cottages:roof_black", prob = 254},
		T["_____"], T["_____"], T["_____"], T["_____"], T["_____"], T["_____"], T["_____"], T["_____"], T["_____"], T["_____"], T["_____"], T["_____"], T["_____"], T["_____"], {param2 = 1, name = "cottages:roof_black", prob = 254},
		T["_____"], T["_____"], {param2 = 3, name = "cottages:roof_black", prob = 254},
		T["_____"], T["_____"], T["_____"], T["_____"], T["_____"], T["_____"], T["_____"], T["_____"], T["_____"], T["_____"], T["_____"], T["_____"], T["_____"], T["_____"], T["_____"], T["_____"], {param2 = 1, name = "cottages:roof_black", prob = 254},
		{param2 = 3, name = "cottages:roof_black", prob = 254},
		T["_____"], T["_____"], T["_____"], T["_____"], T["_____"], T["_____"], T["_____"], T["_____"], T["_____"], T["_____"], T["_____"], T["_____"], T["_____"], T["_____"], T["_____"], T["_____"], T["_____"], T["_____"], T["_____"], T["_____"], T["_____"], T["_____"], T["_____"], T["_____"], T["_____"], T["_____"], T["_____"], T["_____"], T["_____"], T["_____"], T["_____"], T["_____"], T["_____"], T["_____"], T["_____"], T["_____"], T["_____"], T["_____"], T["_____"], T["_____"], T["_____"], T["_____"], T["_____"], T["_____"], T["_____"], T["_____"], T["_____"], T["_____"], T["_____"], T["_____"], T["_____"], T["_____"], T["_____"], T["_____"], T["_____"], T["_____"], T["_____"], T["_____"], T["_____"], T["_____"], T["_____"], T["_____"], T["_____"], T["_____"], T["_____"], T["_____"], T["_____"], T["_____"], T["_____"], T["_____"], T["_____"], T["_____"], T["_____"], T["_____"], T["_____"], T["_____"], T["_____"], T["_____"], T["_____"], T["_____"], T["_____"], T["_____"], T["_____"], T["_____"], T["_____"], T["_____"], T["_____"], T["_____"], T["_____"], T["_____"], T["_____"], T["_____"], T["_____"], T["_____"], T["_____"], T["_____"], T["_____"], T["_____"], T["_____"], T["_____"], T["_____"], T["_____"], T["_____"], T["ddddd"], T["ddddd"], T["ddddd"], T["ddddd"], T["ddddd"], T["ddddd"], T["ddddd"], T["ddddd"], T["ddddd"], T["ddddd"], T["ddddd"], T["ddddd"], T["ddddd"], T["ddddd"], T["ddddd"], T["ddddd"], T["ddddd"], T["ddddd"], T["ddddd"], T["ddddd"], T["ddddd"], T["ddddd"], T["ddddd"], T["ddddd"], T["ddddd"], T["ddddd"], T["ddddd"], T["ddddd"], T["ddddd"], T["ddddd"], T["ddddd"], T["ddddd"], T["ddddd"], T["ddddd"], T["ddddd"], T["ddddd"], T["ddddd"], T["ddddd"], T["ddddd"], T["ddddd"], T["ddddd"], T["ddddd"], T["ddddd"], T["ddddd"], T["ddddd"], T["ddddd"], T["ddddd"], T["ddddd"], T["ddddd"], T["ddddd"], T["ddddd"], T["ddddd"], T["ddddd"], T["ddddd"], T["ddddd"], T["ddddd"], T["ddddd"], T["ddddd"], T["ddddd"], T["ddddd"], T["ddddd"], T["ddddd"], T["ddddd"], T["ddddd"], T["ddddd"], T["ddddd"], T["ddddd"], T["ddddd"], T["ddddd"], T["ddddd"], T["ddddd"], T["ddddd"], T["ddddd"], T["ddddd"], T["ddddd"], T["ddddd"], T["sssss"], T["sssss"], T["sssss"], T["sssss"], T["sssss"], T["ddddd"], T["C0m00"], T["C0m00"], T["C0m00"], T["C0m00"], T["C0m00"], T["C0m00"], T["C0m00"], T["ddddd"], T["ddddd"], T["ddddd"], T["ddddd"], T["ddddd"], T["ddddd"], T["_____"], T["_____"], T["_____"], T["_____"], T["_____"], T["_____"], T["_____"], T["T0m00"], T["K0m00"], T["K0m00"], T["K0m00"], T["K0m00"], T["T0m02"], T["_____"], T["_____"], T["_____"], T["_____"], T["_____"], T["_____"], T["_____"], T["_____"], T["_____"], T["_____"], T["_____"], T["_____"], T["_____"], T["T0m00"], T["K0m00"], T["K0m00"], T["K0m00"], T["K0m00"], T["T0m02"], T["_____"], T["_____"], T["_____"], T["_____"], T["_____"], T["_____"], T["_____"], T["_____"], T["_____"], T["_____"], T["_____"], T["_____"], T["_____"], T["T0m00"], T["T0m12"], T["T0m12"], T["T0m12"], T["T0m12"], T["T0m02"], T["_____"], T["_____"], T["_____"], T["_____"], T["_____"], T["_____"], T["_____"], T["_____"], T["_____"], T["_____"], T["_____"], T["_____"], T["_____"], T["T0m00"], T["K0m00"], T["K0m00"], T["K0m00"], T["K0m00"], T["T0m02"], T["_____"], T["_____"], T["_____"], T["_____"], T["_____"], T["_____"], T["_____"], T["_____"], T["_____"], T["_____"], T["_____"], T["_____"], T["_____"], T["T0m00"], T["K0m00"], {param2 = 2, name = "cottages:glass_pane", prob = 254},
		T["K0m00"], T["K0m00"], T["T0m02"], T["_____"], T["_____"], T["_____"], T["_____"], T["_____"], T["_____"], T["_____"], T["_____"], T["_____"], T["_____"], T["_____"], T["_____"], {param2 = 1, name = "cottages:roof_black", prob = 254},
		T["T0m09"], T["T0m12"], T["T0m12"], T["T0m12"], T["T0m12"], T["T0m09"], {param2 = 3, name = "cottages:roof_black", prob = 254},
		T["_____"], T["_____"], T["_____"], T["_____"], T["_____"], T["_____"], T["_____"], T["_____"], T["_____"], T["_____"], T["_____"], T["_____"], T["T0m01"], T["W0m00"], {param2 = 2, name = "lib_ecology:tree_default_wood_door_centered_right", prob = 254},
		{param2 = 2, name = "lib_ecology:tree_default_wood_door_centered", prob = 254},
		T["W0m00"], {param2 = 3, name = "cottages:roof_connector_black", prob = 254},
		T["_____"], T["_____"], T["_____"], T["_____"], T["_____"], T["_____"], T["_____"], T["_____"], T["_____"], T["_____"], T["_____"], T["_____"], T["_____"], T["T0m01"], T["W0m00"], T["_____"],
		T["_____"],
		{param2 = 3, name = "cottages:roof_connector_black", prob = 254},
		T["_____"], T["_____"], T["_____"], T["_____"], T["_____"], T["_____"], T["_____"], T["_____"], T["_____"], T["_____"], T["_____"], T["_____"], T["_____"], {param2 = 1, name = "cottages:roof_flat_black", prob = 254},
		{param2 = 1, name = "cottages:roof_flat_black", prob = 254},
		{param2 = 1, name = "cottages:roof_flat_black", prob = 254},
		{param2 = 1, name = "cottages:roof_connector_black", prob = 254},
		{param2 = 3, name = "cottages:roof_connector_black", prob = 254},
		T["_____"], T["_____"], T["_____"], T["_____"], T["_____"], T["_____"], T["_____"], T["_____"], T["_____"], T["_____"], T["_____"], T["_____"], T["_____"], T["_____"], T["_____"], T["_____"], T["_____"], T["_____"], T["_____"], T["_____"], T["_____"], T["_____"], T["_____"], T["_____"], T["_____"], T["_____"], T["_____"], T["_____"], T["_____"], T["_____"], T["_____"], T["_____"], T["_____"], T["_____"], T["_____"], T["_____"], T["_____"], T["_____"], T["_____"], T["_____"], T["_____"], T["_____"], T["_____"], T["_____"], T["_____"], T["_____"], T["_____"], T["_____"], T["_____"], T["_____"], T["_____"], T["_____"], T["_____"], T["_____"], T["_____"], T["_____"], T["_____"], T["_____"], T["_____"], T["_____"], T["_____"], T["_____"], T["_____"], T["_____"], T["_____"], T["_____"], T["_____"], T["_____"], T["_____"], T["_____"], T["_____"], T["_____"], T["_____"], T["_____"], T["_____"], T["_____"], T["_____"], T["_____"], T["_____"], T["_____"], T["_____"], T["_____"], T["_____"], T["_____"], T["_____"], T["_____"], T["_____"], T["_____"], T["_____"], T["_____"], T["_____"], T["_____"], T["_____"], T["_____"], T["_____"], T["_____"], T["_____"], T["_____"], T["_____"], T["_____"], T["_____"], T["_____"], T["_____"], T["ddddd"], T["ddddd"], T["ddddd"], T["ddddd"], T["ddddd"], T["ddddd"], T["ddddd"], T["ddddd"], T["ddddd"], T["ddddd"], T["ddddd"], T["ddddd"], T["ddddd"], T["ddddd"], T["ddddd"], T["ddddd"], T["ddddd"], T["ddddd"], T["ddddd"], T["ddddd"], T["ddddd"], T["ddddd"], T["ddddd"], T["ddddd"], T["ddddd"], T["ddddd"], T["ddddd"], T["ddddd"], T["ddddd"], T["ddddd"], T["ddddd"], T["ddddd"], T["ddddd"], T["ddddd"], T["ddddd"], T["ddddd"], T["ddddd"], T["ddddd"], T["ddddd"], T["ddddd"], T["ddddd"], T["ddddd"], T["ddddd"], T["ddddd"], T["ddddd"], T["ddddd"], T["ddddd"], T["ddddd"], T["ddddd"], T["ddddd"], T["ddddd"], T["ddddd"], T["ddddd"], T["ddddd"], T["ddddd"], T["ddddd"], T["ddddd"], T["ddddd"], T["ddddd"], T["ddddd"], T["ddddd"], T["ddddd"], T["ddddd"], T["ddddd"], T["ddddd"], T["ddddd"], T["ddddd"], T["ddddd"], T["ddddd"], T["ddddd"], T["ddddd"], T["ddddd"], T["ddddd"], T["ddddd"], T["ddddd"], T["ddddd"], T["sssss"], T["sssss"], T["sssss"], T["sssss"], T["sssss"], T["ddddd"], T["C0m00"], T["C0m00"], T["K0m00"], T["K0m00"], T["K0m00"], T["K0m00"], T["C0m00"], T["ddddd"], T["ddddd"], T["ddddd"], T["ddddd"], T["ddddd"], T["ddddd"], T["W0n00"], T["W0L20"], T["W0n00"], T["W0L20"], T["W0n00"], T["_____"], T["_____"], T["K0m00"], T["Bn0S0"], T["Bn0S0"], T["Bn0S0"], T["Bn0S0"], T["K0m00"], T["_____"], T["_____"], T["P0m00"], T["_____"], T["_____"], T["_____"], T["W0n00"], {param2 = 0, name = "cottages:rope", prob = 254},
		T["W0n00"], {param2 = 0, name = "cottages:rope", prob = 254},
		T["W0n00"], T["_____"], T["_____"], T["K0m00"], T["TwW00"], T["_____"], T["_____"], T["TwW00"], T["K0m00"], T["_____"], T["_____"], T["_____"], T["_____"], T["_____"], T["_____"], T["W0n00"], {param2 = 0, name = "cottages:rope", prob = 254},
		T["W0n00"], {param2 = 0, name = "cottages:rope", prob = 254},
		T["W0n00"], T["_____"], T["_____"], T["T0m09"], T["W0L20"], T["W0L20"], T["W0L20"], T["W0L20"], T["K0m00"], T["_____"], T["_____"], T["_____"], T["_____"], T["_____"], T["_____"], T["W0n00"], T["W0n00"], T["W0n00"], T["W0n00"], T["W0n00"], T["_____"], T["_____"], T["K0m00"], T["_____"], T["_____"], T["_____"], T["_____"], T["K0m00"], T["_____"], T["_____"], T["_____"], T["_____"], T["_____"], T["_____"], T["_____"], T["_____"], T["_____"], T["_____"], T["_____"], T["_____"], T["_____"], T["K0m00"], T["_____"], T["_____"], T["_____"], T["_____"], T["K0m00"], T["_____"], T["_____"], T["_____"], T["_____"], T["_____"], T["_____"], T["_____"], T["_____"], T["_____"], T["_____"], T["_____"], T["_____"], {param2 = 1, name = "cottages:roof_black", prob = 254},
		T["T0m09"], T["W0L20"], T["W0L20"], T["W0L20"], T["W0L20"], T["T0m09"], {param2 = 3, name = "cottages:roof_black", prob = 254},
		T["_____"], T["_____"], T["_____"], T["_____"], T["_____"], T["_____"], T["_____"], T["_____"], T["_____"], T["_____"], T["_____"], T["_____"], {param2 = 12, name = "cottages:wood_flat", prob = 254},
		T["_____"], T["_____"], T["_____"], T["_____"], {param2 = 3, name = "cottages:roof_black", prob = 254},
		T["_____"], T["_____"], T["_____"], T["_____"], T["_____"], T["_____"], T["_____"], T["_____"], T["_____"], T["_____"], T["_____"], T["_____"], {param2 = 1, name = "cottages:window_shutter_open", prob = 254},
		{param2 = 1, name = "cottages:glass_pane_side", prob = 254},
		T["_____"], T["_____"], T["_____"], {param2 = 3, name = "cottages:roof_black", prob = 254},
		T["_____"], T["_____"], T["_____"], T["_____"], T["_____"], T["_____"], T["_____"], T["_____"], T["_____"], T["_____"], T["_____"], T["_____"], T["_____"], {param2 = 1, name = "cottages:roof_flat_black", prob = 254},
		{param2 = 1, name = "cottages:roof_flat_black", prob = 254},
		{param2 = 1, name = "cottages:roof_flat_black", prob = 254},
		{param2 = 1, name = "cottages:roof_black", prob = 254},
		{param2 = 3, name = "cottages:roof_black", prob = 254},
		T["_____"], T["_____"], T["_____"], T["_____"], T["_____"], T["_____"], T["_____"], T["_____"], T["_____"], T["_____"], T["_____"], T["_____"], T["_____"], T["_____"], T["_____"], T["_____"], T["_____"], T["_____"], T["_____"], T["_____"], T["_____"], T["_____"], T["_____"], T["_____"], T["_____"], T["_____"], T["_____"], T["_____"], T["_____"], T["_____"], T["_____"], T["_____"], T["_____"], T["_____"], T["_____"], T["_____"], T["_____"], T["_____"], T["_____"], T["_____"], T["_____"], T["_____"], T["_____"], T["_____"], T["_____"], T["_____"], T["_____"], T["_____"], T["_____"], T["_____"], T["_____"], T["_____"], T["_____"], T["_____"], T["_____"], T["_____"], T["_____"], T["_____"], T["_____"], T["_____"], T["_____"], T["_____"], T["_____"], T["_____"], T["_____"], T["_____"], T["_____"], T["_____"], T["_____"], T["_____"], T["_____"], T["_____"], T["_____"], T["_____"], T["_____"], T["_____"], T["_____"], T["_____"], T["_____"], T["_____"], T["_____"], T["_____"], T["_____"], T["_____"], T["_____"], T["_____"], T["_____"], T["_____"], T["_____"], T["_____"], T["_____"], T["_____"], T["_____"], T["_____"], T["_____"], T["_____"], T["_____"], T["_____"], T["_____"], T["_____"], T["_____"], T["_____"], T["_____"], T["ddddd"], T["ddddd"], T["ddddd"], T["ddddd"], T["ddddd"], T["ddddd"], T["ddddd"], T["ddddd"], T["ddddd"], T["ddddd"], T["ddddd"], T["ddddd"], T["ddddd"], T["ddddd"], T["ddddd"], T["ddddd"], T["ddddd"], T["ddddd"], T["ddddd"], T["ddddd"], T["ddddd"], T["ddddd"], T["ddddd"], T["ddddd"], T["ddddd"], T["ddddd"], T["ddddd"], T["ddddd"], T["ddddd"], T["ddddd"], T["ddddd"], T["ddddd"], T["ddddd"], T["ddddd"], T["ddddd"], T["ddddd"], T["ddddd"], T["ddddd"], T["ddddd"], T["ddddd"], T["ddddd"], T["ddddd"], T["ddddd"], T["ddddd"], T["ddddd"], T["ddddd"], T["ddddd"], T["ddddd"], T["ddddd"], T["ddddd"], T["ddddd"], T["ddddd"], T["ddddd"], T["ddddd"], T["ddddd"], T["ddddd"], T["ddddd"], T["ddddd"], T["ddddd"], T["ddddd"], T["ddddd"], T["ddddd"], T["ddddd"], T["ddddd"], T["ddddd"], T["ddddd"], T["ddddd"], T["ddddd"], T["ddddd"], T["ddddd"], T["ddddd"], T["ddddd"], T["ddddd"], T["ddddd"], T["ddddd"], T["ddddd"], T["sssss"], T["sssss"], T["sssss"], T["sssss"], T["sssss"], T["ddddd"], T["C0m00"], T["C0m00"], T["K0m00"], T["K0m00"], T["K0m00"], T["K0m00"], T["C0m00"], T["ddddd"], T["ddddd"], T["ddddd"], T["ddddd"], T["ddddd"], T["ddddd"], T["_____"], T["_____"], T["_____"], T["_____"], T["_____"], T["_____"], T["_____"], T["K0m00"], T["Bn0W0"], {param2 = 2, name = "cottages:table", prob = 254},
		{param2 = 2, name = "cottages:table", prob = 254},
		T["Bn0E0"], T["K0m00"], T["_____"], T["_____"], T["_____"], T["_____"], T["_____"], T["_____"], T["_____"], T["_____"], T["_____"], T["_____"], T["_____"], T["_____"], {param2 = 1, name = "cottages:window_shutter_open", prob = 254},
		{param2 = 1, name = "cottages:glass_pane", prob = 254},
		T["_____"], T["_____"], T["_____"], T["_____"], {param2 = 3, name = "cottages:glass_pane", prob = 254},
		{param2 = 3, name = "cottages:window_shutter_open", prob = 254},
		T["_____"], T["_____"], T["_____"], T["_____"], T["_____"], T["_____"], T["_____"], T["_____"], T["_____"], T["_____"], T["_____"], T["_____"], T["T0m09"], T["W0L20"], T["W0L20"], T["W0L20"], T["W0L20"], T["K0m00"], T["_____"], T["_____"], T["_____"], T["_____"], T["_____"], T["_____"], T["_____"], T["_____"], T["_____"], T["_____"], T["_____"], T["_____"], T["_____"], T["K0m00"], T["_____"], {param2 = 0, name = "beds:fancy_bed_bottom", prob = 254},
		{param2 = 0, name = "beds:fancy_bed_bottom", prob = 254},
		T["_____"], T["K0m00"], T["_____"], T["_____"], T["_____"], T["_____"], T["_____"], T["_____"], T["_____"], T["_____"], T["_____"], T["_____"], T["_____"], T["_____"], {param2 = 1, name = "cottages:window_shutter_open", prob = 254},
		{param2 = 3, name = "cottages:glass_pane", prob = 254},
		T["_____"], T["_____"], T["_____"], T["_____"], T["K0m00"], T["_____"], T["_____"], T["_____"], T["_____"], T["_____"], T["_____"], T["_____"], T["_____"], T["_____"], T["_____"], T["_____"], T["_____"], {param2 = 1, name = "cottages:roof_black", prob = 254},
		T["T0m09"], T["W0L20"], T["W0L20"], T["W0L20"], T["W0L20"], T["T0m09"], {param2 = 3, name = "cottages:roof_black", prob = 254},
		T["_____"], T["_____"], T["_____"], T["_____"], T["_____"], T["_____"], T["_____"], T["_____"], T["_____"], T["_____"], T["_____"], T["_____"], T["T0m03"], T["_____"], {param2 = 1, name = "beds:fancy_bed_bottom", prob = 254},
		{param2 = 1, name = "beds:fancy_bed_top", prob = 254},
		T["Cs0N0"], {param2 = 3, name = "cottages:roof_black", prob = 254},
		T["_____"], T["_____"], T["_____"], T["_____"], T["_____"], T["_____"], T["_____"], T["_____"], T["_____"], T["_____"], T["_____"], T["_____"], T["_____"], T["T0m03"], T["_____"], T["_____"], T["_____"], {param2 = 3, name = "cottages:roof_black", prob = 254},
		T["_____"], T["_____"], T["_____"], T["_____"], T["_____"], T["_____"], T["_____"], T["_____"], T["_____"], T["_____"], T["_____"], T["_____"], T["_____"], {param2 = 1, name = "cottages:roof_flat_black", prob = 254},
		{param2 = 1, name = "cottages:roof_flat_black", prob = 254},
		{param2 = 1, name = "cottages:roof_flat_black", prob = 254},
		{param2 = 1, name = "cottages:roof_black", prob = 254},
		{param2 = 3, name = "cottages:roof_black", prob = 254},
		T["_____"], T["_____"], T["_____"], T["_____"], T["_____"], T["_____"], T["_____"], T["_____"], T["_____"], T["_____"], T["_____"], T["_____"], T["_____"], T["_____"], T["_____"], T["_____"], T["_____"], T["_____"], T["_____"], T["_____"], T["_____"], T["_____"], T["_____"], T["_____"], T["_____"], T["_____"], T["_____"], T["_____"], T["_____"], T["_____"], T["_____"], T["_____"], T["_____"], T["_____"], T["_____"], T["_____"], T["_____"], T["_____"], T["_____"], T["_____"], T["_____"], T["_____"], T["_____"], T["_____"], T["_____"], T["_____"], T["_____"], T["_____"], T["_____"], T["_____"], T["_____"], T["_____"], T["_____"], T["_____"], T["_____"], T["_____"], T["_____"], T["_____"], T["_____"], T["_____"], T["_____"], T["_____"], T["_____"], T["_____"], T["_____"], T["_____"], T["_____"], T["_____"], T["_____"], T["_____"], T["_____"], T["_____"], T["_____"], T["_____"], T["_____"], T["_____"], T["_____"], T["_____"], T["_____"], T["_____"], T["_____"], T["_____"], T["_____"], T["_____"], T["_____"], T["_____"], T["_____"], T["_____"], T["_____"], T["_____"], T["_____"], T["_____"], T["_____"], T["_____"], T["_____"], T["_____"], T["_____"], T["_____"], T["_____"], T["_____"], T["_____"], T["_____"], T["_____"], T["ddddd"], T["ddddd"], T["ddddd"], T["ddddd"], T["ddddd"], T["ddddd"], T["ddddd"], T["ddddd"], T["ddddd"], T["ddddd"], T["ddddd"], T["ddddd"], T["ddddd"], T["ddddd"], T["ddddd"], T["ddddd"], T["ddddd"], T["ddddd"], T["ddddd"], T["ddddd"], T["ddddd"], T["ddddd"], T["ddddd"], T["ddddd"], T["ddddd"], T["ddddd"], T["ddddd"], T["ddddd"], T["ddddd"], T["ddddd"], T["ddddd"], T["ddddd"], T["ddddd"], T["ddddd"], T["ddddd"], T["ddddd"], T["ddddd"], T["ddddd"], T["ddddd"], T["ddddd"], T["ddddd"], T["ddddd"], T["ddddd"], T["ddddd"], T["ddddd"], T["ddddd"], T["ddddd"], T["ddddd"], T["ddddd"], T["ddddd"], T["ddddd"], T["ddddd"], T["ddddd"], T["ddddd"], T["ddddd"], T["ddddd"], T["ddddd"], T["ddddd"], T["ddddd"], T["ddddd"], T["ddddd"], T["ddddd"], T["ddddd"], T["ddddd"], T["ddddd"], T["ddddd"], T["ddddd"], T["ddddd"], T["ddddd"], T["ddddd"], T["ddddd"], T["ddddd"], T["ddddd"], T["ddddd"], T["ddddd"], T["ddddd"], T["sssss"], T["sssss"], T["C0m00"], T["C0m00"], T["C0m00"], T["C0m00"], T["C0m00"], T["C0m00"], T["K0m00"], T["K0m00"], T["K0m00"], T["K0m00"], T["C0m00"], T["ddddd"], T["ddddd"], T["ddddd"], T["ddddd"], T["ddddd"], T["ddddd"], T["_____"], T["_____"], T["_____"], T["_____"], T["_____"], T["_____"], T["_____"], T["K0m00"], T["_____"], T["Bn0S0"], T["Bn0S0"], T["_____"], T["K0m00"], T["_____"], T["_____"], T["_____"], T["_____"], T["_____"], T["_____"], T["_____"], T["_____"], T["_____"], T["_____"], T["_____"], T["_____"], T["_____"], T["K0m00"], T["_____"], T["_____"], T["_____"], T["_____"], T["K0m00"], T["_____"], T["_____"], T["_____"], T["_____"], T["_____"], T["_____"], T["_____"], T["_____"], T["_____"], T["_____"], T["_____"], T["_____"], T["_____"], T["T0m09"], T["W0L20"], T["W0L20"], T["W0L20"], T["W0L20"], T["K0m00"], T["_____"], T["_____"], T["_____"], T["_____"], T["_____"], T["_____"], T["_____"], T["_____"], T["_____"], T["_____"], T["_____"], T["_____"], T["_____"], T["K0m00"], T["_____"], {param2 = 0, name = "beds:fancy_bed_top", prob = 254},
		{param2 = 0, name = "beds:fancy_bed_top", prob = 254},
		T["_____"], T["K0m00"], T["_____"], T["_____"], T["_____"], T["_____"], T["_____"], T["_____"], T["_____"], T["_____"], T["_____"], T["_____"], T["_____"], T["_____"], T["_____"], T["K0m00"], T["TwS00"], T["_____"], T["_____"], T["_____"], T["K0m00"], T["_____"], T["_____"], T["_____"], T["_____"], T["_____"], T["_____"], T["_____"], T["_____"], T["_____"], T["_____"], T["_____"], T["_____"], {param2 = 1, name = "cottages:roof_black", prob = 254},
		T["T0m09"], T["W0L20"], T["W0L20"], T["W0L20"], T["W0L20"], T["T0m09"], {param2 = 3, name = "cottages:roof_black", prob = 254},
		T["_____"], T["_____"], T["_____"], T["_____"], T["_____"], T["_____"], T["_____"], T["_____"], T["_____"], T["_____"], T["_____"], T["_____"], {param2 = 12, name = "cottages:wood_flat", prob = 254},
		T["_____"], {param2 = 1, name = "beds:fancy_bed_bottom", prob = 254},
		{param2 = 1, name = "beds:fancy_bed_top", prob = 254},
		T["Cs0S0"], {param2 = 3, name = "cottages:roof_black", prob = 254},
		T["_____"], T["_____"], T["_____"], T["_____"], T["_____"], T["_____"], T["_____"], T["_____"], T["_____"], T["_____"], T["_____"], T["_____"], {param2 = 1, name = "cottages:window_shutter_open", prob = 254},
		{param2 = 1, name = "cottages:glass_pane_side", prob = 254},
		T["_____"], T["_____"], T["_____"], {param2 = 3, name = "cottages:roof_black", prob = 254},
		T["_____"], T["_____"], T["_____"], T["_____"], T["_____"], T["_____"], T["_____"], T["_____"], T["_____"], T["_____"], T["_____"], T["_____"], T["_____"], {param2 = 1, name = "cottages:roof_flat_black", prob = 254},
		{param2 = 1, name = "cottages:roof_flat_black", prob = 254},
		{param2 = 1, name = "cottages:roof_flat_black", prob = 254},
		{param2 = 1, name = "cottages:roof_black", prob = 254},
		{param2 = 3, name = "cottages:roof_black", prob = 254},
		T["_____"], T["_____"], T["_____"], T["_____"], T["_____"], T["_____"], T["_____"], T["_____"], T["_____"], T["_____"], T["_____"], T["_____"], T["_____"], T["_____"], T["_____"], T["_____"], T["_____"], T["_____"], T["_____"], T["_____"], T["_____"], T["_____"], T["_____"], T["_____"], T["_____"], T["_____"], T["_____"], T["_____"], T["_____"], T["_____"], T["_____"], T["_____"], T["_____"], T["_____"], T["_____"], T["_____"], T["_____"], T["_____"], T["_____"], T["_____"], T["_____"], T["_____"], T["_____"], T["_____"], T["_____"], T["_____"], T["_____"], T["_____"], T["_____"], T["_____"], T["_____"], T["_____"], T["_____"], T["_____"], T["_____"], T["_____"], T["_____"], T["_____"], T["_____"], T["_____"], T["_____"], T["_____"], T["_____"], T["_____"], T["_____"], T["_____"], T["_____"], T["_____"], T["_____"], T["_____"], T["_____"], T["_____"], T["_____"], T["_____"], T["_____"], T["_____"], T["_____"], T["_____"], T["_____"], T["_____"], T["_____"], T["_____"], T["_____"], T["_____"], T["_____"], T["_____"], T["_____"], T["_____"], T["_____"], T["_____"], T["_____"], T["_____"], T["_____"], T["_____"], T["_____"], T["_____"], T["_____"], T["_____"], T["_____"], T["_____"], T["_____"], T["_____"], T["_____"], T["ddddd"], T["ddddd"], T["ddddd"], T["ddddd"], T["ddddd"], T["ddddd"], T["ddddd"], T["ddddd"], T["ddddd"], T["ddddd"], T["ddddd"], T["ddddd"], T["ddddd"], T["ddddd"], T["ddddd"], T["ddddd"], T["ddddd"], T["ddddd"], T["ddddd"], T["ddddd"], T["ddddd"], T["ddddd"], T["ddddd"], T["ddddd"], T["ddddd"], T["ddddd"], T["ddddd"], T["ddddd"], T["ddddd"], T["ddddd"], T["ddddd"], T["ddddd"], T["ddddd"], T["ddddd"], T["ddddd"], T["ddddd"], T["ddddd"], T["ddddd"], T["ddddd"], T["ddddd"], T["ddddd"], T["ddddd"], T["ddddd"], T["ddddd"], T["ddddd"], T["ddddd"], T["ddddd"], T["ddddd"], T["ddddd"], T["ddddd"], T["ddddd"], T["ddddd"], T["ddddd"], T["ddddd"], T["ddddd"], T["ddddd"], T["ddddd"], T["ddddd"], T["ddddd"], T["ddddd"], T["ddddd"], T["ddddd"], T["ddddd"], T["ddddd"], T["ddddd"], T["ddddd"], T["ddddd"], T["ddddd"], T["ddddd"], T["ddddd"], T["ddddd"], T["ddddd"], T["ddddd"], T["ddddd"], T["ddddd"], T["ddddd"], T["sssss"], T["sssss"], T["C0m00"], T["C0m00"], T["C0m00"], T["C0m00"], T["C0m00"], T["C0m00"], T["K0m00"], T["K0m00"], T["K0m00"], T["K0m00"], T["C0m00"], T["ddddd"], T["ddddd"], T["ddddd"], T["ddddd"], T["ddddd"], T["ddddd"], T["_____"], T["_____"], T["_____"], T["_____"], T["_____"], T["_____"], T["_____"], T["T0m00"], T["_____"], T["Bn0E0"], {param2 = 1, name = "cottages:table", prob = 254},
		T["Bn0E0"], T["T0m02"], T["_____"], T["_____"], T["_____"], T["_____"], T["_____"], T["_____"], T["_____"], T["_____"], T["_____"], T["_____"], T["_____"], T["_____"], T["_____"], T["T0m00"], T["_____"], T["_____"], T["_____"], T["_____"], T["T0m02"], T["_____"], T["_____"], T["_____"], T["_____"], T["_____"], T["_____"], T["_____"], T["_____"], T["_____"], T["_____"], T["_____"], T["_____"], T["_____"], T["T0m00"], T["T0m12"], T["T0m12"], T["T0m12"], T["T0m12"], T["T0m02"], T["_____"], T["_____"], T["_____"], T["_____"], T["_____"], T["_____"], T["_____"], T["_____"], T["_____"], T["_____"], T["_____"], T["_____"], T["_____"], T["T0m00"], T["W0m00"], T["W0m00"], T["W0m00"], {param2 = 2, name = "lib_ecology:tree_default_wood_door_centered", prob = 254},
		T["T0m02"], T["_____"], T["_____"], T["_____"], T["_____"], T["_____"], T["_____"], T["_____"], T["_____"], T["_____"], T["_____"], T["_____"], T["_____"], T["_____"], T["T0m00"], T["W0m00"], T["W0m00"], T["W0m00"], T["_____"],
		T["T0m02"], T["_____"], T["_____"], T["_____"], T["_____"], T["_____"], T["_____"], T["_____"], T["_____"], T["_____"], T["_____"], T["_____"], T["_____"], {param2 = 1, name = "cottages:roof_black", prob = 254},
		T["T0m09"], T["T0m12"], T["T0m12"], T["T0m12"], T["T0m12"], T["T0m09"], {param2 = 3, name = "cottages:roof_black", prob = 254},
		T["_____"], T["_____"], T["_____"], T["_____"], T["_____"], T["_____"], T["_____"], T["_____"], T["_____"], T["_____"], T["_____"], T["_____"], T["T0m01"], T["_____"], T["_____"], T["_____"], T["_____"], {param2 = 3, name = "cottages:roof_black", prob = 254},
		T["_____"], T["_____"], T["_____"], T["_____"], T["_____"], T["_____"], T["_____"], T["_____"], T["_____"], T["_____"], T["_____"], T["_____"], T["_____"], T["T0m01"], T["_____"], T["_____"], T["_____"], {param2 = 3, name = "cottages:roof_black", prob = 254},
		T["_____"], T["_____"], T["_____"], T["_____"], T["_____"], T["_____"], T["_____"], T["_____"], T["_____"], T["_____"], T["_____"], T["_____"], T["_____"], {param2 = 0, name = "cottages:roof_flat_black", prob = 254},
		{param2 = 0, name = "cottages:roof_flat_black", prob = 254},
		{param2 = 1, name = "cottages:roof_flat_black", prob = 254},
		{param2 = 1, name = "cottages:roof_black", prob = 254},
		{param2 = 3, name = "cottages:roof_black", prob = 254},
		T["_____"], T["_____"], T["_____"], T["_____"], T["_____"], T["_____"], T["_____"], T["_____"], T["_____"], T["_____"], T["_____"], T["_____"], T["_____"], T["_____"], T["_____"], T["_____"], T["_____"], T["_____"], T["_____"], T["_____"], T["_____"], T["_____"], T["_____"], T["_____"], T["_____"], T["_____"], T["_____"], T["_____"], T["_____"], T["_____"], T["_____"], T["_____"], T["_____"], T["_____"], T["_____"], T["_____"], T["_____"], T["_____"], T["_____"], T["_____"], T["_____"], T["_____"], T["_____"], T["_____"], T["_____"], T["_____"], T["_____"], T["_____"], T["_____"], T["_____"], T["_____"], T["_____"], T["_____"], T["_____"], T["_____"], T["_____"], T["_____"], T["_____"], T["_____"], T["_____"], T["_____"], T["_____"], T["_____"], T["_____"], T["_____"], T["_____"], T["_____"], T["_____"], T["_____"], T["_____"], T["_____"], T["_____"], T["_____"], T["_____"], T["_____"], T["_____"], T["_____"], T["_____"], T["_____"], T["_____"], T["_____"], T["_____"], T["_____"], T["_____"], T["_____"], T["_____"], T["_____"], T["_____"], T["_____"], T["_____"], T["_____"], T["_____"], T["_____"], T["_____"], T["_____"], T["_____"], T["_____"], T["_____"], T["_____"], T["_____"], T["_____"], T["_____"], T["_____"], T["ddddd"], T["ddddd"], T["ddddd"], T["ddddd"], T["ddddd"], T["ddddd"], T["ddddd"], T["ddddd"], T["ddddd"], T["ddddd"], T["ddddd"], T["ddddd"], T["ddddd"], T["ddddd"], T["ddddd"], T["ddddd"], T["ddddd"], T["ddddd"], T["ddddd"], T["ddddd"], T["ddddd"], T["ddddd"], T["ddddd"], T["ddddd"], T["ddddd"], T["ddddd"], T["ddddd"], T["ddddd"], T["ddddd"], T["ddddd"], T["ddddd"], T["ddddd"], T["ddddd"], T["ddddd"], T["ddddd"], T["ddddd"], T["ddddd"], T["ddddd"], T["ddddd"], T["ddddd"], T["ddddd"], T["ddddd"], T["ddddd"], T["ddddd"], T["ddddd"], T["ddddd"], T["ddddd"], T["ddddd"], T["ddddd"], T["ddddd"], T["ddddd"], T["ddddd"], T["ddddd"], T["ddddd"], T["ddddd"], T["ddddd"], T["ddddd"], T["ddddd"], T["ddddd"], T["ddddd"], T["ddddd"], T["ddddd"], T["ddddd"], T["ddddd"], T["ddddd"], T["ddddd"], T["ddddd"], T["ddddd"], T["ddddd"], T["ddddd"], T["ddddd"], T["ddddd"], T["ddddd"], T["ddddd"], T["ddddd"], T["ddddd"], T["ddddd"], T["C0m00"], T["C0m00"], T["C0m00"], T["C0m00"], T["C0m00"], T["C0m00"], T["C0m00"], T["K0m00"], T["K0m00"], T["K0m00"], T["K0m00"], T["C0m00"], T["ddddd"], T["ddddd"], T["ddddd"], T["ddddd"], T["ddddd"], T["ddddd"], T["_____"], T["_____"], T["_____"], T["_____"], T["_____"], T["_____"], T["_____"], T["K0m00"], {param2 = 2, name = "lib_ecology:tree_default_wood_door_centered_right", prob = 254},
		T["Bn0E0"], {param2 = 1, name = "cottages:table", prob = 254},
		T["Bn0E0"], T["K0m00"], T["_____"], T["_____"], T["_____"], T["P0m00"], T["_____"], T["_____"], T["_____"], T["_____"], T["_____"], T["_____"], T["_____"], T["_____"], T["_____"], T["K0m00"], T["_____"],
		T["_____"], T["_____"], T["_____"], T["K0m00"], T["_____"], T["_____"], T["_____"], T["_____"], T["_____"], T["_____"], T["_____"], T["_____"], T["_____"], T["_____"], T["_____"], T["_____"], T["TwN00"], T["T0m09"], T["W0L20"], T["W0L20"], T["W0L20"], T["W0L20"], T["K0m00"], T["_____"], T["_____"], T["_____"], T["_____"], T["_____"], T["_____"], T["_____"], T["_____"], T["_____"], T["_____"], T["_____"], T["_____"], T["_____"], T["K0m00"], T["_____"], T["_____"], {param2 = 3, name = "lib_ecology:tree_default_wood_door_centered", prob = 254},
		T["_____"], T["K0m00"], T["_____"], T["_____"], T["_____"], T["_____"], T["_____"], T["_____"], T["_____"], T["_____"], T["_____"], T["_____"], T["_____"], T["_____"], T["_____"], T["K0m00"], T["TwE00"], T["_____"], T["_____"],
		T["_____"], {param2 = 1, name = "cottages:glass_pane", prob = 254},
		{param2 = 3, name = "cottages:window_shutter_open", prob = 254},
		T["_____"], T["_____"], T["_____"], T["_____"], T["_____"], T["_____"], T["_____"], T["_____"], T["_____"], T["_____"], T["_____"], {param2 = 1, name = "cottages:roof_black", prob = 254},
		T["T0m09"], T["W0L20"], T["W0L20"], T["T0m09"], T["W0L20"], T["T0m09"], {param2 = 3, name = "cottages:roof_black", prob = 254},
		T["_____"], T["_____"], T["_____"], T["_____"], T["_____"], T["_____"], T["_____"], T["_____"], T["_____"], T["_____"], T["_____"], T["_____"], {param2 = 1, name = "cottages:roof_black", prob = 254},
		T["T0m01"], T["_____"], T["_____"], T["_____"], {param2 = 3, name = "cottages:roof_black", prob = 254},
		T["_____"], T["_____"], T["_____"], T["_____"], T["_____"], T["_____"], T["_____"], T["_____"], T["_____"], T["_____"], T["_____"], T["_____"], T["_____"], T["_____"], T["T0m01"], T["TwE00"], T["_____"], {param2 = 3, name = "cottages:roof_black", prob = 254},
		T["_____"], T["_____"], T["_____"], T["_____"], T["_____"], T["_____"], T["_____"], T["_____"], T["_____"], T["_____"], T["_____"], T["_____"], T["_____"], T["_____"], T["_____"], {param2 = 1, name = "cottages:roof_flat_black", prob = 254},
		{param2 = 1, name = "cottages:roof_black", prob = 254},
		{param2 = 3, name = "cottages:roof_black", prob = 254},
		T["_____"], T["_____"], T["_____"], T["_____"], T["_____"], T["_____"], T["_____"], T["_____"], T["_____"], T["_____"], T["_____"], T["_____"], T["_____"], T["_____"], T["_____"], T["_____"], T["_____"], T["_____"], T["_____"], T["_____"], T["_____"], T["_____"], T["_____"], T["_____"], T["_____"], T["_____"], T["_____"], T["_____"], T["_____"], T["_____"], T["_____"], T["_____"], T["_____"], T["_____"], T["_____"], T["_____"], T["_____"], T["_____"], T["_____"], T["_____"], T["_____"], T["_____"], T["_____"], T["_____"], T["_____"], T["_____"], T["_____"], T["_____"], T["_____"], T["_____"], T["_____"], T["_____"], T["_____"], T["_____"], T["_____"], T["_____"], T["_____"], T["_____"], T["_____"], T["_____"], T["_____"], T["_____"], T["_____"], T["_____"], T["_____"], T["_____"], T["_____"], T["_____"], T["_____"], T["_____"], T["_____"], T["_____"], T["_____"], T["_____"], T["_____"], T["_____"], T["_____"], T["_____"], T["_____"], T["_____"], T["_____"], T["_____"], T["_____"], T["_____"], T["_____"], T["_____"], T["_____"], T["_____"], T["_____"], T["_____"], T["_____"], T["_____"], T["_____"], T["_____"], T["_____"], T["_____"], T["_____"], T["_____"], T["_____"], T["_____"], T["_____"], T["_____"], T["_____"], T["ddddd"], T["ddddd"], T["ddddd"], T["ddddd"], T["ddddd"], T["ddddd"], T["ddddd"], T["ddddd"], T["ddddd"], T["ddddd"], T["ddddd"], T["ddddd"], T["ddddd"], T["ddddd"], T["ddddd"], T["ddddd"], T["ddddd"], T["ddddd"], T["ddddd"], T["ddddd"], T["ddddd"], T["ddddd"], T["ddddd"], T["ddddd"], T["ddddd"], T["ddddd"], T["ddddd"], T["ddddd"], T["ddddd"], T["ddddd"], T["ddddd"], T["ddddd"], T["ddddd"], T["ddddd"], T["ddddd"], T["ddddd"], T["ddddd"], T["ddddd"], T["ddddd"], T["ddddd"], T["ddddd"], T["ddddd"], T["ddddd"], T["ddddd"], T["ddddd"], T["ddddd"], T["ddddd"], T["ddddd"], T["ddddd"], T["ddddd"], T["ddddd"], T["ddddd"], T["ddddd"], T["ddddd"], T["ddddd"], T["ddddd"], T["ddddd"], T["ddddd"], T["ddddd"], T["ddddd"], T["ddddd"], T["ddddd"], T["ddddd"], T["ddddd"], T["ddddd"], T["ddddd"], T["ddddd"], T["ddddd"], T["ddddd"], T["ddddd"], T["ddddd"], T["ddddd"], T["ddddd"], T["ddddd"], T["ddddd"], T["ddddd"], T["C0m00"], T["C0m00"], T["C0m00"], T["C0m00"], T["C0m00"], T["C0m00"], T["C0m00"], T["C0m00"], T["K0m00"], T["K0m00"], T["K0m00"], T["K0m00"], T["C0m00"], T["ddddd"], T["ddddd"], T["ddddd"], T["ddddd"], T["ddddd"], T["ddddd"], T["_____"], T["_____"], T["_____"], T["_____"], T["_____"], T["_____"], T["_____"], {param2 = 3, name = "lib_ecology:tree_default_wood_door_centered", prob = 254},
		T["_____"], T["W0m00"], T["Bn0N0"], T["Bn0E0"], T["K0m00"], T["_____"], T["_____"], T["_____"], T["_____"], T["_____"], T["_____"], T["_____"], T["_____"], T["_____"], T["_____"], T["_____"], T["_____"], T["_____"], T["_____"],
		T["_____"], T["W0m00"], {param2 = 2, name = "cottages:glass_pane_side", prob = 254},
		{param2 = 2, name = "cottages:glass_pane_side", prob = 254},
		{param2 = 1, name = "cottages:glass_pane", prob = 254},
		{param2 = 3, name = "cottages:window_shutter_open", prob = 254},
		T["_____"], T["_____"], T["_____"], T["_____"], T["_____"], T["_____"], T["_____"], T["_____"], T["_____"], T["_____"], T["_____"], {param2 = 1, name = "cottages:roof_black", prob = 254},
		T["T0m09"], T["W0L20"], T["W0m00"], T["W0m00"], T["W0S02"], T["K0m00"], T["_____"], T["_____"], T["_____"], T["_____"], T["_____"], T["_____"], T["_____"], T["_____"], T["_____"], T["_____"], T["_____"], T["_____"], T["_____"], T["K0m00"], {param2 = 1, name = "beds:fancy_bed_bottom", prob = 254},
		{param2 = 1, name = "beds:fancy_bed_top", prob = 254},
		T["W0m00"], T["_____"], T["K0m00"], T["_____"], T["_____"], T["_____"], T["_____"], T["_____"], T["_____"], T["_____"], T["_____"], T["_____"], T["_____"], T["_____"], T["_____"], {param2 = 1, name = "cottages:window_shutter_open", prob = 254},
		{param2 = 3, name = "cottages:glass_pane", prob = 254},
		T["_____"], T["_____"], T["W0m00"], T["_____"], T["K0m00"], T["_____"], T["_____"], T["_____"], T["_____"], T["_____"], T["_____"], T["_____"], T["_____"], T["_____"], T["_____"], T["_____"], T["_____"], {param2 = 1, name = "cottages:roof_black", prob = 254},
		T["T0m09"], T["W0L20"], T["W0L20"], T["T0m09"], T["W0L20"], T["T0m09"], {param2 = 3, name = "cottages:roof_black", prob = 254},
		T["_____"], T["_____"], T["_____"], T["_____"], T["_____"], T["_____"], T["_____"], T["_____"], T["_____"], T["_____"], T["_____"], T["_____"], {param2 = 1, name = "cottages:roof_black", prob = 254},
		T["_____"], T["_____"], T["_____"], T["_____"], {param2 = 3, name = "cottages:roof_black", prob = 254},
		T["_____"], T["_____"], T["_____"], T["_____"], T["_____"], T["_____"], T["_____"], T["_____"], T["_____"], T["_____"], T["_____"], T["_____"], T["_____"], {param2 = 1, name = "cottages:window_shutter_open", prob = 254},
		{param2 = 1, name = "cottages:glass_pane_side", prob = 254},
		T["_____"], T["_____"], {param2 = 3, name = "cottages:roof_black", prob = 254},
		T["_____"], T["_____"], T["_____"], T["_____"], T["_____"], T["_____"], T["_____"], T["_____"], T["_____"], T["_____"], T["_____"], T["_____"], T["_____"], T["_____"], T["_____"], {param2 = 1, name = "cottages:roof_flat_black", prob = 254},
		{param2 = 1, name = "cottages:roof_black", prob = 254},
		{param2 = 3, name = "cottages:roof_black", prob = 254},
		T["_____"], T["_____"], T["_____"], T["_____"], T["_____"], T["_____"], T["_____"], T["_____"], T["_____"], T["_____"], T["_____"], T["_____"], T["_____"], T["_____"], T["_____"], T["_____"], T["_____"], T["_____"], T["_____"], T["_____"], T["_____"], T["_____"], T["_____"], T["_____"], T["_____"], T["_____"], T["_____"], T["_____"], T["_____"], T["_____"], T["_____"], T["_____"], T["_____"], T["_____"], T["_____"], T["_____"], T["_____"], T["_____"], T["_____"], T["_____"], T["_____"], T["_____"], T["_____"], T["_____"], T["_____"], T["_____"], T["_____"], T["_____"], T["_____"], T["_____"], T["_____"], T["_____"], T["_____"], T["_____"], T["_____"], T["_____"], T["_____"], T["_____"], T["_____"], T["_____"], T["_____"], T["_____"], T["_____"], T["_____"], T["_____"], T["_____"], T["_____"], T["_____"], T["_____"], T["_____"], T["_____"], T["_____"], T["_____"], T["_____"], T["_____"], T["_____"], T["_____"], T["_____"], T["_____"], T["_____"], T["_____"], T["_____"], T["_____"], T["_____"], T["_____"], T["_____"], T["_____"], T["_____"], T["_____"], T["_____"], T["_____"], T["_____"], T["_____"], T["_____"], T["_____"], T["_____"], T["_____"], T["_____"], T["_____"], T["_____"], T["_____"], T["_____"], T["_____"], T["ddddd"], T["ddddd"], T["ddddd"], T["ddddd"], T["ddddd"], T["ddddd"], T["ddddd"], T["ddddd"], T["ddddd"], T["ddddd"], T["ddddd"], T["ddddd"], T["ddddd"], T["ddddd"], T["ddddd"], T["ddddd"], T["ddddd"], T["ddddd"], T["ddddd"], T["ddddd"], T["ddddd"], T["ddddd"], T["ddddd"], T["ddddd"], T["ddddd"], T["ddddd"], T["ddddd"], T["ddddd"], T["ddddd"], T["ddddd"], T["ddddd"], T["ddddd"], T["ddddd"], T["ddddd"], T["ddddd"], T["ddddd"], T["ddddd"], T["ddddd"], T["ddddd"], T["ddddd"], T["ddddd"], T["ddddd"], T["ddddd"], T["ddddd"], T["ddddd"], T["ddddd"], T["ddddd"], T["ddddd"], T["ddddd"], T["ddddd"], T["ddddd"], T["ddddd"], T["ddddd"], T["ddddd"], T["ddddd"], T["ddddd"], T["ddddd"], T["ddddd"], T["ddddd"], T["ddddd"], T["ddddd"], T["ddddd"], T["ddddd"], T["ddddd"], T["ddddd"], T["ddddd"], T["ddddd"], T["ddddd"], T["ddddd"], T["ddddd"], T["ddddd"], T["ddddd"], T["ddddd"], T["ddddd"], T["ddddd"], T["ddddd"], T["C0m00"], T["C0m00"], T["C0m00"], T["C0m00"], T["C0m00"], T["C0m00"], T["C0m00"], T["C0m00"], T["K0m00"], T["K0m00"], T["K0m00"], T["K0m00"], T["C0m00"], T["ddddd"], T["ddddd"], T["ddddd"], T["ddddd"], T["ddddd"], T["ddddd"], T["_____"], {param2 = 9, name = "cottages:wood_flat", prob = 254},
		T["W0m00"], T["_____"], T["_____"], T["_____"], T["_____"], T["K0m00"], T["_____"], T["W0S01"], T["Sf0N0"], T["Sf0N0"], T["K0m00"], T["_____"], T["_____"], T["_____"], T["_____"], T["_____"], T["_____"], T["_____"], T["_____"], T["W0n00"], T["_____"], T["_____"], T["_____"], T["_____"], T["K0m00"], T["_____"], T["_____"], T["W0S01"], T["W0m00"], T["K0m00"], T["_____"], {param2 = 0, name = "cottages:window_shutter_open", prob = 254},
		T["_____"], T["_____"], T["_____"], T["_____"], T["_____"], T["_____"], {param2 = 2, name = "cottages:roof_flat_black", prob = 254},
		T["_____"], T["_____"], T["_____"], T["TwN00"], T["T0m09"], T["_____"], T["_____"], T["_____"], T["_____"], T["K0m00"], T["_____"], T["_____"], T["_____"], T["_____"], T["_____"], T["_____"], T["_____"], T["_____"], T["_____"], T["_____"], T["_____"], T["_____"], T["_____"], T["K0m00"], T["Cs0N0"], {param2 = 7, name = "cottages:wood_flat", prob = 254},
		T["_____"], T["_____"], T["K0m00"], T["_____"], T["_____"], T["_____"], T["_____"], T["_____"], T["_____"], T["_____"], T["_____"], T["_____"], T["_____"], T["_____"], T["_____"], T["_____"], T["K0m00"], T["_____"], T["Cs0N0"], T["_____"], T["_____"], {param2 = 1, name = "cottages:glass_pane", prob = 254},
		{param2 = 3, name = "cottages:window_shutter_open", prob = 254},
		T["_____"], {param2 = 0, name = "cottages:window_shutter_open", prob = 254},
		T["_____"], T["_____"], T["_____"], T["_____"], T["_____"], T["_____"], T["_____"], T["_____"], {param2 = 0, name = "cottages:roof_black", prob = 254},
		{param2 = 0, name = "cottages:roof_black", prob = 254},
		T["T0m09"], T["W0L20"], T["W0L20"], T["T0m09"], T["W0L20"], T["T0m09"], {param2 = 0, name = "cottages:roof_black", prob = 254},
		{param2 = 0, name = "cottages:roof_black", prob = 254},
		{param2 = 0, name = "cottages:roof_black", prob = 254},
		{param2 = 0, name = "cottages:roof_black", prob = 254},
		{param2 = 0, name = "cottages:roof_black", prob = 254},
		{param2 = 0, name = "cottages:roof_black", prob = 254},
		T["_____"], T["_____"], T["_____"], T["_____"], T["_____"], T["_____"], T["_____"], {param2 = 1, name = "cottages:roof_black", prob = 254},
		T["T0m01"], T["_____"], T["_____"], T["_____"], {param2 = 3, name = "cottages:roof_connector_black", prob = 254},
		T["_____"], T["_____"], T["_____"], T["_____"], T["_____"], T["_____"], T["_____"], T["_____"], T["_____"], T["_____"], T["_____"], T["_____"], T["_____"], T["_____"], T["T0m01"], T["TwE00"], T["_____"], {param2 = 3, name = "cottages:roof_connector_black", prob = 254},
		T["_____"], T["_____"], T["_____"], T["_____"], T["_____"], T["_____"], T["_____"], T["_____"], T["_____"], T["_____"], T["_____"], T["_____"], T["_____"], T["_____"], T["_____"], {param2 = 1, name = "cottages:roof_flat_black", prob = 254},
		{param2 = 1, name = "cottages:roof_black", prob = 254},
		{param2 = 3, name = "cottages:roof_black", prob = 254},
		T["_____"], T["_____"], T["_____"], T["_____"], T["_____"], T["_____"], T["_____"], T["_____"], T["_____"], T["_____"], T["_____"], T["_____"], T["_____"], T["_____"], T["_____"], T["_____"], T["_____"], T["_____"], T["_____"], T["_____"], T["_____"], T["_____"], T["_____"], T["_____"], T["_____"], T["_____"], T["_____"], T["_____"], T["_____"], T["_____"], T["_____"], T["_____"], T["_____"], T["_____"], T["_____"], T["_____"], T["_____"], T["_____"], T["_____"], T["_____"], T["_____"], T["_____"], T["_____"], T["_____"], T["_____"], T["_____"], T["_____"], T["_____"], T["_____"], T["_____"], T["_____"], T["_____"], T["_____"], T["_____"], T["_____"], T["_____"], T["_____"], T["_____"], T["_____"], T["_____"], T["_____"], T["_____"], T["_____"], T["_____"], T["_____"], T["_____"], T["_____"], T["_____"], T["_____"], T["_____"], T["_____"], T["_____"], T["_____"], T["_____"], T["_____"], T["_____"], T["_____"], T["_____"], T["_____"], T["_____"], T["_____"], T["_____"], T["_____"], T["_____"], T["_____"], T["_____"], T["_____"], T["_____"], T["_____"], T["_____"], T["_____"], T["_____"], T["_____"], T["_____"], T["_____"], T["_____"], T["_____"], T["_____"], T["_____"], T["_____"], T["_____"], T["_____"], T["_____"], T["ddddd"], T["ddddd"], T["ddddd"], T["ddddd"], T["ddddd"], T["ddddd"], T["ddddd"], T["ddddd"], T["ddddd"], T["ddddd"], T["ddddd"], T["ddddd"], T["ddddd"], T["ddddd"], T["ddddd"], T["ddddd"], T["ddddd"], T["ddddd"], T["ddddd"], T["ddddd"], T["ddddd"], T["ddddd"], T["ddddd"], T["ddddd"], T["ddddd"], T["ddddd"], T["ddddd"], T["C0m00"], T["C0m00"], T["C0m00"], T["C0m00"], T["C0m00"], T["ddddd"], T["ddddd"], T["ddddd"], T["ddddd"], T["ddddd"], T["ddddd"], T["ddddd"], T["ddddd"], T["ddddd"], T["ddddd"], T["ddddd"], T["ddddd"], T["ddddd"], T["C0m00"], T["C0m00"], T["C0m00"], T["C0m00"], T["C0m00"], T["C0m00"], T["ddddd"], T["ddddd"], T["ddddd"], T["ddddd"], T["ddddd"], T["ddddd"], T["ddddd"], T["ddddd"], T["ddddd"], T["ddddd"], T["ddddd"], T["ddddd"], T["ddddd"], T["C0m00"], T["C0m00"], T["C0m00"], T["C0m00"], T["C0m00"], T["C0m00"], T["ddddd"], T["ddddd"], T["ddddd"], T["ddddd"], T["ddddd"], T["ddddd"], T["C0m00"], T["W0m00"], T["W0m00"], T["C0m00"], T["C0m00"], T["C0m00"], T["C0m00"], T["C0m00"], T["K0m00"], T["C0m00"], T["C0m00"], T["C0m00"], T["C0m00"], T["C0m00"], T["C0m00"], T["C0m00"], T["C0m00"], T["C0m00"], T["C0m00"], {param2 = 18, name = "cottages:wood_flat", prob = 254},
		T["wwwww"], T["wwwww"], {param2 = 12, name = "cottages:wood_flat", prob = 254},
		T["_____"], T["_____"], T["K0m00"], T["T0m00"], {param2 = 2, name = "lib_ecology:tree_default_wood_door_centered", prob = 254},
		T["K0m00"], T["T0m00"], T["K0m00"], T["T0m02"], T["K0m00"], T["K0m00"], T["T0m02"], T["K0m00"], T["T0m02"], T["_____"], T["_____"], T["_____"], T["_____"], T["_____"], T["_____"], T["_____"], T["K0m00"], T["T0m00"], T["_____"],
		T["K0m00"], T["T0m00"], T["K0m00"], T["T0m02"], T["K0m00"], {param2 = 0, name = "cottages:glass_pane", prob = 254},
		T["T0m02"], T["K0m00"], T["T0m02"], T["_____"], T["_____"], T["_____"], {param2 = 2, name = "cottages:roof_flat_black", prob = 254},
		T["_____"], T["_____"], T["_____"], T["K0m00"], T["T0m00"], T["T0m12"], T["T0m12"], T["T0m00"], T["W0S00"], T["T0m02"], T["T0m12"], T["T0m12"], T["T0m09"], T["T0m12"], T["T0m02"], T["_____"], T["_____"], T["_____"], T["_____"], T["_____"], T["_____"], T["_____"], T["K0m00"], T["T0m00"], T["W0m00"], T["W0m00"], T["T0m00"], T["_____"], T["T0m02"], T["K0m00"], T["K0m00"], T["K0m00"], T["K0m00"], T["T0m02"], T["_____"], T["_____"], T["_____"], T["_____"], T["_____"], T["_____"], T["_____"], T["K0m00"], T["T0m00"], T["W0m00"], T["W0m00"], T["T0m00"], T["_____"], T["T0m02"], T["K0m00"], T["K0m00"], {param2 = 0, name = "cottages:glass_pane", prob = 254},
		T["K0m00"], T["T0m02"], T["_____"], T["_____"], T["_____"], T["_____"], T["_____"], T["_____"], T["_____"], T["W0m00"], T["T0m09"], T["W0m00"], T["W0m00"], T["T0m09"], T["W0L20"], T["T0m09"], T["T0m12"], T["T0m12"], T["T0m12"], T["T0m12"], T["T0m09"], T["_____"], T["_____"], T["_____"], T["_____"], T["_____"], {param2 = 0, name = "cottages:roof_black", prob = 254},
		{param2 = 0, name = "cottages:roof_black", prob = 254},
		{param2 = 0, name = "cottages:roof_connector_black", prob = 254},
		{param2 = 0, name = "cottages:roof_connector_black", prob = 254},
		T["W0m00"], T["_____"], T["_____"], T["W0m00"], {param2 = 0, name = "cottages:roof_black", prob = 254},
		{param2 = 0, name = "cottages:roof_black", prob = 254},
		{param2 = 0, name = "cottages:roof_black", prob = 254},
		{param2 = 0, name = "cottages:roof_black", prob = 254},
		{param2 = 0, name = "cottages:roof_black", prob = 254},
		{param2 = 0, name = "cottages:roof_connector_black", prob = 254},
		{param2 = 0, name = "cottages:roof_black", prob = 254},
		T["_____"], T["_____"], T["_____"], T["_____"], T["_____"], T["_____"], T["_____"], T["_____"], {param2 = 1, name = "cottages:roof_black", prob = 254},
		T["_____"], T["_____"], {param2 = 3, name = "cottages:roof_black", prob = 254},
		T["_____"], T["_____"], T["_____"], T["_____"], T["_____"], T["_____"], T["_____"], T["_____"], T["_____"], T["_____"], T["_____"], T["_____"], T["_____"], T["_____"], T["_____"], T["_____"], {param2 = 1, name = "cottages:roof_black", prob = 254},
		{param2 = 3, name = "cottages:roof_black", prob = 254},
		T["_____"], T["_____"], T["_____"], T["_____"], T["_____"], T["_____"], T["_____"], T["_____"], T["_____"], T["_____"], T["_____"], T["_____"], T["_____"], T["_____"], T["_____"], T["_____"], T["_____"], T["_____"], T["_____"], T["_____"], T["_____"], T["_____"], T["_____"], T["_____"], T["_____"], T["_____"], T["_____"], T["_____"], T["_____"], T["_____"], T["_____"], T["_____"], T["_____"], T["_____"], T["_____"], T["_____"], T["_____"], T["_____"], T["_____"], T["_____"], T["_____"], T["_____"], T["_____"], T["_____"], T["_____"], T["_____"], T["_____"], T["_____"], T["_____"], T["_____"], T["_____"], T["_____"], T["_____"], T["_____"], T["_____"], T["_____"], T["_____"], T["_____"], T["_____"], T["_____"], T["_____"], T["_____"], T["_____"], T["_____"], T["_____"], T["_____"], T["_____"], T["_____"], T["_____"], T["_____"], T["_____"], T["_____"], T["_____"], T["_____"], T["_____"], T["_____"], T["_____"], T["_____"], T["_____"], T["_____"], T["_____"], T["_____"], T["_____"], T["_____"], T["_____"], T["_____"], T["_____"], T["_____"], T["_____"], T["_____"], T["_____"], T["_____"], T["_____"], T["_____"], T["_____"], T["_____"], T["_____"], T["_____"], T["_____"], T["_____"], T["_____"], T["_____"], T["_____"], T["ddddd"], T["ddddd"], T["ddddd"], T["ddddd"], T["ddddd"], T["ddddd"], T["ddddd"], T["ddddd"], T["ddddd"], T["ddddd"], T["ddddd"], T["ddddd"], T["ddddd"], T["ddddd"], T["ddddd"], T["ddddd"], T["ddddd"], T["ddddd"], T["ddddd"], T["ddddd"], T["ddddd"], T["ddddd"], T["ddddd"], T["ddddd"], T["ddddd"], T["ddddd"], T["C0m00"], {param2 = 1, name = "cottages:barrel_lying", prob = 254},
		{param2 = 1, name = "cottages:barrel_lying", prob = 254},
		{param2 = 1, name = "cottages:barrel_lying", prob = 254},
		T["Sf0S0"], T["C0m00"], T["ddddd"], T["ddddd"], T["ddddd"], T["ddddd"], T["ddddd"], T["ddddd"], T["ddddd"], T["ddddd"], T["ddddd"], T["ddddd"], T["ddddd"], T["ddddd"], T["ddddd"], T["C0m00"], T["_____"], T["_____"], T["_____"], T["Sf0S0"], T["C0m00"], T["ddddd"], T["ddddd"], T["ddddd"], T["ddddd"], T["ddddd"], T["ddddd"], T["ddddd"], T["ddddd"], T["ddddd"], T["ddddd"], T["ddddd"], T["ddddd"], T["ddddd"], T["C0m00"], T["C0S22"], T["C0S22"], T["C0S22"], T["C0S22"], T["C0m00"], T["ddddd"], T["ddddd"], T["ddddd"], T["ddddd"], T["ddddd"], T["ddddd"], T["C0m00"], T["C0m00"], T["C0m00"], T["C0m00"], T["C0m00"], T["C0m00"], T["K0m00"], T["K0m00"], T["K0m00"], T["K0m00"], T["K0m00"], T["K0m00"], T["K0m00"], T["K0m00"], T["K0m00"], T["K0m00"], T["K0m00"], T["C0m00"], T["C0m00"], T["_____"], {param2 = 7, name = "cottages:wood_flat", prob = 254},
		{param2 = 7, name = "cottages:wood_flat", prob = 254},
		T["_____"], T["_____"], T["K0m00"], T["Bn0S0"], T["Bn0S0"], T["_____"], T["Bn0S0"], T["Bn0S0"], T["Bn0S0"], T["Bn0E0"], {param2 = 1, name = "cottages:table", prob = 254},
		T["Bn0W0"], T["Bn0S0"], T["Bn0S0"], T["K0m00"], T["_____"], T["_____"], T["_____"], T["_____"], T["_____"], T["_____"], T["K0m00"], T["TwW00"], T["_____"], T["_____"], T["_____"], T["_____"], T["_____"], T["_____"], T["_____"], T["_____"], T["_____"], T["TwN00"], T["K0m00"], T["_____"], T["_____"], T["_____"], T["_____"], T["_____"], T["_____"], T["K0m00"], T["W0L20"], T["T0m09"], T["W0L20"], T["W0L20"], T["T0m09"], T["W0L20"], T["C0m00"], T["W0L20"], T["W0L20"], T["T0m09"], T["W0L20"], T["K0m00"], T["_____"], T["_____"], T["_____"], T["_____"], T["_____"], T["_____"], T["K0m00"], T["_____"], T["_____"], T["_____"], T["_____"], {param2 = 3, name = "lib_ecology:tree_default_wood_door_centered", prob = 254},
		T["_____"], {param2 = 3, name = "lib_ecology:tree_default_wood_door_centered", prob = 254},
		T["_____"], T["_____"], T["_____"], T["_____"], T["K0m00"], T["_____"], T["_____"], T["_____"], T["_____"], T["_____"], T["_____"], T["K0m00"], T["_____"], T["_____"], T["_____"], T["_____"], T["_____"],
		T["_____"], T["_____"],
		T["_____"], T["_____"], T["_____"], T["_____"], T["K0m00"], T["_____"], T["_____"], T["_____"], T["_____"], T["_____"], T["_____"], T["K0m00"], T["W0L20"], T["T0m09"], T["W0L20"], T["W0L20"], T["T0m09"], T["W0L20"], T["T0m09"], T["W0L20"], T["W0L20"], T["W0L20"], T["W0L20"], T["T0m09"], T["_____"], T["_____"], T["_____"], T["_____"], T["_____"], T["_____"], T["K0m00"], {param2 = 1, name = "beds:fancy_bed_bottom", prob = 254},
		{param2 = 1, name = "beds:fancy_bed_top", prob = 254},
		T["Cs0E0"], {param2 = 0, name = "lib_ecology:tree_default_wood_door_centered", prob = 254},
		T["W0m00"], T["Cs0S0"], T["K0m00"], T["Sf0S0"], T["Sf0S0"], T["_____"], T["Bn0S0"], T["K0m00"], T["_____"], T["_____"], T["_____"], T["_____"], T["_____"], {param2 = 0, name = "cottages:roof_black", prob = 254},
		{param2 = 0, name = "cottages:roof_connector_black", prob = 254},
		{param2 = 0, name = "cottages:roof_black", prob = 254},
		{param2 = 0, name = "cottages:roof_black", prob = 254},
		{param2 = 0, name = "cottages:roof_connector_black", prob = 254},
		T["_____"],
		T["W0m00"], {param2 = 0, name = "cottages:roof_connector_black", prob = 254},
		{param2 = 0, name = "cottages:roof_connector_black", prob = 254},
		{param2 = 0, name = "cottages:roof_black", prob = 254},
		{param2 = 0, name = "cottages:roof_black", prob = 254},
		{param2 = 0, name = "cottages:roof_black", prob = 254},
		{param2 = 0, name = "cottages:roof_black", prob = 254},
		{param2 = 0, name = "cottages:roof_connector_black", prob = 254},
		{param2 = 0, name = "cottages:roof_black", prob = 254},
		T["_____"], T["_____"], T["_____"], T["_____"], T["_____"], T["_____"], T["_____"], T["_____"], T["_____"], {param2 = 1, name = "cottages:roof_black", prob = 254},
		{param2 = 3, name = "cottages:roof_connector_black", prob = 254},
		T["_____"], T["_____"], T["_____"], T["_____"], T["_____"], T["_____"], T["_____"], T["_____"], T["_____"], T["_____"], T["_____"], T["_____"], T["_____"], T["_____"], T["_____"], T["_____"], T["_____"], T["_____"], T["_____"], T["_____"], T["_____"], T["_____"], T["_____"], T["_____"], T["_____"], T["_____"], T["_____"], T["_____"], T["_____"], T["_____"], T["_____"], T["_____"], T["_____"], T["_____"], T["_____"], T["_____"], T["_____"], T["_____"], T["_____"], T["_____"], T["_____"], T["_____"], T["_____"], T["_____"], T["_____"], T["_____"], T["_____"], T["_____"], T["_____"], T["_____"], T["_____"], T["_____"], T["_____"], T["_____"], T["_____"], T["_____"], T["_____"], T["_____"], T["_____"], T["_____"], T["_____"], T["_____"], T["_____"], T["_____"], T["_____"], T["_____"], T["_____"], T["_____"], T["_____"], T["_____"], T["_____"], T["_____"], T["_____"], T["_____"], T["_____"], T["_____"], T["_____"], T["_____"], T["_____"], T["_____"], T["_____"], T["_____"], T["_____"], T["_____"], T["_____"], T["_____"], T["_____"], T["_____"], T["_____"], T["_____"], T["_____"], T["_____"], T["_____"], T["_____"], T["_____"], T["_____"], T["_____"], T["_____"], T["_____"], T["_____"], T["_____"], T["_____"], T["_____"], T["ddddd"], T["ddddd"], T["ddddd"], T["ddddd"], T["ddddd"], T["ddddd"], T["ddddd"], T["ddddd"], T["ddddd"], T["ddddd"], T["ddddd"], T["ddddd"], T["ddddd"], T["ddddd"], T["ddddd"], T["ddddd"], T["ddddd"], T["ddddd"], T["ddddd"], T["ddddd"], T["ddddd"], T["ddddd"], T["ddddd"], T["ddddd"], T["ddddd"], T["ddddd"], T["C0m00"], T["_____"], T["_____"], T["_____"], T["_____"], T["C0m00"], T["ddddd"], T["ddddd"], T["ddddd"], T["ddddd"], T["ddddd"], T["ddddd"], T["ddddd"], T["ddddd"], T["ddddd"], T["ddddd"], T["ddddd"], T["ddddd"], T["ddddd"], T["C0m00"], T["_____"], T["_____"], T["_____"], T["_____"], T["C0m00"], T["ddddd"], T["ddddd"], T["ddddd"], T["ddddd"], T["ddddd"], T["ddddd"], T["ddddd"], T["ddddd"], T["ddddd"], T["ddddd"], T["ddddd"], T["ddddd"], T["ddddd"], T["C0m00"], T["TwE00"], T["_____"], T["_____"], T["_____"], T["C0m00"], T["ddddd"], T["ddddd"], T["ddddd"], T["ddddd"], T["ddddd"], T["ddddd"], T["C0m00"], T["C0m00"], T["C0m00"], T["C0m00"], T["C0m00"], T["C0m00"], T["K0m00"], T["K0m00"], T["K0m00"], T["K0m00"], T["K0m00"], T["K0m00"], T["K0m00"], T["K0m00"], T["K0m00"], T["K0m00"], T["K0m00"], T["C0m00"], T["C0m00"], T["_____"], T["_____"], T["_____"], T["_____"], T["_____"], T["K0m00"], {param2 = 2, name = "cottages:table", prob = 254},
		{param2 = 2, name = "cottages:table", prob = 254},
		T["_____"], {param2 = 2, name = "cottages:table", prob = 254},
		{param2 = 2, name = "cottages:table", prob = 254},
		T["_____"], T["_____"], T["_____"], T["_____"], {param2 = 2, name = "cottages:table", prob = 254},
		{param2 = 2, name = "cottages:table", prob = 254},
		T["K0m00"], T["_____"], T["_____"], T["_____"], T["_____"], T["_____"], {param2 = 1, name = "cottages:window_shutter_open", prob = 254},
		{param2 = 3, name = "cottages:glass_pane", prob = 254},
		T["_____"], T["_____"], T["_____"], T["_____"], T["_____"], T["_____"], T["_____"], T["_____"], T["_____"], T["_____"], T["_____"], {param2 = 3, name = "cottages:glass_pane", prob = 254},
		{param2 = 3, name = "cottages:window_shutter_open", prob = 254},
		T["_____"], T["_____"], T["_____"], T["_____"], T["_____"], T["K0m00"], T["W0L20"], T["T0m09"], T["W0L20"], T["W0L20"], T["T0m09"], T["W0L20"], T["C0m00"], T["W0L20"], T["W0L20"], T["T0m09"], T["W0L20"], T["K0m00"], T["_____"], T["_____"], T["_____"], T["_____"], T["_____"], T["_____"], T["K0m00"], T["_____"], {param2 = 0, name = "beds:fancy_bed_bottom", prob = 254},
		{param2 = 0, name = "beds:fancy_bed_bottom", prob = 254},
		T["_____"], T["W0m00"], T["_____"], T["C0m00"], T["_____"], {param2 = 0, name = "beds:fancy_bed_bottom", prob = 254},
		{param2 = 0, name = "beds:fancy_bed_bottom", prob = 254},
		T["_____"], T["K0m00"], T["_____"], T["_____"], T["_____"], T["_____"], T["_____"], {param2 = 1, name = "cottages:window_shutter_open", prob = 254},
		{param2 = 3, name = "cottages:glass_pane", prob = 254},
		T["_____"], T["_____"], T["_____"], T["_____"], T["W0m00"], T["_____"], T["W0m00"], T["_____"], T["_____"], T["_____"], T["_____"], {param2 = 3, name = "cottages:glass_pane", prob = 254},
		{param2 = 3, name = "cottages:window_shutter_open", prob = 254},
		T["_____"], T["_____"], T["_____"], T["_____"], T["_____"], T["K0m00"], T["W0L20"], T["T0m09"], T["W0L20"], T["W0L20"], T["T0m09"], T["W0L20"], T["T0m09"], T["W0L20"], T["W0L20"], T["W0L20"], T["W0L20"], T["T0m09"], T["_____"], T["_____"], T["_____"], T["_____"], T["_____"], T["_____"], T["K0m00"], T["_____"], T["_____"], {param2 = 1, name = "lib_ecology:tree_default_wood_door_centered_right", prob = 254},
		{param2 = 3, name = "lib_ecology:tree_default_wood_door_centered", prob = 254},
		T["_____"], T["_____"], {param2 = 3, name = "lib_ecology:tree_default_wood_door_centered", prob = 254},
		T["_____"], T["_____"], T["Bn0E0"], {param2 = 2, name = "cottages:table", prob = 254},
		T["K0m00"], T["_____"], T["_____"], T["_____"], T["_____"], T["_____"], {param2 = 1, name = "cottages:window_shutter_open", prob = 254},
		{param2 = 3, name = "cottages:glass_pane", prob = 254},
		T["_____"], T["_____"], T["_____"],
		T["_____"],
		T["_____"], T["_____"], T["_____"],
		T["_____"], T["_____"], T["_____"], T["_____"], T["K0m00"], T["_____"], T["_____"], T["_____"], T["_____"], T["_____"], {param2 = 0, name = "cottages:roof_black", prob = 254},
		{param2 = 0, name = "cottages:roof_connector_black", prob = 254},
		{param2 = 0, name = "cottages:roof_black", prob = 254},
		{param2 = 0, name = "cottages:roof_black", prob = 254},
		{param2 = 0, name = "cottages:roof_black", prob = 254},
		{param2 = 0, name = "cottages:roof_connector_black", prob = 254},
		{param2 = 0, name = "cottages:roof_connector_black", prob = 254},
		{param2 = 0, name = "cottages:roof_black", prob = 254},
		{param2 = 0, name = "cottages:roof_connector_black", prob = 254},
		{param2 = 0, name = "cottages:roof_black", prob = 254},
		{param2 = 0, name = "cottages:roof_black", prob = 254},
		{param2 = 0, name = "cottages:roof_black", prob = 254},
		{param2 = 0, name = "cottages:roof_black", prob = 254},
		{param2 = 0, name = "cottages:roof_connector_black", prob = 254},
		{param2 = 0, name = "cottages:roof_black", prob = 254},
		T["_____"], T["_____"], T["_____"], T["_____"], T["_____"], T["_____"], T["_____"], T["_____"], T["_____"], T["_____"], T["_____"], T["_____"], T["_____"], T["_____"], T["_____"], T["_____"], T["_____"], T["_____"], T["_____"], T["_____"], T["_____"], T["_____"], T["_____"], T["_____"], T["_____"], T["_____"], T["_____"], T["_____"], T["_____"], T["_____"], T["_____"], T["_____"], T["_____"], T["_____"], T["_____"], T["_____"], T["_____"], T["_____"], T["_____"], T["_____"], T["_____"], T["_____"], T["_____"], T["_____"], T["_____"], T["_____"], T["_____"], T["_____"], T["_____"], T["_____"], T["_____"], T["_____"], T["_____"], T["_____"], T["_____"], T["_____"], T["_____"], T["_____"], T["_____"], T["_____"], T["_____"], T["_____"], T["_____"], T["_____"], T["_____"], T["_____"], T["_____"], T["_____"], T["_____"], T["_____"], T["_____"], T["_____"], T["_____"], T["_____"], T["_____"], T["_____"], T["_____"], T["_____"], T["_____"], T["_____"], T["_____"], T["_____"], T["_____"], T["_____"], T["_____"], T["_____"], T["_____"], T["_____"], T["_____"], T["_____"], T["_____"], T["_____"], T["_____"], T["_____"], T["_____"], T["ddddd"], T["ddddd"], T["ddddd"], T["ddddd"], T["ddddd"], T["ddddd"], T["ddddd"], T["ddddd"], T["ddddd"], T["ddddd"], T["ddddd"], T["ddddd"], T["ddddd"], T["ddddd"], T["ddddd"], T["ddddd"], T["ddddd"], T["ddddd"], T["ddddd"], T["ddddd"], T["ddddd"], T["ddddd"], T["ddddd"], T["ddddd"], T["ddddd"], T["ddddd"], T["C0m00"], {param2 = 1, name = "cottages:barrel_lying", prob = 254},
		{param2 = 1, name = "cottages:barrel_lying", prob = 254},
		{param2 = 1, name = "cottages:barrel_lying", prob = 254},
		T["_____"], T["C0m00"], T["ddddd"], T["ddddd"], T["ddddd"], T["ddddd"], T["ddddd"], T["ddddd"], T["ddddd"], T["ddddd"], T["ddddd"], T["ddddd"], T["ddddd"], T["ddddd"], T["ddddd"], T["C0m00"], T["_____"], T["_____"], T["_____"], T["_____"], T["C0m00"], T["ddddd"], T["ddddd"], T["ddddd"], T["ddddd"], T["ddddd"], T["ddddd"], T["ddddd"], T["ddddd"], T["ddddd"], T["ddddd"], T["ddddd"], T["ddddd"], T["ddddd"], T["C0m00"], T["C0S20"], T["C0S20"], T["C0S20"], T["C0S20"], T["C0m00"], T["ddddd"], T["ddddd"], T["ddddd"], T["ddddd"], T["ddddd"], T["ddddd"], T["C0m00"], T["C0m00"], T["C0m00"], T["C0m00"], T["C0m00"], T["C0m00"], T["K0m00"], T["K0m00"], T["K0m00"], T["K0m00"], T["K0m00"], T["K0m00"], T["K0m00"], T["K0m00"], T["K0m00"], T["K0m00"], T["K0m00"], T["C0m00"], T["C0m00"], T["_____"], T["_____"], T["_____"], T["_____"], T["_____"], T["K0m00"], T["Bn0S0"], T["Bn0S0"], T["_____"], T["Bn0S0"], T["Bn0S0"], T["_____"], T["C0m00"], T["C0m00"], T["_____"], T["Bn0S0"], T["Bn0S0"], T["K0m00"], T["_____"], T["_____"], T["_____"], T["_____"], T["_____"], T["_____"], T["K0m00"], T["_____"], T["_____"], T["_____"], T["_____"], T["_____"], T["_____"], T["TwN00"], T["C0m00"], T["_____"], T["_____"], T["_____"], T["K0m00"], T["_____"], T["_____"], T["_____"], T["_____"], T["_____"], T["TwN00"], T["K0m00"], T["W0L20"], T["T0m09"], T["W0L20"], T["W0L20"], T["T0m09"], T["W0L20"], T["C0m00"], T["C0m00"], T["W0L20"], T["T0m09"], T["W0L20"], T["K0m00"], T["TwE00"], T["_____"], T["_____"], T["_____"], T["_____"], {param2 = 1, name = "cottages:roof_flat_black", prob = 254},
		T["K0m00"], T["_____"], {param2 = 0, name = "beds:fancy_bed_top", prob = 254},
		{param2 = 0, name = "beds:fancy_bed_top", prob = 254},
		T["Cs0N0"], T["T0m00"], T["_____"], T["Fu0W0"], T["_____"], {param2 = 0, name = "beds:fancy_bed_top", prob = 254},
		{param2 = 0, name = "beds:fancy_bed_top", prob = 254},
		T["_____"], T["K0m00"], T["_____"], T["_____"], T["_____"], T["_____"], T["_____"], T["_____"], T["K0m00"], T["TwS00"], T["_____"], T["_____"], T["Cs0N0"], T["T0m00"], T["_____"], T["C0m00"], T["TwS00"], T["_____"], T["_____"], T["_____"], T["K0m00"], T["_____"], T["_____"], T["_____"], T["_____"], T["_____"], T["_____"], T["K0m00"], T["W0L20"], T["T0m09"], T["W0L20"], T["W0m00"], T["T0m09"], T["W0L20"], T["T0m09"], T["W0L20"], T["W0L20"], T["W0L20"], T["W0L20"], T["T0m09"], T["_____"], T["_____"], T["_____"], T["_____"], T["_____"], T["_____"], T["K0m00"], T["W0m00"], T["W0m00"], T["_____"], T["W0m00"], {param2 = 3, name = "beds:fancy_bed_top", prob = 254},
		{param2 = 3, name = "beds:fancy_bed_bottom", prob = 254},
		T["K0m00"], T["_____"], T["_____"], T["_____"], T["Bn0S0"], T["K0m00"], T["_____"], T["_____"], T["_____"], T["_____"], T["_____"], T["_____"], T["K0m00"], T["W0m00"], T["W0m00"], T["_____"], T["W0m00"], T["_____"], T["_____"], T["K0m00"], T["_____"], T["_____"], T["_____"], T["_____"], {param2 = 1, name = "cottages:glass_pane", prob = 254},
		{param2 = 3, name = "cottages:window_shutter_open", prob = 254},
		T["_____"], T["_____"], T["_____"], T["_____"], T["_____"], T["K0m00"], T["W0m00"], T["W0m00"], T["W0m00"], T["W0m00"], T["TwS00"], T["_____"], T["K0m00"], T["_____"], T["_____"], T["_____"], T["_____"], T["K0m00"], T["_____"], T["_____"], T["_____"], T["_____"], {param2 = 0, name = "cottages:roof_black", prob = 254},
		{param2 = 0, name = "cottages:roof_black", prob = 254},
		{param2 = 0, name = "cottages:roof_connector_black", prob = 254},
		{param2 = 0, name = "cottages:roof_connector_black", prob = 254},
		{param2 = 0, name = "cottages:roof_connector_black", prob = 254},
		{param2 = 0, name = "cottages:roof_connector_black", prob = 254},
		{param2 = 0, name = "cottages:roof_connector_black", prob = 254},
		{param2 = 0, name = "cottages:roof_black", prob = 254},
		{param2 = 0, name = "cottages:roof_black", prob = 254},
		{param2 = 0, name = "cottages:roof_connector_black", prob = 254},
		{param2 = 0, name = "cottages:roof_black", prob = 254},
		{param2 = 0, name = "cottages:roof_black", prob = 254},
		{param2 = 0, name = "cottages:roof_black", prob = 254},
		{param2 = 0, name = "cottages:roof_black", prob = 254},
		{param2 = 0, name = "cottages:roof_connector_black", prob = 254},
		{param2 = 0, name = "cottages:roof_black", prob = 254},
		T["_____"], T["_____"], T["_____"], T["_____"], T["_____"], T["_____"], T["_____"], T["_____"], T["_____"], T["_____"], T["_____"], T["_____"], T["_____"], T["_____"], T["_____"], T["_____"], T["_____"], T["_____"], T["_____"], T["_____"], T["_____"], T["_____"], T["_____"], T["_____"], T["_____"], T["_____"], T["_____"], T["_____"], T["_____"], T["_____"], T["_____"], T["_____"], T["_____"], T["_____"], T["_____"], T["_____"], T["_____"], T["_____"], T["_____"], T["_____"], T["_____"], T["_____"], T["_____"], T["_____"], T["_____"], T["_____"], T["_____"], T["_____"], T["_____"], T["_____"], T["_____"], T["_____"], T["_____"], T["_____"], T["_____"], T["_____"], T["_____"], T["_____"], T["_____"], T["_____"], T["_____"], T["_____"], T["_____"], T["_____"], T["_____"], T["_____"], T["_____"], T["_____"], T["_____"], T["_____"], T["_____"], T["_____"], T["_____"], T["_____"], T["_____"], T["_____"], T["ddddd"], T["ddddd"], T["ddddd"], T["ddddd"], T["ddddd"], T["ddddd"], T["ddddd"], T["ddddd"], T["ddddd"], T["ddddd"], T["ddddd"], T["ddddd"], T["ddddd"], T["ddddd"], T["ddddd"], T["ddddd"], T["ddddd"], T["ddddd"], T["ddddd"], T["ddddd"], T["ddddd"], T["ddddd"], T["ddddd"], T["ddddd"], T["ddddd"], T["ddddd"], T["C0m00"], T["C0m00"], T["C0m00"], T["C0m00"], T["_____"], T["C0m00"], T["ddddd"], T["ddddd"], T["ddddd"], T["ddddd"], T["ddddd"], T["ddddd"], T["ddddd"], T["ddddd"], T["ddddd"], T["ddddd"], T["ddddd"], T["ddddd"], T["ddddd"], T["C0m00"], T["C0m00"], T["W0n00"], T["C0m00"], T["_____"], T["C0m00"], T["ddddd"], T["ddddd"], T["ddddd"], T["ddddd"], T["ddddd"], T["ddddd"], T["ddddd"], T["ddddd"], T["ddddd"], T["ddddd"], T["ddddd"], T["ddddd"], T["ddddd"], T["C0m00"], T["C0m00"], T["C0m00"], T["C0m00"], T["C0m00"], T["C0m00"], T["ddddd"], T["ddddd"], T["ddddd"], T["ddddd"], T["ddddd"], T["ddddd"], T["C0m00"], T["C0m00"], T["C0m00"], T["C0m00"], T["C0m00"], T["C0m00"], T["K0m00"], T["K0m00"], T["K0m00"], T["K0m00"], T["K0m00"], T["K0m00"], T["K0m00"], T["K0m00"], T["K0m00"], T["K0m00"], T["K0m00"], T["C0m00"], T["C0m00"], T["_____"], T["_____"], T["_____"], T["_____"], T["_____"], {param2 = 3, name = "lib_ecology:tree_default_wood_door_centered", prob = 254},
		T["_____"], T["_____"], T["_____"], T["_____"], T["_____"], T["_____"], T["Fu0E0"], T["Fu0W0"], T["_____"], T["_____"], T["_____"], {param2 = 1, name = "lib_ecology:tree_default_wood_door_centered", prob = 254},
		T["_____"], T["_____"], T["_____"], T["_____"], T["_____"], T["_____"], T["_____"],
		T["_____"], T["_____"], T["_____"], T["_____"], T["_____"], T["_____"], T["_____"], T["_____"], T["_____"], T["_____"], T["_____"], T["_____"],
		T["_____"], T["_____"], T["_____"], T["_____"], T["_____"], T["_____"], T["K0m00"], T["W0L20"], T["T0m09"], T["W0L20"], T["W0L20"], T["T0m09"], T["W0L20"], T["_____"], T["C0m00"], T["W0L20"], T["T0m09"], T["W0L20"], T["W0m00"], {param2 = 3, name = "cottages:roof_black", prob = 254},
		T["_____"], T["_____"], T["_____"], T["_____"], {param2 = 1, name = "cottages:roof_flat_black", prob = 254},
		T["K0m00"], T["W0m00"], T["W0m00"], T["W0m00"], T["W0m00"], T["W0S03"], T["_____"], T["C0m00"], T["C0m00"], T["W0m00"], T["W0m00"], T["Cs0S0"], T["K0m00"], T["_____"], T["_____"], T["_____"], T["_____"], T["_____"], T["_____"], T["K0m00"], T["W0m00"], T["W0m00"], T["W0m00"], T["W0S03"], T["_____"], T["_____"], T["C0m00"], T["C0m00"], T["W0m00"], T["W0m00"], T["Cs0N0"], T["W0m00"], T["_____"], T["_____"], T["_____"], T["_____"], T["_____"], T["_____"],
		{param2 = 18, name = "cottages:wood_flat", prob = 254},
		T["W0m00"], T["T0m09"], T["W0S03"], T["_____"], T["_____"], T["_____"], T["T0m09"], T["C0m00"], T["T0m12"], T["T0m12"], T["T0m12"], T["T0m09"], T["_____"], T["_____"], T["_____"], T["_____"], T["_____"], T["_____"], T["K0m00"], T["Cs0S0"], T["W0m00"], T["_____"], T["_____"], {param2 = 7, name = "cottages:wood_flat", prob = 254},
		T["W0m00"], T["W0m00"], T["Fu0W0"], T["_____"], T["_____"], T["_____"], T["K0m00"], T["_____"], T["_____"], T["_____"], T["_____"], T["_____"], T["_____"], T["K0m00"], T["_____"], T["W0m00"], T["_____"], T["_____"], T["W0m00"], T["W0m00"], T["W0m00"], T["C0m00"], T["_____"], T["_____"], T["_____"], T["K0m00"], T["_____"], T["_____"], T["_____"], T["_____"], T["_____"], {param2 = 1, name = "cottages:window_shutter_open", prob = 254},
		{param2 = 1, name = "cottages:glass_pane", prob = 254},
		T["TwW00"], T["_____"], T["W0m00"], T["_____"], T["W0m00"], T["W0m00"], T["W0m00"], T["C0m00"], T["_____"], T["_____"], T["_____"], T["K0m00"], T["_____"], T["_____"], T["_____"], T["_____"], T["_____"], T["_____"], T["K0m00"], T["_____"], T["_____"], T["W0m00"], T["_____"], T["W0m00"], T["W0m00"], T["W0m00"], T["C0m00"], T["_____"], T["_____"], T["_____"], T["K0m00"], T["_____"], T["_____"], T["_____"], T["_____"], {param2 = 1, name = "cottages:roof_flat_black", prob = 254},
		{param2 = 1, name = "cottages:roof_flat_black", prob = 254},
		{param2 = 1, name = "cottages:roof_flat_black", prob = 254},
		{param2 = 1, name = "cottages:roof_flat_black", prob = 254},
		{param2 = 1, name = "cottages:roof_flat_black", prob = 254},
		{param2 = 1, name = "cottages:roof_flat_black", prob = 254},
		{param2 = 1, name = "cottages:roof_flat_black", prob = 254},
		{param2 = 1, name = "cottages:roof_flat_black", prob = 254},
		{param2 = 1, name = "cottages:roof_flat_black", prob = 254},
		{param2 = 1, name = "cottages:roof_flat_black", prob = 254},
		T["C0m00"], {param2 = 1, name = "cottages:roof_flat_black", prob = 254},
		{param2 = 1, name = "cottages:roof_flat_black", prob = 254},
		{param2 = 1, name = "cottages:roof_flat_black", prob = 254},
		{param2 = 1, name = "cottages:roof_flat_black", prob = 254},
		{param2 = 1, name = "cottages:roof_flat_black", prob = 254},
		T["_____"], T["_____"], T["_____"], T["_____"], T["_____"], T["_____"], T["_____"], T["_____"], T["_____"], T["_____"], T["_____"], T["_____"], T["_____"], T["C0m00"], T["_____"], T["_____"], T["_____"], T["_____"], T["_____"], T["_____"], T["_____"], T["_____"], T["_____"], T["_____"], T["_____"], T["_____"], T["_____"], T["_____"], T["_____"], T["_____"], T["_____"], T["_____"], T["_____"], T["_____"], T["_____"], T["_____"], T["_____"], T["_____"], T["_____"], T["_____"], T["_____"], T["_____"], T["_____"], T["_____"], T["_____"], T["_____"], T["_____"], T["_____"], T["_____"], T["_____"], T["_____"], T["_____"], T["_____"], T["_____"], T["_____"], T["_____"], T["_____"], T["ddddd"], T["ddddd"], T["ddddd"], T["ddddd"], T["ddddd"], T["ddddd"], T["ddddd"], T["ddddd"], T["ddddd"], T["ddddd"], T["ddddd"], T["ddddd"], T["ddddd"], T["ddddd"], T["ddddd"], T["ddddd"], T["ddddd"], T["ddddd"], T["ddddd"], T["ddddd"], T["ddddd"], T["ddddd"], T["ddddd"], T["ddddd"], T["ddddd"], T["ddddd"], T["C0m00"], {param2 = 1, name = "cottages:barrel_lying", prob = 254},
		{param2 = 3, name = "cottages:barrel_lying", prob = 254},
		{param2 = 3, name = "cottages:barrel_lying", prob = 254},
		T["_____"], T["C0m00"], T["ddddd"], T["ddddd"], T["ddddd"], T["ddddd"], T["ddddd"], T["ddddd"], T["ddddd"], T["ddddd"], T["ddddd"], T["ddddd"], T["ddddd"], T["ddddd"], T["ddddd"], T["C0m00"], T["_____"], T["_____"], T["_____"], T["_____"], T["C0m00"], T["ddddd"], T["ddddd"], T["ddddd"], T["ddddd"], T["ddddd"], T["ddddd"], T["ddddd"], T["ddddd"], T["ddddd"], T["ddddd"], T["ddddd"], T["ddddd"], T["ddddd"], T["C0m00"], T["C0S22"], T["C0S22"], T["C0S22"], T["C0S22"], T["C0m00"], T["ddddd"], T["ddddd"], T["ddddd"], T["ddddd"], T["ddddd"], T["ddddd"], T["C0m00"], T["C0m00"], T["C0m00"], T["C0m00"], T["C0m00"], T["C0m00"], T["K0m00"], T["K0m00"], T["K0m00"], T["K0m00"], T["K0m00"], T["K0m00"], T["K0m00"], T["K0m00"], T["K0m00"], T["K0m00"], T["K0m00"], T["C0m00"], T["C0m00"], T["_____"], T["_____"], T["_____"], T["_____"], T["_____"], T["K0m00"], T["Bn0N0"], T["Bn0N0"], T["_____"], T["Bn0E0"], {param2 = 1, name = "cottages:table", prob = 254},
		T["Bn0W0"], T["C0m00"], T["C0m00"], T["_____"], T["Bn0N0"], T["Bn0N0"], T["K0m00"], T["_____"], T["_____"], T["_____"], T["_____"], T["_____"], T["_____"], T["K0m00"], T["_____"], T["_____"], T["_____"], T["_____"], T["_____"], T["_____"], T["TwN00"], T["C0m00"], T["_____"], T["_____"], T["_____"], T["K0m00"], T["_____"], T["_____"], T["_____"], T["_____"], T["_____"], T["_____"], T["K0m00"], T["W0L20"], T["T0m09"], T["W0L20"], T["W0L20"], T["T0m09"], T["W0L20"], T["C0m00"], T["C0m00"], T["W0L20"], T["T0m09"], T["W0L20"], T["K0m00"], T["TwE00"], T["_____"], T["_____"], T["_____"], T["_____"], {param2 = 1, name = "cottages:roof_flat_black", prob = 254},
		T["K0m00"], T["_____"], {param2 = 2, name = "beds:fancy_bed_top", prob = 254},
		{param2 = 2, name = "beds:fancy_bed_top", prob = 254},
		T["Cs0S0"], T["T0m00"], T["_____"], T["Fu0W0"], T["_____"], {param2 = 2, name = "beds:fancy_bed_top", prob = 254},
		{param2 = 2, name = "beds:fancy_bed_top", prob = 254},
		T["_____"], T["K0m00"], T["_____"], T["_____"], T["_____"], T["_____"], T["_____"], T["_____"], T["K0m00"], T["TwW00"], T["_____"], T["_____"], T["Cs0S0"], T["T0m00"], T["_____"], T["C0m00"], T["TwW00"], T["_____"], T["_____"], T["_____"], T["K0m00"], T["_____"], T["_____"], T["_____"], T["_____"], T["_____"], T["_____"], T["K0m00"], T["W0L20"], T["T0m09"], T["W0L20"], T["W0m00"], T["T0m09"], T["W0L20"], T["T0m09"], T["W0L20"], T["W0L20"], T["W0L20"], T["W0L20"], T["T0m09"], T["_____"], T["_____"], T["_____"], T["_____"], T["_____"], T["_____"], T["K0m00"], T["_____"], {param2 = 3, name = "lib_ecology:tree_default_wood_door_centered", prob = 254},
		T["_____"], {param2 = 2, name = "cottages:fence_small", prob = 254},
		{param2 = 2, name = "cottages:fence_small", prob = 254},
		T["_____"], {param2 = 3, name = "lib_ecology:tree_default_wood_door_centered", prob = 254},
		T["_____"], T["_____"], {param2 = 1, name = "beds:fancy_bed_bottom", prob = 254},
		{param2 = 1, name = "beds:fancy_bed_top", prob = 254},
		T["K0m00"], T["_____"], T["_____"], T["_____"], T["_____"], T["_____"], T["_____"], T["K0m00"], T["_____"], T["_____"],
		T["_____"], T["_____"], T["_____"], T["_____"], T["_____"],
		T["_____"], T["_____"], T["_____"], T["_____"], {param2 = 1, name = "cottages:glass_pane", prob = 254},
		{param2 = 3, name = "cottages:window_shutter_open", prob = 254},
		T["_____"], T["_____"], T["_____"], T["_____"], T["_____"], T["K0m00"], T["_____"], T["_____"], T["W0m00"], T["_____"], T["_____"], T["_____"], T["K0m00"], T["TwE00"], T["_____"], T["_____"], T["_____"], T["K0m00"], T["_____"], T["_____"], T["_____"], T["_____"], {param2 = 2, name = "cottages:roof_black", prob = 254},
		{param2 = 2, name = "cottages:roof_black", prob = 254},
		{param2 = 2, name = "cottages:roof_connector_black", prob = 254},
		{param2 = 2, name = "cottages:roof_black", prob = 254},
		{param2 = 2, name = "cottages:roof_black", prob = 254},
		{param2 = 2, name = "cottages:roof_connector_black", prob = 254},
		{param2 = 2, name = "cottages:roof_black", prob = 254},
		{param2 = 2, name = "cottages:roof_black", prob = 254},
		{param2 = 2, name = "cottages:roof_black", prob = 254},
		{param2 = 2, name = "cottages:roof_connector_black", prob = 254},
		{param2 = 2, name = "cottages:roof_black", prob = 254},
		{param2 = 2, name = "cottages:roof_black", prob = 254},
		{param2 = 2, name = "cottages:roof_black", prob = 254},
		{param2 = 2, name = "cottages:roof_black", prob = 254},
		{param2 = 2, name = "cottages:roof_connector_black", prob = 254},
		{param2 = 2, name = "cottages:roof_black", prob = 254},
		T["_____"], T["_____"], T["_____"], T["_____"], T["_____"], T["_____"], T["_____"], T["_____"], T["_____"], T["_____"], T["_____"], T["_____"], T["_____"], T["_____"], T["_____"], T["_____"], T["_____"], T["_____"], T["_____"], T["_____"], T["_____"], T["_____"], T["_____"], T["_____"], T["_____"], T["_____"], T["_____"], T["_____"], T["_____"], T["_____"], T["_____"], T["_____"], T["_____"], T["_____"], T["_____"], T["_____"], T["_____"], T["_____"], T["_____"], T["_____"], T["_____"], T["_____"], T["_____"], T["_____"], T["_____"], T["_____"], T["_____"], T["_____"], T["_____"], T["_____"], T["_____"], T["_____"], T["_____"], T["_____"], T["_____"], T["_____"], T["_____"], T["_____"], T["_____"], T["_____"], T["_____"], T["_____"], T["_____"], T["_____"], T["_____"], T["_____"], T["_____"], T["_____"], T["_____"], T["_____"], T["_____"], T["_____"], T["_____"], T["_____"], T["_____"], T["_____"], T["ddddd"], T["ddddd"], T["ddddd"], T["ddddd"], T["ddddd"], T["ddddd"], T["ddddd"], T["ddddd"], T["ddddd"], T["ddddd"], T["ddddd"], T["ddddd"], T["ddddd"], T["ddddd"], T["ddddd"], T["ddddd"], T["ddddd"], T["ddddd"], T["ddddd"], T["ddddd"], T["ddddd"], T["ddddd"], T["ddddd"], T["ddddd"], T["ddddd"], T["ddddd"], T["C0m00"], T["_____"], T["_____"], T["_____"], T["_____"], T["C0m00"], T["ddddd"], T["ddddd"], T["ddddd"], T["ddddd"], T["ddddd"], T["ddddd"], T["ddddd"], T["ddddd"], T["ddddd"], T["ddddd"], T["ddddd"], T["ddddd"], T["ddddd"], T["C0m00"], T["_____"], T["_____"], T["_____"], T["_____"], T["C0m00"], T["ddddd"], T["ddddd"], T["ddddd"], T["ddddd"], T["ddddd"], T["ddddd"], T["ddddd"], T["ddddd"], T["ddddd"], T["ddddd"], T["ddddd"], T["ddddd"], T["ddddd"], T["C0m00"], T["TwE00"], T["_____"], T["_____"], T["_____"], T["C0m00"], T["ddddd"], T["ddddd"], T["ddddd"], T["ddddd"], T["ddddd"], T["ddddd"], T["C0m00"], T["C0m00"], T["C0m00"], T["C0m00"], T["C0m00"], T["C0m00"], T["K0m00"], T["K0m00"], T["K0m00"], T["K0m00"], T["K0m00"], T["K0m00"], T["K0m00"], T["K0m00"], T["K0m00"], T["K0m00"], T["K0m00"], T["C0m00"], T["C0m00"], T["_____"], T["_____"], T["_____"], T["_____"], T["_____"], T["K0m00"], {param2 = 0, name = "cottages:table", prob = 254},
		{param2 = 0, name = "cottages:table", prob = 254},
		T["_____"], T["Bn0E0"], {param2 = 1, name = "cottages:table", prob = 254},
		T["Bn0W0"], T["_____"], T["_____"], T["_____"], {param2 = 0, name = "cottages:table", prob = 254},
		{param2 = 0, name = "cottages:table", prob = 254},
		T["K0m00"], T["_____"], T["_____"], T["_____"], T["_____"], T["_____"], {param2 = 1, name = "cottages:window_shutter_open", prob = 254},
		{param2 = 3, name = "cottages:glass_pane", prob = 254},
		T["_____"], T["_____"], T["_____"], T["_____"], T["_____"], T["_____"], T["_____"], T["_____"], T["_____"], T["_____"], T["_____"], {param2 = 3, name = "cottages:glass_pane", prob = 254},
		{param2 = 3, name = "cottages:window_shutter_open", prob = 254},
		T["_____"], T["_____"], T["_____"], T["_____"], T["_____"], T["K0m00"], T["W0L20"], T["T0m09"], T["W0L20"], T["W0L20"], T["T0m09"], T["W0L20"], T["C0m00"], T["W0L20"], T["W0L20"], T["T0m09"], T["W0L20"], T["K0m00"], T["_____"], T["_____"], T["_____"], T["_____"], T["_____"], T["_____"], T["K0m00"], T["_____"], {param2 = 2, name = "beds:fancy_bed_bottom", prob = 254},
		{param2 = 2, name = "beds:fancy_bed_bottom", prob = 254},
		T["_____"], T["W0m00"], T["_____"], T["C0m00"], T["_____"], {param2 = 2, name = "beds:fancy_bed_bottom", prob = 254},
		{param2 = 2, name = "beds:fancy_bed_bottom", prob = 254},
		T["_____"], T["K0m00"], T["_____"], T["_____"], T["_____"], T["_____"], T["_____"], {param2 = 1, name = "cottages:window_shutter_open", prob = 254},
		{param2 = 3, name = "cottages:glass_pane", prob = 254},
		T["_____"], T["_____"], T["_____"], T["_____"], T["W0m00"], T["_____"], T["W0m00"], T["_____"], T["_____"], T["_____"], T["_____"], {param2 = 3, name = "cottages:glass_pane", prob = 254},
		{param2 = 3, name = "cottages:window_shutter_open", prob = 254},
		T["_____"], T["_____"], T["_____"], T["_____"], T["_____"], T["K0m00"], T["W0L20"], T["T0m09"], T["W0L20"], T["W0L20"], T["T0m09"], T["W0L20"], T["T0m09"], T["W0L20"], T["W0L20"], T["W0L20"], T["W0L20"], T["T0m09"], T["_____"], T["_____"], T["_____"], T["_____"], T["_____"], T["_____"], T["K0m00"], T["_____"], {param2 = 0, name = "beds:fancy_bed_bottom", prob = 254},
		T["W0m00"], T["_____"], T["_____"], T["Cs0N0"], T["K0m00"], T["_____"], T["_____"], {param2 = 1, name = "beds:fancy_bed_bottom", prob = 254},
		{param2 = 1, name = "beds:fancy_bed_top", prob = 254},
		T["K0m00"], T["_____"], T["_____"], T["_____"], T["_____"], T["_____"], {param2 = 1, name = "cottages:window_shutter_open", prob = 254},
		{param2 = 3, name = "cottages:glass_pane", prob = 254},
		T["_____"], T["_____"], T["W0m00"], T["_____"], T["_____"], T["Cs0N0"], T["K0m00"], T["_____"], T["_____"], T["_____"], T["_____"], T["K0m00"], T["_____"], T["_____"], T["_____"], T["_____"], T["_____"], {param2 = 2, name = "cottages:roof_black", prob = 254},
		{param2 = 2, name = "cottages:roof_connector_black", prob = 254},
		{param2 = 2, name = "cottages:roof_black", prob = 254},
		{param2 = 2, name = "cottages:roof_black", prob = 254},
		{param2 = 2, name = "cottages:roof_connector_black", prob = 254},
		{param2 = 2, name = "cottages:roof_black", prob = 254},
		{param2 = 2, name = "cottages:roof_black", prob = 254},
		{param2 = 2, name = "cottages:roof_black", prob = 254},
		{param2 = 2, name = "cottages:roof_connector_black", prob = 254},
		{param2 = 2, name = "cottages:roof_black", prob = 254},
		{param2 = 2, name = "cottages:roof_black", prob = 254},
		{param2 = 2, name = "cottages:roof_black", prob = 254},
		{param2 = 2, name = "cottages:roof_black", prob = 254},
		{param2 = 2, name = "cottages:roof_connector_black", prob = 254},
		{param2 = 2, name = "cottages:roof_black", prob = 254},
		T["_____"], T["_____"], T["_____"], T["_____"], T["_____"], T["_____"], T["_____"], T["_____"], T["_____"], T["_____"], T["_____"], T["_____"], T["_____"], T["_____"], T["_____"], T["_____"], T["_____"], T["_____"], T["_____"], T["_____"], T["_____"], T["_____"], T["_____"], T["_____"], T["_____"], T["_____"], T["_____"], T["_____"], T["_____"], T["_____"], T["_____"], T["_____"], T["_____"], T["_____"], T["_____"], T["_____"], T["_____"], T["_____"], T["_____"], T["_____"], T["_____"], T["_____"], T["_____"], T["_____"], T["_____"], T["_____"], T["_____"], T["_____"], T["_____"], T["_____"], T["_____"], T["_____"], T["_____"], T["_____"], T["_____"], T["_____"], T["_____"], T["_____"], T["_____"], T["_____"], T["_____"], T["_____"], T["_____"], T["_____"], T["_____"], T["_____"], T["_____"], T["_____"], T["_____"], T["_____"], T["_____"], T["_____"], T["_____"], T["_____"], T["_____"], T["_____"], T["_____"], T["_____"], T["_____"], T["_____"], T["_____"], T["_____"], T["_____"], T["_____"], T["_____"], T["_____"], T["_____"], T["_____"], T["_____"], T["_____"], T["_____"], T["_____"], T["_____"], T["_____"], T["_____"], T["ddddd"], T["ddddd"], T["ddddd"], T["ddddd"], T["ddddd"], T["ddddd"], T["ddddd"], T["ddddd"], T["ddddd"], T["ddddd"], T["ddddd"], T["ddddd"], T["ddddd"], T["ddddd"], T["ddddd"], T["ddddd"], T["ddddd"], T["ddddd"], T["ddddd"], T["ddddd"], T["ddddd"], T["ddddd"], T["ddddd"], T["ddddd"], T["ddddd"], T["ddddd"], T["C0m00"], {param2 = 1, name = "cottages:barrel_lying", prob = 254},
		{param2 = 1, name = "cottages:barrel_lying", prob = 254},
		{param2 = 1, name = "cottages:barrel_lying", prob = 254},
		T["_____"], T["C0m00"], T["ddddd"], T["ddddd"], T["ddddd"], T["ddddd"], T["ddddd"], T["ddddd"], T["ddddd"], T["ddddd"], T["ddddd"], T["ddddd"], T["ddddd"], T["ddddd"], T["ddddd"], T["C0m00"], T["_____"], T["_____"], T["_____"], T["_____"], T["C0m00"], T["ddddd"], T["ddddd"], T["ddddd"], T["ddddd"], T["ddddd"], T["ddddd"], T["ddddd"], T["ddddd"], T["ddddd"], T["ddddd"], T["ddddd"], T["ddddd"], T["ddddd"], T["C0m00"], T["C0S20"], T["C0S20"], T["C0S20"], T["C0S20"], T["C0m00"], T["ddddd"], T["ddddd"], T["ddddd"], T["ddddd"], T["ddddd"], T["ddddd"], T["C0m00"], T["ddddd"], T["C0m00"], T["C0m00"], T["C0m00"], T["C0m00"], T["K0m00"], T["K0m00"], T["K0m00"], T["K0m00"], T["K0m00"], T["K0m00"], T["K0m00"], T["K0m00"], T["K0m00"], T["K0m00"], T["K0m00"], T["C0m00"], T["C0m00"], T["_____"], T["P0m00"], T["_____"], T["_____"], T["_____"], T["K0m00"], T["Bn0N0"], T["Bn0N0"], {param2 = 9, name = "cottages:wood_flat", prob = 254},
		{param2 = 9, name = "cottages:wood_flat", prob = 254},
		T["_____"], T["_____"], T["Bn0E0"], {param2 = 1, name = "cottages:table", prob = 254},
		T["Bn0W0"], T["Bn0N0"], T["Bn0N0"], T["K0m00"], T["_____"], T["_____"], T["_____"], T["_____"], T["_____"], T["_____"], T["K0m00"], T["TwS00"], T["_____"], T["_____"], T["_____"], T["_____"], T["_____"], T["_____"], T["_____"], T["_____"], T["_____"], T["TwN00"], T["K0m00"], T["_____"], T["_____"], T["_____"], T["_____"], T["_____"], T["_____"], T["K0m00"], T["W0L20"], T["T0m09"], T["W0L20"], T["W0L20"], T["T0m09"], T["W0L20"], T["C0m00"], T["W0L20"], T["W0L20"], T["T0m09"], T["W0L20"], T["K0m00"], T["_____"], T["_____"], T["_____"], T["_____"], T["_____"], T["_____"], T["K0m00"], T["_____"], T["_____"], T["_____"], T["_____"], {param2 = 3, name = "lib_ecology:tree_default_wood_door_centered", prob = 254},
		T["_____"], {param2 = 3, name = "lib_ecology:tree_default_wood_door_centered", prob = 254},
		T["_____"], T["_____"], T["_____"], T["_____"], T["K0m00"], T["_____"], T["_____"], T["_____"], T["_____"], T["_____"], T["_____"], T["K0m00"], T["_____"], T["_____"], T["_____"], T["_____"], T["_____"],
		T["_____"], T["_____"],
		T["_____"], T["_____"], T["_____"], T["_____"], T["K0m00"], T["_____"], T["_____"], T["_____"], T["_____"], T["_____"], T["_____"], T["K0m00"], T["W0L20"], T["T0m09"], T["W0L20"], T["W0L20"], T["T0m09"], T["W0L20"], T["T0m09"], T["W0L20"], T["W0L20"], T["W0L20"], T["W0L20"], T["T0m09"], T["_____"], T["_____"], T["_____"], T["_____"], T["_____"], T["_____"], T["K0m00"], T["_____"], {param2 = 0, name = "beds:fancy_bed_top", prob = 254},
		T["W0m00"], T["W0m00"], {param2 = 0, name = "lib_ecology:tree_default_wood_door_centered", prob = 254},
		T["W0m00"], T["K0m00"], T["_____"], T["_____"], T["_____"], T["_____"], T["K0m00"], T["_____"], T["_____"], T["_____"], T["_____"], T["_____"], {param2 = 2, name = "cottages:roof_black", prob = 254},
		{param2 = 2, name = "cottages:roof_connector_black", prob = 254},
		{param2 = 2, name = "cottages:roof_black", prob = 254},
		{param2 = 2, name = "cottages:roof_black", prob = 254},
		{param2 = 1, name = "cottages:roof_connector_black", prob = 254},
		T["W0m00"], T["_____"],
		{param2 = 3, name = "cottages:roof_connector_black", prob = 254},
		{param2 = 2, name = "cottages:roof_connector_black", prob = 254},
		{param2 = 2, name = "cottages:roof_black", prob = 254},
		{param2 = 2, name = "cottages:roof_black", prob = 254},
		{param2 = 2, name = "cottages:roof_black", prob = 254},
		{param2 = 2, name = "cottages:roof_black", prob = 254},
		{param2 = 2, name = "cottages:roof_connector_black", prob = 254},
		{param2 = 2, name = "cottages:roof_black", prob = 254},
		T["_____"], T["_____"], T["_____"], T["_____"], T["_____"], T["_____"], T["_____"], T["_____"], T["_____"], {param2 = 1, name = "cottages:roof_connector_black", prob = 254},
		{param2 = 3, name = "cottages:roof_black", prob = 254},
		T["_____"], T["_____"], T["_____"], T["_____"], T["_____"], T["_____"], T["_____"], T["_____"], T["_____"], T["_____"], T["_____"], T["_____"], T["_____"], T["_____"], T["_____"], T["_____"], T["_____"], T["_____"], T["_____"], T["_____"], T["_____"], T["_____"], T["_____"], T["_____"], T["_____"], T["_____"], T["_____"], T["_____"], T["_____"], T["_____"], T["_____"], T["_____"], T["_____"], T["_____"], T["_____"], T["_____"], T["_____"], T["_____"], T["_____"], T["_____"], T["_____"], T["_____"], T["_____"], T["_____"], T["_____"], T["_____"], T["_____"], T["_____"], T["_____"], T["_____"], T["_____"], T["_____"], T["_____"], T["_____"], T["_____"], T["_____"], T["_____"], T["_____"], T["_____"], T["_____"], T["_____"], T["_____"], T["_____"], T["_____"], T["_____"], T["_____"], T["_____"], T["_____"], T["_____"], T["_____"], T["_____"], T["_____"], T["_____"], T["_____"], T["_____"], T["_____"], T["_____"], T["_____"], T["_____"], T["_____"], T["_____"], T["_____"], T["_____"], T["_____"], T["_____"], T["_____"], T["_____"], T["_____"], T["_____"], T["_____"], T["_____"], T["_____"], T["_____"], T["_____"], T["_____"], T["_____"], T["_____"], T["_____"], T["_____"], T["_____"], T["_____"], T["_____"], T["_____"], T["ddddd"], T["ddddd"], T["ddddd"], T["ddddd"], T["ddddd"], T["ddddd"], T["ddddd"], T["ddddd"], T["ddddd"], T["ddddd"], T["ddddd"], T["ddddd"], T["ddddd"], T["ddddd"], T["ddddd"], T["ddddd"], T["ddddd"], T["ddddd"], T["ddddd"], T["ddddd"], T["ddddd"], T["ddddd"], T["ddddd"], T["ddddd"], T["ddddd"], T["ddddd"], T["C0m00"], T["C0m00"], T["C0m00"], T["C0m00"], {param2 = 2, name = "lib_ecology:tree_default_wood_door_centered", prob = 254},
		T["C0m00"], T["C0m00"], T["C0m00"], T["C0m00"], T["C0m00"], T["ddddd"], T["ddddd"], T["ddddd"], T["ddddd"], T["ddddd"], T["ddddd"], T["ddddd"], T["ddddd"], T["ddddd"], T["C0m00"], T["C0m00"], T["C0m00"], T["C0m00"], T["_____"],
		T["C0m00"], T["C0m00"], T["C0m00"], T["C0m00"], T["C0m00"], T["ddddd"], T["ddddd"], T["ddddd"], T["ddddd"], T["ddddd"], T["ddddd"], T["ddddd"], T["ddddd"], T["ddddd"], T["C0m00"], T["C0m00"], T["C0m00"], T["C0m00"], T["C0m00"], T["C0m00"], T["C0m00"], T["C0m00"], T["C0m00"], T["C0m00"], T["ddddd"], T["ddddd"], T["C0m00"], T["C0m00"], T["C0m00"], T["C0m00"], T["C0m00"], T["C0m00"], T["C0m00"], T["C0m00"], T["C0m00"], T["C0m00"], T["C0m00"], T["C0m00"], {param2 = 2, name = "default:cobble", prob = 254},
		T["K0m00"], T["K0m00"], T["C0m00"], T["C0m00"], T["C0m00"], T["C0m00"], T["_____"], T["_____"], T["_____"], T["_____"], T["_____"], T["_____"], T["K0m00"], T["T0m02"], {param2 = 3, name = "cottages:barrel_lying", prob = 254},
		{param2 = 1, name = "cottages:barrel_lying", prob = 254},
		T["T0m02"], {param2 = 2, name = "cottages:half_door", prob = 254},
		T["T0m02"], {param2 = 1, name = "cottages:table", prob = 254},
		T["Bn0W0"], T["T0m02"], T["K0m00"], T["T0m02"], T["_____"], T["_____"], T["_____"], T["_____"], T["_____"], T["_____"], T["_____"], T["K0m00"], T["T0m02"], {param2 = 0, name = "cottages:wood_flat", prob = 254},
		{param2 = 0, name = "cottages:wood_flat", prob = 254},
		T["T0m02"], T["_____"], T["T0m02"], T["_____"], T["_____"], T["T0m02"], T["K0m00"], T["T0m02"], T["_____"], T["_____"], T["_____"], T["_____"], T["_____"], T["_____"], T["_____"], T["K0m00"], T["T0m02"], T["T0m12"], T["T0m12"], T["T0m09"], T["T0m12"], T["T0m02"], T["T0m12"], T["T0m12"], T["T0m09"], T["T0m12"], T["T0m02"], T["_____"], T["_____"], T["_____"], T["_____"], T["_____"], T["_____"], T["_____"], T["K0m00"], T["T0m02"], T["W0m00"], T["W0m00"], T["T0m02"], T["_____"], T["T0m02"], T["K0m00"], T["K0m00"], T["K0m00"], T["K0m00"], T["T0m02"], T["_____"], T["_____"], T["_____"], T["_____"], T["_____"], T["_____"], T["_____"], T["K0m00"], T["T0m00"], T["W0m00"], T["W0m00"], T["T0m02"], T["_____"], T["T0m00"], T["K0m00"], {param2 = 2, name = "cottages:glass_pane", prob = 254},
		T["K0m00"], T["K0m00"], T["T0m02"], T["_____"], T["_____"], T["_____"], T["_____"], T["_____"], T["_____"], T["_____"], T["W0m00"], T["T0m09"], T["W0m00"], T["W0m00"], T["T0m09"], T["T0m12"], T["T0m09"], T["T0m12"], T["T0m12"], T["T0m12"], T["T0m12"], T["T0m09"], T["_____"], T["_____"], T["_____"], T["_____"], T["_____"], T["_____"], {param2 = 2, name = "cottages:roof_black", prob = 254},
		{param2 = 2, name = "cottages:roof_connector_black", prob = 254},
		{param2 = 2, name = "cottages:roof_black", prob = 254},
		T["W0m00"], T["Cs0S0"], T["_____"], T["Cs0S0"], {param2 = 3, name = "cottages:roof_black", prob = 254},
		{param2 = 2, name = "cottages:roof_black", prob = 254},
		{param2 = 2, name = "cottages:roof_black", prob = 254},
		{param2 = 2, name = "cottages:roof_black", prob = 254},
		{param2 = 2, name = "cottages:roof_black", prob = 254},
		{param2 = 2, name = "cottages:roof_connector_black", prob = 254},
		{param2 = 2, name = "cottages:roof_black", prob = 254},
		T["_____"], T["_____"], T["_____"], T["_____"], T["_____"], T["_____"], T["_____"], T["_____"], {param2 = 1, name = "cottages:roof_black", prob = 254},
		T["TwW00"], T["_____"], {param2 = 3, name = "cottages:roof_black", prob = 254},
		T["_____"], T["_____"], T["_____"], T["_____"], T["_____"], T["_____"], T["_____"], T["_____"], T["_____"], T["_____"], T["_____"], T["_____"], T["_____"], T["_____"], T["_____"], T["_____"], {param2 = 1, name = "cottages:roof_black", prob = 254},
		{param2 = 3, name = "cottages:roof_black", prob = 254},
