



local T = lib_towns.schems.T


return {
	size = {x = 7,y = 7,z = 7},
	data = {
		T["_____"], T["_____"], T["C0S20"], T["C0S00"], T["C0S20"], T["_____"], T["_____"],
		T["_____"], T["_____"], T["W0n00"], T["_____"], T["W0n00"], T["_____"], T["_____"],
		T["_____"], T["_____"], T["W0n00"], T["_____"], T["W0n00"], T["_____"], T["_____"],
		T["_____"], T["_____"], T["W0L00"], T["W0L20"], T["W0L00"], T["_____"], T["_____"],
		T["_____"], T["_____"], T["_____"], T["_____"], T["_____"], T["_____"], T["_____"],
		T["_____"], T["_____"], T["_____"], T["_____"], T["_____"], T["_____"], T["_____"],
		T["_____"], T["_____"], T["_____"], T["_____"], T["_____"], T["_____"], T["_____"],

		T["_____"], T["C0m00"], T["C0m00"], T["C0m00"], T["C0m00"], T["C0m00"], T["_____"],
		T["_____"], T["C0m00"], T["W0m00"], T["W0dS0"], T["W0m00"], T["C0m00"], T["_____"],
		T["_____"], T["C0m00"], T["W0m00"], T["_____"], T["W0m00"], T["C0m00"], T["_____"],
		T["_____"], T["C0m00"], T["W0m00"], T["W0m00"], T["W0m00"], T["C0m00"], T["_____"],
		T["_____"], T["T0m00"], T["T0m12"], T["T0m12"], T["T0m12"], T["T0m00"], T["_____"],
		T["_____"], T["W0n00"], T["W0n00"], T["W0n00"], T["W0n00"], T["W0n00"], T["_____"],
		T["_____"], T["_____"], T["_____"], T["_____"], T["_____"], T["_____"], T["_____"],

		T["_____"], T["C0m00"], T["C0m00"], T["C0m00"], T["C0m00"], T["C0m00"], T["_____"],
		T["_____"], T["W0m00"], T["_____"], T["_____"], T["_____"], T["W0m00"], T["_____"],
		T["W0n00"], T["W0m00"], T["_____"], T["_____"], T["_____"], T["W0m00"], T["W0n00"],
		T["W0L00"], T["W0m00"], T["_____"], T["_____"], T["_____"], T["W0m00"], T["W0L00"],
		T["_____"], T["T0m06"], T["W0m00"], T["W0m00"], T["W0m00"], T["T0m06"], T["_____"],
		T["_____"], T["W0n00"], T["_____"], T["_____"], T["_____"], T["W0n00"], T["_____"],
		T["_____"], T["_____"], T["_____"], T["_____"], T["_____"], T["_____"], T["_____"],

		T["_____"], T["C0m00"], T["C0m00"], T["C0m00"], T["C0m00"], T["C0m00"], T["_____"],
		T["_____"], T["W0m00"], T["Bb0N0"], T["_____"], T["_____"], T["W0m00"], T["_____"],
		T["_____"], T["Xp0W0"], T["_____"], T["_____"], T["_____"], T["Xp0W0"], T["_____"],
		T["W0L23"], T["W0m00"], T["_____"], T["_____"], T["_____"], T["W0m00"], T["W0L21"],
		T["_____"], T["T0m06"], T["W0m00"], T["W0m00"], T["W0m00"], T["T0m06"], T["_____"],
		T["_____"], T["W0n00"], T["_____"], T["_____"], T["_____"], T["W0n00"], T["_____"],
		T["_____"], T["_____"], T["_____"], T["_____"], T["_____"], T["_____"], T["_____"],

		T["_____"], T["C0m00"], T["C0m00"], T["C0m00"], T["C0m00"], T["C0m00"], T["_____"],
		T["_____"], T["W0m00"], T["Bt0N0"], T["Cs0N0"], T["Ld0E0"], T["W0m00"], T["_____"],
		T["W0n00"], T["W0m00"], T["_____"], T["_____"], T["Ld0E0"], T["W0m00"], T["W0n00"],
		T["W0L00"], T["W0m00"], T["_____"], T["_____"], T["Ld0E0"], T["W0m00"], T["W0L00"],
		T["_____"], T["T0m06"], T["W0m00"], T["W0m00"], T["Ld0E0"], T["T0m06"], T["_____"],
		T["_____"], T["W0n00"], T["_____"], T["_____"], T["W0TN0"], T["W0n00"], T["_____"],
		T["_____"], T["_____"], T["_____"], T["_____"], T["_____"], T["_____"], T["_____"],

		T["_____"], T["C0m00"], T["C0m00"], T["C0m00"], T["C0m00"], T["C0m00"], T["_____"],
		T["_____"], T["C0m00"], T["W0m00"], T["W0m00"], T["W0m00"], T["C0m00"], T["_____"],
		T["_____"], T["C0m00"], T["W0m00"], T["Xp0N0"], T["W0m00"], T["C0m00"], T["_____"],
		T["_____"], T["C0m00"], T["W0m00"], T["W0m00"], T["W0m00"], T["C0m00"], T["_____"],
		T["_____"], T["T0m00"], T["T0m12"], T["T0m12"], T["T0m12"], T["T0m00"], T["_____"],
		T["_____"], T["W0n00"], T["W0n00"], T["W0n00"], T["W0n00"], T["W0n00"], T["_____"],
		T["_____"], T["_____"], T["_____"], T["_____"], T["_____"], T["_____"], T["_____"],

		T["_____"], T["_____"], T["_____"], T["_____"], T["_____"], T["_____"], T["_____"],
		T["_____"], T["_____"], T["_____"], T["_____"], T["_____"], T["_____"], T["_____"],
		T["_____"], T["_____"], T["W0n00"], T["_____"], T["W0n00"], T["_____"], T["_____"],
		T["_____"], T["_____"], T["W0L00"], T["W0L22"], T["W0L00"], T["_____"], T["_____"],
		T["_____"], T["_____"], T["_____"], T["_____"], T["_____"], T["_____"], T["_____"],
		T["_____"], T["_____"], T["_____"], T["_____"], T["_____"], T["_____"], T["_____"],
		T["_____"], T["_____"], T["_____"], T["_____"], T["_____"], T["_____"], T["_____"],
	},
	yslice_prob = {
		{prob = 254,ypos = 0},
		{prob = 254,ypos = 1},
		{prob = 254,ypos = 2},
		{prob = 254,ypos = 3},
		{prob = 254,ypos = 4},
		{prob = 254,ypos = 5},
		{prob = 254,ypos = 6}
	}
}