



local T = lib_towns.schems.T


return {
	size = {x = 11,y = 10,z = 8},
	data = {
		T["_____"], T["_____"], T["_____"], T["_____"], T["_____"], T["_____"], T["_____"], T["_____"], T["C0S00"], T["_____"], T["_____"],
		T["_____"], T["_____"], T["_____"], T["_____"], T["_____"], T["_____"], T["_____"], T["_____"], T["_____"], T["_____"], T["_____"],
		T["_____"], T["_____"], T["_____"], T["_____"], T["_____"], T["_____"], T["_____"], T["_____"], T["_____"], T["_____"], T["_____"],
		T["_____"], T["_____"], T["_____"], T["_____"], T["_____"], T["_____"], T["_____"], T["_____"], T["_____"], T["_____"], T["_____"],
		T["K0S20"], T["K0S20"], T["K0S20"], T["K0S20"], T["K0S20"], T["K0S20"], T["K0S20"], T["K0S20"], T["K0S20"], T["K0S20"], T["K0S20"],
		T["K0S00"], T["W0S00"], T["W0S00"], T["W0S00"], T["W0S00"], T["W0S00"], T["W0S00"], T["W0S00"], T["W0S00"], T["W0S00"], T["K0S00"],
		T["_____"], T["_____"], T["_____"], T["_____"], T["_____"], T["_____"], T["_____"], T["_____"], T["_____"], T["_____"], T["_____"],
		T["_____"], T["_____"], T["_____"], T["_____"], T["_____"], T["_____"], T["_____"], T["_____"], T["_____"], T["_____"], T["_____"],
		T["_____"], T["_____"], T["_____"], T["_____"], T["_____"], T["_____"], T["_____"], T["_____"], T["_____"], T["_____"], T["_____"],
		T["_____"], T["_____"], T["_____"], T["_____"], T["_____"], T["_____"], T["_____"], T["_____"], T["_____"], T["_____"], T["_____"],

		T["_____"], T["C0m00"], T["C0m00"], T["C0m00"], T["C0m00"], T["C0m00"], T["C0m00"], T["C0m00"], T["C0m00"], T["C0m00"], T["_____"],
		T["_____"], T["C0m00"], T["K0m00"], T["K0S20"], T["K0S20"], T["K0S20"], T["K0S20"], T["K0m00"], T["W0dS0"], T["C0m00"], T["_____"],
		T["_____"], T["C0m00"], T["W0m00"], T["Xp0N0"], T["Xp0N0"], T["Xp0N0"], T["Xp0N0"], T["W0m00"], T["_____"], T["C0m00"], T["_____"],
		T["_____"], T["C0m00"], T["W0m00"], T["Xp0N0"], T["Xp0N0"], T["Xp0N0"], T["Xp0N0"], T["W0m00"], T["C0S20"], T["C0m00"], T["_____"],
		T["_____"], T["C0m00"], T["W0m00"], T["W0S20"], T["W0S20"], T["W0S20"], T["W0S20"], T["W0m00"], T["C0m00"], T["C0m00"], T["_____"],
		T["K0S22"], T["C0m00"], T["C0m00"], T["C0m00"], T["C0m00"], T["C0m00"], T["C0m00"], T["C0m00"], T["C0m00"], T["C0m00"], T["K0S22"],
		T["K0S00"], T["W0S00"], T["W0S00"], T["W0S00"], T["W0S00"], T["W0S00"], T["W0S00"], T["W0S00"], T["W0S00"], T["W0S00"], T["K0S00"],
		T["_____"], T["_____"], T["_____"], T["_____"], T["_____"], T["_____"], T["_____"], T["_____"], T["_____"], T["_____"], T["_____"],
		T["_____"], T["_____"], T["_____"], T["_____"], T["_____"], T["_____"], T["_____"], T["_____"], T["_____"], T["_____"], T["_____"],
		T["_____"], T["_____"], T["_____"], T["_____"], T["_____"], T["_____"], T["_____"], T["_____"], T["_____"], T["_____"], T["_____"],

		T["_____"], T["C0m00"], T["C0m00"], T["C0m00"], T["C0m00"], T["C0m00"], T["C0m00"], T["C0m00"], T["C0m00"], T["C0m00"], T["_____"],
		T["_____"], T["K0m00"], T["Cs0W0"], T["_____"], T["_____"], T["_____"], T["_____"], T["_____"], T["_____"], T["K0m00"], T["_____"],
		T["_____"], T["W0m00"], T["_____"], T["_____"], T["_____"], T["_____"], T["_____"], T["TwW00"], T["_____"], T["W0m00"], T["_____"],
		T["_____"], T["W0m00"], T["_____"], T["_____"], T["_____"], T["_____"], T["_____"], T["_____"], T["_____"], T["W0m00"], T["_____"],
		T["_____"], T["W0m00"], T["W0m00"], T["W0m00"], T["W0m00"], T["W0m00"], T["W0m00"], T["W0m00"], T["W0m00"], T["W0m00"], T["_____"],
		T["_____"], T["C0m00"], T["C0m00"], T["C0m00"], T["C0m00"], T["C0m00"], T["C0m00"], T["C0m00"], T["C0m00"], T["C0m00"], T["_____"],
		T["K0S22"], T["C0m00"], T["C0m00"], T["C0m00"], T["C0m00"], T["C0m00"], T["C0m00"], T["C0m00"], T["C0m00"], T["C0m00"], T["K0S22"],
		T["K0S00"], T["W0S00"], T["W0S00"], T["W0S00"], T["W0S00"], T["W0S00"], T["W0S00"], T["W0S00"], T["W0S00"], T["W0S00"], T["K0S00"],
		T["_____"], T["_____"], T["_____"], T["_____"], T["_____"], T["_____"], T["_____"], T["_____"], T["_____"], T["_____"], T["_____"],
		T["_____"], T["_____"], T["_____"], T["_____"], T["_____"], T["_____"], T["_____"], T["_____"], T["_____"], T["_____"], T["_____"],

		T["_____"], T["C0m00"], T["C0m00"], T["C0m00"], T["C0m00"], T["C0m00"], T["C0m00"], T["C0m00"], T["C0m00"], T["C0m00"], T["_____"],
		T["_____"], T["K0S23"], T["SwE00"], T["_____"], T["_____"], T["_____"], T["_____"], T["_____"], T["_____"], T["K0S21"], T["_____"],
		T["_____"], T["Xp0W0"], T["_____"], T["_____"], T["_____"], T["_____"], T["_____"], T["_____"], T["_____"], T["Xp0W0"], T["_____"],
		T["_____"], T["Xp0W0"], T["_____"], T["_____"], T["_____"], T["_____"], T["_____"], T["_____"], T["_____"], T["Xp0W0"], T["_____"],
		T["_____"], T["W0S23"], T["_____"], T["_____"], T["_____"], T["_____"], T["_____"], T["_____"], T["_____"], T["W0S21"], T["_____"],
		T["_____"], T["C0m00"], T["_____"], T["_____"], T["_____"], T["_____"], T["_____"], T["_____"], T["_____"], T["C0m00"], T["_____"],
		T["_____"], T["C0S22"], T["_____"], T["_____"], T["_____"], T["_____"], T["_____"], T["_____"], T["_____"], T["C0S22"], T["_____"],
		T["K0S22"], T["C0m00"], T["C0m00"], T["C0m00"], T["C0m00"], T["C0m00"], T["C0m00"], T["C0m00"], T["C0m00"], T["C0m00"], T["K0S22"],
		T["K0S00"], T["W0S00"], T["W0S00"], T["W0S00"], T["W0S00"], T["W0S00"], T["W0S00"], T["W0S00"], T["W0S00"], T["W0S00"], T["K0S00"],
		T["_____"], T["_____"], T["_____"], T["_____"], T["_____"], T["_____"], T["_____"], T["_____"], T["_____"], T["_____"], T["_____"],

		T["_____"], T["C0m00"], T["C0m00"], T["C0m00"], T["C0m00"], T["C0m00"], T["C0m00"], T["C0m00"], T["C0m00"], T["C0m00"], T["_____"],
		T["_____"], T["K0S23"], T["W0S03"], T["W0n00"], T["_____"], T["W0n00"], T["_____"], T["_____"], T["_____"], T["K0S21"], T["_____"],
		T["_____"], T["Xp0W0"], T["_____"], T["SwN00"], T["_____"], T["SwN00"], T["_____"], T["_____"], T["_____"], T["Xp0W0"], T["_____"],
		T["_____"], T["Xp0W0"], T["_____"], T["_____"], T["_____"], T["_____"], T["_____"], T["_____"], T["_____"], T["Xp0W0"], T["_____"],
		T["_____"], T["W0S23"], T["_____"], T["_____"], T["_____"], T["_____"], T["_____"], T["_____"], T["_____"], T["W0S21"], T["_____"],
		T["_____"], T["C0m00"], T["_____"], T["_____"], T["_____"], T["_____"], T["_____"], T["_____"], T["_____"], T["C0m00"], T["_____"],
		T["_____"], T["C0S20"], T["_____"], T["_____"], T["_____"], T["_____"], T["_____"], T["_____"], T["_____"], T["C0S20"], T["_____"],
		T["K0S20"], T["C0m00"], T["C0m00"], T["C0m00"], T["C0m00"], T["C0m00"], T["C0m00"], T["C0m00"], T["C0m00"], T["C0m00"], T["K0S20"],
		T["K0S02"], T["W0S02"], T["W0S02"], T["W0S02"], T["W0S02"], T["W0S02"], T["W0S02"], T["W0S02"], T["W0S02"], T["W0S02"], T["K0S02"],
		T["_____"], T["_____"], T["_____"], T["_____"], T["_____"], T["_____"], T["_____"], T["_____"], T["_____"], T["_____"], T["_____"],

		T["_____"], T["C0m00"], T["C0m00"], T["C0m00"], T["C0m00"], T["C0m00"], T["C0m00"], T["C0m00"], T["C0m00"], T["C0m00"], T["_____"],
		T["_____"], T["K0m00"], T["_____"], T["W0S00"], T["W0S00"], T["W0S00"], T["SwS00"], T["_____"], T["_____"], T["K0m00"], T["_____"],
		T["_____"], T["W0m00"], T["_____"], T["_____"], T["_____"], T["_____"], T["_____"], T["_____"], T["_____"], T["W0m00"], T["_____"],
		T["_____"], T["W0m00"], T["Bs0N0"], T["Bs0N0"], T["Bs0N0"], T["Bs0N0"], T["Bs0N0"], T["Bs0N0"], T["Bs0N0"], T["W0m00"], T["_____"],
		T["_____"], T["W0m00"], T["W0m00"], T["W0m00"], T["W0m00"], T["W0m00"], T["W0m00"], T["W0m00"], T["W0m00"], T["W0m00"], T["_____"],
		T["_____"], T["C0m00"], T["C0m00"], T["C0m00"], T["C0m00"], T["C0m00"], T["C0m00"], T["C0m00"], T["C0m00"], T["C0m00"], T["_____"],
		T["K0S20"], T["C0m00"], T["C0m00"], T["C0m00"], T["C0m00"], T["C0m00"], T["C0m00"], T["C0m00"], T["C0m00"], T["C0m00"], T["K0S20"],
		T["K0S02"], T["W0S02"], T["W0S02"], T["W0S02"], T["W0S02"], T["W0S02"], T["W0S02"], T["W0S02"], T["W0S02"], T["W0S02"], T["K0S02"],
		T["_____"], T["_____"], T["_____"], T["_____"], T["_____"], T["_____"], T["_____"], T["_____"], T["_____"], T["_____"], T["_____"],
		T["_____"], T["_____"], T["_____"], T["_____"], T["_____"], T["_____"], T["_____"], T["_____"], T["_____"], T["_____"], T["_____"],

		T["_____"], T["C0m00"], T["C0m00"], T["C0m00"], T["C0m00"], T["C0m00"], T["C0m00"], T["C0m00"], T["C0m00"], T["C0m00"], T["_____"],
		T["_____"], T["C0m00"], T["K0m00"], T["K0S22"], T["K0S22"], T["K0m00"], T["K0S22"], T["K0S22"], T["K0m00"], T["C0m00"], T["_____"],
		T["_____"], T["C0m00"], T["W0m00"], T["Xp0N0"], T["Xp0N0"], T["W0m00"], T["Xp0N0"], T["Xp0N0"], T["W0m00"], T["C0m00"], T["_____"],
		T["_____"], T["C0m00"], T["W0m00"], T["W0S22"], T["W0S22"], T["W0m00"], T["W0S22"], T["W0S22"], T["W0m00"], T["C0m00"], T["_____"],
		T["_____"], T["C0m00"], T["C0m00"], T["C0m00"], T["C0m00"], T["C0m00"], T["C0m00"], T["C0m00"], T["C0m00"], T["C0m00"], T["_____"],
		T["K0S20"], T["C0m00"], T["C0m00"], T["C0m00"], T["C0m00"], T["C0m00"], T["C0m00"], T["C0m00"], T["C0m00"], T["C0m00"], T["K0S20"],
		T["K0S02"], T["W0S02"], T["W0S02"], T["W0S02"], T["W0S02"], T["W0S02"], T["W0S02"], T["W0S02"], T["W0S02"], T["W0S02"], T["K0S02"],
		T["_____"], T["_____"], T["_____"], T["_____"], T["_____"], T["_____"], T["_____"], T["_____"], T["_____"], T["_____"], T["_____"],
		T["_____"], T["_____"], T["_____"], T["_____"], T["_____"], T["_____"], T["_____"], T["_____"], T["_____"], T["_____"], T["_____"],
		T["_____"], T["_____"], T["_____"], T["_____"], T["_____"], T["_____"], T["_____"], T["_____"], T["_____"], T["_____"], T["_____"],

		T["_____"], T["_____"], T["_____"], T["_____"], T["_____"], T["_____"], T["_____"], T["_____"], T["_____"], T["_____"], T["_____"],
		T["_____"], T["_____"], T["_____"], T["_____"], T["_____"], T["_____"], T["_____"], T["_____"], T["_____"], T["_____"], T["_____"],
		T["_____"], T["_____"], T["_____"], T["_____"], T["_____"], T["_____"], T["_____"], T["_____"], T["_____"], T["_____"], T["_____"],
		T["_____"], T["_____"], T["_____"], T["_____"], T["_____"], T["_____"], T["_____"], T["_____"], T["_____"], T["_____"], T["_____"],
		T["K0S22"], T["K0S22"], T["K0S22"], T["K0S22"], T["K0S22"], T["K0S22"], T["K0S22"], T["K0S22"], T["K0S22"], T["K0S22"], T["K0S22"],
		T["K0S02"], T["W0S02"], T["W0S02"], T["W0S02"], T["W0S02"], T["W0S02"], T["W0S02"], T["W0S02"], T["W0S02"], T["W0S02"], T["K0S02"],
		T["_____"], T["_____"], T["_____"], T["_____"], T["_____"], T["_____"], T["_____"], T["_____"], T["_____"], T["_____"], T["_____"],
		T["_____"], T["_____"], T["_____"], T["_____"], T["_____"], T["_____"], T["_____"], T["_____"], T["_____"], T["_____"], T["_____"],
		T["_____"], T["_____"], T["_____"], T["_____"], T["_____"], T["_____"], T["_____"], T["_____"], T["_____"], T["_____"], T["_____"],
		T["_____"], T["_____"], T["_____"], T["_____"], T["_____"], T["_____"], T["_____"], T["_____"], T["_____"], T["_____"], T["_____"],
	},
	yslice_prob = {
		{prob = 254,ypos = 0},
		{prob = 254,ypos = 1},
		{prob = 254,ypos = 2},
		{prob = 254,ypos = 3},
		{prob = 254,ypos = 4},
		{prob = 254,ypos = 5},
		{prob = 254,ypos = 6},
		{prob = 254,ypos = 7},
		{prob = 254,ypos = 8},
		{prob = 254,ypos = 9}
	}
}