


local T = lib_towns.schems.T

return {
	yslice_prob = {
		{prob = 254,ypos = 0},
		{prob = 254,ypos = 1},
		{prob = 254,ypos = 2},
		{prob = 254,ypos = 3},
		{prob = 254,ypos = 4},
		{prob = 254,ypos = 5}
	},
	data = {
		T["_____"], T["_____"], T["C0m00"], T["_____"], T["_____"], T["_____"], T["_____"], T["_____"], T["C0m00"], T["_____"], T["_____"], T["_____"], {param2 = 1,name = "cottages:roof_wood",prob = 254},
		T["_____"], T["C0m00"], T["_____"], T["_____"], {param2 = 3,name = "cottages:roof_wood",prob = 254},
		T["_____"], {param2 = 1,name = "cottages:roof_wood",prob = 254},
		T["C0m00"], T["_____"], {param2 = 3,name = "cottages:roof_wood",prob = 254},
		T["_____"], T["_____"], T["_____"], T["C0m00"], {param2 = 3,name = "cottages:roof_wood",prob = 254},
		T["_____"], T["_____"], T["_____"], T["_____"], T["C0m00"], T["_____"], T["_____"], T["_____"], T["_____"], T["C0m00"], T["C0m00"], T["C0m00"], T["C0m00"], T["_____"], T["_____"], T["C0m00"], T["C0m00"], {param2 = 2,name = "cottages:glass_pane",prob = 254},
		T["C0m00"], T["_____"], {param2 = 1,name = "cottages:roof_wood",prob = 254},
		T["C0m00"], T["C0m00"], T["C0m00"], T["C0m00"], {param2 = 3,name = "cottages:roof_wood",prob = 254},
		T["_____"], {param2 = 1,name = "cottages:roof_connector_wood",prob = 254},
		T["C0m00"], T["C0m00"], {param2 = 3,name = "cottages:roof_connector_wood",prob = 254},
		T["_____"], T["_____"], T["_____"], {param2 = 1,name = "cottages:roof_connector_wood",prob = 254},
		{param2 = 3,name = "cottages:roof_connector_wood",prob = 254},
		T["_____"], T["_____"], T["_____"], T["_____"], T["_____"], T["_____"], T["_____"], T["_____"], T["C0m00"], T["C0m00"], {param2 = 2,name = "lib_forge:furnace",prob = 254},
		T["C0m00"], T["C0m00"], T["C0m00"], T["C0m00"], T["_____"], T["_____"], T["_____"], T["_____"], T["C0m00"], {param2 = 1,name = "cottages:roof_connector_wood",prob = 254},
		T["_____"], T["_____"], T["_____"], T["_____"], {param2 = 3,name = "cottages:roof_connector_wood",prob = 254},
		T["_____"], {param2 = 1,name = "cottages:roof_wood",prob = 254},
		T["_____"], T["_____"], {param2 = 3,name = "cottages:roof_wood",prob = 254},
		T["_____"], T["_____"], T["_____"], {param2 = 1,name = "cottages:roof_wood",prob = 254},
		{param2 = 3,name = "cottages:roof_wood",prob = 254},
		T["_____"], T["_____"], T["_____"], T["_____"], T["_____"], T["_____"], T["_____"], T["_____"], {param2 = 1,name = "air",prob = 254},
		T["_____"], T["_____"], T["_____"], T["_____"], T["C0m00"], T["_____"], T["_____"], T["_____"], T["_____"], T["_____"], T["C0m00"], {param2 = 1,name = "cottages:roof_connector_wood",prob = 254},
		T["_____"], T["_____"], T["_____"], T["_____"], {param2 = 3,name = "cottages:roof_connector_wood",prob = 254},
		T["_____"], {param2 = 1,name = "cottages:roof_wood",prob = 254},
		T["_____"], T["_____"], {param2 = 3,name = "cottages:roof_wood",prob = 254},
		T["_____"], T["_____"], T["_____"], {param2 = 1,name = "cottages:roof_wood",prob = 254},
		{param2 = 3,name = "cottages:roof_wood",prob = 254},
		T["_____"], T["_____"], T["_____"], T["_____"], T["_____"], T["_____"], T["_____"], T["_____"], T["C0m00"], T["_____"], T["_____"], T["_____"], T["_____"], T["C0m00"], T["C0m00"], T["_____"], T["_____"], T["_____"], T["_____"], {param2 = 1,name = "cottages:glass_pane",prob = 254},
		{param2 = 1,name = "cottages:roof_connector_wood",prob = 254},
		T["_____"], T["_____"], T["_____"], T["_____"], {param2 = 3,name = "cottages:roof_connector_wood",prob = 254},
		T["_____"], {param2 = 1,name = "cottages:roof_wood",prob = 254},
		T["_____"], T["_____"], {param2 = 3,name = "cottages:roof_wood",prob = 254},
		T["_____"], T["_____"], T["_____"], {param2 = 1,name = "cottages:roof_wood",prob = 254},
		{param2 = 3,name = "cottages:roof_wood",prob = 254},
		T["_____"], T["_____"], T["_____"], T["_____"], T["_____"], T["_____"], T["_____"], T["_____"], T["C0m00"], {param2 = 0,name = "cottages:bench",prob = 254},
		{param2 = 0,name = "cottages:bench",prob = 254},
		T["_____"], {param2 = 1,name = "cottages:shelf",prob = 254},
		T["C0m00"], {param2 = 3,name = "cottages:glass_pane",prob = 254},
		T["_____"], T["_____"], T["_____"], T["_____"], T["C0m00"], {param2 = 1,name = "cottages:roof_connector_wood",prob = 254},
		T["_____"], T["_____"], T["_____"], T["_____"], {param2 = 3,name = "cottages:roof_connector_wood",prob = 254},
		T["_____"], {param2 = 1,name = "cottages:roof_wood",prob = 254},
		T["_____"], T["_____"], {param2 = 3,name = "cottages:roof_wood",prob = 254},
		T["_____"], T["_____"], T["_____"], {param2 = 1,name = "cottages:roof_wood",prob = 254},
		{param2 = 3,name = "cottages:roof_wood",prob = 254},
		T["_____"], T["_____"], T["_____"], T["_____"], T["_____"], T["_____"], T["_____"], T["_____"], T["C0m00"], {param2 = 0,name = "cottages:table",prob = 254},
		{param2 = 0,name = "cottages:table",prob = 254},
		T["_____"], {param2 = 1,name = "cottages:shelf",prob = 254},
		T["C0m00"], T["C0m00"], T["_____"], T["_____"], T["_____"], T["_____"], {param2 = 1,name = "cottages:glass_pane",prob = 254},
		{param2 = 1,name = "cottages:roof_connector_wood",prob = 254},
		T["_____"], T["_____"], T["_____"], T["_____"], {param2 = 3,name = "cottages:roof_connector_wood",prob = 254},
		T["_____"], {param2 = 1,name = "cottages:roof_wood",prob = 254},
		T["_____"], T["_____"], {param2 = 3,name = "cottages:roof_wood",prob = 254},
		T["_____"], T["_____"], T["_____"], {param2 = 1,name = "cottages:roof_wood",prob = 254},
		{param2 = 3,name = "cottages:roof_wood",prob = 254},
		T["_____"], T["_____"], T["_____"], T["_____"], T["_____"], T["_____"], T["_____"], T["_____"], T["C0m00"], {param2 = 2,name = "cottages:bench",prob = 254},
		{param2 = 2,name = "cottages:bench",prob = 254},
		T["_____"], T["_____"], T["C0m00"], {param2 = 3,name = "cottages:glass_pane",prob = 254},
		T["_____"], T["_____"], T["_____"], T["_____"], T["C0m00"], {param2 = 1,name = "cottages:roof_connector_wood",prob = 254},
		T["_____"], T["_____"], T["_____"], T["_____"], {param2 = 3,name = "cottages:roof_connector_wood",prob = 254},
		T["_____"], {param2 = 1,name = "cottages:roof_wood",prob = 254},
		T["_____"], T["_____"], {param2 = 3,name = "cottages:roof_wood",prob = 254},
		T["_____"], T["_____"], T["_____"], {param2 = 1,name = "cottages:roof_wood",prob = 254},
		{param2 = 3,name = "cottages:roof_wood",prob = 254},
		T["_____"], T["_____"], T["_____"], T["_____"], T["_____"], T["_____"], T["_____"], T["_____"], T["C0m00"], {param2 = 0,name = "lib_chests:chest",prob = 254},
		{param2 = 0,name = "lib_chests:chest",prob = 254},
		{param2 = 0,name = "lib_chests:chest",prob = 254},
		{param2 = 0,name = "lib_chests:chest",prob = 254},
		T["C0m00"], T["C0m00"], {param2 = 0,name = "lib_chests:chest",prob = 254},
		{param2 = 0,name = "lib_chests:chest",prob = 254},
		{param2 = 0,name = "lib_chests:chest",prob = 254},
		{param2 = 0,name = "lib_chests:chest",prob = 254},
		T["C0m00"], {param2 = 1,name = "cottages:roof_connector_wood",prob = 254},
		T["_____"], T["_____"], T["_____"], T["_____"], {param2 = 3,name = "cottages:roof_connector_wood",prob = 254},
		T["_____"], {param2 = 1,name = "cottages:roof_wood",prob = 254},
		T["_____"], T["_____"], {param2 = 3,name = "cottages:roof_wood",prob = 254},
		T["_____"], T["_____"], T["_____"], {param2 = 1,name = "cottages:roof_wood",prob = 254},
		{param2 = 3,name = "cottages:roof_wood",prob = 254},
		T["_____"], T["_____"], T["_____"], T["_____"], T["_____"], T["_____"], T["_____"], T["_____"], T["_____"], T["C0m00"], T["C0m00"], T["C0m00"], T["C0m00"], T["_____"], T["_____"], T["C0m00"], T["C0m00"], T["C0m00"], T["C0m00"], T["_____"], {param2 = 1,name = "cottages:roof_wood",prob = 254},
		T["C0m00"], T["C0m00"], T["C0m00"], T["C0m00"], {param2 = 3,name = "cottages:roof_wood",prob = 254},
		T["_____"], {param2 = 1,name = "cottages:roof_connector_wood",prob = 254},
		T["C0m00"], T["C0m00"], {param2 = 3,name = "cottages:roof_connector_wood",prob = 254},
		T["_____"], T["_____"], T["_____"], {param2 = 1,name = "cottages:roof_connector_wood",prob = 254},
		{param2 = 3,name = "cottages:roof_connector_wood",prob = 254},
		T["_____"], T["_____"], T["_____"], T["_____"], T["_____"], T["_____"], T["_____"], T["_____"], T["_____"], T["_____"], T["_____"], T["_____"], T["_____"], T["_____"], T["_____"], T["_____"], T["_____"], T["_____"], T["_____"], T["_____"], {param2 = 1,name = "cottages:roof_wood",prob = 254},
		T["_____"], T["_____"], T["_____"], T["_____"], {param2 = 3,name = "cottages:roof_wood",prob = 254},
		T["_____"], {param2 = 1,name = "cottages:roof_wood",prob = 254},
		T["_____"], T["_____"], {param2 = 3,name = "cottages:roof_wood",prob = 254},
		T["_____"], T["_____"], T["_____"], {param2 = 1,name = "cottages:roof_wood",prob = 254},
		{param2 = 3,name = "cottages:roof_wood",prob = 254},
		T["_____"], T["_____"], T["_____"], T["_____"], T["_____"], T["_____"], T["_____"], {param2 = 0,name = "air",prob = 254}
	},
	size = {x = 6,y = 6,z = 11}
}