



local T = lib_towns.schems.T


return {
	size = {x = 11,y = 8,z = 13},
	data = {
		T["_____"], T["_____"], T["_____"], T["_____"], T["_____"], T["_____"], T["_____"], T["C0S00"], T["_____"], T["_____"], T["_____"],
		T["_____"], T["_____"], T["_____"], T["_____"], T["_____"], T["_____"], T["_____"], T["_____"], T["_____"], T["_____"], T["_____"],
		T["_____"], T["_____"], T["_____"], T["_____"], T["_____"], T["_____"], T["_____"], T["_____"], T["_____"], T["_____"], T["_____"],
		T["W1S00"], T["W1S00"], T["W1S00"], T["W1S00"], T["W1S00"], T["W1S00"], T["W1S00"], T["W1S00"], T["W1S00"], T["W1S00"], T["W1S00"],
		T["_____"], T["_____"], T["_____"], T["_____"], T["_____"], T["_____"], T["_____"], T["_____"], T["_____"], T["_____"], T["_____"],
		T["_____"], T["_____"], T["_____"], T["_____"], T["_____"], T["_____"], T["_____"], T["_____"], T["_____"], T["_____"], T["_____"],
		T["_____"], T["_____"], T["_____"], T["_____"], T["_____"], T["_____"], T["_____"], T["_____"], T["_____"], T["_____"], T["_____"],
		T["_____"], T["_____"], T["_____"], T["_____"], T["_____"], T["_____"], T["_____"], T["_____"], T["_____"], T["_____"], T["_____"],

		T["_____"], T["K0m00"], T["K0m00"], T["K0m00"], T["K0m00"], T["K0m00"], T["K0m00"], T["C0m00"], T["K0m00"], T["K0m00"], T["_____"],
		T["_____"], T["K0m00"], T["C0m00"], T["C0m00"], T["C0S20"], T["C0m00"], T["C0m00"], T["W0dS0"], T["C0m00"], T["K0m00"], T["_____"],
		T["_____"], T["K0m00"], T["W0m00"], T["T0m00"], T["Xp0N0"], T["T0m00"], T["W0m00"], T["_____"], T["W0m00"], T["K0m00"], T["_____"],
		T["W1S22"], T["K0m00"], T["C0m00"], T["C0m00"], T["C0m00"], T["C0m00"], T["C0m00"], T["C0m00"], T["C0m00"], T["K0m00"], T["W1S22"],
		T["W1S00"], T["W0S00"], T["W0S00"], T["W0S00"], T["W0S00"], T["W0S00"], T["W0S00"], T["W0S00"], T["W0S00"], T["W0S00"], T["W1S00"],
		T["_____"], T["_____"], T["_____"], T["_____"], T["_____"], T["_____"], T["_____"], T["_____"], T["_____"], T["_____"], T["_____"],
		T["_____"], T["_____"], T["_____"], T["_____"], T["_____"], T["_____"], T["_____"], T["_____"], T["_____"], T["_____"], T["_____"],
		T["_____"], T["_____"], T["_____"], T["_____"], T["_____"], T["_____"], T["_____"], T["_____"], T["_____"], T["_____"], T["_____"],

		T["_____"], T["K0m00"], T["W0m00"], T["W0m00"], T["W0m00"], T["W0m00"], T["W0m00"], T["W0m00"], T["W0m00"], T["K0m00"], T["_____"],
		T["_____"], T["C0m00"], T["_____"], T["W0S02"], T["_____"], T["_____"], T["_____"], T["_____"], T["_____"], T["C0m00"], T["_____"],
		T["_____"], T["T0m00"], T["_____"], T["_____"], T["_____"], T["_____"], T["_____"], T["_____"], T["_____"], T["T0m00"], T["_____"],
		T["_____"], T["C0m00"], T["_____"], T["_____"], T["_____"], T["_____"], T["_____"], T["_____"], T["_____"], T["C0m00"], T["_____"],
		T["W1S22"], T["C0m00"], T["_____"], T["_____"], T["_____"], T["_____"], T["_____"], T["_____"], T["_____"], T["C0m00"], T["W1S22"],
		T["W1S00"], T["W0S00"], T["W0S00"], T["W0S00"], T["W0S00"], T["W0S00"], T["W0S00"], T["W0S00"], T["W0S00"], T["W0S00"], T["W1S00"],
		T["_____"], T["_____"], T["_____"], T["_____"], T["_____"], T["_____"], T["_____"], T["_____"], T["_____"], T["_____"], T["_____"],
		T["_____"], T["_____"], T["_____"], T["_____"], T["_____"], T["_____"], T["_____"], T["_____"], T["_____"], T["_____"], T["_____"],

		T["_____"], T["K0m00"], T["W0m00"], T["W0m00"], T["W0m00"], T["W0m00"], T["W0m00"], T["W0m00"], T["W0m00"], T["K0m00"], T["_____"],
		T["_____"], T["C0S23"], T["W0S03"], T["W0n00"], T["_____"], T["_____"], T["_____"], T["_____"], T["_____"], T["C0S21"], T["_____"],
		T["_____"], T["Xp0W0"], T["_____"], T["SwN00"], T["_____"], T["_____"], T["_____"], T["_____"], T["_____"], T["Xp0W0"], T["_____"],
		T["_____"], T["C0m00"], T["_____"], T["_____"], T["_____"], T["_____"], T["_____"], T["_____"], T["_____"], T["C0m00"], T["_____"],
		T["_____"], T["C0m00"], T["_____"], T["_____"], T["_____"], T["_____"], T["_____"], T["_____"], T["_____"], T["C0m00"], T["_____"],
		T["W1S22"], T["C0m00"], T["W0m00"], T["_____"], T["_____"], T["_____"], T["_____"], T["_____"], T["_____"], T["C0m00"], T["W1S22"],
		T["W1S00"], T["W0S00"], T["W0S00"], T["W0S00"], T["W0S00"], T["W0S00"], T["W0S00"], T["W0S00"], T["W0S00"], T["W0S00"], T["W1S00"],
		T["_____"], T["_____"], T["_____"], T["_____"], T["_____"], T["_____"], T["_____"], T["_____"], T["_____"], T["_____"], T["_____"],

		T["_____"], T["K0m00"], T["W0m00"], T["W0m00"], T["W0m00"], T["W0m00"], T["W0m00"], T["W0m00"], T["W0m00"], T["K0m00"], T["_____"],
		T["_____"], T["C0S23"], T["W0S03"], T["W0n00"], T["_____"], T["_____"], T["W0S03"], T["W0n00"], T["W0S01"], T["C0S21"], T["_____"],
		T["_____"], T["Xp0W0"], T["_____"], T["SwN00"], T["_____"], T["_____"], T["_____"], T["SwN00"], T["_____"], T["Xp0W0"], T["_____"],
		T["_____"], T["C0m00"], T["_____"], T["_____"], T["_____"], T["_____"], T["_____"], T["_____"], T["_____"], T["C0m00"], T["_____"],
		T["_____"], T["C0m00"], T["_____"], T["_____"], T["_____"], T["_____"], T["_____"], T["_____"], T["_____"], T["C0m00"], T["_____"],
		T["W1S20"], T["C0m00"], T["W0m00"], T["_____"], T["_____"], T["_____"], T["_____"], T["_____"], T["_____"], T["C0m00"], T["W1S20"],
		T["W1S02"], T["W0S02"], T["W0S02"], T["W0i02"], T["W0m00"], T["W0i03"], T["W0S02"], T["W0S02"], T["W0S02"], T["W0S02"], T["W1S02"],
		T["_____"], T["_____"], T["_____"], T["_____"], T["_____"], T["_____"], T["_____"], T["_____"], T["_____"], T["_____"], T["_____"],

		T["_____"], T["K0m00"], T["W0m00"], T["W0m00"], T["W0m00"], T["W0m00"], T["W0m00"], T["W0m00"], T["W0m00"], T["K0m00"], T["_____"],
		T["_____"], T["C0m00"], T["_____"], T["_____"], T["_____"], T["_____"], T["_____"], T["W0S00"], T["_____"], T["C0m00"], T["_____"],
		T["_____"], T["T0m00"], T["_____"], T["_____"], T["_____"], T["_____"], T["_____"], T["_____"], T["_____"], T["T0m00"], T["_____"],
		T["_____"], T["C0m00"], T["_____"], T["_____"], T["_____"], T["_____"], T["_____"], T["TwS00"], T["_____"], T["C0m00"], T["_____"],
		T["W1S20"], T["C0m00"], T["_____"], T["_____"], T["_____"], T["_____"], T["_____"], T["_____"], T["_____"], T["C0m00"], T["W1S20"],
		T["W1S02"], T["W0S02"], T["W0i02"], T["_____"], T["_____"], T["_____"], T["W0i03"], T["W0S02"], T["W0S02"], T["W0S02"], T["W1S02"],
		T["_____"], T["_____"], T["_____"], T["W0S01"], T["W0m00"], T["W0S03"], T["_____"], T["_____"], T["_____"], T["_____"], T["_____"],
		T["_____"], T["_____"], T["_____"], T["_____"], T["_____"], T["_____"], T["_____"], T["_____"], T["_____"], T["_____"], T["_____"],

		T["_____"], T["K0m00"], T["W0m00"], T["W0m00"], T["W0m00"], T["W0m00"], T["W0m00"], T["C0m00"], T["K0m00"], T["K0m00"], T["_____"],
		T["_____"], T["C0m00"], T["_____"], T["_____"], T["_____"], T["_____"], T["_____"], T["C0m00"], T["C0m00"], T["K0m00"], T["_____"],
		T["_____"], T["W0m00"], T["_____"], T["_____"], T["_____"], T["_____"], T["_____"], T["C0m00"], T["C0m00"], T["K0m00"], T["_____"],
		T["W1S20"], T["C0m00"], T["W0L20"], T["W0L20"], T["W0L20"], T["W0L20"], T["W0L23"], T["C0m00"], T["C0m00"], T["K0m00"], T["W1S20"],
		T["W1S02"], T["W0i02"], T["W0n00"], T["W0n00"], T["W0n00"], T["W0n00"], T["W0n00"], T["W0i03"], T["W0S02"], T["W0S02"], T["W1S02"],
		T["_____"], T["_____"], T["W0S01"], T["_____"], T["_____"], T["_____"], T["W0S03"], T["_____"], T["_____"], T["_____"], T["_____"],
		T["_____"], T["_____"], T["_____"], T["W0S01"], T["W0m00"], T["W0S03"], T["_____"], T["_____"], T["_____"], T["_____"], T["_____"],
		T["_____"], T["_____"], T["_____"], T["_____"], T["_____"], T["_____"], T["_____"], T["_____"], T["_____"], T["_____"], T["_____"],

		T["_____"], T["K0m00"], T["W0m00"], T["W0m00"], T["W0m00"], T["W0m00"], T["W0m00"], T["K0m00"], T["_____"], T["_____"], T["_____"],
		T["_____"], T["C0m00"], T["_____"], T["_____"], T["_____"], T["_____"], T["_____"], T["C0m00"], T["_____"], T["_____"], T["_____"],
		T["_____"], T["T0m00"], T["_____"], T["_____"], T["_____"], T["_____"], T["_____"], T["T0m00"], T["_____"], T["_____"], T["_____"],
		T["W1i02"], T["C0m00"], T["W0L20"], T["W0L20"], T["W0L20"], T["W0L20"], T["W0L23"], T["C0m00"], T["W1i03"], T["W1S02"], T["W1S02"],
		T["_____"], T["W0S01"], T["_____"], T["_____"], T["_____"], T["_____"], T["_____"], T["W0S03"], T["_____"], T["_____"], T["_____"],
		T["_____"], T["_____"], T["W0S01"], T["_____"], T["_____"], T["_____"], T["W0S03"], T["_____"], T["_____"], T["_____"], T["_____"],
		T["_____"], T["_____"], T["_____"], T["W0S01"], T["W0m00"], T["W0S03"], T["_____"], T["_____"], T["_____"], T["_____"], T["_____"],
		T["_____"], T["_____"], T["_____"], T["_____"], T["_____"], T["_____"], T["_____"], T["_____"], T["_____"], T["_____"], T["_____"],

		T["_____"], T["K0m00"], T["W0m00"], T["W0m00"], T["W0m00"], T["W0m00"], T["W0m00"], T["K0m00"], T["_____"], T["_____"], T["_____"],
		T["_____"], T["C0S23"], T["W0gN0"], T["W0m00"], T["W0L20"], T["W0L20"], T["W0m00"], T["C0S21"], T["_____"], T["_____"], T["_____"],
		T["_____"], T["Xp0W0"], T["_____"], T["_____"], T["_____"], T["_____"], T["_____"], T["Xp0W0"], T["_____"], T["_____"], T["_____"],
		T["W1S01"], T["C0m00"], T["W0L20"], T["W0L20"], T["W0L20"], T["W0L20"], T["W0L23"], T["C0m00"], T["W1S03"], T["_____"], T["_____"],
		T["_____"], T["W0S01"], T["Cs0W0"], T["_____"], T["_____"], T["_____"], T["Cs0E0"], T["W0S03"], T["_____"], T["_____"], T["_____"],
		T["_____"], T["_____"], T["W0S01"], T["_____"], T["_____"], T["_____"], T["W0S03"], T["_____"], T["_____"], T["_____"], T["_____"],
		T["_____"], T["_____"], T["_____"], T["W0S01"], T["W0m00"], T["W0S03"], T["_____"], T["_____"], T["_____"], T["_____"], T["_____"],
		T["_____"], T["_____"], T["_____"], T["_____"], T["_____"], T["_____"], T["_____"], T["_____"], T["_____"], T["_____"], T["_____"],

		T["_____"], T["K0m00"], T["W0m00"], T["W0m00"], T["W0m00"], T["W0m00"], T["W0m00"], T["K0m00"], T["_____"], T["_____"], T["_____"],
		T["_____"], T["C0S23"], T["_____"], T["_____"], T["_____"], T["_____"], T["_____"], T["C0S21"], T["_____"], T["_____"], T["_____"],
		T["_____"], T["Xp0W0"], T["_____"], T["_____"], T["_____"], T["_____"], T["_____"], T["Xp0W0"], T["_____"], T["_____"], T["_____"],
		T["W1S01"], T["C0m00"], T["W0L20"], T["W0L20"], T["W0L20"], T["W0L20"], T["W0L23"], T["C0m00"], T["W1S03"], T["_____"], T["_____"],
		T["_____"], T["W0S01"], T["Cs0W0"], T["_____"], T["_____"], T["_____"], T["Cs0E0"], T["W0S03"], T["_____"], T["_____"], T["_____"],
		T["_____"], T["_____"], T["W0S01"], T["_____"], T["_____"], T["_____"], T["W0S03"], T["_____"], T["_____"], T["_____"], T["_____"],
		T["_____"], T["_____"], T["_____"], T["W0S01"], T["W0m00"], T["W0S03"], T["_____"], T["_____"], T["_____"], T["_____"], T["_____"],
		T["_____"], T["_____"], T["_____"], T["_____"], T["_____"], T["_____"], T["_____"], T["_____"], T["_____"], T["_____"], T["_____"],

		T["_____"], T["K0m00"], T["W0m00"], T["W0m00"], T["W0m00"], T["W0m00"], T["W0m00"], T["K0m00"], T["_____"], T["_____"], T["_____"],
		T["_____"], T["C0m00"], T["_____"], T["Ld0E0"], T["_____"], T["_____"], T["Cs0N0"], T["C0m00"], T["_____"], T["_____"], T["_____"],
		T["_____"], T["T0m00"], T["_____"], T["Ld0E0"], T["TwS00"], T["_____"], T["_____"], T["T0m00"], T["_____"], T["_____"], T["_____"],
		T["W1S01"], T["C0m00"], T["W0L20"], T["Ld0E0"], T["W0L20"], T["W0L20"], T["W0L20"], T["C0m00"], T["W1S03"], T["_____"], T["_____"],
		T["_____"], T["W0S01"], T["_____"], T["_____"], T["_____"], T["_____"], T["_____"], T["W0S03"], T["_____"], T["_____"], T["_____"],
		T["_____"], T["_____"], T["W0S01"], T["_____"], T["_____"], T["_____"], T["W0S03"], T["_____"], T["_____"], T["_____"], T["_____"],
		T["_____"], T["_____"], T["_____"], T["W0S01"], T["W0m00"], T["W0S03"], T["_____"], T["_____"], T["_____"], T["_____"], T["_____"],
		T["_____"], T["_____"], T["_____"], T["_____"], T["_____"], T["_____"], T["_____"], T["_____"], T["_____"], T["_____"], T["_____"],

		T["_____"], T["K0m00"], T["K0m00"], T["K0m00"], T["K0m00"], T["K0m00"], T["K0m00"], T["K0m00"], T["_____"], T["_____"], T["_____"],
		T["_____"], T["K0m00"], T["C0m00"], T["C0m00"], T["C0m00"], T["C0m00"], T["C0m00"], T["K0m00"], T["_____"], T["_____"], T["_____"],
		T["_____"], T["K0m00"], T["C0m00"], T["C0m00"], T["C0m00"], T["C0m00"], T["C0m00"], T["K0m00"], T["_____"], T["_____"], T["_____"],
		T["W1S01"], T["K0m00"], T["C0m00"], T["C0m00"], T["C0m00"], T["C0m00"], T["C0m00"], T["K0m00"], T["W1S03"], T["_____"], T["_____"],
		T["_____"], T["W0S01"], T["C0m00"], T["T0m00"], T["Xp0N0"], T["T0m00"], T["C0m00"], T["W0S03"], T["_____"], T["_____"], T["_____"],
		T["_____"], T["_____"], T["W0S01"], T["C0m00"], T["C0m00"], T["C0m00"], T["W0S03"], T["_____"], T["_____"], T["_____"], T["_____"],
		T["_____"], T["_____"], T["_____"], T["W0S01"], T["W0m00"], T["W0S03"], T["_____"], T["_____"], T["_____"], T["_____"], T["_____"],
		T["_____"], T["_____"], T["_____"], T["_____"], T["_____"], T["_____"], T["_____"], T["_____"], T["_____"], T["_____"], T["_____"],

		T["_____"], T["_____"], T["_____"], T["_____"], T["_____"], T["_____"], T["_____"], T["_____"], T["_____"], T["_____"], T["_____"],
		T["_____"], T["_____"], T["_____"], T["_____"], T["_____"], T["_____"], T["_____"], T["_____"], T["_____"], T["_____"], T["_____"],
		T["_____"], T["_____"], T["_____"], T["_____"], T["_____"], T["_____"], T["_____"], T["_____"], T["_____"], T["_____"], T["_____"],
		T["W1S01"], T["W1S21"], T["_____"], T["_____"], T["_____"], T["_____"], T["_____"], T["W1S23"], T["W1S03"], T["_____"], T["_____"],
		T["_____"], T["W1S01"], T["W1S21"], T["_____"], T["_____"], T["_____"], T["W1S23"], T["W1S03"], T["_____"], T["_____"], T["_____"],
		T["_____"], T["_____"], T["W1S01"], T["W1S21"], T["_____"], T["W1S23"], T["W1S03"], T["_____"], T["_____"], T["_____"], T["_____"],
		T["_____"], T["_____"], T["_____"], T["W1S01"], T["W1S22"], T["W1S03"], T["_____"], T["_____"], T["_____"], T["_____"], T["_____"],
		T["_____"], T["_____"], T["_____"], T["_____"], T["_____"], T["_____"], T["_____"], T["_____"], T["_____"], T["_____"], T["_____"],
	},
	yslice_prob = {
		{prob = 254,ypos = 0},
		{prob = 254,ypos = 1},
		{prob = 254,ypos = 2},
		{prob = 254,ypos = 3},
		{prob = 254,ypos = 4},
		{prob = 254,ypos = 5},
		{prob = 254,ypos = 6},
		{prob = 254,ypos = 7}
	}
}