return {
	yslice_prob = {
		{
			prob = 254,
			ypos = 0
		},
		{
			prob = 254,
			ypos = 1
		},
		{
			prob = 254,
			ypos = 2
		},
		{
			prob = 254,
			ypos = 3
		},
		{
			prob = 254,
			ypos = 4
		},
		{
			prob = 254,
			ypos = 5
		},
		{
			prob = 254,
			ypos = 6
		}
	},
	data = {
		{
			param2 = 0,
			name = "lib_materials:dirt",
			prob = 254
		},
		{
			param2 = 0,
			name = "lib_materials:stone_cobble",
			prob = 254
		},
		{
			param2 = 3,
			name = "lib_ecology:tree_default_wood_fence",
			prob = 254
		},
		{
			param2 = 3,
			name = "lib_ecology:tree_default_wood_fence",
			prob = 254
		},
		{
			param2 = 0,
			name = "cottages:roof_connector_wood",
			prob = 254
		},
		{
			param2 = 0,
			name = "air",
			prob = 254
		},
		{
			param2 = 0,
			name = "air",
			prob = 254
		},
		{
			param2 = 0,
			name = "lib_materials:stone_brick",
			prob = 254
		},
		{
			param2 = 0,
			name = "air",
			prob = 254
		},
		{
			param2 = 0,
			name = "air",
			prob = 254
		},
		{
			param2 = 0,
			name = "air",
			prob = 254
		},
		{
			param2 = 3,
			name = "lib_ecology:tree_default_wood_fence",
			prob = 254
		},
		{
			param2 = 0,
			name = "cottages:roof_connector_wood",
			prob = 254
		},
		{
			param2 = 0,
			name = "air",
			prob = 254
		},
		{
			param2 = 0,
			name = "lib_materials:stone_cobble",
			prob = 254
		},
		{
			param2 = 0,
			name = "air",
			prob = 254
		},
		{
			param2 = 0,
			name = "air",
			prob = 254
		},
		{
			param2 = 0,
			name = "air",
			prob = 254
		},
		{
			param2 = 3,
			name = "lib_ecology:tree_default_wood_fence",
			prob = 254
		},
		{
			param2 = 1,
			name = "torch:torch",
			prob = 254
		},
		{
			param2 = 2,
			name = "cottages:roof_flat_wood",
			prob = 254
		},
		{
			param2 = 0,
			name = "lib_materials:stone_brick",
			prob = 254
		},
		{
			param2 = 0,
			name = "air",
			prob = 254
		},
		{
			param2 = 0,
			name = "air",
			prob = 254
		},
		{
			param2 = 0,
			name = "air",
			prob = 254
		},
		{
			param2 = 3,
			name = "lib_ecology:tree_default_wood_fence",
			prob = 254
		},
		{
			param2 = 2,
			name = "cottages:roof_connector_wood",
			prob = 254
		},
		{
			param2 = 0,
			name = "air",
			prob = 254
		},
		{
			param2 = 0,
			name = "lib_materials:dirt",
			prob = 254
		},
		{
			param2 = 0,
			name = "lib_materials:stone_cobble",
			prob = 254
		},
		{
			param2 = 3,
			name = "lib_ecology:tree_default_wood_fence",
			prob = 254
		},
		{
			param2 = 3,
			name = "lib_ecology:tree_default_wood_fence",
			prob = 254
		},
		{
			param2 = 2,
			name = "cottages:roof_connector_wood",
			prob = 254
		},
		{
			param2 = 0,
			name = "air",
			prob = 254
		},
		{
			param2 = 0,
			name = "air",
			prob = 254
		}
	},
	size = {x = 1,y = 7,z = 5}
}