



local T = lib_towns.schems.T


return {
	size = {x = 6,y = 7,z = 6},
	data = {
		T["_____"], T["_____"], T["C0S00"], T["_____"], T["_____"], T["_____"],
		T["_____"], T["_____"], T["_____"], T["_____"], T["_____"], T["_____"],
		T["_____"], T["_____"], T["_____"], T["W0TN0"], T["_____"], T["_____"],
		T["_____"], T["_____"], T["W0TN0"], T["_____"], T["_____"], T["_____"],
		T["_____"], T["_____"], T["_____"], T["_____"], T["_____"], T["_____"],
		T["_____"], T["_____"], T["_____"], T["_____"], T["_____"], T["_____"],
		T["_____"], T["_____"], T["_____"], T["_____"], T["_____"], T["_____"],

		T["_____"], T["C0m00"], T["C0m00"], T["C0m00"], T["C0m00"], T["_____"],
		T["_____"], T["T0m00"], T["W0dS0"], T["W0m00"], T["T0m00"], T["_____"],
		T["_____"], T["T0m00"], T["_____"], T["W0m00"], T["T0m00"], T["_____"],
		T["_____"], T["T0m00"], T["W0S20"], T["W0m00"], T["T0m00"], T["_____"],
		T["_____"], T["W0S01"], T["T0m00"], T["T0m00"], T["W0S03"], T["_____"],
		T["_____"], T["_____"], T["W0S01"], T["W0S03"], T["_____"], T["_____"],
		T["_____"], T["_____"], T["_____"], T["_____"], T["_____"], T["_____"],

		T["_____"], T["C0m00"], T["ddddd"], T["ddddd"], T["C0m00"], T["_____"],
		T["_____"], T["W0m00"], T["_____"], T["_____"], T["W0m00"], T["_____"],
		T["_____"], T["W0m00"], T["_____"], T["_____"], T["W0m00"], T["_____"],
		T["_____"], T["W0m00"], T["_____"], T["_____"], T["W0m00"], T["_____"],
		T["W0S01"], T["T0m00"], T["T0m00"], T["T0m00"], T["T0m00"], T["W0S03"],
		T["_____"], T["W0S01"], T["T0m00"], T["T0m00"], T["W0S03"], T["_____"],
		T["_____"], T["_____"], T["W0L00"], T["W0L00"], T["_____"], T["_____"],

		T["_____"], T["C0m00"], T["ddddd"], T["ddddd"], T["C0m00"], T["_____"],
		T["_____"], T["W0S01"], T["_____"], T["_____"], T["W0S03"], T["_____"],
		T["_____"], T["W0TE0"], T["_____"], T["_____"], T["W0TW0"], T["_____"],
		T["_____"], T["W0S23"], T["_____"], T["_____"], T["W0S21"], T["_____"],
		T["W0S01"], T["T0m00"], T["T0m00"], T["T0m00"], T["T0m00"], T["W0S03"],
		T["_____"], T["T0m00"], T["T0m00"], T["T0m00"], T["T0m00"], T["_____"],
		T["_____"], T["W0S01"], T["W0L00"], T["W0L00"], T["W0S03"], T["_____"],

		T["_____"], T["C0m00"], T["ddddd"], T["ddddd"], T["C0m00"], T["_____"],
		T["_____"], T["W0m00"], T["_____"], T["W0n00"], T["W0m00"], T["_____"],
		T["_____"], T["W0m00"], T["_____"], T["SwN00"], T["W0m00"], T["_____"],
		T["_____"], T["W0m00"], T["_____"], T["_____"], T["W0m00"], T["_____"],
		T["W0S01"], T["T0m00"], T["T0m00"], T["T0m00"], T["T0m00"], T["W0S03"],
		T["_____"], T["W0S01"], T["T0m00"], T["T0m00"], T["W0S03"], T["_____"],
		T["_____"], T["_____"], T["W0L00"], T["W0L00"], T["_____"], T["_____"],

		T["_____"], T["C0m00"], T["C0m00"], T["C0m00"], T["C0m00"], T["_____"],
		T["_____"], T["T0m00"], T["W0m00"], T["W0m00"], T["T0m00"], T["_____"],
		T["_____"], T["T0m00"], T["W0S22"], T["W0S02"], T["T0m00"], T["_____"],
		T["_____"], T["T0m00"], T["W0m00"], T["W0m00"], T["T0m00"], T["_____"],
		T["_____"], T["W0S01"], T["T0m00"], T["T0m00"], T["W0S03"], T["_____"],
		T["_____"], T["_____"], T["W0S01"], T["W0S03"], T["_____"], T["_____"],
		T["_____"], T["_____"], T["_____"], T["_____"], T["_____"], T["_____"],
	},
	yslice_prob = {
		{prob = 254,ypos = 0},
		{prob = 254,ypos = 1},
		{prob = 254,ypos = 2},
		{prob = 254,ypos = 3},
		{prob = 254,ypos = 4},
		{prob = 254,ypos = 5},
		{prob = 254,ypos = 6}
	}
}