



local T = lib_towns.schems.T


return {
	size = {x = 11,y = 8,z = 11},
	data = {
		T["_____"], T["_____"], T["_____"], T["C0S00"], T["_____"], T["_____"], T["_____"], T["_____"], T["_____"], T["_____"], T["_____"],
		T["_____"], T["_____"], T["_____"], T["_____"], T["_____"], T["W0TE0"], T["ggggg"], T["ggggg"], T["W0TW0"], T["_____"], T["_____"],
		T["_____"], T["_____"], T["_____"], T["_____"], T["_____"], T["W0TN0"], T["TrN00"], T["TrN00"], T["W0TN0"], T["_____"], T["_____"],
		T["W0S00"], T["W0S00"], T["W0S00"], T["W0S00"], T["W0S00"], T["W0S00"], T["W0S00"], T["W0S00"], T["W0S00"], T["W0S00"], T["W0S00"],
		T["_____"], T["_____"], T["_____"], T["_____"], T["_____"], T["_____"], T["_____"], T["_____"], T["_____"], T["_____"], T["_____"],
		T["_____"], T["_____"], T["_____"], T["_____"], T["_____"], T["_____"], T["_____"], T["_____"], T["_____"], T["_____"], T["_____"],
		T["_____"], T["_____"], T["_____"], T["_____"], T["_____"], T["_____"], T["_____"], T["_____"], T["_____"], T["_____"], T["_____"],
		T["_____"], T["_____"], T["_____"], T["_____"], T["_____"], T["_____"], T["_____"], T["_____"], T["_____"], T["_____"], T["_____"],

		T["_____"], T["C0m00"], T["C0m00"], T["C0m00"], T["C0m00"], T["C0m00"], T["C0m00"], T["C0m00"], T["C0m00"], T["C0m00"], T["_____"],
		T["_____"], T["T0m00"], T["W0m00"], T["W0dS0"], T["W0m00"], T["C0m00"], T["C0m00"], T["C0m00"], T["C0m00"], T["T0m00"], T["_____"],
		T["_____"], T["T0m00"], T["W0m00"], T["_____"], T["W0m00"], T["T0m00"], T["Xp0N0"], T["Xp0N0"], T["T0m00"], T["T0m00"], T["_____"],
		T["W0S22"], T["T0m00"], T["W0m00"], T["W0m00"], T["W0m00"], T["W0m00"], T["W0m00"], T["W0m00"], T["W0m00"], T["T0m00"], T["W0S22"],
		T["W0S00"], T["W1S00"], T["W1S00"], T["W1S00"], T["W1S00"], T["W1S00"], T["W1S00"], T["W1S00"], T["W1S00"], T["W1S00"], T["W0S00"],
		T["_____"], T["_____"], T["_____"], T["_____"], T["_____"], T["_____"], T["_____"], T["_____"], T["_____"], T["_____"], T["_____"],
		T["_____"], T["_____"], T["_____"], T["_____"], T["_____"], T["_____"], T["_____"], T["_____"], T["_____"], T["_____"], T["_____"],
		T["_____"], T["_____"], T["_____"], T["_____"], T["_____"], T["_____"], T["_____"], T["_____"], T["_____"], T["_____"], T["_____"],

		T["_____"], T["C0m00"], T["W0m00"], T["W0m00"], T["W0m00"], T["W0m00"], T["X0m00"], T["X0m00"], T["X0m00"], T["C0m00"], T["_____"],
		T["_____"], T["C0m00"], T["_____"], T["_____"], T["_____"], T["_____"], T["_____"], T["X0m00"], T["_____"], T["C0m00"], T["_____"],
		T["W0TE0"], T["T0m00"], T["_____"], T["_____"], T["_____"], T["_____"], T["_____"], T["_____"], T["_____"], T["T0m00"], T["W0TW0"],
		T["_____"], T["C0m00"], T["_____"], T["TwW00"], T["_____"], T["_____"], T["_____"], T["_____"], T["_____"], T["C0m00"], T["_____"],
		T["W0S22"], T["C0m00"], T["W0m00"], T["W0m00"], T["W0m00"], T["W0m00"], T["W0m00"], T["W0m00"], T["W0m00"], T["C0m00"], T["W0S22"],
		T["W0S00"], T["W1S00"], T["W1S00"], T["W1S00"], T["W1S00"], T["W1S00"], T["W1S00"], T["W1S00"], T["W1S00"], T["W1S00"], T["W0S00"],
		T["_____"], T["_____"], T["_____"], T["_____"], T["_____"], T["_____"], T["_____"], T["_____"], T["_____"], T["_____"], T["_____"],
		T["_____"], T["_____"], T["_____"], T["_____"], T["_____"], T["_____"], T["_____"], T["_____"], T["_____"], T["_____"], T["_____"],

		T["_____"], T["C0m00"], T["W0m00"], T["W0m00"], T["W0m00"], T["W0m00"], T["X0m00"], T["X0m00"], T["X0m00"], T["C0m00"], T["_____"],
		T["_____"], T["C0m00"], T["_____"], T["_____"], T["_____"], T["_____"], T["_____"], T["X0m00"], T["_____"], T["C0m00"], T["_____"],
		T["_____"], T["Xp0W0"], T["_____"], T["_____"], T["_____"], T["_____"], T["_____"], T["_____"], T["_____"], T["Xp0W0"], T["_____"],
		T["_____"], T["C0m00"], T["_____"], T["_____"], T["_____"], T["_____"], T["_____"], T["_____"], T["_____"], T["C0m00"], T["_____"],
		T["_____"], T["C0m00"], T["W0S22"], T["W0S22"], T["W0S22"], T["W0S22"], T["W0S22"], T["W0S22"], T["W0S22"], T["C0m00"], T["_____"],
		T["W0S22"], T["C0m00"], T["W0m00"], T["W0m00"], T["W0m00"], T["W0m00"], T["W0m00"], T["W0m00"], T["W0m00"], T["C0m00"], T["W0S22"],
		T["W0S00"], T["W1S00"], T["W1S00"], T["W1S00"], T["W1S00"], T["W1S00"], T["W1S00"], T["W1S00"], T["W1S00"], T["W1S00"], T["W0S00"],
		T["_____"], T["_____"], T["_____"], T["_____"], T["_____"], T["_____"], T["_____"], T["_____"], T["_____"], T["_____"], T["_____"],

		T["_____"], T["C0m00"], T["W0m00"], T["W0m00"], T["W0m00"], T["W0m00"], T["X0m00"], T["X0m00"], T["X0m00"], T["C0m00"], T["_____"],
		T["_____"], T["C0m00"], T["W0S03"], T["W0n00"], T["_____"], T["_____"], T["_____"], T["_____"], T["_____"], T["C0m00"], T["_____"],
		T["_____"], T["Xp0W0"], T["_____"], T["SwN00"], T["_____"], T["_____"], T["_____"], T["_____"], T["_____"], T["Xp0W0"], T["_____"],
		T["_____"], T["C0m00"], T["_____"], T["_____"], T["_____"], T["_____"], T["_____"], T["_____"], T["_____"], T["C0m00"], T["_____"],
		T["_____"], T["C0m00"], T["W0S20"], T["W0S20"], T["W0S20"], T["W0S20"], T["W0S20"], T["W0S20"], T["W0S20"], T["C0m00"], T["_____"],
		T["W0S20"], T["C0m00"], T["W0m00"], T["W0m00"], T["W0m00"], T["W0m00"], T["W0m00"], T["W0m00"], T["W0m00"], T["C0m00"], T["W0S20"],
		T["W0S02"], T["W1S02"], T["W1S02"], T["W1S02"], T["W1S02"], T["W1S02"], T["W1S02"], T["W1S02"], T["W1S02"], T["W1S02"], T["W0S02"],
		T["_____"], T["_____"], T["_____"], T["_____"], T["_____"], T["_____"], T["_____"], T["_____"], T["_____"], T["_____"], T["_____"],

		T["_____"], T["C0m00"], T["W0m00"], T["W0m00"], T["W0m00"], T["W0m00"], T["W0m00"], T["W0m00"], T["W0m00"], T["C0m00"], T["_____"],
		T["_____"], T["C0m00"], T["_____"], T["W0S00"], T["_____"], T["_____"], T["_____"], T["_____"], T["_____"], T["C0m00"], T["_____"],
		T["W0TE0"], T["T0m00"], T["_____"], T["_____"], T["_____"], T["_____"], T["_____"], T["_____"], T["_____"], T["T0m00"], T["W0TW0"],
		T["_____"], T["C0m00"], T["_____"], T["_____"], T["_____"], T["_____"], T["_____"], T["TwS00"], T["_____"], T["C0m00"], T["_____"],
		T["W0S20"], T["C0m00"], T["W0m00"], T["W0m00"], T["W0m00"], T["W0m00"], T["W0m00"], T["W0m00"], T["W0m00"], T["C0m00"], T["W0S20"],
		T["W0S02"], T["W1S02"], T["W1S02"], T["W1S02"], T["W1S02"], T["W1S02"], T["W1S02"], T["W1S02"], T["W1S02"], T["W1S02"], T["W0S02"],
		T["_____"], T["_____"], T["_____"], T["_____"], T["_____"], T["_____"], T["_____"], T["_____"], T["_____"], T["_____"], T["_____"],
		T["_____"], T["_____"], T["_____"], T["_____"], T["_____"], T["_____"], T["_____"], T["_____"], T["_____"], T["_____"], T["_____"],

		T["_____"], T["C0m00"], T["C0m00"], T["C0m00"], T["C0m00"], T["C0m00"], T["C0m00"], T["C0m00"], T["C0m00"], T["C0m00"], T["_____"],
		T["_____"], T["T0m00"], T["C0m00"], T["C0m00"], T["C0m00"], T["C0m00"], T["W0m00"], T["W0dN0"], T["W0m00"], T["T0m00"], T["_____"],
		T["_____"], T["T0m00"], T["T0m00"], T["Xp0N0"], T["Xp0N0"], T["T0m00"], T["W0m00"], T["_____"], T["W0m00"], T["T0m00"], T["_____"],
		T["W0S20"], T["T0m00"], T["W0m00"], T["W0m00"], T["W0m00"], T["W0m00"], T["W0m00"], T["W0m00"], T["W0m00"], T["T0m00"], T["W0S20"],
		T["W0S02"], T["W1S02"], T["W1S02"], T["W1S02"], T["W1S02"], T["W1S02"], T["W1S02"], T["W1S02"], T["W1S02"], T["W1S02"], T["W0S02"],
		T["_____"], T["_____"], T["_____"], T["_____"], T["_____"], T["_____"], T["_____"], T["_____"], T["_____"], T["_____"], T["_____"],
		T["_____"], T["_____"], T["_____"], T["_____"], T["_____"], T["_____"], T["_____"], T["_____"], T["_____"], T["_____"], T["_____"],
		T["_____"], T["_____"], T["_____"], T["_____"], T["_____"], T["_____"], T["_____"], T["_____"], T["_____"], T["_____"], T["_____"],

		T["_____"], T["_____"], T["_____"], T["W0n00"], T["_____"], T["_____"], T["_____"], T["C0S02"], T["_____"], T["W0n00"], T["_____"],
		T["_____"], T["_____"], T["_____"], T["_____"], T["_____"], T["_____"], T["_____"], T["_____"], T["_____"], T["_____"], T["_____"],
		T["_____"], T["_____"], T["W0TS0"], T["_____"], T["_____"], T["W0TS0"], T["_____"], T["_____"], T["_____"], T["_____"], T["_____"],
		T["W0S02"], T["W0S02"], T["W0S02"], T["W0S02"], T["W0S02"], T["W0S02"], T["W0S02"], T["W0S02"], T["W0S02"], T["W0S02"], T["W0S02"],
		T["_____"], T["_____"], T["_____"], T["_____"], T["_____"], T["_____"], T["_____"], T["_____"], T["_____"], T["_____"], T["_____"],
		T["_____"], T["_____"], T["_____"], T["_____"], T["_____"], T["_____"], T["_____"], T["_____"], T["_____"], T["_____"], T["_____"],
		T["_____"], T["_____"], T["_____"], T["_____"], T["_____"], T["_____"], T["_____"], T["_____"], T["_____"], T["_____"], T["_____"],
		T["_____"], T["_____"], T["_____"], T["_____"], T["_____"], T["_____"], T["_____"], T["_____"], T["_____"], T["_____"], T["_____"],

		T["_____"], T["_____"], T["_____"], T["W0n00"], T["_____"], T["_____"], T["_____"], T["_____"], T["_____"], T["W0n00"], T["_____"],
		T["_____"], T["_____"], T["_____"], T["_____"], T["_____"], T["_____"], T["_____"], T["_____"], T["_____"], T["_____"], T["_____"],
		T["_____"], T["_____"], T["_____"], T["_____"], T["_____"], T["_____"], T["_____"], T["_____"], T["_____"], T["_____"], T["_____"],
		T["_____"], T["_____"], T["_____"], T["_____"], T["_____"], T["_____"], T["_____"], T["_____"], T["_____"], T["_____"], T["_____"],
		T["_____"], T["_____"], T["_____"], T["_____"], T["_____"], T["_____"], T["_____"], T["_____"], T["_____"], T["_____"], T["_____"],
		T["_____"], T["_____"], T["_____"], T["_____"], T["_____"], T["_____"], T["_____"], T["_____"], T["_____"], T["_____"], T["_____"],
		T["_____"], T["_____"], T["_____"], T["_____"], T["_____"], T["_____"], T["_____"], T["_____"], T["_____"], T["_____"], T["_____"],
		T["_____"], T["_____"], T["_____"], T["_____"], T["_____"], T["_____"], T["_____"], T["_____"], T["_____"], T["_____"], T["_____"],

		T["_____"], T["_____"], T["_____"], T["W0n00"], T["_____"], T["_____"], T["_____"], T["_____"], T["_____"], T["W0n00"], T["_____"],
		T["_____"], T["_____"], T["_____"], T["_____"], T["_____"], T["_____"], T["_____"], T["_____"], T["_____"], T["_____"], T["_____"],
		T["_____"], T["_____"], T["_____"], T["_____"], T["_____"], T["_____"], T["_____"], T["_____"], T["_____"], T["_____"], T["_____"],
		T["_____"], T["_____"], T["_____"], T["_____"], T["_____"], T["_____"], T["_____"], T["_____"], T["_____"], T["_____"], T["_____"],
		T["_____"], T["_____"], T["_____"], T["_____"], T["_____"], T["_____"], T["_____"], T["_____"], T["_____"], T["_____"], T["_____"],
		T["_____"], T["_____"], T["_____"], T["_____"], T["_____"], T["_____"], T["_____"], T["_____"], T["_____"], T["_____"], T["_____"],
		T["_____"], T["_____"], T["_____"], T["_____"], T["_____"], T["_____"], T["_____"], T["_____"], T["_____"], T["_____"], T["_____"],
		T["_____"], T["_____"], T["_____"], T["_____"], T["_____"], T["_____"], T["_____"], T["_____"], T["_____"], T["_____"], T["_____"],

		T["_____"], T["_____"], T["_____"], T["W0n00"], T["W0n00"], T["W0n00"], T["W0n00"], T["W0n00"], T["W0n00"], T["W0n00"], T["_____"],
		T["_____"], T["_____"], T["_____"], T["_____"], T["_____"], T["_____"], T["_____"], T["_____"], T["_____"], T["_____"], T["_____"],
		T["_____"], T["_____"], T["_____"], T["_____"], T["_____"], T["_____"], T["_____"], T["_____"], T["_____"], T["_____"], T["_____"],
		T["_____"], T["_____"], T["_____"], T["_____"], T["_____"], T["_____"], T["_____"], T["_____"], T["_____"], T["_____"], T["_____"],
		T["_____"], T["_____"], T["_____"], T["_____"], T["_____"], T["_____"], T["_____"], T["_____"], T["_____"], T["_____"], T["_____"],
		T["_____"], T["_____"], T["_____"], T["_____"], T["_____"], T["_____"], T["_____"], T["_____"], T["_____"], T["_____"], T["_____"],
		T["_____"], T["_____"], T["_____"], T["_____"], T["_____"], T["_____"], T["_____"], T["_____"], T["_____"], T["_____"], T["_____"],
		T["_____"], T["_____"], T["_____"], T["_____"], T["_____"], T["_____"], T["_____"], T["_____"], T["_____"], T["_____"], T["_____"],
	},
	yslice_prob = {
		{prob = 254,ypos = 0},
		{prob = 254,ypos = 1},
		{prob = 254,ypos = 2},
		{prob = 254,ypos = 3},
		{prob = 254,ypos = 4},
		{prob = 254,ypos = 5},
		{prob = 254,ypos = 6},
		{prob = 254,ypos = 7}
	}
}