



local T = lib_towns.schems.T


return {
	yslice_prob = {
		{prob = 254,ypos = 0},
		{prob = 254,ypos = 1},
		{prob = 254,ypos = 2},
		{prob = 254,ypos = 3},
		{prob = 254,ypos = 4},
		{prob = 254,ypos = 5},
		{prob = 254,ypos = 6},
		{prob = 254,ypos = 7},
		{prob = 254,ypos = 8},
		{prob = 254,ypos = 9},
		{prob = 254,ypos = 10},
		{prob = 254,ypos = 11},
		{prob = 254,ypos = 12},
		{prob = 254,ypos = 13},
		{prob = 254,ypos = 14},
		{prob = 254,ypos = 15},
		{prob = 254,ypos = 16},
		{prob = 254,ypos = 17},
		{prob = 254,ypos = 18},
		{prob = 254,ypos = 19},
		{prob = 254,ypos = 20},
		{prob = 254,ypos = 21},
		{prob = 254,ypos = 22},
		{prob = 254,ypos = 23},
		{prob = 254,ypos = 24},
		{prob = 254,ypos = 25},
		{prob = 254,ypos = 26},
		{prob = 254,ypos = 27},
		{prob = 254,ypos = 28},
		{prob = 254,ypos = 29},
		{prob = 254,ypos = 30},
		{prob = 254,ypos = 31},
		{prob = 254,ypos = 32},
		{prob = 254,ypos = 33},
		{prob = 254,ypos = 34},
		{prob = 254,ypos = 35},
		{prob = 254,ypos = 36},
		{prob = 254,ypos = 37},
		{prob = 254,ypos = 38},
		{prob = 254,ypos = 39},
		{prob = 254,ypos = 40},
		{prob = 254,ypos = 41},
		{prob = 254,ypos = 42},
		{prob = 254,ypos = 43}
	},
	data = {
		T["ddddd"], T["ddddd"], T["ddddd"], T["ddddd"], T["ddddd"], T["ddddd"], T["ddddd"], T["ddddd"], T["ddddd"], T["ddddd"], T["ddddd"], T["ddddd"], T["ddddd"], T["ddddd"], T["ddddd"], T["ddddd"], T["ddddd"], T["ddddd"], T["ddddd"], T["ddddd"], T["ddddd"], T["ddddd"], T["ddddd"], T["ddddd"], T["ddddd"], T["ddddd"], T["ddddd"], T["ddddd"], T["ddddd"], T["ddddd"], T["ddddd"], T["ddddd"], T["ddddd"], T["ddddd"], T["ddddd"], T["ddddd"], T["ddddd"], T["ddddd"], T["ddddd"], T["ddddd"], T["ddddd"], T["ddddd"], T["ddddd"], T["ddddd"], T["ddddd"], T["ddddd"], T["ddddd"], T["ddddd"], T["ddddd"], T["ddddd"], T["ddddd"], T["ddddd"], T["ddddd"], T["ddddd"], T["ddddd"], T["ddddd"], T["ddddd"], T["ddddd"], T["ddddd"], T["ddddd"], T["ddddd"], T["ddddd"], T["ddddd"], T["ddddd"], T["ddddd"], T["ddddd"], T["ddddd"], T["ddddd"], T["ddddd"], T["ddddd"], T["ddddd"], T["ddddd"], T["_____"], T["_____"], T["_____"], T["_____"], T["_____"], T["_____"], T["_____"], T["_____"], T["_____"], T["_____"], T["_____"], T["_____"], T["_____"], T["_____"], T["_____"], T["_____"], T["_____"], T["_____"], T["_____"], T["_____"], T["_____"], T["_____"], T["_____"], T["_____"], {param2 = 1,name = "cottages:roof_wood",prob = 254},
		T["_____"], T["_____"], T["_____"], T["_____"], {param2 = 3,name = "cottages:roof_wood",prob = 254},
		T["_____"], T["_____"], T["_____"], T["_____"], T["_____"], T["_____"], T["_____"], {param2 = 1,name = "cottages:roof_wood",prob = 254},
		T["_____"], T["_____"], {param2 = 3,name = "cottages:roof_wood",prob = 254},
		T["_____"], T["_____"], T["_____"], T["_____"], T["_____"], T["_____"], T["_____"], T["_____"], T["_____"], {param2 = 1,name = "cottages:roof_wood",prob = 254},
		{param2 = 3,name = "cottages:roof_wood",prob = 254},
		T["_____"], T["_____"], T["_____"], T["_____"], T["_____"], T["_____"], T["_____"], T["_____"], T["_____"], T["_____"], T["_____"], T["_____"], T["_____"], T["_____"], T["_____"], T["_____"], T["_____"], T["_____"], T["_____"], T["_____"], T["_____"], T["_____"], T["_____"], T["_____"], T["_____"], T["_____"], T["_____"], T["_____"], T["_____"], T["_____"], T["_____"], T["_____"], T["_____"], T["_____"], T["_____"], T["_____"], T["_____"], T["_____"], T["_____"], T["_____"], T["_____"], T["_____"], T["_____"], T["_____"], T["_____"], T["_____"], T["_____"], T["_____"], T["_____"], T["_____"], T["_____"], T["_____"], T["_____"], T["_____"], T["_____"], T["_____"], T["_____"], T["_____"], T["_____"], T["_____"], T["_____"], T["_____"], T["_____"], T["_____"], T["_____"], T["_____"], T["_____"], T["_____"], T["_____"], T["_____"], T["_____"], T["_____"], T["_____"], T["_____"], T["_____"], T["_____"], T["_____"], T["_____"], T["_____"], T["_____"], T["_____"], T["_____"], T["_____"], T["_____"], T["_____"], T["_____"], T["_____"], T["_____"], T["_____"], T["_____"], T["_____"], T["_____"], T["_____"], T["_____"], T["_____"], T["_____"], T["_____"], T["_____"], T["_____"], T["_____"], T["_____"], T["_____"], T["_____"], T["_____"], T["_____"], T["_____"], T["_____"], T["_____"], T["_____"], T["_____"], T["_____"], T["_____"], T["_____"], T["_____"], T["_____"], T["_____"], T["_____"], T["_____"], T["_____"], T["_____"], T["_____"], T["_____"], T["_____"], T["_____"], T["_____"], T["_____"], T["_____"], T["_____"], T["_____"], T["_____"], T["_____"], T["_____"], T["_____"], T["_____"], T["_____"], T["_____"], T["_____"], T["_____"], T["_____"], T["_____"], T["_____"], T["_____"], T["_____"], T["_____"], T["_____"], T["_____"], T["_____"], T["_____"], T["_____"], T["_____"], T["_____"], T["_____"], T["_____"], T["_____"], T["_____"], T["_____"], T["_____"], T["_____"], T["_____"], T["_____"], T["_____"], T["_____"], T["_____"], T["_____"], T["_____"], T["_____"], T["_____"], T["_____"], T["_____"], T["_____"], T["_____"], T["_____"], T["_____"], T["_____"], T["_____"], T["_____"], T["_____"], T["_____"], T["_____"], T["_____"], T["_____"], T["_____"], T["_____"], T["_____"], T["_____"], T["_____"], T["_____"], T["_____"], T["_____"], T["_____"], T["_____"], T["_____"], T["_____"], T["_____"], T["_____"], T["_____"], T["_____"], T["_____"], T["_____"], T["_____"], T["_____"], T["_____"], T["_____"], T["_____"], T["_____"], T["_____"], T["_____"], T["_____"], T["_____"], T["_____"], T["_____"], T["_____"], T["_____"], T["_____"], T["_____"], T["_____"], T["_____"], T["_____"], T["_____"], T["_____"], T["_____"], T["_____"], T["_____"], T["_____"], T["_____"], T["_____"], T["_____"], T["_____"], T["_____"], T["_____"], T["_____"], T["_____"], T["_____"], T["_____"], T["_____"], T["_____"], T["_____"], T["_____"], T["_____"], T["_____"], T["_____"], T["_____"], T["_____"], T["_____"], T["_____"], T["_____"], T["_____"], T["_____"], T["_____"], T["_____"], T["_____"], T["_____"], T["_____"], T["_____"], T["_____"], T["_____"], T["_____"], T["_____"], T["_____"], T["_____"], T["_____"], T["_____"], T["_____"], T["_____"], T["_____"], T["_____"], T["_____"], T["_____"], T["_____"], T["_____"], T["_____"], T["_____"], T["_____"], T["_____"], T["_____"], T["_____"], T["_____"], T["_____"], T["_____"], T["_____"], T["_____"], T["_____"], T["_____"], T["_____"], T["_____"], T["_____"], T["_____"], T["_____"], T["_____"], T["_____"], T["_____"], T["_____"], T["_____"], T["_____"], T["_____"], T["_____"], T["_____"], T["_____"], T["_____"], T["_____"], T["_____"], T["_____"], T["_____"], T["_____"], T["_____"], T["_____"], T["_____"], T["_____"], T["_____"], T["_____"], T["_____"], T["_____"], T["_____"], T["_____"], T["_____"], T["_____"], T["_____"], T["_____"], T["_____"], T["_____"], T["_____"], T["_____"], T["_____"], T["_____"], T["_____"], T["_____"], T["_____"], T["_____"], T["_____"], T["_____"], T["_____"], T["_____"], T["_____"], T["_____"], T["_____"], T["_____"], T["_____"], T["_____"], T["_____"], T["_____"], T["_____"], T["_____"], T["_____"], T["_____"], T["_____"], T["_____"], T["_____"], T["_____"], T["_____"], T["_____"], T["_____"], T["_____"], T["_____"], T["_____"], T["_____"], T["_____"], T["_____"], T["_____"], T["_____"], T["_____"], T["_____"], T["_____"], T["_____"], T["_____"], T["_____"], T["_____"], T["_____"], T["_____"], T["_____"], T["_____"], T["_____"], T["_____"], T["_____"], T["_____"], T["_____"], T["_____"], T["_____"], T["_____"], T["_____"], T["_____"], T["_____"], T["_____"], T["_____"], T["_____"], T["_____"], T["_____"], T["_____"], T["_____"], T["_____"], T["_____"], T["_____"], T["_____"], T["_____"], T["_____"], T["_____"], T["_____"], T["_____"], T["_____"], T["_____"], T["_____"], T["_____"], T["_____"], T["_____"], T["_____"], T["ddddd"], T["ddddd"], T["ddddd"], T["ddddd"], T["ddddd"], T["ddddd"], T["ddddd"], T["ddddd"], T["ddddd"], T["ddddd"], T["ddddd"], T["ddddd"], T["ddddd"], T["ddddd"], T["ddddd"], T["ddddd"], T["ddddd"], T["ddddd"], T["ddddd"], T["ddddd"], T["ddddd"], T["ddddd"], T["ddddd"], T["ddddd"], T["ddddd"], T["ddddd"], T["ddddd"], T["ddddd"], T["ddddd"], T["ddddd"], T["ddddd"], T["ddddd"], T["ddddd"], T["ddddd"], T["ddddd"], T["ddddd"], T["ddddd"], T["ddddd"], T["ddddd"], T["ddddd"], T["ddddd"], T["ddddd"], T["ddddd"], T["ddddd"], T["ddddd"], T["ddddd"], T["ddddd"], T["ddddd"], T["ddddd"], T["ddddd"], T["ddddd"], T["ddddd"], T["ddddd"], T["ddddd"], T["ddddd"], T["ddddd"], T["ddddd"], T["ddddd"], T["ddddd"], T["ddddd"], T["ddddd"], T["K0m00"], T["S0m00"], T["S0m00"], T["S0m00"], T["S0m00"], T["S0m00"], T["S0m00"], T["S0m00"], T["S0m00"], T["S0m00"], T["K0m00"], T["_____"], T["K0m00"], T["Cs0N0"], T["Cs0N0"], T["K0m00"], T["_____"], T["_____"], T["_____"], T["_____"], T["_____"], T["_____"], T["_____"], T["_____"], T["K0m00"], T["Cs0N0"], T["Cs0N0"], T["K0m00"], T["_____"], T["_____"], T["_____"], T["_____"], T["_____"], T["_____"], T["_____"], {param2 = 1,name = "cottages:roof_wood",prob = 254},
		T["K0m00"], T["Cs0N0"], T["_____"], T["K0m00"], {param2 = 3,name = "cottages:roof_wood",prob = 254},
		T["_____"], T["_____"], T["_____"], T["_____"], T["_____"], T["_____"], T["_____"], {param2 = 1,name = "cottages:roof_connector_wood",prob = 254},
		T["_____"], T["_____"], {param2 = 3,name = "cottages:roof_connector_wood",prob = 254},
		T["_____"], T["_____"], T["_____"], T["_____"], T["_____"], T["_____"], T["_____"], T["_____"], T["_____"], {param2 = 1,name = "cottages:roof_wood",prob = 254},
		{param2 = 3,name = "cottages:roof_wood",prob = 254},
		T["_____"], T["_____"], T["_____"], T["_____"], T["_____"], T["_____"], T["_____"], T["_____"], T["_____"], T["_____"], T["_____"], T["_____"], T["_____"], T["_____"], T["_____"], T["_____"], T["_____"], T["_____"], T["_____"], T["_____"], T["_____"], T["_____"], T["_____"], T["_____"], T["_____"], T["_____"], T["_____"], T["_____"], T["_____"], T["_____"], T["_____"], T["_____"], T["_____"], T["_____"], T["_____"], T["_____"], T["_____"], T["_____"], T["_____"], T["_____"], T["_____"], T["_____"], T["_____"], T["_____"], T["_____"], T["_____"], T["_____"], T["_____"], T["_____"], T["_____"], T["_____"], T["_____"], T["_____"], T["_____"], T["_____"], T["_____"], T["_____"], T["_____"], T["_____"], T["_____"], T["_____"], T["_____"], T["_____"], T["_____"], T["_____"], T["_____"], T["_____"], T["_____"], T["_____"], T["_____"], T["_____"], T["_____"], T["_____"], T["_____"], T["_____"], T["_____"], T["_____"], T["_____"], T["_____"], T["_____"], T["_____"], T["_____"], T["_____"], T["_____"], T["_____"], T["_____"], T["_____"], T["_____"], T["_____"], T["_____"], T["_____"], T["_____"], T["_____"], T["_____"], T["_____"], T["_____"], T["_____"], T["_____"], T["_____"], T["_____"], T["_____"], T["_____"], T["_____"], T["_____"], T["_____"], T["_____"], T["_____"], T["_____"], T["_____"], T["_____"], T["_____"], T["_____"], T["_____"], T["_____"], T["_____"], T["_____"], T["_____"], T["_____"], T["_____"], T["_____"], T["_____"], T["_____"], T["_____"], T["_____"], T["_____"], T["_____"], T["_____"], T["_____"], T["_____"], T["_____"], T["_____"], T["_____"], T["_____"], T["_____"], T["_____"], T["_____"], T["_____"], T["_____"], T["_____"], T["_____"], T["_____"], T["_____"], T["_____"], T["_____"], T["_____"], T["_____"], T["_____"], T["_____"], T["_____"], T["_____"], T["_____"], T["_____"], T["_____"], T["_____"], T["_____"], T["_____"], T["_____"], T["_____"], T["_____"], T["_____"], T["_____"], T["_____"], T["_____"], T["_____"], T["_____"], T["_____"], T["_____"], T["_____"], T["_____"], T["_____"], T["_____"], T["_____"], T["_____"], T["_____"], T["_____"], T["_____"], T["_____"], T["_____"], T["_____"], T["_____"], T["_____"], T["_____"], T["_____"], T["_____"], T["_____"], T["_____"], T["_____"], T["_____"], T["_____"], T["_____"], T["_____"], T["_____"], T["_____"], T["_____"], T["_____"], T["_____"], T["_____"], T["_____"], T["_____"], T["_____"], T["_____"], T["_____"], T["_____"], T["_____"], T["_____"], T["_____"], T["_____"], T["_____"], T["_____"], T["_____"], T["_____"], T["_____"], T["_____"], T["_____"], T["_____"], T["_____"], T["_____"], T["_____"], T["_____"], T["_____"], T["_____"], T["_____"], T["_____"], T["_____"], T["_____"], T["_____"], T["_____"], T["_____"], T["_____"], T["_____"], T["_____"], T["_____"], T["_____"], T["_____"], T["_____"], T["_____"], T["_____"], T["_____"], T["_____"], T["_____"], T["_____"], T["_____"], T["_____"], T["_____"], T["_____"], T["_____"], T["_____"], T["_____"], T["_____"], T["_____"], T["_____"], T["_____"], T["_____"], T["_____"], T["_____"], T["_____"], T["_____"], T["_____"], T["_____"], T["_____"], T["_____"], T["_____"], T["_____"], T["_____"], T["_____"], T["_____"], T["_____"], T["_____"], T["_____"], T["_____"], T["_____"], T["_____"], T["_____"], T["_____"], T["_____"], T["_____"], T["_____"], T["_____"], T["_____"], T["_____"], T["_____"], T["_____"], T["_____"], T["_____"], T["_____"], T["_____"], T["_____"], T["_____"], T["_____"], T["_____"], T["_____"], T["_____"], T["_____"], T["_____"], T["_____"], T["_____"], T["_____"], T["_____"], T["_____"], T["_____"], T["_____"], T["_____"], T["_____"], T["_____"], T["_____"], T["_____"], T["_____"], T["_____"], T["_____"], T["_____"], T["_____"], T["_____"], T["_____"], T["_____"], T["_____"], T["_____"], T["_____"], T["_____"], T["_____"], T["_____"], T["_____"], T["_____"], T["_____"], T["_____"], T["_____"], T["_____"], T["_____"], T["_____"], T["_____"], T["_____"], T["_____"], T["_____"], T["_____"], T["_____"], T["_____"], T["_____"], T["_____"], T["_____"], T["_____"], T["_____"], T["_____"], T["_____"], T["_____"], T["_____"], T["_____"], T["_____"], T["_____"], T["_____"], T["_____"], T["_____"], T["_____"], T["_____"], T["_____"], T["_____"], T["_____"], T["_____"], T["_____"], T["_____"], T["_____"], T["_____"], T["_____"], T["_____"], T["_____"], T["_____"], T["_____"], T["_____"], T["_____"], T["_____"], T["_____"], T["_____"], T["_____"], T["_____"], T["_____"], T["_____"], T["_____"], T["_____"], T["_____"], T["_____"], T["_____"], T["_____"], T["_____"], T["_____"], T["_____"], T["_____"], T["_____"], T["_____"], T["_____"], T["_____"], T["_____"], T["_____"], T["_____"], T["_____"], T["_____"], T["_____"], T["_____"], T["_____"], T["_____"], T["_____"], T["_____"], T["_____"], T["_____"], T["_____"], T["_____"], T["_____"], T["ddddd"], T["ddddd"], T["ddddd"], T["ddddd"], T["ddddd"], T["ddddd"], T["ddddd"], T["ddddd"], T["ddddd"], T["ddddd"], T["ddddd"], T["ddddd"], T["ddddd"], T["ddddd"], T["ddddd"], T["ddddd"], T["ddddd"], T["ddddd"], T["ddddd"], T["ddddd"], T["ddddd"], T["ddddd"], T["ddddd"], T["ddddd"], T["ddddd"], T["ddddd"], T["ddddd"], T["ddddd"], T["ddddd"], T["ddddd"], T["ddddd"], T["ddddd"], T["ddddd"], T["ddddd"], T["ddddd"], T["ddddd"], T["ddddd"], T["ddddd"], T["ddddd"], T["ddddd"], T["ddddd"], T["ddddd"], T["ddddd"], T["ddddd"], T["ddddd"], T["ddddd"], T["ddddd"], T["ddddd"], T["ddddd"], T["ddddd"], T["ddddd"], T["ddddd"], T["ddddd"], T["ddddd"], T["ddddd"], T["ddddd"], T["ddddd"], T["ddddd"], T["ddddd"], T["ddddd"], T["ddddd"], T["S0m00"], T["S0m00"], T["S0m00"], T["S0m00"], T["S0m00"], T["S0m00"], T["S0m00"], T["S0m00"], T["S0m00"], T["S0m00"], T["S0m00"], T["_____"], {param2 = 1,name = "cottages:shelf",prob = 254},
		{param2 = 3,name = "cottages:shelf",prob = 254},
		{param2 = 2,name = "cottages:table",prob = 254},
		{param2 = 2,name = "cottages:table",prob = 254},
		T["_____"], T["_____"], T["_____"], T["_____"], T["_____"], T["_____"], T["_____"], T["_____"], {param2 = 1,name = "cottages:shelf",prob = 254},
		{param2 = 3,name = "cottages:shelf",prob = 254},
		T["_____"], T["_____"], T["_____"], T["_____"], T["_____"], T["_____"], T["_____"], T["_____"], T["_____"], {param2 = 1,name = "cottages:roof_wood",prob = 254},
		T["_____"], {param2 = 3,name = "cottages:shelf",prob = 254},
		T["_____"], T["_____"], {param2 = 3,name = "cottages:roof_wood",prob = 254},
		T["_____"], T["_____"], T["_____"], T["_____"], T["_____"], T["_____"], T["_____"], {param2 = 1,name = "cottages:roof_wood",prob = 254},
		T["_____"], T["_____"], {param2 = 3,name = "cottages:roof_wood",prob = 254},
		T["_____"], T["_____"], T["_____"], T["_____"], T["_____"], T["_____"], T["_____"], T["_____"], T["_____"], {param2 = 1,name = "cottages:roof_wood",prob = 254},
		{param2 = 3,name = "cottages:roof_wood",prob = 254},
		T["_____"], T["_____"], T["_____"], T["_____"], T["_____"], T["_____"], T["_____"], T["_____"], T["_____"], T["_____"], T["_____"], T["_____"], T["_____"], T["_____"], T["_____"], T["_____"], T["_____"], T["_____"], T["_____"], T["_____"], T["_____"], T["_____"], T["_____"], T["_____"], T["_____"], T["_____"], T["_____"], T["_____"], T["_____"], T["_____"], T["_____"], T["_____"], T["_____"], T["_____"], T["_____"], T["_____"], T["_____"], T["_____"], T["_____"], T["_____"], T["_____"], T["_____"], T["_____"], T["_____"], T["_____"], T["_____"], T["_____"], T["_____"], T["_____"], T["_____"], T["_____"], T["_____"], T["_____"], T["_____"], T["_____"], T["_____"], T["_____"], T["_____"], T["_____"], T["_____"], T["_____"], T["_____"], T["_____"], T["_____"], T["_____"], T["_____"], T["_____"], T["_____"], T["_____"], T["_____"], T["_____"], T["_____"], T["_____"], T["_____"], T["_____"], T["_____"], T["_____"], T["_____"], T["_____"], T["_____"], T["_____"], T["_____"], T["_____"], T["_____"], T["_____"], T["_____"], T["_____"], T["_____"], T["_____"], T["_____"], T["_____"], T["_____"], T["_____"], T["_____"], T["_____"], T["_____"], T["_____"], T["_____"], T["_____"], T["_____"], T["_____"], T["_____"], T["_____"], T["_____"], T["_____"], T["_____"], T["_____"], T["_____"], T["_____"], T["_____"], T["_____"], T["_____"], T["_____"], T["_____"], T["_____"], T["_____"], T["_____"], T["_____"], T["_____"], T["_____"], T["_____"], T["_____"], T["_____"], T["_____"], T["_____"], T["_____"], T["_____"], T["_____"], T["_____"], T["_____"], T["_____"], T["_____"], T["_____"], T["_____"], T["_____"], T["_____"], T["_____"], T["_____"], T["_____"], T["_____"], T["_____"], T["_____"], T["_____"], T["_____"], T["_____"], T["_____"], T["_____"], T["_____"], T["_____"], T["_____"], T["_____"], T["_____"], T["_____"], T["_____"], T["_____"], T["_____"], T["_____"], T["_____"], T["_____"], T["_____"], T["_____"], T["_____"], T["_____"], T["_____"], T["_____"], T["_____"], T["_____"], T["_____"], T["_____"], T["_____"], T["_____"], T["_____"], T["_____"], T["_____"], T["_____"], T["_____"], T["_____"], T["_____"], T["_____"], T["_____"], T["_____"], T["_____"], T["_____"], T["_____"], T["_____"], T["_____"], T["_____"], T["_____"], T["_____"], T["_____"], T["_____"], T["_____"], T["_____"], T["_____"], T["_____"], T["_____"], T["_____"], T["_____"], T["_____"], T["_____"], T["_____"], T["_____"], T["_____"], T["_____"], T["_____"], T["_____"], T["_____"], T["_____"], T["_____"], T["_____"], T["_____"], T["_____"], T["_____"], T["_____"], T["_____"], T["_____"], T["_____"], T["_____"], T["_____"], T["_____"], T["_____"], T["_____"], T["_____"], T["_____"], T["_____"], T["_____"], T["_____"], T["_____"], T["_____"], T["_____"], T["_____"], T["_____"], T["_____"], T["_____"], T["_____"], T["_____"], T["_____"], T["_____"], T["_____"], T["_____"], T["_____"], T["_____"], T["_____"], T["_____"], T["_____"], T["_____"], T["_____"], T["_____"], T["_____"], T["_____"], T["_____"], T["_____"], T["_____"], T["_____"], T["_____"], T["_____"], T["_____"], T["_____"], T["_____"], T["_____"], T["_____"], T["_____"], T["_____"], T["_____"], T["_____"], T["_____"], T["_____"], T["_____"], T["_____"], T["_____"], T["_____"], T["_____"], T["_____"], T["_____"], T["_____"], T["_____"], T["_____"], T["_____"], T["_____"], T["_____"], T["_____"], T["_____"], T["_____"], T["_____"], T["_____"], T["_____"], T["_____"], T["_____"], T["_____"], T["_____"], T["_____"], T["_____"], T["_____"], T["_____"], T["_____"], T["_____"], T["_____"], T["_____"], T["_____"], T["_____"], T["_____"], T["_____"], T["_____"], T["_____"], T["_____"], T["_____"], T["_____"], T["_____"], T["_____"], T["_____"], T["_____"], T["_____"], T["_____"], T["_____"], T["_____"], T["_____"], T["_____"], T["_____"], T["_____"], T["_____"], T["_____"], T["_____"], T["_____"], T["_____"], T["_____"], T["_____"], T["_____"], T["_____"], T["_____"], T["_____"], T["_____"], T["_____"], T["_____"], T["_____"], T["_____"], T["_____"], T["_____"], T["_____"], T["_____"], T["_____"], T["_____"], T["_____"], T["_____"], T["_____"], T["_____"], T["_____"], T["_____"], T["_____"], T["_____"], T["_____"], T["_____"], T["_____"], T["_____"], T["_____"], T["_____"], T["_____"], T["_____"], T["_____"], T["_____"], T["_____"], T["_____"], T["_____"], T["_____"], T["_____"], T["_____"], T["_____"], T["_____"], T["_____"], T["_____"], T["_____"], T["_____"], T["_____"], T["_____"], T["_____"], T["_____"], T["_____"], T["_____"], T["_____"], T["_____"], T["_____"], T["_____"], T["_____"], T["_____"], T["_____"], T["_____"], T["_____"], T["_____"], T["_____"], T["_____"], T["_____"], T["_____"], T["_____"], T["_____"], T["_____"], T["_____"], T["_____"], T["_____"], T["_____"], T["_____"], T["_____"], T["_____"], T["_____"], T["_____"], T["_____"], T["ddddd"], T["ddddd"], T["ddddd"], T["ddddd"], T["ddddd"], T["ddddd"], T["ddddd"], T["ddddd"], T["ddddd"], T["ddddd"], T["ddddd"], T["ddddd"], T["ddddd"], T["ddddd"], T["ddddd"], T["ddddd"], T["ddddd"], T["ddddd"], T["ddddd"], T["ddddd"], T["ddddd"], T["ddddd"], T["ddddd"], T["ddddd"], T["ddddd"], T["ddddd"], T["ddddd"], T["ddddd"], T["ddddd"], T["ddddd"], T["ddddd"], T["ddddd"], T["ddddd"], T["ddddd"], T["ddddd"], T["ddddd"], T["ddddd"], T["ddddd"], T["ddddd"], T["ddddd"], T["ddddd"], T["ddddd"], T["ddddd"], T["ddddd"], T["ddddd"], T["ddddd"], T["ddddd"], T["ddddd"], T["ddddd"], T["ddddd"], T["ddddd"], T["ddddd"], T["ddddd"], T["ddddd"], T["ddddd"], T["ddddd"], T["ddddd"], T["ddddd"], T["ddddd"], T["ddddd"], T["ddddd"], T["S0m00"], T["S0m00"], T["S0m00"], T["S0m00"], T["S0m00"], T["S0m00"], T["S0m00"], T["S0m00"], T["S0m00"], T["S0m00"], T["S0m00"], T["_____"], {param2 = 1,name = "cottages:shelf",prob = 254},
		{param2 = 3,name = "cottages:shelf",prob = 254},
		{param2 = 0,name = "carts:rail",prob = 254},
		{param2 = 0,name = "carts:rail",prob = 254},
		{param2 = 0,name = "carts:rail",prob = 254},
		{param2 = 0,name = "carts:rail",prob = 254},
		{param2 = 0,name = "carts:rail",prob = 254},
		{param2 = 0,name = "carts:rail",prob = 254},
		{param2 = 0,name = "carts:rail",prob = 254},
		T["_____"], T["_____"], T["_____"], {param2 = 1,name = "cottages:shelf",prob = 254},
		{param2 = 3,name = "cottages:shelf",prob = 254},
		T["_____"], T["_____"], T["_____"], T["_____"], T["_____"], T["_____"], T["_____"], T["_____"], T["_____"], {param2 = 1,name = "cottages:roof_wood",prob = 254},
		T["_____"], T["_____"], T["_____"], T["_____"], {param2 = 3,name = "cottages:roof_wood",prob = 254},
		T["_____"], T["_____"], T["_____"], T["_____"], T["_____"], T["_____"], T["_____"], {param2 = 1,name = "cottages:roof_wood",prob = 254},
		T["_____"], T["_____"], {param2 = 3,name = "cottages:roof_wood",prob = 254},
		T["_____"], T["_____"], T["_____"], T["_____"], T["_____"], T["_____"], T["_____"], T["_____"], T["_____"], {param2 = 1,name = "cottages:roof_wood",prob = 254},
		{param2 = 3,name = "cottages:roof_wood",prob = 254},
		T["_____"], T["_____"], T["_____"], T["_____"], T["_____"], T["_____"], T["_____"], T["_____"], T["_____"], T["_____"], T["_____"], T["_____"], T["_____"], T["_____"], T["_____"], T["_____"], T["_____"], T["_____"], T["_____"], T["_____"], T["_____"], T["_____"], T["_____"], T["_____"], T["_____"], T["_____"], T["_____"], T["_____"], T["_____"], T["_____"], T["_____"], T["_____"], T["_____"], T["_____"], T["_____"], T["_____"], T["_____"], T["_____"], T["_____"], T["_____"], T["_____"], T["_____"], T["_____"], T["_____"], T["_____"], T["_____"], T["_____"], T["_____"], T["_____"], T["_____"], T["_____"], T["_____"], T["_____"], T["_____"], T["_____"], T["_____"], T["_____"], T["_____"], T["_____"], T["_____"], T["_____"], T["_____"], T["_____"], T["_____"], T["_____"], T["_____"], T["_____"], T["_____"], T["_____"], T["_____"], T["_____"], T["_____"], T["_____"], T["_____"], T["_____"], T["_____"], T["_____"], T["_____"], T["_____"], T["_____"], T["_____"], T["_____"], T["_____"], T["_____"], T["_____"], T["_____"], T["_____"], T["_____"], T["_____"], T["_____"], T["_____"], T["_____"], T["_____"], T["_____"], T["_____"], T["_____"], T["_____"], T["_____"], T["_____"], T["_____"], T["_____"], T["_____"], T["_____"], T["_____"], T["_____"], T["_____"], T["_____"], T["_____"], T["_____"], T["_____"], T["_____"], T["_____"], T["_____"], T["_____"], T["_____"], T["_____"], T["_____"], T["_____"], T["_____"], T["_____"], T["_____"], T["_____"], T["_____"], T["_____"], T["_____"], T["_____"], T["_____"], T["_____"], T["_____"], T["_____"], T["_____"], T["_____"], T["_____"], T["_____"], T["_____"], T["_____"], T["_____"], T["_____"], T["_____"], T["_____"], T["_____"], T["_____"], T["_____"], T["_____"], T["_____"], T["_____"], T["_____"], T["_____"], T["_____"], T["_____"], T["_____"], T["_____"], T["_____"], T["_____"], T["_____"], T["_____"], T["_____"], T["_____"], T["_____"], T["_____"], T["_____"], T["_____"], T["_____"], T["_____"], T["_____"], T["_____"], T["_____"], T["_____"], T["_____"], T["_____"], T["_____"], T["_____"], T["_____"], T["_____"], T["_____"], T["_____"], T["_____"], T["_____"], T["_____"], T["_____"], T["_____"], T["_____"], T["_____"], T["_____"], T["_____"], T["_____"], T["_____"], T["_____"], T["_____"], T["_____"], T["_____"], T["_____"], T["_____"], T["_____"], T["_____"], T["_____"], T["_____"], T["_____"], T["_____"], T["_____"], T["_____"], T["_____"], T["_____"], T["_____"], T["_____"], T["_____"], T["_____"], T["_____"], T["_____"], T["_____"], T["_____"], T["_____"], T["_____"], T["_____"], T["_____"], T["_____"], T["_____"], T["_____"], T["_____"], T["_____"], T["_____"], T["_____"], T["_____"], T["_____"], T["_____"], T["_____"], T["_____"], T["_____"], T["_____"], T["_____"], T["_____"], T["_____"], T["_____"], T["_____"], T["_____"], T["_____"], T["_____"], T["_____"], T["_____"], T["_____"], T["_____"], T["_____"], T["_____"], T["_____"], T["_____"], T["_____"], T["_____"], T["_____"], T["_____"], T["_____"], T["_____"], T["_____"], T["_____"], T["_____"], T["_____"], T["_____"], T["_____"], T["_____"], T["_____"], T["_____"], T["_____"], T["_____"], T["_____"], T["_____"], T["_____"], T["_____"], T["_____"], T["_____"], T["_____"], T["_____"], T["_____"], T["_____"], T["_____"], T["_____"], T["_____"], T["_____"], T["_____"], T["_____"], T["_____"], T["_____"], T["_____"], T["_____"], T["_____"], T["_____"], T["_____"], T["_____"], T["_____"], T["_____"], T["_____"], T["_____"], T["_____"], T["_____"], T["_____"], T["_____"], T["_____"], T["_____"], T["_____"], T["_____"], T["_____"], T["_____"], T["_____"], T["_____"], T["_____"], T["_____"], T["_____"], T["_____"], T["_____"], T["_____"], T["_____"], T["_____"], T["_____"], T["_____"], T["_____"], T["_____"], T["_____"], T["_____"], T["_____"], T["_____"], T["_____"], T["_____"], T["_____"], T["_____"], T["_____"], T["_____"], T["_____"], T["_____"], T["_____"], T["_____"], T["_____"], T["_____"], T["_____"], T["_____"], T["_____"], T["_____"], T["_____"], T["_____"], T["_____"], T["_____"], T["_____"], T["_____"], T["_____"], T["_____"], T["_____"], T["_____"], T["_____"], T["_____"], T["_____"], T["_____"], T["_____"], T["_____"], T["_____"], T["_____"], T["_____"], T["_____"], T["_____"], T["_____"], T["_____"], T["_____"], T["_____"], T["_____"], T["_____"], T["_____"], T["_____"], T["_____"], T["_____"], T["_____"], T["_____"], T["_____"], T["_____"], T["_____"], T["_____"], T["_____"], T["_____"], T["_____"], T["_____"], T["_____"], T["_____"], T["_____"], T["_____"], T["_____"], T["_____"], T["_____"], T["_____"], T["_____"], T["_____"], T["_____"], T["_____"], T["_____"], T["_____"], T["_____"], T["_____"], T["_____"], T["_____"], T["_____"], T["_____"], T["_____"], T["_____"], T["_____"], T["_____"], T["_____"], T["_____"], T["_____"], T["_____"], T["_____"], T["ddddd"], T["ddddd"], T["ddddd"], T["ddddd"], T["ddddd"], T["ddddd"], T["ddddd"], T["ddddd"], T["ddddd"], T["ddddd"], T["ddddd"], T["ddddd"], T["ddddd"], T["ddddd"], T["ddddd"], T["ddddd"], T["ddddd"], T["ddddd"], T["ddddd"], T["ddddd"], T["ddddd"], T["ddddd"], T["ddddd"], T["ddddd"], T["ddddd"], T["ddddd"], T["ddddd"], T["ddddd"], T["ddddd"], T["ddddd"], T["ddddd"], T["ddddd"], T["ddddd"], T["ddddd"], T["ddddd"], T["ddddd"], T["ddddd"], T["ddddd"], T["ddddd"], T["ddddd"], T["ddddd"], T["ddddd"], T["ddddd"], T["ddddd"], T["ddddd"], T["ddddd"], T["ddddd"], T["ddddd"], T["ddddd"], T["ddddd"], T["ddddd"], T["ddddd"], T["ddddd"], T["ddddd"], T["ddddd"], T["ddddd"], T["ddddd"], T["ddddd"], T["ddddd"], T["ddddd"], T["ddddd"], T["S0m00"], T["S0m00"], T["S0m00"], T["K0m00"], T["K0m00"], T["K0m00"], T["K0m00"], T["S0m00"], T["S0m00"], T["S0m00"], T["S0m00"], T["_____"], T["K0m00"], {param2 = 3,name = "cottages:shelf",prob = 254},
		{param2 = 0,name = "carts:rail",prob = 254},
		T["K0m00"], T["_____"], {param2 = 0,name = "carts:rail",prob = 254},
		T["_____"], T["K0m00"], {param2 = 0,name = "carts:rail",prob = 254},
		T["_____"], T["_____"], T["_____"], T["K0m00"], T["_____"], T["_____"], T["K0m00"], T["_____"], T["_____"], T["_____"], T["K0m00"], T["_____"], T["_____"], T["_____"], {param2 = 1,name = "cottages:roof_wood",prob = 254},
		T["K0m00"], {param2 = 3,name = "torch:torch_wall",prob = 254},
		T["_____"], T["K0m00"], T["K0m00"], T["_____"], T["K0m00"], T["K0m00"], T["_____"], T["_____"], T["_____"], T["_____"], {param2 = 1,name = "cottages:roof_connector_wood",prob = 254},
		T["_____"], T["_____"], T["K0m00"], T["K0m00"], T["K0m00"], T["K0m00"], T["K0m00"], T["_____"], T["_____"], T["_____"], T["_____"], T["_____"], {param2 = 1,name = "cottages:roof_wood",prob = 254},
		{param2 = 3,name = "cottages:roof_wood",prob = 254},
		T["K0m00"], T["_____"], T["_____"], T["_____"], T["K0m00"], T["_____"], T["_____"], T["_____"], T["_____"], T["_____"], T["_____"], T["_____"], T["K0m00"], T["_____"], T["_____"], T["_____"], T["K0m00"], T["_____"], T["_____"], T["_____"], T["_____"], T["_____"], T["_____"], T["_____"], T["K0m00"], T["_____"], T["_____"], T["_____"], T["K0m00"], T["_____"], T["_____"], T["_____"], T["_____"], T["_____"], T["_____"], T["_____"], T["K0m00"], T["K0m00"], T["K0m00"], T["K0m00"], T["K0m00"], T["_____"], T["_____"], T["_____"], T["_____"], T["_____"], T["_____"], T["_____"], T["K0m00"], T["_____"], T["_____"], T["_____"], T["K0m00"], T["_____"], T["_____"], T["_____"], T["_____"], T["_____"], T["_____"], T["_____"], {param2 = 3,name = "lib_ecology:tree_default_wood_fence",prob = 254},
		T["_____"], T["_____"], T["_____"], {param2 = 3,name = "lib_ecology:tree_default_wood_fence",prob = 254},
		T["_____"], T["_____"], T["_____"], T["_____"], T["_____"], T["_____"], T["_____"], {param2 = 3,name = "lib_ecology:tree_default_wood_fence",prob = 254},
		T["_____"], T["_____"], T["_____"], {param2 = 3,name = "lib_ecology:tree_default_wood_fence",prob = 254},
		T["_____"], T["_____"], T["_____"], T["_____"], T["_____"], T["_____"], T["_____"], {param2 = 3,name = "lib_ecology:tree_default_wood_fence",prob = 254},
		{param2 = 3,name = "lib_ecology:tree_default_wood_fence",prob = 254},
		{param2 = 3,name = "lib_ecology:tree_default_wood_fence",prob = 254},
		{param2 = 3,name = "lib_ecology:tree_default_wood_fence",prob = 254},
		{param2 = 3,name = "lib_ecology:tree_default_wood_fence",prob = 254},
		T["_____"], T["_____"], T["_____"], T["_____"], T["_____"], T["_____"], T["_____"], {param2 = 3,name = "lib_ecology:tree_default_wood_fence",prob = 254},
		{param2 = 1,name = "torch:torch",prob = 254},
		T["_____"], {param2 = 1,name = "torch:torch",prob = 254},
		{param2 = 3,name = "lib_ecology:tree_default_wood_fence",prob = 254},
		T["_____"], T["_____"], T["_____"], T["_____"], T["_____"], T["_____"], T["_____"], {param2 = 3,name = "lib_ecology:tree_default_wood_fence",prob = 254},
		{param2 = 3,name = "lib_ecology:tree_default_wood_fence",prob = 254},
		{param2 = 3,name = "lib_ecology:tree_default_wood_fence",prob = 254},
		{param2 = 3,name = "lib_ecology:tree_default_wood_fence",prob = 254},
		{param2 = 3,name = "lib_ecology:tree_default_wood_fence",prob = 254},
		T["_____"], T["_____"], T["_____"], T["_____"], T["_____"], T["_____"], T["_____"], {param2 = 3,name = "lib_ecology:tree_default_wood_fence",prob = 254},
		{param2 = 1,name = "torch:torch",prob = 254},
		T["_____"], {param2 = 1,name = "torch:torch",prob = 254},
		{param2 = 3,name = "lib_ecology:tree_default_wood_fence",prob = 254},
		T["_____"], T["_____"], T["_____"], T["_____"], T["_____"], T["_____"], T["_____"], {param2 = 3,name = "lib_ecology:tree_default_wood_fence",prob = 254},
		{param2 = 3,name = "lib_ecology:tree_default_wood_fence",prob = 254},
		{param2 = 3,name = "lib_ecology:tree_default_wood_fence",prob = 254},
		{param2 = 3,name = "lib_ecology:tree_default_wood_fence",prob = 254},
		{param2 = 3,name = "lib_ecology:tree_default_wood_fence",prob = 254},
		T["_____"], T["_____"], T["_____"], T["_____"], T["_____"], T["_____"], T["_____"], {param2 = 3,name = "lib_ecology:tree_default_wood_fence",prob = 254},
		{param2 = 1,name = "torch:torch",prob = 254},
		T["_____"], {param2 = 1,name = "torch:torch",prob = 254},
		{param2 = 3,name = "lib_ecology:tree_default_wood_fence",prob = 254},
		T["_____"], T["_____"], T["_____"], T["_____"], T["_____"], T["_____"], T["_____"], {param2 = 3,name = "lib_ecology:tree_default_wood_fence",prob = 254},
		{param2 = 3,name = "lib_ecology:tree_default_wood_fence",prob = 254},
		{param2 = 3,name = "lib_ecology:tree_default_wood_fence",prob = 254},
		{param2 = 3,name = "lib_ecology:tree_default_wood_fence",prob = 254},
		{param2 = 3,name = "lib_ecology:tree_default_wood_fence",prob = 254},
		T["_____"], T["_____"], T["_____"], T["_____"], T["_____"], T["_____"], T["_____"], {param2 = 1,name = "torch:torch",prob = 254},
		{param2 = 1,name = "torch:torch",prob = 254},
		{param2 = 1,name = "torch:torch",prob = 254},
		{param2 = 1,name = "torch:torch",prob = 254},
		{param2 = 1,name = "torch:torch",prob = 254},
		T["_____"], T["_____"], T["_____"], T["_____"], T["_____"], T["_____"], T["_____"], T["_____"], T["_____"], T["_____"], T["_____"], T["_____"], T["_____"], T["_____"], T["_____"], T["_____"], T["_____"], T["_____"], T["_____"], T["_____"], T["_____"], T["_____"], T["_____"], T["_____"], T["_____"], T["_____"], T["_____"], T["_____"], T["_____"], T["_____"], T["_____"], T["_____"], T["_____"], T["_____"], T["_____"], T["_____"], T["_____"], T["_____"], T["_____"], T["_____"], T["_____"], T["_____"], T["_____"], T["_____"], T["_____"], T["_____"], T["_____"], T["_____"], T["_____"], T["_____"], T["_____"], T["_____"], T["_____"], T["_____"], T["_____"], T["_____"], T["_____"], T["_____"], T["_____"], T["_____"], T["_____"], T["_____"], T["_____"], T["_____"], T["_____"], T["_____"], T["_____"], T["_____"], T["_____"], T["_____"], T["_____"], T["_____"], T["_____"], T["_____"], T["_____"], T["_____"], T["_____"], T["_____"], T["_____"], T["_____"], T["_____"], T["_____"], T["_____"], T["_____"], T["_____"], T["_____"], T["_____"], T["_____"], T["_____"], T["_____"], T["_____"], T["_____"], T["_____"], T["_____"], T["_____"], T["_____"], T["_____"], T["_____"], T["_____"], T["_____"], T["_____"], T["_____"], T["_____"], T["_____"], T["_____"], T["_____"], T["_____"], T["_____"], T["_____"], T["_____"], T["_____"], T["_____"], T["_____"], T["_____"], T["_____"], T["_____"], T["_____"], T["_____"], T["_____"], T["_____"], T["_____"], T["_____"], T["_____"], T["_____"], T["_____"], T["_____"], T["_____"], T["_____"], T["_____"], T["_____"], T["_____"], T["_____"], T["_____"], T["_____"], T["_____"], T["_____"], T["_____"], T["_____"], T["_____"], T["_____"], T["_____"], T["_____"], T["_____"], T["_____"], T["_____"], T["_____"], T["_____"], T["_____"], T["_____"], T["_____"], T["_____"], T["_____"], T["_____"], T["_____"], T["_____"], T["_____"], T["_____"], T["_____"], T["_____"], T["_____"], T["_____"], T["_____"], T["_____"], T["_____"], T["_____"], T["_____"], T["_____"], T["_____"], T["_____"], T["_____"], T["_____"], T["_____"], T["_____"], T["_____"], T["_____"], T["_____"], T["_____"], T["_____"], T["_____"], T["_____"], T["_____"], T["_____"], T["_____"], T["_____"], T["_____"], T["_____"], T["_____"], T["_____"], T["_____"], T["_____"], T["_____"], T["_____"], T["_____"], T["_____"], T["_____"], T["_____"], T["_____"], T["_____"], T["_____"], T["_____"], T["_____"], T["_____"], T["_____"], T["_____"], T["_____"], T["_____"], T["_____"], T["_____"], T["_____"], T["_____"], T["_____"], T["_____"], T["_____"], T["_____"], T["_____"], T["_____"], T["_____"], T["_____"], T["_____"], T["_____"], T["_____"], T["_____"], T["_____"], T["_____"], T["_____"], T["_____"], T["_____"], T["_____"], T["_____"], T["_____"], T["_____"], T["ddddd"], T["ddddd"], T["ddddd"], T["ddddd"], T["ddddd"], {param2 = 5,name = "cottages:ladder_with_rope_and_rail",prob = 254},
		{param2 = 5,name = "cottages:ladder_with_rope_and_rail",prob = 254},
		{param2 = 2,name = "cottages:ladder_with_rope_and_rail",prob = 254},
		T["ddddd"], T["ddddd"], T["ddddd"], T["ddddd"], T["ddddd"], T["ddddd"], T["ddddd"], T["ddddd"], T["ddddd"], {param2 = 5,name = "cottages:ladder_with_rope_and_rail",prob = 254},
		{param2 = 5,name = "cottages:ladder_with_rope_and_rail",prob = 254},
		{param2 = 2,name = "cottages:ladder_with_rope_and_rail",prob = 254},
		T["ddddd"], T["ddddd"], T["ddddd"], T["ddddd"], T["ddddd"], T["ddddd"], T["ddddd"], T["ddddd"], T["ddddd"], {param2 = 5,name = "cottages:ladder_with_rope_and_rail",prob = 254},
		{param2 = 5,name = "cottages:ladder_with_rope_and_rail",prob = 254},
		{param2 = 2,name = "cottages:ladder_with_rope_and_rail",prob = 254},
		T["ddddd"], T["ddddd"], T["ddddd"], T["ddddd"], T["ddddd"], T["ddddd"], T["ddddd"], T["ddddd"], T["ddddd"], {param2 = 5,name = "cottages:ladder_with_rope_and_rail",prob = 254},
		{param2 = 5,name = "cottages:ladder_with_rope_and_rail",prob = 254},
		{param2 = 2,name = "cottages:ladder_with_rope_and_rail",prob = 254},
		T["ddddd"], T["ddddd"], T["ddddd"], T["ddddd"], T["ddddd"], T["ddddd"], T["ddddd"], T["ddddd"], T["ddddd"], {param2 = 5,name = "cottages:ladder_with_rope_and_rail",prob = 254},
		{param2 = 5,name = "cottages:ladder_with_rope_and_rail",prob = 254},
		{param2 = 2,name = "cottages:ladder_with_rope_and_rail",prob = 254},
		T["ddddd"], T["ddddd"], T["ddddd"], T["ddddd"], T["ddddd"], T["S0m00"], T["S0m00"], T["S0m00"], T["K0m00"], {param2 = 5,name = "cottages:ladder_with_rope_and_rail",prob = 254},
		{param2 = 5,name = "cottages:ladder_with_rope_and_rail",prob = 254},
		{param2 = 2,name = "cottages:ladder_with_rope_and_rail",prob = 254},
		T["K0m00"], T["S0m00"], T["S0m00"], T["S0m00"], T["_____"], T["_____"], T["_____"], {param2 = 0,name = "carts:rail",prob = 254},
		T["_____"], {param2 = 5,name = "cottages:ladder_with_rope_and_rail",prob = 254},
		{param2 = 5,name = "cottages:ladder_with_rope_and_rail",prob = 254},
		{param2 = 2,name = "cottages:ladder_with_rope_and_rail",prob = 254},
		T["_____"], {param2 = 0,name = "carts:rail",prob = 254},
		T["_____"], T["_____"], T["_____"], T["_____"], T["_____"], T["_____"], T["_____"], {param2 = 5,name = "cottages:ladder_with_rope_and_rail",prob = 254},
		{param2 = 5,name = "cottages:ladder_with_rope_and_rail",prob = 254},
		{param2 = 2,name = "cottages:ladder_with_rope_and_rail",prob = 254},
		T["_____"], T["_____"], T["_____"], T["_____"], {param2 = 1,name = "cottages:roof_wood",prob = 254},
		T["_____"], T["_____"], T["_____"], T["K0m00"], {param2 = 5,name = "cottages:ladder_with_rope_and_rail",prob = 254},
		{param2 = 5,name = "cottages:ladder_with_rope_and_rail",prob = 254},
		{param2 = 2,name = "cottages:ladder_with_rope_and_rail",prob = 254},
		T["K0m00"], T["_____"], T["_____"], T["_____"], T["_____"], {param2 = 1,name = "cottages:roof_wood",prob = 254},
		T["_____"], T["_____"], T["K0m00"], {param2 = 5,name = "cottages:ladder_with_rope_and_rail",prob = 254},
		{param2 = 5,name = "cottages:ladder_with_rope_and_rail",prob = 254},
		{param2 = 2,name = "cottages:ladder_with_rope_and_rail",prob = 254},
		T["K0m00"], T["_____"], T["_____"], T["_____"], T["_____"], T["_____"], {param2 = 1,name = "cottages:roof_wood",prob = 254},
		{param2 = 3,name = "cottages:roof_wood",prob = 254},
		T["_____"], {param2 = 5,name = "cottages:ladder_with_rope_and_rail",prob = 254},
		{param2 = 5,name = "cottages:ladder_with_rope_and_rail",prob = 254},
		{param2 = 2,name = "cottages:ladder_with_rope_and_rail",prob = 254},
		T["_____"], T["_____"], T["_____"], T["_____"], T["_____"], T["_____"], T["_____"], T["_____"], T["_____"], {param2 = 5,name = "cottages:ladder_with_rope_and_rail",prob = 254},
		{param2 = 5,name = "cottages:ladder_with_rope_and_rail",prob = 254},
		{param2 = 2,name = "cottages:ladder_with_rope_and_rail",prob = 254},
		T["_____"], T["_____"], T["_____"], T["_____"], T["_____"], T["_____"], T["_____"], T["_____"], T["_____"], {param2 = 5,name = "cottages:ladder_with_rope_and_rail",prob = 254},
		{param2 = 5,name = "cottages:ladder_with_rope_and_rail",prob = 254},
		{param2 = 2,name = "cottages:ladder_with_rope_and_rail",prob = 254},
		T["_____"], T["_____"], T["_____"], T["_____"], T["_____"], T["_____"], T["_____"], T["_____"], T["K0m00"], {param2 = 5,name = "cottages:ladder_with_rope_and_rail",prob = 254},
		{param2 = 5,name = "cottages:ladder_with_rope_and_rail",prob = 254},
		{param2 = 2,name = "cottages:ladder_with_rope_and_rail",prob = 254},
		T["K0m00"], T["_____"], T["_____"], T["_____"], T["_____"], T["_____"], T["_____"], T["_____"], T["_____"], {param2 = 5,name = "cottages:ladder_with_rope_and_rail",prob = 254},
		{param2 = 5,name = "cottages:ladder_with_rope_and_rail",prob = 254},
		{param2 = 2,name = "cottages:ladder_with_rope_and_rail",prob = 254},
		T["_____"], T["_____"], T["_____"], T["_____"], T["_____"], T["_____"], T["_____"], T["_____"], T["_____"], {param2 = 5,name = "cottages:ladder_with_rope_and_rail",prob = 254},
		{param2 = 5,name = "cottages:ladder_with_rope_and_rail",prob = 254},
		{param2 = 2,name = "cottages:ladder_with_rope_and_rail",prob = 254},
		T["_____"], T["_____"], T["_____"], T["_____"], T["_____"], T["_____"], T["_____"], T["_____"], T["_____"], {param2 = 5,name = "cottages:ladder_with_rope_and_rail",prob = 254},
		{param2 = 5,name = "cottages:ladder_with_rope_and_rail",prob = 254},
		{param2 = 2,name = "cottages:ladder_with_rope_and_rail",prob = 254},
		T["_____"], T["_____"], T["_____"], T["_____"], T["_____"], T["_____"], T["_____"], T["_____"], {param2 = 3,name = "lib_ecology:tree_default_wood_fence",prob = 254},
		{param2 = 5,name = "cottages:ladder_with_rope_and_rail",prob = 254},
		{param2 = 5,name = "cottages:ladder_with_rope_and_rail",prob = 254},
		{param2 = 2,name = "cottages:ladder_with_rope_and_rail",prob = 254},
		{param2 = 3,name = "lib_ecology:tree_default_wood_fence",prob = 254},
		T["_____"], T["_____"], T["_____"], T["_____"], T["_____"], T["_____"], T["_____"], {param2 = 1,name = "torch:torch",prob = 254},
		{param2 = 5,name = "cottages:ladder_with_rope_and_rail",prob = 254},
		{param2 = 5,name = "cottages:ladder_with_rope_and_rail",prob = 254},
		{param2 = 2,name = "cottages:ladder_with_rope_and_rail",prob = 254},
		{param2 = 1,name = "torch:torch",prob = 254},
		T["_____"], T["_____"], T["_____"], T["_____"], T["_____"], T["_____"], T["_____"], {param2 = 3,name = "lib_ecology:tree_default_wood_fence",prob = 254},
		{param2 = 5,name = "cottages:ladder_with_rope_and_rail",prob = 254},
		{param2 = 5,name = "cottages:ladder_with_rope_and_rail",prob = 254},
		{param2 = 2,name = "cottages:ladder_with_rope_and_rail",prob = 254},
		{param2 = 3,name = "lib_ecology:tree_default_wood_fence",prob = 254},
		T["_____"], T["_____"], T["_____"], T["_____"], T["_____"], T["_____"], T["_____"], {param2 = 1,name = "torch:torch",prob = 254},
		{param2 = 5,name = "cottages:ladder_with_rope_and_rail",prob = 254},
		{param2 = 5,name = "cottages:ladder_with_rope_and_rail",prob = 254},
		{param2 = 2,name = "cottages:ladder_with_rope_and_rail",prob = 254},
		{param2 = 1,name = "torch:torch",prob = 254},
		T["_____"], T["_____"], T["_____"], T["_____"], T["_____"], T["_____"], T["_____"], {param2 = 3,name = "lib_ecology:tree_default_wood_fence",prob = 254},
		{param2 = 5,name = "cottages:ladder_with_rope_and_rail",prob = 254},
		{param2 = 5,name = "cottages:ladder_with_rope_and_rail",prob = 254},
		{param2 = 2,name = "cottages:ladder_with_rope_and_rail",prob = 254},
		{param2 = 3,name = "lib_ecology:tree_default_wood_fence",prob = 254},
		T["_____"], T["_____"], T["_____"], T["_____"], T["_____"], T["_____"], T["_____"], {param2 = 1,name = "torch:torch",prob = 254},
		{param2 = 5,name = "cottages:ladder_with_rope_and_rail",prob = 254},
		{param2 = 5,name = "cottages:ladder_with_rope_and_rail",prob = 254},
		{param2 = 2,name = "cottages:ladder_with_rope_and_rail",prob = 254},
		{param2 = 1,name = "torch:torch",prob = 254},
		T["_____"], T["_____"], T["_____"], T["_____"], T["_____"], T["_____"], T["_____"], {param2 = 3,name = "lib_ecology:tree_default_wood_fence",prob = 254},
		{param2 = 3,name = "lib_ecology:tree_default_wood_fence",prob = 254},
		{param2 = 3,name = "lib_ecology:tree_default_wood_fence",prob = 254},
		{param2 = 3,name = "lib_ecology:tree_default_wood_fence",prob = 254},
		{param2 = 3,name = "lib_ecology:tree_default_wood_fence",prob = 254},
		T["_____"], T["_____"], T["_____"], T["_____"], T["_____"], T["_____"], T["_____"], {param2 = 1,name = "torch:torch",prob = 254},
		{param2 = 3,name = "lib_ecology:tree_default_wood_fence",prob = 254},
		T["_____"], {param2 = 3,name = "lib_ecology:tree_default_wood_fence",prob = 254},
		{param2 = 1,name = "torch:torch",prob = 254},
		T["_____"], T["_____"], T["_____"], T["_____"], T["_____"], T["_____"], T["_____"], T["_____"], {param2 = 3,name = "lib_ecology:tree_default_wood_fence",prob = 254},
		T["_____"], {param2 = 3,name = "lib_ecology:tree_default_wood_fence",prob = 254},
		T["_____"], T["_____"], T["_____"], T["_____"], T["_____"], T["_____"], T["_____"], T["_____"], T["_____"], {param2 = 3,name = "lib_ecology:tree_default_wood_fence",prob = 254},
		T["_____"], {param2 = 3,name = "lib_ecology:tree_default_wood_fence",prob = 254},
		T["_____"], T["_____"], T["_____"], T["_____"], T["_____"], T["_____"], T["_____"], T["_____"], T["_____"], {param2 = 3,name = "lib_ecology:tree_default_wood_fence",prob = 254},
		{param2 = 3,name = "lib_ecology:tree_default_wood_fence",prob = 254},
		{param2 = 3,name = "lib_ecology:tree_default_wood_fence",prob = 254},
		T["_____"], T["_____"], T["_____"], T["_____"], T["_____"], T["_____"], T["_____"], T["_____"], T["_____"], {param2 = 3,name = "lib_ecology:tree_default_wood_fence",prob = 254},
		{param2 = 1,name = "torch:torch",prob = 254},
		{param2 = 3,name = "lib_ecology:tree_default_wood_fence",prob = 254},
		T["_____"], T["_____"], T["_____"], T["_____"], T["_____"], T["_____"], T["_____"], T["_____"], T["_____"], {param2 = 3,name = "lib_ecology:tree_default_wood_fence",prob = 254},
		T["_____"], {param2 = 3,name = "lib_ecology:tree_default_wood_fence",prob = 254},
		T["_____"], T["_____"], T["_____"], T["_____"], T["_____"], T["_____"], T["_____"], T["_____"], T["_____"], {param2 = 3,name = "lib_ecology:tree_default_wood_fence",prob = 254},
		T["_____"], {param2 = 3,name = "lib_ecology:tree_default_wood_fence",prob = 254},
		T["_____"], T["_____"], T["_____"], T["_____"], T["_____"], T["_____"], T["_____"], T["_____"], T["_____"], {param2 = 3,name = "lib_ecology:tree_default_wood_fence",prob = 254},
		{param2 = 3,name = "lib_ecology:tree_default_wood_fence",prob = 254},
		{param2 = 3,name = "lib_ecology:tree_default_wood_fence",prob = 254},
		T["_____"], T["_____"], T["_____"], T["_____"], T["_____"], T["_____"], T["_____"], T["_____"], T["_____"], {param2 = 3,name = "lib_ecology:tree_default_wood_fence",prob = 254},
		{param2 = 1,name = "torch:torch",prob = 254},
		{param2 = 3,name = "lib_ecology:tree_default_wood_fence",prob = 254},
		T["_____"], T["_____"], T["_____"], T["_____"], T["_____"], T["_____"], T["_____"], T["_____"], T["_____"], {param2 = 3,name = "lib_ecology:tree_default_wood_fence",prob = 254},
		T["_____"], {param2 = 3,name = "lib_ecology:tree_default_wood_fence",prob = 254},
		T["_____"], T["_____"], T["_____"], T["_____"], T["_____"], T["_____"], T["_____"], T["_____"], T["_____"], {param2 = 3,name = "lib_ecology:tree_default_wood_fence",prob = 254},
		T["_____"], {param2 = 3,name = "lib_ecology:tree_default_wood_fence",prob = 254},
		T["_____"], T["_____"], T["_____"], T["_____"], T["_____"], T["_____"], T["_____"], T["_____"], T["_____"], {param2 = 3,name = "lib_ecology:tree_default_wood_fence",prob = 254},
		{param2 = 3,name = "lib_ecology:tree_default_wood_fence",prob = 254},
		{param2 = 3,name = "lib_ecology:tree_default_wood_fence",prob = 254},
		T["_____"], T["_____"], T["_____"], T["_____"], T["_____"], T["_____"], T["_____"], T["_____"], T["_____"], {param2 = 1,name = "torch:torch",prob = 254},
		{param2 = 3,name = "lib_ecology:tree_default_wood_fence",prob = 254},
		{param2 = 1,name = "torch:torch",prob = 254},
		T["_____"], T["_____"], T["_____"], T["_____"], T["_____"], T["_____"], T["_____"], T["_____"], T["_____"], T["_____"], {param2 = 3,name = "lib_ecology:tree_default_wood_fence",prob = 254},
		T["_____"], T["_____"], T["_____"], T["_____"], T["_____"], T["_____"], T["_____"], T["_____"], T["_____"], T["_____"], T["_____"], {param2 = 3,name = "lib_ecology:tree_default_wood_fence",prob = 254},
		T["_____"], T["_____"], T["_____"], T["_____"], T["_____"], T["_____"], T["_____"], T["_____"], T["_____"], T["_____"], T["_____"], {param2 = 1,name = "torch:torch",prob = 254},
		T["_____"], T["_____"], T["_____"], T["_____"], T["_____"], T["_____"], T["_____"], T["_____"], T["_____"], T["_____"], T["_____"], T["_____"], T["_____"], T["_____"], T["_____"], T["_____"], T["_____"], T["_____"], T["_____"], T["_____"], T["_____"], T["_____"], T["_____"], T["_____"], T["_____"], T["_____"], T["_____"], T["_____"], T["_____"], T["_____"], T["_____"], T["_____"], T["_____"], T["_____"], T["_____"], T["_____"], T["_____"], T["_____"], T["_____"], T["_____"], T["_____"], T["_____"], T["_____"], T["_____"], T["_____"], T["_____"], T["_____"], T["_____"], T["_____"], T["_____"], T["_____"], T["_____"], T["_____"], T["ddddd"], T["ddddd"], T["ddddd"], T["ddddd"], T["ddddd"], {param2 = 3,name = "cottages:ladder_with_rope_and_rail",prob = 254},
		{param2 = 0,name = "cottages:rope",prob = 254},
		{param2 = 2,name = "cottages:ladder_with_rope_and_rail",prob = 254},
		T["ddddd"], T["ddddd"], T["ddddd"], T["ddddd"], T["ddddd"], T["ddddd"], T["ddddd"], T["ddddd"], T["ddddd"], {param2 = 3,name = "cottages:ladder_with_rope_and_rail",prob = 254},
		{param2 = 0,name = "cottages:rope",prob = 254},
		{param2 = 2,name = "cottages:ladder_with_rope_and_rail",prob = 254},
		T["ddddd"], T["ddddd"], T["ddddd"], T["ddddd"], T["ddddd"], T["ddddd"], T["ddddd"], T["ddddd"], T["ddddd"], {param2 = 3,name = "cottages:ladder_with_rope_and_rail",prob = 254},
		{param2 = 0,name = "cottages:rope",prob = 254},
		{param2 = 2,name = "cottages:ladder_with_rope_and_rail",prob = 254},
		T["ddddd"], T["ddddd"], T["ddddd"], T["ddddd"], T["ddddd"], T["ddddd"], T["ddddd"], T["ddddd"], T["ddddd"], {param2 = 3,name = "cottages:ladder_with_rope_and_rail",prob = 254},
		{param2 = 0,name = "cottages:rope",prob = 254},
		{param2 = 2,name = "cottages:ladder_with_rope_and_rail",prob = 254},
		T["ddddd"], T["ddddd"], T["ddddd"], T["ddddd"], T["ddddd"], T["ddddd"], T["ddddd"], T["ddddd"], T["ddddd"], {param2 = 3,name = "cottages:ladder_with_rope_and_rail",prob = 254},
		{param2 = 0,name = "cottages:rope",prob = 254},
		{param2 = 2,name = "cottages:ladder_with_rope_and_rail",prob = 254},
		T["ddddd"], T["ddddd"], T["ddddd"], T["ddddd"], T["ddddd"], T["S0m00"], T["S0m00"], T["S0m00"], T["K0m00"], {param2 = 3,name = "cottages:ladder_with_rope_and_rail",prob = 254},
		{param2 = 0,name = "cottages:rope",prob = 254},
		{param2 = 2,name = "cottages:ladder_with_rope_and_rail",prob = 254},
		T["S0m00"], T["S0m00"], T["S0m00"], T["S0m00"], {param2 = 0,name = "carts:rail",prob = 254},
		{param2 = 0,name = "carts:rail",prob = 254},
		{param2 = 0,name = "carts:rail",prob = 254},
		{param2 = 0,name = "carts:rail",prob = 254},
		{param2 = 0,name = "carts:rail",prob = 254},
		{param2 = 3,name = "cottages:ladder_with_rope_and_rail",prob = 254},
		{param2 = 0,name = "cottages:rope",prob = 254},
		{param2 = 2,name = "cottages:ladder_with_rope_and_rail",prob = 254},
		{param2 = 0,name = "carts:rail",prob = 254},
		{param2 = 0,name = "carts:rail",prob = 254},
		{param2 = 0,name = "carts:rail",prob = 254},
		{param2 = 0,name = "carts:rail",prob = 254},
		T["_____"], T["_____"], T["_____"], T["_____"], T["_____"], {param2 = 3,name = "cottages:ladder_with_rope_and_rail",prob = 254},
		{param2 = 0,name = "cottages:rope",prob = 254},
		{param2 = 2,name = "cottages:ladder_with_rope_and_rail",prob = 254},
		T["_____"], T["_____"], T["_____"], T["_____"], T["_____"], T["_____"], T["_____"], T["_____"], T["_____"], {param2 = 3,name = "cottages:ladder_with_rope_and_rail",prob = 254},
		{param2 = 0,name = "cottages:rope",prob = 254},
		{param2 = 2,name = "cottages:ladder_with_rope_and_rail",prob = 254},
		T["_____"], T["_____"], T["_____"], T["_____"], T["_____"], T["_____"], T["_____"], T["_____"], T["K0m00"], {param2 = 3,name = "cottages:ladder_with_rope_and_rail",prob = 254},
		{param2 = 0,name = "cottages:rope",prob = 254},
		{param2 = 2,name = "cottages:ladder_with_rope_and_rail",prob = 254},
		T["K0m00"], T["_____"], T["_____"], T["_____"], T["_____"], T["_____"], T["_____"], T["_____"], T["_____"], {param2 = 3,name = "cottages:ladder_with_rope_and_rail",prob = 254},
		{param2 = 0,name = "cottages:rope",prob = 254},
		{param2 = 2,name = "cottages:ladder_with_rope_and_rail",prob = 254},
		T["_____"], T["_____"], T["_____"], T["_____"], T["_____"], T["_____"], T["_____"], T["_____"], T["_____"], {param2 = 3,name = "cottages:ladder_with_rope_and_rail",prob = 254},
		{param2 = 0,name = "cottages:rope",prob = 254},
		{param2 = 2,name = "cottages:ladder_with_rope_and_rail",prob = 254},
		T["_____"], T["_____"], T["_____"], T["_____"], T["_____"], T["_____"], T["_____"], T["_____"], T["_____"], {param2 = 3,name = "cottages:ladder_with_rope_and_rail",prob = 254},
		{param2 = 0,name = "cottages:rope",prob = 254},
		{param2 = 2,name = "cottages:ladder_with_rope_and_rail",prob = 254},
		T["_____"], T["_____"], T["_____"], T["_____"], T["_____"], T["_____"], T["_____"], T["_____"], T["K0m00"], {param2 = 3,name = "cottages:ladder_with_rope_and_rail",prob = 254},
		{param2 = 0,name = "cottages:rope",prob = 254},
		{param2 = 2,name = "cottages:ladder_with_rope_and_rail",prob = 254},
		T["K0m00"], T["_____"], T["_____"], T["_____"], T["_____"], T["_____"], T["_____"], T["_____"], T["_____"], {param2 = 3,name = "cottages:ladder_with_rope_and_rail",prob = 254},
		{param2 = 0,name = "cottages:rope",prob = 254},
		{param2 = 2,name = "cottages:ladder_with_rope_and_rail",prob = 254},
		T["_____"], T["_____"], T["_____"], T["_____"], T["_____"], T["_____"], T["_____"], T["_____"], T["_____"], {param2 = 3,name = "cottages:ladder_with_rope_and_rail",prob = 254},
		{param2 = 0,name = "cottages:rope",prob = 254},
		{param2 = 2,name = "cottages:ladder_with_rope_and_rail",prob = 254},
		T["_____"], T["_____"], T["_____"], T["_____"], T["_____"], T["_____"], T["_____"], T["_____"], T["_____"], {param2 = 3,name = "cottages:ladder_with_rope_and_rail",prob = 254},
		{param2 = 0,name = "cottages:rope",prob = 254},
		{param2 = 2,name = "cottages:ladder_with_rope_and_rail",prob = 254},
		T["_____"], T["_____"], T["_____"], T["_____"], T["_____"], T["_____"], T["_____"], T["_____"], {param2 = 3,name = "lib_ecology:tree_default_wood_fence",prob = 254},
		{param2 = 3,name = "cottages:ladder_with_rope_and_rail",prob = 254},
		{param2 = 0,name = "cottages:rope",prob = 254},
		{param2 = 2,name = "cottages:ladder_with_rope_and_rail",prob = 254},
		{param2 = 3,name = "lib_ecology:tree_default_wood_fence",prob = 254},
		T["_____"], T["_____"], T["_____"], T["_____"], T["_____"], T["_____"], T["_____"], T["_____"], {param2 = 3,name = "cottages:ladder_with_rope_and_rail",prob = 254},
		{param2 = 0,name = "cottages:rope",prob = 254},
		{param2 = 2,name = "cottages:ladder_with_rope_and_rail",prob = 254},
		T["_____"], T["_____"], T["_____"], T["_____"], T["_____"], T["_____"], T["_____"], T["_____"], {param2 = 3,name = "lib_ecology:tree_default_wood_fence",prob = 254},
		{param2 = 3,name = "cottages:ladder_with_rope_and_rail",prob = 254},
		{param2 = 0,name = "cottages:rope",prob = 254},
		{param2 = 2,name = "cottages:ladder_with_rope_and_rail",prob = 254},
		{param2 = 3,name = "lib_ecology:tree_default_wood_fence",prob = 254},
		T["_____"], T["_____"], T["_____"], T["_____"], T["_____"], T["_____"], T["_____"], T["_____"], {param2 = 3,name = "cottages:ladder_with_rope_and_rail",prob = 254},
		{param2 = 0,name = "cottages:rope",prob = 254},
		{param2 = 2,name = "cottages:ladder_with_rope_and_rail",prob = 254},
		T["_____"], T["_____"], T["_____"], T["_____"], T["_____"], T["_____"], T["_____"], T["_____"], {param2 = 3,name = "lib_ecology:tree_default_wood_fence",prob = 254},
		{param2 = 3,name = "cottages:ladder_with_rope_and_rail",prob = 254},
		{param2 = 0,name = "cottages:rope",prob = 254},
		{param2 = 2,name = "cottages:ladder_with_rope_and_rail",prob = 254},
		{param2 = 3,name = "lib_ecology:tree_default_wood_fence",prob = 254},
		T["_____"], T["_____"], T["_____"], T["_____"], T["_____"], T["_____"], T["_____"], T["_____"], {param2 = 3,name = "cottages:ladder_with_rope_and_rail",prob = 254},
		{param2 = 0,name = "cottages:rope",prob = 254},
		{param2 = 2,name = "cottages:ladder_with_rope_and_rail",prob = 254},
		T["_____"], T["_____"], T["_____"], T["_____"], T["_____"], T["_____"], T["_____"], T["_____"], {param2 = 3,name = "lib_ecology:tree_default_wood_fence",prob = 254},
		{param2 = 3,name = "lib_ecology:tree_default_wood_fence",prob = 254},
		{param2 = 0,name = "cottages:rope",prob = 254},
		{param2 = 3,name = "lib_ecology:tree_default_wood_fence",prob = 254},
		{param2 = 3,name = "lib_ecology:tree_default_wood_fence",prob = 254},
		T["_____"], T["_____"], T["_____"], T["_____"], T["_____"], T["_____"], T["_____"], {param2 = 1,name = "torch:torch",prob = 254},
		T["_____"], {param2 = 0,name = "cottages:rope",prob = 254},
		T["_____"], {param2 = 1,name = "torch:torch",prob = 254},
		T["_____"], T["_____"], T["_____"], T["_____"], T["_____"], T["_____"], T["_____"], T["_____"], T["_____"], {param2 = 0,name = "cottages:rope",prob = 254},
		T["_____"], T["_____"], T["_____"], T["_____"], T["_____"], T["_____"], T["_____"], T["_____"], T["_____"], T["_____"], T["_____"], {param2 = 0,name = "cottages:rope",prob = 254},
		T["_____"], T["_____"], T["_____"], T["_____"], T["_____"], T["_____"], T["_____"], T["_____"], T["_____"], T["_____"], {param2 = 3,name = "lib_ecology:tree_default_wood_fence",prob = 254},
		{param2 = 0,name = "cottages:rope",prob = 254},
		{param2 = 3,name = "lib_ecology:tree_default_wood_fence",prob = 254},
		T["_____"], T["_____"], T["_____"], T["_____"], T["_____"], T["_____"], T["_____"], T["_____"], T["_____"], {param2 = 1,name = "torch:torch",prob = 254},
		{param2 = 0,name = "cottages:rope",prob = 254},
		{param2 = 1,name = "torch:torch",prob = 254},
		T["_____"], T["_____"], T["_____"], T["_____"], T["_____"], T["_____"], T["_____"], T["_____"], T["_____"], T["_____"], {param2 = 0,name = "cottages:rope",prob = 254},
		T["_____"], T["_____"], T["_____"], T["_____"], T["_____"], T["_____"], T["_____"], T["_____"], T["_____"], T["_____"], T["_____"], {param2 = 0,name = "cottages:rope",prob = 254},
		T["_____"], T["_____"], T["_____"], T["_____"], T["_____"], T["_____"], T["_____"], T["_____"], T["_____"], T["_____"], {param2 = 3,name = "lib_ecology:tree_default_wood_fence",prob = 254},
		{param2 = 0,name = "cottages:rope",prob = 254},
		{param2 = 3,name = "lib_ecology:tree_default_wood_fence",prob = 254},
		T["_____"], T["_____"], T["_____"], T["_____"], T["_____"], T["_____"], T["_____"], T["_____"], T["_____"], {param2 = 1,name = "torch:torch",prob = 254},
		{param2 = 0,name = "cottages:rope",prob = 254},
		{param2 = 1,name = "torch:torch",prob = 254},
		T["_____"], T["_____"], T["_____"], T["_____"], T["_____"], T["_____"], T["_____"], T["_____"], T["_____"], T["_____"], {param2 = 0,name = "cottages:rope",prob = 254},
		T["_____"], T["_____"], T["_____"], T["_____"], T["_____"], T["_____"], T["_____"], T["_____"], T["_____"], T["_____"], T["_____"], {param2 = 0,name = "cottages:rope",prob = 254},
		T["_____"], T["_____"], T["_____"], T["_____"], T["_____"], T["_____"], T["_____"], T["_____"], T["_____"], T["_____"], {param2 = 3,name = "lib_ecology:tree_default_wood_fence",prob = 254},
		{param2 = 0,name = "cottages:rope",prob = 254},
		{param2 = 3,name = "lib_ecology:tree_default_wood_fence",prob = 254},
		T["_____"], T["_____"], T["_____"], T["_____"], T["_____"], T["_____"], T["_____"], T["_____"], T["_____"], {param2 = 3,name = "lib_ecology:tree_default_wood_fence",prob = 254},
		{param2 = 0,name = "cottages:rope",prob = 254},
		{param2 = 3,name = "lib_ecology:tree_default_wood_fence",prob = 254},
		T["_____"], T["_____"], T["_____"], T["_____"], T["_____"], T["_____"], T["_____"], T["_____"], T["_____"], {param2 = 3,name = "lib_ecology:tree_default_wood_fence",prob = 254},
		{param2 = 0,name = "cottages:rope",prob = 254},
		{param2 = 3,name = "lib_ecology:tree_default_wood_fence",prob = 254},
		T["_____"], T["_____"], T["_____"], T["_____"], T["_____"], T["_____"], T["_____"], T["_____"], T["_____"], {param2 = 3,name = "lib_ecology:tree_default_wood_fence",prob = 254},
		{param2 = 3,name = "lib_ecology:tree_default_wood_fence",prob = 254},
		{param2 = 3,name = "lib_ecology:tree_default_wood_fence",prob = 254},
		T["_____"], T["_____"], T["_____"], T["_____"], T["_____"], T["_____"], T["_____"], T["_____"], T["_____"], {param2 = 1,name = "torch:torch",prob = 254},
		{param2 = 3,name = "lib_ecology:tree_default_wood_fence",prob = 254},
		{param2 = 1,name = "torch:torch",prob = 254},
		T["_____"], T["_____"], T["_____"], T["_____"], T["_____"], T["_____"], T["_____"], T["_____"], T["_____"], T["_____"], {param2 = 3,name = "lib_ecology:tree_default_wood_fence",prob = 254},
		T["_____"], T["_____"], T["_____"], T["_____"], T["_____"], T["_____"], T["_____"], T["_____"], T["_____"], T["_____"], T["_____"], {param2 = 3,name = "lib_ecology:tree_default_wood_fence",prob = 254},
		T["_____"], T["_____"], T["_____"], T["_____"], T["_____"], T["_____"], T["_____"], T["_____"], T["_____"], T["_____"], T["_____"], {param2 = 1,name = "torch:torch",prob = 254},
		T["_____"], T["_____"], T["_____"], T["_____"], T["_____"], T["_____"], T["_____"], T["_____"], T["_____"], T["_____"], T["_____"], T["_____"], T["_____"], T["_____"], T["_____"], T["_____"], T["_____"], T["ddddd"], T["ddddd"], T["ddddd"], T["ddddd"], T["ddddd"], {param2 = 3,name = "cottages:ladder_with_rope_and_rail",prob = 254},
		{param2 = 4,name = "cottages:ladder_with_rope_and_rail",prob = 254},
		{param2 = 4,name = "cottages:ladder_with_rope_and_rail",prob = 254},
		T["ddddd"], T["ddddd"], T["ddddd"], T["ddddd"], T["ddddd"], T["ddddd"], T["ddddd"], T["ddddd"], T["ddddd"], {param2 = 3,name = "cottages:ladder_with_rope_and_rail",prob = 254},
		{param2 = 4,name = "cottages:ladder_with_rope_and_rail",prob = 254},
		{param2 = 4,name = "cottages:ladder_with_rope_and_rail",prob = 254},
		T["ddddd"], T["ddddd"], T["ddddd"], T["ddddd"], T["ddddd"], T["ddddd"], T["ddddd"], T["ddddd"], T["ddddd"], {param2 = 3,name = "cottages:ladder_with_rope_and_rail",prob = 254},
		{param2 = 4,name = "cottages:ladder_with_rope_and_rail",prob = 254},
		{param2 = 4,name = "cottages:ladder_with_rope_and_rail",prob = 254},
		T["ddddd"], T["ddddd"], T["ddddd"], T["ddddd"], T["ddddd"], T["ddddd"], T["ddddd"], T["ddddd"], T["ddddd"], {param2 = 3,name = "cottages:ladder_with_rope_and_rail",prob = 254},
		{param2 = 4,name = "cottages:ladder_with_rope_and_rail",prob = 254},
		{param2 = 4,name = "cottages:ladder_with_rope_and_rail",prob = 254},
		T["ddddd"], T["ddddd"], T["ddddd"], T["ddddd"], T["ddddd"], T["ddddd"], T["ddddd"], T["ddddd"], T["ddddd"], {param2 = 3,name = "cottages:ladder_with_rope_and_rail",prob = 254},
		{param2 = 4,name = "cottages:ladder_with_rope_and_rail",prob = 254},
		{param2 = 4,name = "cottages:ladder_with_rope_and_rail",prob = 254},
		T["ddddd"], T["ddddd"], T["ddddd"], T["ddddd"], T["ddddd"], T["S0m00"], T["S0m00"], T["S0m00"], T["K0m00"], {param2 = 3,name = "cottages:ladder_with_rope_and_rail",prob = 254},
		{param2 = 4,name = "cottages:ladder_with_rope_and_rail",prob = 254},
		{param2 = 4,name = "cottages:ladder_with_rope_and_rail",prob = 254},
		T["K0m00"], T["S0m00"], T["S0m00"], T["S0m00"], T["_____"], T["_____"], T["_____"], {param2 = 0,name = "carts:rail",prob = 254},
		T["_____"], {param2 = 3,name = "cottages:ladder_with_rope_and_rail",prob = 254},
		{param2 = 4,name = "cottages:ladder_with_rope_and_rail",prob = 254},
		{param2 = 4,name = "cottages:ladder_with_rope_and_rail",prob = 254},
		T["_____"], {param2 = 0,name = "carts:rail",prob = 254},
		T["_____"], T["_____"], T["_____"], T["_____"], T["_____"], T["_____"], T["_____"], {param2 = 3,name = "cottages:ladder_with_rope_and_rail",prob = 254},
		{param2 = 4,name = "cottages:ladder_with_rope_and_rail",prob = 254},
		{param2 = 4,name = "cottages:ladder_with_rope_and_rail",prob = 254},
		T["_____"], T["_____"], T["_____"], T["_____"], T["_____"], T["_____"], T["_____"], T["_____"], T["K0m00"], {param2 = 3,name = "cottages:ladder_with_rope_and_rail",prob = 254},
		{param2 = 4,name = "cottages:ladder_with_rope_and_rail",prob = 254},
		{param2 = 4,name = "cottages:ladder_with_rope_and_rail",prob = 254},
		T["K0m00"], T["_____"], T["_____"], T["_____"], T["_____"], T["_____"], T["_____"], T["_____"], T["K0m00"], {param2 = 3,name = "cottages:ladder_with_rope_and_rail",prob = 254},
		{param2 = 4,name = "cottages:ladder_with_rope_and_rail",prob = 254},
		{param2 = 4,name = "cottages:ladder_with_rope_and_rail",prob = 254},
		T["K0m00"], T["_____"], T["_____"], T["_____"], T["_____"], T["_____"], T["_____"], T["_____"], T["_____"], {param2 = 3,name = "cottages:ladder_with_rope_and_rail",prob = 254},
		{param2 = 4,name = "cottages:ladder_with_rope_and_rail",prob = 254},
		{param2 = 4,name = "cottages:ladder_with_rope_and_rail",prob = 254},
		T["_____"], T["_____"], T["_____"], T["_____"], T["_____"], T["_____"], T["_____"], T["_____"], T["_____"], {param2 = 3,name = "cottages:ladder_with_rope_and_rail",prob = 254},
		{param2 = 4,name = "cottages:ladder_with_rope_and_rail",prob = 254},
		{param2 = 4,name = "cottages:ladder_with_rope_and_rail",prob = 254},
		T["_____"], T["_____"], T["_____"], T["_____"], T["_____"], T["_____"], T["_____"], T["_____"], T["_____"], {param2 = 3,name = "cottages:ladder_with_rope_and_rail",prob = 254},
		{param2 = 4,name = "cottages:ladder_with_rope_and_rail",prob = 254},
		{param2 = 4,name = "cottages:ladder_with_rope_and_rail",prob = 254},
		T["_____"], T["_____"], T["_____"], T["_____"], T["_____"], T["_____"], T["_____"], T["_____"], T["K0m00"], {param2 = 3,name = "cottages:ladder_with_rope_and_rail",prob = 254},
		{param2 = 4,name = "cottages:ladder_with_rope_and_rail",prob = 254},
		{param2 = 4,name = "cottages:ladder_with_rope_and_rail",prob = 254},
		T["K0m00"], T["_____"], T["_____"], T["_____"], T["_____"], T["_____"], T["_____"], T["_____"], T["_____"], {param2 = 3,name = "cottages:ladder_with_rope_and_rail",prob = 254},
		{param2 = 4,name = "cottages:ladder_with_rope_and_rail",prob = 254},
		{param2 = 4,name = "cottages:ladder_with_rope_and_rail",prob = 254},
		T["_____"], T["_____"], T["_____"], T["_____"], T["_____"], T["_____"], T["_____"], T["_____"], T["_____"], {param2 = 3,name = "cottages:ladder_with_rope_and_rail",prob = 254},
		{param2 = 4,name = "cottages:ladder_with_rope_and_rail",prob = 254},
		{param2 = 4,name = "cottages:ladder_with_rope_and_rail",prob = 254},
		T["_____"], T["_____"], T["_____"], T["_____"], T["_____"], T["_____"], T["_____"], T["_____"], T["_____"], {param2 = 3,name = "cottages:ladder_with_rope_and_rail",prob = 254},
		{param2 = 4,name = "cottages:ladder_with_rope_and_rail",prob = 254},
		{param2 = 4,name = "cottages:ladder_with_rope_and_rail",prob = 254},
		T["_____"], T["_____"], T["_____"], T["_____"], T["_____"], T["_____"], T["_____"], T["_____"], {param2 = 3,name = "lib_ecology:tree_default_wood_fence",prob = 254},
		{param2 = 3,name = "cottages:ladder_with_rope_and_rail",prob = 254},
		{param2 = 4,name = "cottages:ladder_with_rope_and_rail",prob = 254},
		{param2 = 4,name = "cottages:ladder_with_rope_and_rail",prob = 254},
		{param2 = 3,name = "lib_ecology:tree_default_wood_fence",prob = 254},
		T["_____"], T["_____"], T["_____"], T["_____"], T["_____"], T["_____"], T["_____"], {param2 = 1,name = "torch:torch",prob = 254},
		{param2 = 3,name = "cottages:ladder_with_rope_and_rail",prob = 254},
		{param2 = 4,name = "cottages:ladder_with_rope_and_rail",prob = 254},
		{param2 = 4,name = "cottages:ladder_with_rope_and_rail",prob = 254},
		{param2 = 1,name = "torch:torch",prob = 254},
		T["_____"], T["_____"], T["_____"], T["_____"], T["_____"], T["_____"], T["_____"], {param2 = 3,name = "lib_ecology:tree_default_wood_fence",prob = 254},
		{param2 = 3,name = "cottages:ladder_with_rope_and_rail",prob = 254},
		{param2 = 4,name = "cottages:ladder_with_rope_and_rail",prob = 254},
		{param2 = 4,name = "cottages:ladder_with_rope_and_rail",prob = 254},
		{param2 = 3,name = "lib_ecology:tree_default_wood_fence",prob = 254},
		T["_____"], T["_____"], T["_____"], T["_____"], T["_____"], T["_____"], T["_____"], {param2 = 1,name = "torch:torch",prob = 254},
		{param2 = 3,name = "cottages:ladder_with_rope_and_rail",prob = 254},
		{param2 = 4,name = "cottages:ladder_with_rope_and_rail",prob = 254},
		{param2 = 4,name = "cottages:ladder_with_rope_and_rail",prob = 254},
		{param2 = 1,name = "torch:torch",prob = 254},
		T["_____"], T["_____"], T["_____"], T["_____"], T["_____"], T["_____"], T["_____"], {param2 = 3,name = "lib_ecology:tree_default_wood_fence",prob = 254},
		{param2 = 3,name = "cottages:ladder_with_rope_and_rail",prob = 254},
		{param2 = 4,name = "cottages:ladder_with_rope_and_rail",prob = 254},
		{param2 = 4,name = "cottages:ladder_with_rope_and_rail",prob = 254},
		{param2 = 3,name = "lib_ecology:tree_default_wood_fence",prob = 254},
		T["_____"], T["_____"], T["_____"], T["_____"], T["_____"], T["_____"], T["_____"], {param2 = 1,name = "torch:torch",prob = 254},
		{param2 = 3,name = "cottages:ladder_with_rope_and_rail",prob = 254},
		{param2 = 4,name = "cottages:ladder_with_rope_and_rail",prob = 254},
		{param2 = 4,name = "cottages:ladder_with_rope_and_rail",prob = 254},
		{param2 = 1,name = "torch:torch",prob = 254},
		T["_____"], T["_____"], T["_____"], T["_____"], T["_____"], T["_____"], T["_____"], {param2 = 3,name = "lib_ecology:tree_default_wood_fence",prob = 254},
		{param2 = 3,name = "lib_ecology:tree_default_wood_fence",prob = 254},
		{param2 = 3,name = "lib_ecology:tree_default_wood_fence",prob = 254},
		{param2 = 3,name = "lib_ecology:tree_default_wood_fence",prob = 254},
		{param2 = 3,name = "lib_ecology:tree_default_wood_fence",prob = 254},
		T["_____"], T["_____"], T["_____"], T["_____"], T["_____"], T["_____"], T["_____"], {param2 = 1,name = "torch:torch",prob = 254},
		{param2 = 3,name = "lib_ecology:tree_default_wood_fence",prob = 254},
		T["_____"], {param2 = 3,name = "lib_ecology:tree_default_wood_fence",prob = 254},
		{param2 = 1,name = "torch:torch",prob = 254},
		T["_____"], T["_____"], T["_____"], T["_____"], T["_____"], T["_____"], T["_____"], T["_____"], {param2 = 3,name = "lib_ecology:tree_default_wood_fence",prob = 254},
		T["_____"], {param2 = 3,name = "lib_ecology:tree_default_wood_fence",prob = 254},
		T["_____"], T["_____"], T["_____"], T["_____"], T["_____"], T["_____"], T["_____"], T["_____"], T["_____"], {param2 = 3,name = "lib_ecology:tree_default_wood_fence",prob = 254},
		T["_____"], {param2 = 3,name = "lib_ecology:tree_default_wood_fence",prob = 254},
		T["_____"], T["_____"], T["_____"], T["_____"], T["_____"], T["_____"], T["_____"], T["_____"], T["_____"], {param2 = 3,name = "lib_ecology:tree_default_wood_fence",prob = 254},
		{param2 = 3,name = "lib_ecology:tree_default_wood_fence",prob = 254},
		{param2 = 3,name = "lib_ecology:tree_default_wood_fence",prob = 254},
		T["_____"], T["_____"], T["_____"], T["_____"], T["_____"], T["_____"], T["_____"], T["_____"], T["_____"], {param2 = 3,name = "lib_ecology:tree_default_wood_fence",prob = 254},
		{param2 = 1,name = "torch:torch",prob = 254},
		{param2 = 3,name = "lib_ecology:tree_default_wood_fence",prob = 254},
		T["_____"], T["_____"], T["_____"], T["_____"], T["_____"], T["_____"], T["_____"], T["_____"], T["_____"], {param2 = 3,name = "lib_ecology:tree_default_wood_fence",prob = 254},
		T["_____"], {param2 = 3,name = "lib_ecology:tree_default_wood_fence",prob = 254},
		T["_____"], T["_____"], T["_____"], T["_____"], T["_____"], T["_____"], T["_____"], T["_____"], T["_____"], {param2 = 3,name = "lib_ecology:tree_default_wood_fence",prob = 254},
		T["_____"], {param2 = 3,name = "lib_ecology:tree_default_wood_fence",prob = 254},
		T["_____"], T["_____"], T["_____"], T["_____"], T["_____"], T["_____"], T["_____"], T["_____"], T["_____"], {param2 = 3,name = "lib_ecology:tree_default_wood_fence",prob = 254},
		{param2 = 3,name = "lib_ecology:tree_default_wood_fence",prob = 254},
		{param2 = 3,name = "lib_ecology:tree_default_wood_fence",prob = 254},
		T["_____"], T["_____"], T["_____"], T["_____"], T["_____"], T["_____"], T["_____"], T["_____"], T["_____"], {param2 = 3,name = "lib_ecology:tree_default_wood_fence",prob = 254},
		{param2 = 1,name = "torch:torch",prob = 254},
		{param2 = 3,name = "lib_ecology:tree_default_wood_fence",prob = 254},
		T["_____"], T["_____"], T["_____"], T["_____"], T["_____"], T["_____"], T["_____"], T["_____"], T["_____"], {param2 = 3,name = "lib_ecology:tree_default_wood_fence",prob = 254},
		T["_____"], {param2 = 3,name = "lib_ecology:tree_default_wood_fence",prob = 254},
		T["_____"], T["_____"], T["_____"], T["_____"], T["_____"], T["_____"], T["_____"], T["_____"], T["_____"], {param2 = 3,name = "lib_ecology:tree_default_wood_fence",prob = 254},
		T["_____"], {param2 = 3,name = "lib_ecology:tree_default_wood_fence",prob = 254},
		T["_____"], T["_____"], T["_____"], T["_____"], T["_____"], T["_____"], T["_____"], T["_____"], T["_____"], {param2 = 3,name = "lib_ecology:tree_default_wood_fence",prob = 254},
		{param2 = 3,name = "lib_ecology:tree_default_wood_fence",prob = 254},
		{param2 = 3,name = "lib_ecology:tree_default_wood_fence",prob = 254},
		T["_____"], T["_____"], T["_____"], T["_____"], T["_____"], T["_____"], T["_____"], T["_____"], T["_____"], {param2 = 1,name = "torch:torch",prob = 254},
		{param2 = 3,name = "lib_ecology:tree_default_wood_fence",prob = 254},
		{param2 = 1,name = "torch:torch",prob = 254},
		T["_____"], T["_____"], T["_____"], T["_____"], T["_____"], T["_____"], T["_____"], T["_____"], T["_____"], T["_____"], {param2 = 3,name = "lib_ecology:tree_default_wood_fence",prob = 254},
		T["_____"], T["_____"], T["_____"], T["_____"], T["_____"], T["_____"], T["_____"], T["_____"], T["_____"], T["_____"], T["_____"], {param2 = 3,name = "lib_ecology:tree_default_wood_fence",prob = 254},
		T["_____"], T["_____"], T["_____"], T["_____"], T["_____"], T["_____"], T["_____"], T["_____"], T["_____"], T["_____"], T["_____"], {param2 = 1,name = "torch:torch",prob = 254},
		T["_____"], T["_____"], T["_____"], T["_____"], T["_____"], T["_____"], T["_____"], T["_____"], T["_____"], T["_____"], T["_____"], T["_____"], T["_____"], T["_____"], T["_____"], T["_____"], T["_____"], T["_____"], T["_____"], T["_____"], T["_____"], T["_____"], T["_____"], T["_____"], T["_____"], T["_____"], T["_____"], T["_____"], T["_____"], T["_____"], T["_____"], T["_____"], T["_____"], T["_____"], T["_____"], T["_____"], T["_____"], T["_____"], T["_____"], T["_____"], T["_____"], T["_____"], T["_____"], T["_____"], T["_____"], T["_____"], T["_____"], T["_____"], T["_____"], T["_____"], T["_____"], T["_____"], T["_____"], T["ddddd"], T["ddddd"], T["ddddd"], T["ddddd"], T["ddddd"], T["ddddd"], T["ddddd"], T["ddddd"], T["ddddd"], T["ddddd"], T["ddddd"], T["ddddd"], T["ddddd"], T["ddddd"], T["ddddd"], T["ddddd"], T["ddddd"], T["ddddd"], T["ddddd"], T["ddddd"], T["ddddd"], T["ddddd"], T["ddddd"], T["ddddd"], T["ddddd"], T["ddddd"], T["ddddd"], T["ddddd"], T["ddddd"], T["ddddd"], T["ddddd"], T["ddddd"], T["ddddd"], T["ddddd"], T["ddddd"], T["ddddd"], T["ddddd"], T["ddddd"], T["ddddd"], T["ddddd"], T["ddddd"], T["ddddd"], T["ddddd"], T["ddddd"], T["ddddd"], T["ddddd"], T["ddddd"], T["ddddd"], T["ddddd"], T["ddddd"], T["ddddd"], T["ddddd"], T["ddddd"], T["ddddd"], T["ddddd"], T["ddddd"], T["ddddd"], T["ddddd"], T["ddddd"], T["ddddd"], T["ddddd"], T["S0m00"], T["S0m00"], T["S0m00"], T["K0m00"], T["K0m00"], T["K0m00"], T["K0m00"], T["K0m00"], T["S0m00"], T["S0m00"], T["S0m00"], T["_____"], T["_____"], T["_____"], {param2 = 0,name = "carts:rail",prob = 254},
		T["K0m00"], T["_____"], {param2 = 0,name = "carts:rail",prob = 254},
		T["_____"], T["K0m00"], {param2 = 0,name = "carts:rail",prob = 254},
		T["_____"], T["_____"], T["_____"], T["_____"], T["_____"], T["_____"], T["K0m00"], T["_____"], T["_____"], T["_____"], T["K0m00"], T["_____"], T["_____"], T["_____"], T["_____"], T["_____"], T["_____"], T["_____"], T["K0m00"], T["K0m00"], T["_____"], T["K0m00"], T["K0m00"], T["_____"], T["_____"], T["_____"], T["_____"], T["_____"], T["_____"], T["_____"], T["K0m00"], T["K0m00"], T["K0m00"], T["K0m00"], T["K0m00"], T["_____"], T["_____"], T["_____"], T["_____"], T["_____"], T["_____"], T["_____"], T["K0m00"], T["_____"], T["_____"], T["_____"], T["K0m00"], T["_____"], T["_____"], T["_____"], T["_____"], T["_____"], T["_____"], T["_____"], T["K0m00"], T["_____"], T["_____"], T["_____"], T["K0m00"], T["_____"], T["_____"], T["_____"], T["_____"], T["_____"], T["_____"], T["_____"], T["K0m00"], T["_____"], T["_____"], T["_____"], T["K0m00"], T["_____"], T["_____"], T["_____"], T["_____"], T["_____"], T["_____"], T["_____"], T["K0m00"], T["K0m00"], T["K0m00"], T["K0m00"], T["K0m00"], T["_____"], T["_____"], T["_____"], T["_____"], T["_____"], T["_____"], T["_____"], T["K0m00"], T["_____"], T["_____"], T["_____"], T["K0m00"], T["_____"], T["_____"], T["_____"], T["_____"], T["_____"], T["_____"], T["_____"], {param2 = 3,name = "lib_ecology:tree_default_wood_fence",prob = 254},
		T["_____"], T["_____"], T["_____"], {param2 = 3,name = "lib_ecology:tree_default_wood_fence",prob = 254},
		T["_____"], T["_____"], T["_____"], T["_____"], T["_____"], T["_____"], T["_____"], {param2 = 3,name = "lib_ecology:tree_default_wood_fence",prob = 254},
		T["_____"], T["_____"], T["_____"], {param2 = 3,name = "lib_ecology:tree_default_wood_fence",prob = 254},
		T["_____"], T["_____"], T["_____"], T["_____"], T["_____"], T["_____"], T["_____"], {param2 = 3,name = "lib_ecology:tree_default_wood_fence",prob = 254},
		{param2 = 3,name = "lib_ecology:tree_default_wood_fence",prob = 254},
		{param2 = 3,name = "lib_ecology:tree_default_wood_fence",prob = 254},
		{param2 = 3,name = "lib_ecology:tree_default_wood_fence",prob = 254},
		{param2 = 3,name = "lib_ecology:tree_default_wood_fence",prob = 254},
		T["_____"], T["_____"], T["_____"], T["_____"], T["_____"], T["_____"], T["_____"], {param2 = 3,name = "lib_ecology:tree_default_wood_fence",prob = 254},
		{param2 = 1,name = "torch:torch",prob = 254},
		T["_____"], {param2 = 1,name = "torch:torch",prob = 254},
		{param2 = 3,name = "lib_ecology:tree_default_wood_fence",prob = 254},
		T["_____"], T["_____"], T["_____"], T["_____"], T["_____"], T["_____"], T["_____"], {param2 = 3,name = "lib_ecology:tree_default_wood_fence",prob = 254},
		{param2 = 3,name = "lib_ecology:tree_default_wood_fence",prob = 254},
		{param2 = 3,name = "lib_ecology:tree_default_wood_fence",prob = 254},
		{param2 = 3,name = "lib_ecology:tree_default_wood_fence",prob = 254},
		{param2 = 3,name = "lib_ecology:tree_default_wood_fence",prob = 254},
		T["_____"], T["_____"], T["_____"], T["_____"], T["_____"], T["_____"], T["_____"], {param2 = 3,name = "lib_ecology:tree_default_wood_fence",prob = 254},
		{param2 = 1,name = "torch:torch",prob = 254},
		T["_____"], {param2 = 1,name = "torch:torch",prob = 254},
		{param2 = 3,name = "lib_ecology:tree_default_wood_fence",prob = 254},
		T["_____"], T["_____"], T["_____"], T["_____"], T["_____"], T["_____"], T["_____"], {param2 = 3,name = "lib_ecology:tree_default_wood_fence",prob = 254},
		{param2 = 3,name = "lib_ecology:tree_default_wood_fence",prob = 254},
		{param2 = 3,name = "lib_ecology:tree_default_wood_fence",prob = 254},
		{param2 = 3,name = "lib_ecology:tree_default_wood_fence",prob = 254},
		{param2 = 3,name = "lib_ecology:tree_default_wood_fence",prob = 254},
		T["_____"], T["_____"], T["_____"], T["_____"], T["_____"], T["_____"], T["_____"], {param2 = 3,name = "lib_ecology:tree_default_wood_fence",prob = 254},
		{param2 = 1,name = "torch:torch",prob = 254},
		T["_____"], {param2 = 1,name = "torch:torch",prob = 254},
		{param2 = 3,name = "lib_ecology:tree_default_wood_fence",prob = 254},
		T["_____"], T["_____"], T["_____"], T["_____"], T["_____"], T["_____"], T["_____"], {param2 = 3,name = "lib_ecology:tree_default_wood_fence",prob = 254},
		{param2 = 3,name = "lib_ecology:tree_default_wood_fence",prob = 254},
		{param2 = 3,name = "lib_ecology:tree_default_wood_fence",prob = 254},
		{param2 = 3,name = "lib_ecology:tree_default_wood_fence",prob = 254},
		{param2 = 3,name = "lib_ecology:tree_default_wood_fence",prob = 254},
		T["_____"], T["_____"], T["_____"], T["_____"], T["_____"], T["_____"], T["_____"], {param2 = 1,name = "torch:torch",prob = 254},
		{param2 = 1,name = "torch:torch",prob = 254},
		{param2 = 1,name = "torch:torch",prob = 254},
		{param2 = 1,name = "torch:torch",prob = 254},
		{param2 = 1,name = "torch:torch",prob = 254},
		T["_____"], T["_____"], T["_____"], T["_____"], T["_____"], T["_____"], T["_____"], T["_____"], T["_____"], T["_____"], T["_____"], T["_____"], T["_____"], T["_____"], T["_____"], T["_____"], T["_____"], T["_____"], T["_____"], T["_____"], T["_____"], T["_____"], T["_____"], T["_____"], T["_____"], T["_____"], T["_____"], T["_____"], T["_____"], T["_____"], T["_____"], T["_____"], T["_____"], T["_____"], T["_____"], T["_____"], T["_____"], T["_____"], T["_____"], T["_____"], T["_____"], T["_____"], T["_____"], T["_____"], T["_____"], T["_____"], T["_____"], T["_____"], T["_____"], T["_____"], T["_____"], T["_____"], T["_____"], T["_____"], T["_____"], T["_____"], T["_____"], T["_____"], T["_____"], T["_____"], T["_____"], T["_____"], T["_____"], T["_____"], T["_____"], T["_____"], T["_____"], T["_____"], T["_____"], T["_____"], T["_____"], T["_____"], T["_____"], T["_____"], T["_____"], T["_____"], T["_____"], T["_____"], T["_____"], T["_____"], T["_____"], T["_____"], T["_____"], T["_____"], T["_____"], T["_____"], T["_____"], T["_____"], T["_____"], T["_____"], T["_____"], T["_____"], T["_____"], T["_____"], T["_____"], T["_____"], T["_____"], T["_____"], T["_____"], T["_____"], T["_____"], T["_____"], T["_____"], T["_____"], T["_____"], T["_____"], T["_____"], T["_____"], T["_____"], T["_____"], T["_____"], T["_____"], T["_____"], T["_____"], T["_____"], T["_____"], T["_____"], T["_____"], T["_____"], T["_____"], T["_____"], T["_____"], T["_____"], T["_____"], T["_____"], T["_____"], T["_____"], T["_____"], T["_____"], T["_____"], T["_____"], T["_____"], T["_____"], T["_____"], T["_____"], T["_____"], T["_____"], T["_____"], T["_____"], T["_____"], T["_____"], T["_____"], T["_____"], T["_____"], T["_____"], T["_____"], T["_____"], T["_____"], T["_____"], T["_____"], T["_____"], T["_____"], T["_____"], T["_____"], T["_____"], T["_____"], T["_____"], T["_____"], T["_____"], T["_____"], T["_____"], T["_____"], T["_____"], T["_____"], T["_____"], T["_____"], T["_____"], T["_____"], T["_____"], T["_____"], T["_____"], T["_____"], T["_____"], T["_____"], T["_____"], T["_____"], T["_____"], T["_____"], T["_____"], T["_____"], T["_____"], T["_____"], T["_____"], T["_____"], T["_____"], T["_____"], T["_____"], T["_____"], T["_____"], T["_____"], T["_____"], T["_____"], T["_____"], T["_____"], T["_____"], T["_____"], T["_____"], T["_____"], T["_____"], T["_____"], T["_____"], T["_____"], T["_____"], T["_____"], T["_____"], T["_____"], T["_____"], T["_____"], T["_____"], T["_____"], T["_____"], T["_____"], T["_____"], T["_____"], T["_____"], T["_____"], T["_____"], T["_____"], T["_____"], T["_____"], T["_____"], T["_____"], T["_____"], T["_____"], T["_____"], T["_____"], T["_____"], T["_____"], T["_____"], T["_____"], T["_____"], T["ddddd"], T["ddddd"], T["ddddd"], T["ddddd"], T["ddddd"], T["ddddd"], T["ddddd"], T["ddddd"], T["ddddd"], T["ddddd"], T["ddddd"], T["ddddd"], T["ddddd"], T["ddddd"], T["ddddd"], T["ddddd"], T["ddddd"], T["ddddd"], T["ddddd"], T["ddddd"], T["ddddd"], T["ddddd"], T["ddddd"], T["ddddd"], T["ddddd"], T["ddddd"], T["ddddd"], T["ddddd"], T["ddddd"], T["ddddd"], T["ddddd"], T["ddddd"], T["ddddd"], T["ddddd"], T["ddddd"], T["ddddd"], T["ddddd"], T["ddddd"], T["ddddd"], T["ddddd"], T["ddddd"], T["ddddd"], T["ddddd"], T["ddddd"], T["ddddd"], T["ddddd"], T["ddddd"], T["ddddd"], T["ddddd"], T["ddddd"], T["ddddd"], T["ddddd"], T["ddddd"], T["ddddd"], T["ddddd"], T["ddddd"], T["ddddd"], T["ddddd"], T["ddddd"], T["ddddd"], T["ddddd"], T["S0m00"], T["S0m00"], T["S0m00"], T["S0m00"], T["S0m00"], T["S0m00"], T["S0m00"], T["S0m00"], T["S0m00"], T["S0m00"], T["S0m00"], T["_____"], T["_____"], T["_____"], {param2 = 0,name = "carts:rail",prob = 254},
		{param2 = 0,name = "carts:rail",prob = 254},
		{param2 = 0,name = "carts:rail",prob = 254},
		{param2 = 0,name = "carts:rail",prob = 254},
		{param2 = 0,name = "carts:rail",prob = 254},
		{param2 = 0,name = "carts:rail",prob = 254},
		{param2 = 0,name = "carts:rail",prob = 254},
		T["_____"], T["_____"], T["_____"], T["_____"], T["_____"], T["_____"], T["_____"], T["_____"], T["_____"], T["_____"], T["_____"], T["_____"], T["_____"], T["_____"], T["_____"], T["_____"], T["_____"], T["_____"], T["_____"], T["_____"], T["_____"], T["_____"], T["_____"], T["_____"], T["_____"], T["_____"], T["_____"], T["_____"], T["_____"], T["_____"], T["_____"], T["_____"], T["_____"], T["_____"], T["_____"], T["_____"], T["_____"], T["_____"], T["_____"], T["_____"], T["_____"], T["_____"], T["_____"], T["_____"], T["_____"], T["_____"], T["_____"], T["_____"], T["_____"], T["_____"], T["_____"], T["_____"], T["_____"], T["_____"], T["_____"], T["_____"], T["_____"], T["_____"], T["_____"], T["_____"], T["_____"], T["_____"], T["_____"], T["_____"], T["_____"], T["_____"], T["_____"], T["_____"], T["_____"], T["_____"], T["_____"], T["_____"], T["_____"], T["_____"], T["_____"], T["_____"], T["_____"], T["_____"], T["_____"], T["_____"], T["_____"], T["_____"], T["_____"], T["_____"], T["_____"], T["_____"], T["_____"], T["_____"], T["_____"], T["_____"], T["_____"], T["_____"], T["_____"], T["_____"], T["_____"], T["_____"], T["_____"], T["_____"], T["_____"], T["_____"], T["_____"], T["_____"], T["_____"], T["_____"], T["_____"], T["_____"], T["_____"], T["_____"], T["_____"], T["_____"], T["_____"], T["_____"], T["_____"], T["_____"], T["_____"], T["_____"], T["_____"], T["_____"], T["_____"], T["_____"], T["_____"], T["_____"], T["_____"], T["_____"], T["_____"], T["_____"], T["_____"], T["_____"], T["_____"], T["_____"], T["_____"], T["_____"], T["_____"], T["_____"], T["_____"], T["_____"], T["_____"], T["_____"], T["_____"], T["_____"], T["_____"], T["_____"], T["_____"], T["_____"], T["_____"], T["_____"], T["_____"], T["_____"], T["_____"], T["_____"], T["_____"], T["_____"], T["_____"], T["_____"], T["_____"], T["_____"], T["_____"], T["_____"], T["_____"], T["_____"], T["_____"], T["_____"], T["_____"], T["_____"], T["_____"], T["_____"], T["_____"], T["_____"], T["_____"], T["_____"], T["_____"], T["_____"], T["_____"], T["_____"], T["_____"], T["_____"], T["_____"], T["_____"], T["_____"], T["_____"], T["_____"], T["_____"], T["_____"], T["_____"], T["_____"], T["_____"], T["_____"], T["_____"], T["_____"], T["_____"], T["_____"], T["_____"], T["_____"], T["_____"], T["_____"], T["_____"], T["_____"], T["_____"], T["_____"], T["_____"], T["_____"], T["_____"], T["_____"], T["_____"], T["_____"], T["_____"], T["_____"], T["_____"], T["_____"], T["_____"], T["_____"], T["_____"], T["_____"], T["_____"], T["_____"], T["_____"], T["_____"], T["_____"], T["_____"], T["_____"], T["_____"], T["_____"], T["_____"], T["_____"], T["_____"], T["_____"], T["_____"], T["_____"], T["_____"], T["_____"], T["_____"], T["_____"], T["_____"], T["_____"], T["_____"], T["_____"], T["_____"], T["_____"], T["_____"], T["_____"], T["_____"], T["_____"], T["_____"], T["_____"], T["_____"], T["_____"], T["_____"], T["_____"], T["_____"], T["_____"], T["_____"], T["_____"], T["_____"], T["_____"], T["_____"], T["_____"], T["_____"], T["_____"], T["_____"], T["_____"], T["_____"], T["_____"], T["_____"], T["_____"], T["_____"], T["_____"], T["_____"], T["_____"], T["_____"], T["_____"], T["_____"], T["_____"], T["_____"], T["_____"], T["_____"], T["_____"], T["_____"], T["_____"], T["_____"], T["_____"], T["_____"], T["_____"], T["_____"], T["_____"], T["_____"], T["_____"], T["_____"], T["_____"], T["_____"], T["_____"], T["_____"], T["_____"], T["_____"], T["_____"], T["_____"], T["_____"], T["_____"], T["_____"], T["_____"], T["_____"], T["_____"], T["_____"], T["_____"], T["_____"], T["_____"], T["_____"], T["_____"], T["_____"], T["_____"], T["_____"], T["_____"], T["_____"], T["_____"], T["_____"], T["_____"], T["_____"], T["_____"], T["_____"], T["_____"], T["_____"], T["_____"], T["_____"], T["_____"], T["_____"], T["_____"], T["_____"], T["_____"], T["_____"], T["_____"], T["_____"], T["_____"], T["_____"], T["_____"], T["_____"], T["_____"], T["_____"], T["_____"], T["_____"], T["_____"], T["_____"], T["_____"], T["_____"], T["_____"], T["_____"], T["_____"], T["_____"], T["_____"], T["_____"], T["_____"], T["_____"], T["_____"], T["_____"], T["_____"], T["_____"], T["_____"], T["_____"], T["_____"], T["_____"], T["_____"], T["_____"], T["_____"], T["_____"], T["_____"], T["_____"], T["_____"], T["_____"], T["_____"], T["_____"], T["_____"], T["_____"], T["_____"], T["_____"], T["_____"], T["_____"], T["_____"], T["_____"], T["_____"], T["_____"], T["_____"], T["_____"], T["_____"], T["_____"], T["_____"], T["_____"], T["_____"], T["_____"], T["_____"], T["_____"], T["_____"], T["_____"], T["_____"], T["_____"], T["_____"], T["_____"], T["_____"], T["_____"], T["_____"], T["_____"], T["_____"], T["_____"], T["_____"], T["_____"], T["_____"], T["_____"], T["_____"], T["_____"], T["_____"], T["_____"], T["_____"], T["_____"], T["_____"], T["_____"], T["_____"], T["_____"], T["_____"], T["_____"], T["_____"], T["_____"], T["_____"], T["_____"], T["_____"], T["_____"], T["_____"], T["_____"], T["_____"], T["_____"], T["_____"], T["_____"], T["_____"], T["_____"], T["_____"], T["_____"], T["_____"], T["_____"], T["_____"], T["_____"], T["_____"], T["_____"], T["_____"], T["_____"], T["_____"], T["_____"], T["_____"], T["_____"], T["_____"], T["_____"], T["ddddd"], T["ddddd"], T["ddddd"], T["ddddd"], T["ddddd"], T["ddddd"], T["ddddd"], T["ddddd"], T["ddddd"], T["ddddd"], T["ddddd"], T["ddddd"], T["ddddd"], T["ddddd"], T["ddddd"], T["ddddd"], T["ddddd"], T["ddddd"], T["ddddd"], T["ddddd"], T["ddddd"], T["ddddd"], T["ddddd"], T["ddddd"], T["ddddd"], T["ddddd"], T["ddddd"], T["ddddd"], T["ddddd"], T["ddddd"], T["ddddd"], T["ddddd"], T["ddddd"], T["ddddd"], T["ddddd"], T["ddddd"], T["ddddd"], T["ddddd"], T["ddddd"], T["ddddd"], T["ddddd"], T["ddddd"], T["ddddd"], T["ddddd"], T["ddddd"], T["ddddd"], T["ddddd"], T["ddddd"], T["ddddd"], T["ddddd"], T["ddddd"], T["ddddd"], T["ddddd"], T["ddddd"], T["ddddd"], T["ddddd"], T["ddddd"], T["ddddd"], T["ddddd"], T["ddddd"], T["ddddd"], T["S0m00"], T["S0m00"], T["S0m00"], T["S0m00"], T["S0m00"], T["S0m00"], T["S0m00"], T["S0m00"], T["S0m00"], T["S0m00"], T["S0m00"], T["_____"], T["_____"], T["_____"], T["_____"], T["_____"], T["_____"], T["_____"], T["_____"], T["_____"], T["_____"], T["_____"], T["_____"], T["_____"], T["_____"], T["_____"], T["_____"], T["_____"], T["_____"], T["_____"], T["_____"], T["_____"], T["_____"], T["_____"], T["_____"], T["_____"], T["_____"], T["_____"], T["_____"], T["_____"], T["_____"], T["_____"], T["_____"], T["_____"], T["_____"], T["_____"], T["_____"], T["_____"], T["_____"], T["_____"], T["_____"], T["_____"], T["_____"], T["_____"], T["_____"], T["_____"], T["_____"], T["_____"], T["_____"], T["_____"], T["_____"], T["_____"], T["_____"], T["_____"], T["_____"], T["_____"], T["_____"], T["_____"], T["_____"], T["_____"], T["_____"], T["_____"], T["_____"], T["_____"], T["_____"], T["_____"], T["_____"], T["_____"], T["_____"], T["_____"], T["_____"], T["_____"], T["_____"], T["_____"], T["_____"], T["_____"], T["_____"], T["_____"], T["_____"], T["_____"], T["_____"], T["_____"], T["_____"], T["_____"], T["_____"], T["_____"], T["_____"], T["_____"], T["_____"], T["_____"], T["_____"], T["_____"], T["_____"], T["_____"], T["_____"], T["_____"], T["_____"], T["_____"], T["_____"], T["_____"], T["_____"], T["_____"], T["_____"], T["_____"], T["_____"], T["_____"], T["_____"], T["_____"], T["_____"], T["_____"], T["_____"], T["_____"], T["_____"], T["_____"], T["_____"], T["_____"], T["_____"], T["_____"], T["_____"], T["_____"], T["_____"], T["_____"], T["_____"], T["_____"], T["_____"], T["_____"], T["_____"], T["_____"], T["_____"], T["_____"], T["_____"], T["_____"], T["_____"], T["_____"], T["_____"], T["_____"], T["_____"], T["_____"], T["_____"], T["_____"], T["_____"], T["_____"], T["_____"], T["_____"], T["_____"], T["_____"], T["_____"], T["_____"], T["_____"], T["_____"], T["_____"], T["_____"], T["_____"], T["_____"], T["_____"], T["_____"], T["_____"], T["_____"], T["_____"], T["_____"], T["_____"], T["_____"], T["_____"], T["_____"], T["_____"], T["_____"], T["_____"], T["_____"], T["_____"], T["_____"], T["_____"], T["_____"], T["_____"], T["_____"], T["_____"], T["_____"], T["_____"], T["_____"], T["_____"], T["_____"], T["_____"], T["_____"], T["_____"], T["_____"], T["_____"], T["_____"], T["_____"], T["_____"], T["_____"], T["_____"], T["_____"], T["_____"], T["_____"], T["_____"], T["_____"], T["_____"], T["_____"], T["_____"], T["_____"], T["_____"], T["_____"], T["_____"], T["_____"], T["_____"], T["_____"], T["_____"], T["_____"], T["_____"], T["_____"], T["_____"], T["_____"], T["_____"], T["_____"], T["_____"], T["_____"], T["_____"], T["_____"], T["_____"], T["_____"], T["_____"], T["_____"], T["_____"], T["_____"], T["_____"], T["_____"], T["_____"], T["_____"], T["_____"], T["_____"], T["_____"], T["_____"], T["_____"], T["_____"], T["_____"], T["_____"], T["_____"], T["_____"], T["_____"], T["_____"], T["_____"], T["_____"], T["_____"], T["_____"], T["_____"], T["_____"], T["_____"], T["_____"], T["_____"], T["_____"], T["_____"], T["_____"], T["_____"], T["_____"], T["_____"], T["_____"], T["_____"], T["_____"], T["_____"], T["_____"], T["_____"], T["_____"], T["_____"], T["_____"], T["_____"], T["_____"], T["_____"], T["_____"], T["_____"], T["_____"], T["_____"], T["_____"], T["_____"], T["_____"], T["_____"], T["_____"], T["_____"], T["_____"], T["_____"], T["_____"], T["_____"], T["_____"], T["_____"], T["_____"], T["_____"], T["_____"], T["_____"], T["_____"], T["_____"], T["_____"], T["_____"], T["_____"], T["_____"], T["_____"], T["_____"], T["_____"], T["_____"], T["_____"], T["_____"], T["_____"], T["_____"], T["_____"], T["_____"], T["_____"], T["_____"], T["_____"], T["_____"], T["_____"], T["_____"], T["_____"], T["_____"], T["_____"], T["_____"], T["_____"], T["_____"], T["_____"], T["_____"], T["_____"], T["_____"], T["_____"], T["_____"], T["_____"], T["_____"], T["_____"], T["_____"], T["_____"], T["_____"], T["_____"], T["_____"], T["_____"], T["_____"], T["_____"], T["_____"], T["_____"], T["_____"], T["_____"], T["_____"], T["_____"], T["_____"], T["_____"], T["_____"], T["_____"], T["_____"], T["_____"], T["_____"], T["_____"], T["_____"], T["_____"], T["_____"], T["_____"], T["_____"], T["_____"], T["_____"], T["_____"], T["_____"], T["_____"], T["_____"], T["_____"], T["_____"], T["_____"], T["_____"], T["_____"], T["_____"], T["_____"], T["_____"], T["_____"], T["_____"], T["_____"], T["_____"], T["_____"], T["_____"], T["_____"], T["_____"], T["_____"], T["_____"], T["_____"], T["_____"], T["_____"], T["_____"], T["_____"], T["_____"], T["_____"], T["_____"], T["_____"], T["_____"], T["_____"], T["_____"], T["_____"], T["_____"], T["_____"], T["_____"], T["_____"], T["_____"], T["_____"], T["_____"], T["_____"], T["_____"], T["_____"], T["_____"], T["_____"], T["_____"], T["_____"], T["_____"], T["_____"], T["_____"], T["_____"], T["_____"], T["_____"], T["_____"], T["_____"], T["_____"], T["_____"], T["_____"], T["_____"], T["_____"], T["_____"], T["_____"], T["_____"], T["_____"], T["_____"], T["_____"], T["_____"], T["_____"], T["_____"], T["_____"], T["_____"], T["_____"], T["_____"], T["_____"], T["_____"], T["_____"], T["_____"], T["_____"], T["_____"], T["_____"], T["_____"], T["_____"], T["_____"], T["_____"], T["_____"], T["_____"], T["_____"], T["_____"], T["_____"], T["_____"], T["_____"], T["_____"], T["_____"], T["_____"], T["_____"], T["_____"], T["_____"], T["_____"], T["_____"], T["_____"], T["_____"], T["_____"], T["_____"], T["ddddd"], T["ddddd"], T["ddddd"], T["ddddd"], T["ddddd"], T["ddddd"], T["ddddd"], T["ddddd"], T["ddddd"], T["ddddd"], T["ddddd"], T["ddddd"], T["ddddd"], T["ddddd"], T["ddddd"], T["ddddd"], T["ddddd"], T["ddddd"], T["ddddd"], T["ddddd"], T["ddddd"], T["ddddd"], T["ddddd"], T["ddddd"], T["ddddd"], T["ddddd"], T["ddddd"], T["ddddd"], T["ddddd"], T["ddddd"], T["ddddd"], T["ddddd"], T["ddddd"], T["ddddd"], T["ddddd"], T["ddddd"], T["ddddd"], T["ddddd"], T["ddddd"], T["ddddd"], T["ddddd"], T["ddddd"], T["ddddd"], T["ddddd"], T["ddddd"], T["ddddd"], T["ddddd"], T["ddddd"], T["ddddd"], T["ddddd"], T["ddddd"], T["ddddd"], T["ddddd"], T["ddddd"], T["ddddd"], T["ddddd"], T["ddddd"], T["ddddd"], T["ddddd"], T["ddddd"], T["ddddd"], T["K0m00"], T["S0m00"], T["S0m00"], T["S0m00"], T["K0m00"], T["K0m00"], T["K0m00"], T["S0m00"], T["S0m00"], T["S0m00"], T["K0m00"], T["_____"], T["_____"], T["_____"], T["_____"], T["_____"], T["_____"], T["_____"], T["_____"], T["_____"], T["_____"], T["_____"], T["_____"], T["_____"], T["_____"], T["_____"], T["_____"], T["_____"], T["_____"], T["_____"], T["_____"], T["_____"], T["_____"], T["_____"], T["_____"], T["_____"], T["_____"], T["_____"], T["_____"], T["_____"], T["_____"], T["_____"], T["_____"], T["_____"], T["_____"], T["_____"], T["_____"], T["_____"], T["_____"], T["_____"], T["_____"], T["_____"], T["_____"], T["_____"], T["_____"], T["_____"], T["_____"], T["_____"], T["_____"], T["_____"], T["_____"], T["_____"], T["_____"], T["_____"], T["_____"], T["_____"], T["_____"], T["_____"], T["_____"], T["_____"], T["_____"], T["___