



local T = lib_towns.schems.T


return {
	size = {x = 10,y = 7,z = 8},
	data = {
		T["_____"], T["C0S00"], T["C0S00"], T["C0S00"], T["_____"], T["_____"], T["_____"], T["_____"], T["_____"], T["_____"],
		T["_____"], T["_____"], T["_____"], T["_____"], T["_____"], T["_____"], T["_____"], T["_____"], T["_____"], T["_____"],
		T["_____"], T["_____"], T["_____"], T["_____"], T["_____"], T["_____"], T["_____"], T["_____"], T["_____"], T["_____"],
		T["_____"], T["_____"], T["_____"], T["_____"], T["_____"], T["_____"], T["_____"], T["_____"], T["_____"], T["_____"],
		T["_____"], T["_____"], T["_____"], T["_____"], T["_____"], T["_____"], T["_____"], T["_____"], T["_____"], T["_____"],
		T["_____"], T["_____"], T["_____"], T["_____"], T["_____"], T["_____"], T["_____"], T["_____"], T["_____"], T["_____"],
		T["_____"], T["_____"], T["_____"], T["_____"], T["_____"], T["_____"], T["_____"], T["_____"], T["_____"], T["_____"],

		T["C0m00"], T["C0m00"], T["C0m00"], T["C0m00"], T["C0m00"], T["C0m00"], T["C0m00"], T["C0m00"], T["C0m00"], T["C0m00"],
		T["W0n00"], T["_____"], T["_____"], T["_____"], T["W0n00"], T["W0n00"], T["T0m00"], T["K0m00"], T["K0m00"], T["T0m00"],
		T["W0n00"], T["_____"], T["_____"], T["_____"], T["W0n00"], T["_____"], T["T0m00"], T["K0m00"], T["Xp0S0"], T["T0m00"],
		T["W0n00"], T["_____"], T["_____"], T["_____"], T["W0n00"], T["_____"], T["T0m00"], T["K0m00"], T["K0m00"], T["T0m00"],
		T["C0m00"], T["C0S20"], T["C0S20"], T["C0S20"], T["C0m00"], T["C0S20"], T["C0m00"], T["C0m00"], T["C0m00"], T["C0m00"],
		T["X0m00"], T["X0L00"], T["X0L00"], T["X0L00"], T["X0L00"], T["X0L00"], T["X0L00"], T["X0L00"], T["X0L00"], T["X0m00"],
		T["_____"], T["_____"], T["_____"], T["_____"], T["_____"], T["_____"], T["_____"], T["_____"], T["_____"], T["_____"],

		T["C0m00"], T["C0m00"], T["C0m00"], T["C0m00"], T["C0m00"], T["C0m00"], T["C0m00"], T["C0m00"], T["C0m00"], T["C0m00"],
		T["_____"], T["X0m00"], T["_____"], T["_____"], T["_____"], T["_____"], T["W0dW0"], T["_____"], T["_____"], T["K0m00"],
		T["_____"], T["_____"], T["_____"], T["_____"], T["_____"], T["_____"], T["_____"], T["_____"], T["_____"], T["K0m00"],
		T["_____"], T["_____"], T["_____"], T["_____"], T["_____"], T["_____"], T["K0m00"], T["_____"], T["_____"], T["K0m00"],
		T["C0S23"], T["C0m00"], T["C0m00"], T["C0m00"], T["C0m00"], T["C0m00"], T["C0m00"], T["C0m00"], T["C0m00"], T["C0m00"],
		T["X0L00"], T["_____"], T["_____"], T["_____"], T["_____"], T["_____"], T["_____"], T["_____"], T["_____"], T["X0L00"],
		T["_____"], T["_____"], T["_____"], T["_____"], T["_____"], T["_____"], T["_____"], T["_____"], T["_____"], T["_____"],

		T["C0m00"], T["C0m00"], T["C0m00"], T["C0m00"], T["C0m00"], T["C0m00"], T["C0m00"], T["C0m00"], T["C0m00"], T["C0m00"],
		T["_____"], T["_____"], T["_____"], T["_____"], T["_____"], T["_____"], T["K0m00"], T["_____"], T["_____"], T["K0m00"],
		T["_____"], T["_____"], T["_____"], T["_____"], T["_____"], T["_____"], T["K0m00"], T["_____"], T["_____"], T["Xp0E0"],
		T["_____"], T["_____"], T["_____"], T["_____"], T["_____"], T["_____"], T["K0m00"], T["_____"], T["_____"], T["K0m00"],
		T["C0S23"], T["C0m00"], T["C0m00"], T["C0m00"], T["C0m00"], T["C0m00"], T["C0m00"], T["C0m00"], T["C0m00"], T["C0m00"],
		T["X0L00"], T["_____"], T["_____"], T["_____"], T["_____"], T["_____"], T["_____"], T["_____"], T["_____"], T["X0L00"],
		T["_____"], T["_____"], T["_____"], T["_____"], T["_____"], T["_____"], T["_____"], T["_____"], T["_____"], T["_____"],

		T["C0m00"], T["C0m00"], T["C0m00"], T["C0m00"], T["C0m00"], T["C0m00"], T["C0m00"], T["C0m00"], T["C0m00"], T["C0m00"],
		T["_____"], T["_____"], T["_____"], T["C0m00"], T["K0m00"], T["K0m00"], T["_____"], T["_____"], T["_____"], T["K0m00"],
		T["_____"], T["_____"], T["_____"], T["Fu0E0"], T["K0m00"], T["K0m00"], T["_____"], T["_____"], T["_____"], T["K0m00"],
		T["_____"], T["_____"], T["_____"], T["Fu0E0"], T["K0m00"], T["K0m00"], T["_____"], T["_____"], T["_____"], T["K0m00"],
		T["C0S23"], T["C0m00"], T["C0m00"], T["C0m00"], T["C0m00"], T["C0m00"], T["C0m00"], T["C0m00"], T["C0m00"], T["C0m00"],
		T["X0L00"], T["_____"], T["_____"], T["_____"], T["_____"], T["_____"], T["_____"], T["_____"], T["_____"], T["X0L00"],
		T["_____"], T["_____"], T["_____"], T["_____"], T["_____"], T["_____"], T["_____"], T["_____"], T["_____"], T["_____"],

		T["C0m00"], T["C0m00"], T["C0m00"], T["C0m00"], T["C0m00"], T["C0m00"], T["C0m00"], T["C0m00"], T["C0m00"], T["C0m00"],
		T["C0m00"], T["C0m00"], T["C0m00"], T["C0m00"], T["Cs0W0"], T["_____"], T["_____"], T["W0n00"], T["W0S01"], T["K0m00"],
		T["Xb0E0"], T["_____"], T["_____"], T["C0m00"], T["_____"], T["_____"], T["_____"], T["SwN00"], T["_____"], T["Xp0E0"],
		T["C0m00"], T["C0m00"], T["C0m00"], T["C0m00"], T["X0L00"], T["_____"], T["_____"], T["_____"], T["_____"], T["K0m00"],
		T["C0m00"], T["C0m00"], T["C0m00"], T["C0m00"], T["C0m00"], T["C0m00"], T["C0m00"], T["C0m00"], T["C0m00"], T["C0m00"],
		T["X0L00"], T["_____"], T["_____"], T["_____"], T["_____"], T["_____"], T["_____"], T["_____"], T["_____"], T["X0L00"],
		T["_____"], T["_____"], T["_____"], T["_____"], T["_____"], T["_____"], T["_____"], T["_____"], T["_____"], T["_____"],

		T["C0m00"], T["C0m00"], T["C0m00"], T["C0m00"], T["C0m00"], T["C0m00"], T["C0m00"], T["C0m00"], T["C0m00"], T["C0m00"],
		T["C0m00"], T["lllll"], T["lllll"], T["C0m00"], T["Cs0W0"], T["_____"], T["_____"], T["W0S00"], T["_____"], T["K0m00"],
		T["Xb0W0"], T["_____"], T["_____"], T["C0m00"], T["_____"], T["_____"], T["_____"], T["_____"], T["_____"], T["K0m00"],
		T["C0m00"], T["C0m00"], T["C0m00"], T["C0m00"], T["X0L00"], T["_____"], T["_____"], T["_____"], T["_____"], T["K0m00"],
		T["C0m00"], T["C0m00"], T["C0m00"], T["C0m00"], T["C0m00"], T["C0m00"], T["C0m00"], T["C0m00"], T["C0m00"], T["C0m00"],
		T["X0L00"], T["_____"], T["_____"], T["_____"], T["_____"], T["_____"], T["_____"], T["_____"], T["_____"], T["X0L00"],
		T["_____"], T["_____"], T["_____"], T["_____"], T["_____"], T["_____"], T["_____"], T["_____"], T["_____"], T["_____"],

		T["C0m00"], T["C0m00"], T["C0m00"], T["C0m00"], T["C0m00"], T["C0m00"], T["C0m00"], T["C0m00"], T["C0m00"], T["C0m00"],
		T["K0m00"], T["K0m00"], T["K0m00"], T["K0m00"], T["K0m00"], T["K0m00"], T["K0m00"], T["K0m00"], T["K0m00"], T["T0m00"],
		T["K0m00"], T["K0m00"], T["K0m00"], T["K0m00"], T["K0m00"], T["Xp0N0"], T["K0m00"], T["Xp0N0"], T["K0m00"], T["T0m00"],
		T["K0m00"], T["K0m00"], T["K0m00"], T["K0m00"], T["K0m00"], T["K0m00"], T["K0m00"], T["K0m00"], T["K0m00"], T["T0m00"],
		T["C0m00"], T["C0m00"], T["C0m00"], T["C0m00"], T["C0m00"], T["C0m00"], T["C0m00"], T["C0m00"], T["C0m00"], T["C0m00"],
		T["X0m00"], T["X0L00"], T["X0L00"], T["X0L00"], T["X0L00"], T["X0L00"], T["X0L00"], T["X0L00"], T["X0L00"], T["X0m00"],
		T["_____"], T["_____"], T["_____"], T["_____"], T["_____"], T["_____"], T["_____"], T["_____"], T["_____"], T["_____"],
	},
	yslice_prob = {
		{prob = 254,ypos = 0},
		{prob = 254,ypos = 1},
		{prob = 254,ypos = 2},
		{prob = 254,ypos = 3},
		{prob = 254,ypos = 4},
		{prob = 254,ypos = 5},
		{prob = 254,ypos = 6}
	}
}