



local T = lib_towns.schems.T


return {
	size = {x = 6,y = 6,z = 6},
	data = {
		T["ggggg"], T["C0S20"], T["C0S00"], T["C0S20"], T["ggggg"], T["ggggg"],
		T["_____"], T["W0n00"], T["_____"], T["W0n00"], T["_____"], T["_____"],
		T["_____"], T["W0n00"], T["_____"], T["W0n00"], T["_____"], T["_____"],
		T["_____"], T["W0L00"], T["W0L20"], T["W0L00"], T["_____"], T["_____"],
		T["_____"], T["_____"], T["_____"], T["_____"], T["_____"], T["_____"],
		T["_____"], T["_____"], T["_____"], T["_____"], T["_____"], T["_____"],

		T["ggggg"], T["C0m00"], T["C0m00"], T["C0m00"], T["C0m00"], T["ggggg"],
		T["_____"], T["T0m00"], T["W0dS0"], T["T0m00"], T["T0m00"], T["_____"],
		T["_____"], T["T0m00"], T["_____"], T["T0m00"], T["T0m00"], T["_____"],
		T["_____"], T["T0m00"], T["W0m00"], T["T0m00"], T["T0m00"], T["_____"],
		T["_____"], T["W0L00"], T["W0S01"], T["W0S03"], T["W0L00"], T["_____"],
		T["_____"], T["_____"], T["_____"], T["_____"], T["_____"], T["_____"],

		T["ggggg"], T["C0m00"], T["W0m00"], T["W0m00"], T["C0m00"], T["ggggg"],
		T["_____"], T["W0m00"], T["_____"], T["_____"], T["W0m00"], T["_____"],
		T["_____"], T["W0m00"], T["_____"], T["_____"], T["W0m00"], T["_____"],
		T["W0L00"], T["W0m00"], T["_____"], T["_____"], T["W0m00"], T["W0L00"],
		T["_____"], T["W0S00"], T["T0m00"], T["T0m00"], T["W0S00"], T["_____"],
		T["_____"], T["_____"], T["_____"], T["_____"], T["_____"], T["_____"],

		T["ggggg"], T["C0m00"], T["W0m00"], T["W0m00"], T["C0m00"], T["ggggg"],
		T["_____"], T["T0m00"], T["_____"], T["_____"], T["T0m00"], T["_____"],
		T["_____"], T["W0n00"], T["_____"], T["_____"], T["W0n00"], T["_____"],
		T["W0L23"], T["T0m00"], T["_____"], T["_____"], T["T0m00"], T["W0L21"],
		T["_____"], T["T0m00"], T["T0m00"], T["T0m00"], T["T0m00"], T["_____"],
		T["_____"], T["W0L00"], T["W0L00"], T["W0L00"], T["W0L00"], T["_____"],

		T["ggggg"], T["C0m00"], T["W0m00"], T["W0m00"], T["C0m00"], T["ggggg"],
		T["_____"], T["W0m00"], T["W0n00"], T["_____"], T["W0m00"], T["_____"],
		T["_____"], T["W0m00"], T["SwN00"], T["_____"], T["W0m00"], T["_____"],
		T["W0L00"], T["W0m00"], T["_____"], T["_____"], T["W0m00"], T["W0L00"],
		T["_____"], T["W0S02"], T["T0m00"], T["T0m00"], T["W0S02"], T["_____"],
		T["_____"], T["_____"], T["_____"], T["_____"], T["_____"], T["_____"],

		T["ggggg"], T["C0m00"], T["C0m00"], T["C0m00"], T["C0m00"], T["ggggg"],
		T["_____"], T["T0m00"], T["W0S02"], T["W0S22"], T["T0m00"], T["_____"],
		T["_____"], T["T0m00"], T["W0m00"], T["W0S02"], T["T0m00"], T["_____"],
		T["_____"], T["T0m00"], T["W0S22"], T["W0m00"], T["T0m00"], T["_____"],
		T["_____"], T["W0L00"], T["W0S01"], T["W0S03"], T["W0L00"], T["_____"],
		T["_____"], T["_____"], T["_____"], T["_____"], T["_____"], T["_____"],
	},
	yslice_prob = {
		{prob = 254,ypos = 0},
		{prob = 254,ypos = 1},
		{prob = 254,ypos = 2},
		{prob = 254,ypos = 3},
		{prob = 254,ypos = 4},
		{prob = 254,ypos = 5}
	}
}