



local T = lib_towns.schems.T


return {
	size = {x = 6,y = 11,z = 6},
	data = {
		T["S0m00"], T["S0m00"], T["S0m00"], T["S0m00"], T["S0m00"], T["S0m00"],
		T["ddddd"], T["ddddd"], T["ddddd"], T["ddddd"], T["ddddd"], T["ddddd"],
		T["ddddd"], T["ddddd"], T["ddddd"], T["ddddd"], T["ddddd"], T["ddddd"],
		T["ggggg"], T["ddddd"], T["ggggg"], T["ggggg"], T["ddddd"], T["ggggg"],
		T["C0L00"], T["C0m00"], T["C0S00"], T["C0S00"], T["C0m00"], T["C0L00"],
		T["_____"], T["_____"], T["_____"], T["_____"], T["_____"], T["_____"],
		T["_____"], T["_____"], T["_____"], T["_____"], T["_____"], T["_____"],
		T["_____"], T["_____"], T["_____"], T["_____"], T["_____"], T["_____"],
		T["_____"], T["_____"], T["_____"], T["_____"], T["_____"], T["_____"],
		T["_____"], T["_____"], T["_____"], T["_____"], T["_____"], T["_____"],
		T["_____"], T["_____"], T["_____"], T["_____"], T["_____"], T["_____"],

		T["S0m00"], T["S0m00"], T["S0m00"], T["S0m00"], T["S0m00"], T["S0m00"],
		T["ddddd"], T["ddddd"], T["ddddd"], T["ddddd"], T["ddddd"], T["ddddd"],
		T["ddddd"], T["ddddd"], T["ddddd"], T["ddddd"], T["ddddd"], T["ddddd"],
		T["ddddd"], T["ddddd"], T["ddddd"], T["ddddd"], T["ddddd"], T["ddddd"],
		T["C0m00"], T["C0m00"], T["C0m00"], T["C0m00"], T["C0m00"], T["C0m00"],
		T["_____"], T["C0m00"], T["C0L00"], T["C0L00"], T["C0m00"], T["_____"],
		T["_____"], T["W0n00"], T["_____"], T["_____"], T["W0n00"], T["_____"],
		T["_____"], T["W0n00"], T["_____"], T["_____"], T["W0n00"], T["_____"],
		T["_____"], T["C0m00"], T["C0S20"], T["C0S20"], T["C0m00"], T["_____"],
		T["_____"], T["C0pw0"], T["_____"], T["_____"], T["C0pw0"], T["_____"],
		T["_____"], T["_____"], T["_____"], T["_____"], T["_____"], T["_____"],

		T["S0m00"], T["S0m00"], T["S0m00"], T["S0m00"], T["S0m00"], T["S0m00"],
		T["ddddd"], T["ddddd"], T["wwwww"], T["wwwww"], T["ddddd"], T["ddddd"],
		T["ddddd"], T["ddddd"], T["wwwww"], T["wwwww"], T["ddddd"], T["ddddd"],
		T["ggggg"], T["ddddd"], T["wwwww"], T["wwwww"], T["ddddd"], T["ggggg"],
		T["C0S01"], T["C0m00"], T["wwwww"], T["wwwww"], T["C0m00"], T["C0S03"],
		T["_____"], T["C0L00"], T["_____"], T["_____"], T["C0L00"], T["_____"],
		T["_____"], T["_____"], T["_____"], T["_____"], T["_____"], T["_____"],
		T["_____"], T["_____"], T["_____"], T["_____"], T["_____"], T["_____"],
		T["_____"], T["C0S23"], T["C0L20"], T["C0L20"], T["C0S21"], T["_____"],
		T["_____"], T["_____"], T["_____"], T["_____"], T["_____"], T["_____"],
		T["_____"], T["_____"], T["_____"], T["_____"], T["_____"], T["_____"],

		T["S0m00"], T["S0m00"], T["S0m00"], T["S0m00"], T["S0m00"], T["S0m00"],
		T["ddddd"], T["ddddd"], T["wwwww"], T["wwwww"], T["ddddd"], T["ddddd"],
		T["ddddd"], T["ddddd"], T["wwwww"], T["wwwww"], T["ddddd"], T["ddddd"],
		T["ggggg"], T["ddddd"], T["wwwww"], T["wwwww"], T["ddddd"], T["ggggg"],
		T["C0S01"], T["C0m00"], T["wwwww"], T["wwwww"], T["C0m00"], T["C0S03"],
		T["_____"], T["C0L00"], T["_____"], T["_____"], T["C0L00"], T["_____"],
		T["_____"], T["_____"], T["_____"], T["_____"], T["_____"], T["_____"],
		T["_____"], T["_____"], T["_____"], T["_____"], T["_____"], T["_____"],
		T["_____"], T["C0S23"], T["C0L20"], T["C0L20"], T["C0S21"], T["_____"],
		T["_____"], T["_____"], T["_____"], T["_____"], T["_____"], T["_____"],
		T["_____"], T["_____"], T["_____"], T["_____"], T["_____"], T["_____"],

		T["S0m00"], T["S0m00"], T["S0m00"], T["S0m00"], T["S0m00"], T["S0m00"],
		T["ddddd"], T["ddddd"], T["ddddd"], T["ddddd"], T["ddddd"], T["ddddd"],
		T["ddddd"], T["ddddd"], T["ddddd"], T["ddddd"], T["ddddd"], T["ddddd"],
		T["ddddd"], T["ddddd"], T["ddddd"], T["ddddd"], T["ddddd"], T["ddddd"],
		T["C0m00"], T["C0m00"], T["C0m00"], T["C0m00"], T["C0m00"], T["C0m00"],
		T["_____"], T["C0m00"], T["C0L00"], T["C0L00"], T["C0m00"], T["_____"],
		T["_____"], T["W0n00"], T["_____"], T["_____"], T["W0n00"], T["_____"],
		T["_____"], T["W0n00"], T["_____"], T["_____"], T["W0n00"], T["_____"],
		T["_____"], T["C0m00"], T["C0S22"], T["C0S22"], T["C0m00"], T["_____"],
		T["_____"], T["C0pw0"], T["_____"], T["_____"], T["C0pw0"], T["_____"],
		T["_____"], T["_____"], T["_____"], T["_____"], T["_____"], T["_____"],

		T["S0m00"], T["S0m00"], T["S0m00"], T["S0m00"], T["S0m00"], T["S0m00"],
		T["ddddd"], T["ddddd"], T["ddddd"], T["ddddd"], T["ddddd"], T["ddddd"],
		T["ddddd"], T["ddddd"], T["ddddd"], T["ddddd"], T["ddddd"], T["ddddd"],
		T["ggggg"], T["ddddd"], T["ggggg"], T["ggggg"], T["ddddd"], T["ggggg"],
		T["C0L00"], T["C0m00"], T["C0S02"], T["C0S02"], T["C0m00"], T["C0L00"],
		T["_____"], T["_____"], T["_____"], T["_____"], T["_____"], T["_____"],
		T["_____"], T["_____"], T["_____"], T["_____"], T["_____"], T["_____"],
		T["_____"], T["_____"], T["_____"], T["_____"], T["_____"], T["_____"],
		T["_____"], T["_____"], T["_____"], T["_____"], T["_____"], T["_____"],
		T["_____"], T["_____"], T["_____"], T["_____"], T["_____"], T["_____"],
		T["_____"], T["_____"], T["_____"], T["_____"], T["_____"], T["_____"],
	},
	yslice_prob = {
		{prob = 254,ypos = 0},
		{prob = 254,ypos = 1},
		{prob = 254,ypos = 2},
		{prob = 254,ypos = 3},
		{prob = 254,ypos = 4},
		{prob = 254,ypos = 5},
		{prob = 254,ypos = 6},
		{prob = 254,ypos = 7},
		{prob = 254,ypos = 8},
		{prob = 254,ypos = 9},
		{prob = 254,ypos = 10}
	}
}