

--Air, Lava, and Water constants used throughout schematics
		local __ = {name = "air", param2 = 0, prob = 0}
		
		local M0 = {name = "default:tree", param2 = 0, prob = 254}
		local M1 = {name = "", param2 = 0, prob = 254}
		local M2 = {name = "", param2 = 0, prob = 254}
		local M3 = {name = "", param2 = 0, prob = 254}
		local M5 = {name = "stairs:slab_wood", param2 = 0, prob = 254}
		local M6 = {name = "", param2 = 0, prob = 254}
		local M7 = {name = "stairs:stair_wood", param2 = 2, prob = 254}
		local M8 = {name = "", param2 = 0, prob = 254}
		local MN = {name = "default:tree", param2 = 4, prob = 254}
		local MS = {name = "default:tree", param2 = 8, prob = 254}
		local ME = {name = "default:tree", param2 = 12, prob = 254}
		local MW = {name = "default:tree", param2 = 16, prob = 254}

		local M0 = {name = "default:tree", param2 = 0, prob = 254}
		
		local WW = {name = "default:wood", param2 = 0, prob = 254}
		
		local FF = {name = "default:fence_wood", param2 = 0, prob = 254}
		local F0 = {name = "default:furnace", param2 = 0, prob = 254}
		local F1 = {name = "default:furnace", param2 = 1, prob = 254}
		local F2 = {name = "default:furnace", param2 = 2, prob = 254}
		local F3 = {name = "default:furnace", param2 = 3, prob = 254}
		local F5 = {name = "lib_tools:dual_furnace_inactive", param2 = 0, prob = 254}
		
		local CC = {name = "default:cobble", param2 = 0, prob = 254}
		local C0 = {name = "default:chest", param2 = 0, prob = 254}
		local C1 = {name = "default:chest", param2 = 1, prob = 254}
		local C2 = {name = "default:chest", param2 = 2, prob = 254}
		local C3 = {name = "default:chest", param2 = 3, prob = 254}
		
		local B0 = {name = "beds:bed_bottom", param2 = 0, prob = 254}
		local B1 = {name = "beds:bed_bottom", param2 = 1, prob = 254}
		local B2 = {name = "beds:bed_bottom", param2 = 2, prob = 254}
		local B3 = {name = "beds:bed_bottom", param2 = 3, prob = 254}
		local B5 = {name = "beds:bed_top", param2 = 0, prob = 254}
		local B6 = {name = "beds:bed_top", param2 = 1, prob = 254}
		local B7 = {name = "beds:bed_top", param2 = 2, prob = 254}
		local B8 = {name = "beds:bed_top", param2 = 3, prob = 254}
		local BN = {name = "default:bookshelf", param2 = 0, prob = 254}
		local BE = {name = "default:bookshelf", param2 = 1, prob = 254}
		local BS = {name = "default:bookshelf", param2 = 2, prob = 254}
		local BW = {name = "default:bookshelf", param2 = 3, prob = 254}

		local DD = {name = "default:dirt", param2 = 0, prob = 254}
		local D0 = {name = "lib_doors:tree_default_wood_door_centered_with_window", param2 = 0, prob = 254}
		local D1 = {name = "lib_doors:tree_default_wood_door_centered_with_window", param2 = 1, prob = 254}
		local D2 = {name = "lib_doors:tree_default_wood_door_centered_with_window", param2 = 2, prob = 254}
		local D3 = {name = "lib_doors:tree_default_wood_door_centered_with_window", param2 = 3, prob = 254}
		local D5 = {name = "doors:trapdoor", param2 = 0, prob = 254}

		local MC = {name = "default:mossycobble", param2 = 0, prob = 254}
		
		local H0 = {name = "castle_farming:hides", param2 = 0, prob = 254}
		
		local GG = {name = "default:glass", param2 = 0, prob = 254}
		local OG = {name = "default:obsidian_glass", param2 = 0, prob = 254}
		
		local T0 = {name = "default:torch", param2 = 0, prob = 254}
		local T1 = {name = "default:torch", param2 = 1, prob = 254}
		local T2 = {name = "default:torch", param2 = 2, prob = 254}
		local T3 = {name = "default:torch", param2 = 3, prob = 254}
		local T4 = {name = "default:torch", param2 = 4, prob = 254}
		local T5 = {name = "default:torch", param2 = 5, prob = 254}
		
		local S0 = {name = "stairs:stair_wood", param2 = 0, prob = 254}
		local S1 = {name = "stairs:stair_wood", param2 = 1, prob = 254}
		local S2 = {name = "stairs:stair_wood", param2 = 2, prob = 254}
		local S3 = {name = "stairs:stair_wood", param2 = 3, prob = 254}
		
		local L5 = {name = "default:ladder", param2 = 5, prob = 254}
		
		local SB = {name = "default:steelblock", param2 = 0, prob = 254}
		
local le_temp_schem


le_temp_schem = {
	size = {x = 6,y = 4,z = 4},
	data = {
		__, SB, SB, SB, SB, __,
		__, SB, SB, SB, SB, __,
		__, OG, OG, SB, SB, __,
		__, SB, SB, SB, SB, __,
		
		SB, SB, SB, SB, SB, SB,
		SB, __, __, __, L5, SB,
		SB, T3, __, __, L5, OG,
		SB, SB, OG, SB, D5, SB,
		
		SB, SB, SB, SB, SB, SB,
		SB, F0, C0, B1, B6, SB,
		SB, T3, __, __, __, OG,
		SB, SB, OG, SB, SB, SB,
		
		__, SB, SB, SB, SB, __,
		__, SB, SB, SB, SB, __,
		__, OG, OG, SB, SB, __,
		__, SB, SB, SB, SB, __
	},
	yslice_prob = {
		{ypos = 0,prob = 254},
		{ypos = 1,prob = 254},
		{ypos = 2,prob = 254},
		{ypos = 3,prob = 254}
	}
}
lib_towns.schematics["schem_ruin_bunker_x6_y4_z4_r000"] = le_temp_schem

le_temp_schem = {
	size = {x = 5,y = 6,z = 9},
	data = {
		FF, FF, __, FF, FF,
		__, __, __, __, __,
		__, __, __, __, __,
		__, __, __, __, __,
		__, __, __, __, __,
		__, __, __, __, __,

		FF, __, __, __, FF,
		__, __, __, __, __,
		__, __, __, __, __,
		__, __, __, __, __,
		__, __, __, __, __,
		__, __, __, __, __,

		FF, __, S0, __, FF,
		__, __, __, __, __,
		__, T4, __, T4, __,
		__, __, __, __, __,
		__, __, __, __, __,
		__, __, __, __, __,

		M0, WW, WW, WW, M0,
		M2, WW, D0, WW, M2,
		M2, WW, __, WW, M1,
		M2, WW, WW, WW, M1,
		__, WW, WW, WW, __,
		__, __, WW, __, __,

		WW, WW, WW, WW, WW,
		WW, F2, __, F5, WW,
		WW, T5, __, T5, WW,
		WW, __, __, __, WW,
		__, WW, WW, WW, __,
		__, __, WW, __, __,

		WW, WW, WW, WW, WW,
		WW, __, __, __, WW,
		GG, __, __, __, GG,
		WW, __, __, __, WW,
		__, WW, GG, WW, __,
		__, __, GG, __, __,

		WW, WW, WW, WW, WW,
		WW, B0, __, __, WW,
		GG, __, __, __, GG,
		WW, __, __, __, WW,
		__, WW, GG, WW, __,
		__, __, GG, __, __,

		WW, WW, WW, WW, WW,
		WW, B5, __, C0, WW,
		WW, T4, __, T4, WW,
		WW, __, __, __, WW,
		__, WW, WW, WW, __,
		__, __, WW, __, __,

		M2, WW, WW, WW, M3,
		M0, WW, WW, WW, M1,
		M0, WW, GG, WW, M1,
		M0, WW, WW, WW, M1,
		__, WW, WW, WW, __,
		__, __, WW, __, __
	},
	yslice_prob = {
		{ypos = 0,prob = 254},
		{ypos = 1,prob = 254},
		{ypos = 2,prob = 254},
		{ypos = 3,prob = 254},
		{ypos = 4,prob = 254},
		{ypos = 5,prob = 254}
	}
}
lib_towns.schematics["schem_ruin_cabin_x5_y6_z9_r000"] = le_temp_schem

le_temp_schem = {
	size = {x = 5,y = 6,z = 9},
	data = {
		__, __, __, FF, FF,
		__, __, __, __, __,
		__, __, __, __, __,
		__, __, __, __, __,
		__, __, __, __, __,
		__, __, __, __, __,

		FF, __, __, __, __,
		__, __, __, __, __,
		__, __, __, __, __,
		__, __, __, __, __,
		__, __, __, __, __,
		__, __, __, __, __,

		FF, __, S0, __, __,
		__, __, __, __, __,
		__, __, __, __, __,
		__, __, __, __, __,
		__, __, __, __, __,
		__, __, __, __, __,

		__, __, WW, WW, M0,
		__, __, __, WW, M2,
		__, __, __, WW, __,
		__, __, WW, WW, __,
		__, __, __, WW, __,
		__, __, __, __, __,

		WW, __, WW, WW, __,
		WW, __, __, __, WW,
		WW, __, __, __, WW,
		__, __, __, __, WW,
		__, __, __, WW, __,
		__, __, __, __, __,

		WW, WW, WW, WW, WW,
		WW, __, __, __, WW,
		GG, __, __, __, __,
		WW, __, __, __, __,
		__, WW, __, __, __,
		__, __, __, __, __,

		WW, WW, __, WW, WW,
		WW, __, __, __, WW,
		__, __, __, __, GG,
		__, __, __, __, __,
		__, __, __, __, __,
		__, __, GG, __, __,

		WW, WW, WW, WW, WW,
		__, __, __, __, WW,
		__, __, __, __, WW,
		__, __, __, __, __,
		__, __, WW, __, __,
		__, __, WW, __, __,

		M2, WW, WW, WW, M3,
		M0, WW, WW, __, M1,
		M0, WW, GG, __, M1,
		M0, WW, WW, __, __,
		M0, WW, WW, __, __,
		__, __, WW, __, __
	},
	yslice_prob = {
		{ypos = 0,prob = 254},
		{ypos = 1,prob = 254},
		{ypos = 2,prob = 254},
		{ypos = 3,prob = 254},
		{ypos = 4,prob = 254},
		{ypos = 5,prob = 254}
	}
}
lib_towns.schematics["schem_ruin_cabin_old_x5_y6_z9_r000"] = le_temp_schem

le_temp_schem = {
	size = {x = 10,y = 18,z = 18},
	data = {
		M2, WW, WW, WW, WW, WW, WW, WW, WW, M3,
		M2, WW, WW, WW, WW, WW, WW, WW, WW, M2,
		M2, WW, WW, WW, WW, WW, WW, WW, WW, M2,
		M2, WW, WW, WW, GG, GG, WW, WW, WW, M2,
		M2, WW, WW, WW, GG, GG, WW, WW, WW, M2,
		M2, WW, WW, WW, GG, GG, WW, WW, WW, M2,
		__, WW, WW, GG, GG, GG, GG, WW, WW, __,
		__, __, WW, WW, GG, GG, WW, WW, __, __,
		__, __, __, WW, WW, WW, WW, __, __, __,
		__, __, __, __, MS, MS, __, __, __, __,
		__, __, __, __, __, __, __, __, __, __,
		__, __, __, __, __, __, __, __, __, __,
		__, __, __, __, __, __, __, __, __, __,
		__, __, __, __, __, __, __, __, __, __,
		__, __, __, __, __, __, __, __, __, __,
		__, __, __, __, __, __, __, __, __, __,
		__, __, __, __, __, __, __, __, __, __,
		__, __, __, __, __, __, __, __, __, MC,

		WW, WW, WW, WW, WW, WW, WW, WW, WW, WW,
		WW, M7, M7, M7, M7, M7, M7, M7, M7, WW,
		WW, T5, __, __, __, __, __, __, T5, WW,
		WW, T5, __, __, __, __, __, __, T5, WW,
		WW, T5, __, __, __, __, __, __, T5, WW,
		WW, __, __, __, __, __, __, __, __, WW,
		__, WW, T0, __, __, __, __, T0, WW, __,
		__, __, WW, __, __, __, __, WW, __, __,
		__, __, __, WW, __, __, WW, __, __, __,
		__, __, __, __, MS, MS, __, __, __, __,
		__, __, __, __, __, __, __, __, __, __,
		__, __, __, __, __, __, __, __, __, __,
		__, __, __, __, __, __, __, __, __, __,
		__, __, __, __, __, __, __, __, __, __,
		__, __, __, __, __, __, __, __, __, __,
		__, __, __, __, __, __, __, __, __, __,
		__, __, __, __, __, __, __, __, __, __,
		__, __, __, __, __, __, __, __, __, __,

		WW, WW, WW, WW, WW, WW, WW, WW, WW, WW,
		WW, M5, M5, M5, M5, M5, M5, M5, M5, WW,
		WW, __, __, __, __, __, __, __, __, WW,
		WW, __, __, __, __, __, __, __, __, WW,
		WW, __, __, __, __, __, __, __, __, WW,
		WW, __, __, __, __, __, __, __, __, WW,
		__, WW, T0, __, __, __, __, T0, WW, __,
		__, __, WW, __, __, __, __, WW, __, __,
		__, __, __, WW, __, __, WW, __, __, __,
		__, __, __, __, MS, MS, __, __, __, __,
		__, __, __, __, __, __, __, __, __, __,
		__, __, __, __, __, __, __, __, __, __,
		__, __, __, __, __, __, __, __, __, __,
		__, __, __, __, __, __, __, __, __, __,
		__, __, __, __, __, __, __, __, __, __,
		__, __, __, __, __, __, __, __, __, __,
		__, __, __, __, __, __, __, __, __, __,
		__, __, __, __, __, __, __, __, __, __,

		WW, WW, WW, WW, WW, WW, WW, WW, WW, WW,
		WW, M5, M5, M5, M5, M5, M5, M5, M5, WW,
		WW, __, __, __, __, __, __, __, __, WW,
		WW, __, __, __, __, __, __, __, __, WW,
		WW, __, __, __, __, __, __, __, __, WW,
		WW, __, __, __, __, __, __, __, __, WW,
		__, WW, T0, __, __, __, __, T0, WW, __,
		__, __, WW, __, __, __, __, WW, __, __,
		__, __, __, WW, __, __, WW, __, __, __,
		__, __, __, __, MS, MS, __, __, __, __,
		__, __, __, __, __, __, __, __, __, __,
		__, __, __, __, __, __, __, __, __, __,
		__, __, __, __, __, __, __, __, __, __,
		__, __, __, __, __, __, __, __, __, __,
		__, __, __, __, __, __, __, __, __, __,
		__, __, __, __, __, __, __, __, __, __,
		__, __, __, __, __, __, __, __, __, __,
		__, __, __, __, __, __, __, __, __, __,

		WW, WW, WW, WW, WW, WW, WW, WW, WW, WW,
		WW, M5, M5, M5, M5, M5, M5, M5, M5, WW,
		WW, __, __, __, __, __, __, __, __, WW,
		WW, __, __, __, __, __, __, __, __, WW,
		WW, __, __, __, __, __, __, __, __, WW,
		WW, __, __, __, __, __, __, __, __, WW,
		__, WW, T0, __, __, __, __, T0, WW, __,
		__, __, WW, __, __, __, __, WW, __, __,
		__, __, __, WW, __, __, WW, __, __, __,
		__, __, __, __, MS, MS, __, __, __, __,
		__, __, __, __, __, __, __, __, __, __,
		__, __, __, __, __, __, __, __, __, __,
		__, __, __, __, __, __, __, __, __, __,
		__, __, __, __, __, __, __, __, __, __,
		__, __, __, __, __, __, __, __, __, __,
		__, __, __, __, __, __, __, __, __, __,
		__, __, __, __, __, __, __, __, __, __,
		__, __, __, __, __, __, __, __, __, __,

		WW, WW, WW, WW, WW, WW, WW, WW, WW, WW,
		WW, FF, FF, __, FF, FF, __, FF, FF, WW,
		WW, __, __, __, M5, M5, __, __, __, WW,
		WW, T3, __, __, __, __, __, __, T2, WW,
		WW, __, __, __, __, __, __, __, __, WW,
		WW, __, __, __, __, __, __, __, __, WW,
		__, WW, T0, __, __, __, __, T0, WW, __,
		__, __, WW, __, __, __, __, WW, __, __,
		__, __, __, WW, __, __, WW, __, __, __,
		__, __, __, __, MS, MS, __, __, __, __,
		__, __, __, __, __, __, __, __, __, __,
		__, __, __, __, __, __, __, __, __, __,
		__, __, __, __, __, __, __, __, __, __,
		__, __, __, __, __, __, __, __, __, __,
		__, __, __, __, __, __, __, __, __, __,
		__, __, __, __, __, __, __, __, __, __,
		__, __, __, __, __, __, __, __, __, __,
		__, __, __, __, __, __, __, __, __, __,

		WW, WW, WW, WW, WW, WW, WW, WW, WW, WW,
		WW, __, __, __, __, __, __, __, __, WW,
		GG, __, __, __, __, __, __, __, __, GG,
		GG, __, __, __, __, __, __, __, __, GG,
		GG, __, __, __, __, __, __, __, __, GG,
		WW, __, __, __, __, __, __, __, __, WW,
		__, WW, T0, __, __, __, __, T0, WW, __,
		__, __, WW, __, __, __, __, WW, __, __,
		__, __, __, WW, __, __, WW, __, __, __,
		__, __, __, __, MS, MS, __, __, __, __,
		__, __, __, __, __, __, __, __, __, __,
		__, __, __, __, __, __, __, __, __, __,
		__, __, __, __, __, __, __, __, __, __,
		__, __, __, __, __, __, __, __, __, __,
		__, __, __, __, __, __, __, __, __, __,
		__, __, __, __, __, __, __, __, __, __,
		__, __, __, __, __, __, __, __, __, __,
		__, __, __, __, __, __, __, __, __, __,

		WW, WW, WW, WW, WW, WW, WW, WW, WW, WW,
		WW, S0, S0, S0, __, __, S0, S0, S0, WW,
		WW, __, __, __, __, __, __, __, __, WW,
		WW, T3, __, __, __, __, __, __, T2, WW,
		WW, __, __, __, __, __, __, __, __, WW,
		WW, __, __, __, __, __, __, __, __, WW,
		__, WW, T0, __, __, __, __, T0, WW, __,
		__, __, WW, __, __, __, __, WW, __, __,
		__, __, __, WW, __, __, WW, __, __, __,
		__, __, __, __, MS, MS, __, __, __, __,
		__, __, __, __, __, __, __, __, __, __,
		__, __, __, __, __, __, __, __, __, __,
		__, __, __, __, __, __, __, __, __, __,
		__, __, __, __, __, __, __, __, __, __,
		__, __, __, __, __, __, __, __, __, __,
		__, __, __, __, __, __, __, __, __, __,
		__, __, __, __, __, __, __, __, __, __,
		__, __, __, __, __, __, __, __, __, __,

		WW, WW, WW, WW, WW, WW, WW, WW, WW, WW,
		WW, __, __, __, __, __, __, __, __, WW,
		WW, __, __, __, __, __, __, __, __, WW,
		WW, T3, __, __, __, __, __, __, T2, WW,
		WW, __, __, __, __, __, __, __, __, WW,
		WW, __, __, __, __, __, __, __, __, WW,
		__, WW, T0, __, __, __, __, T0, WW, __,
		__, __, WW, __, __, __, __, WW, __, __,
		__, __, __, WW, __, __, WW, __, __, __,
		__, __, __, __, MS, MS, __, __, __, __,
		__, __, __, __, __, __, __, __, __, __,
		__, __, __, __, __, __, __, __, __, __,
		__, __, __, __, __, __, __, __, __, __,
		__, __, __, __, __, __, __, __, __, __,
		__, __, __, __, __, __, __, __, __, __,
		__, __, __, __, __, __, __, __, __, __,
		__, __, __, __, __, __, __, __, __, __,
		__, __, __, __, __, __, __, __, __, __,

		WW, WW, WW, WW, WW, WW, WW, WW, WW, WW,
		WW, S0, S0, S0, __, __, S0, S0, S0, WW,
		GG, __, __, __, __, __, __, __, __, GG,
		GG, __, __, __, __, __, __, __, __, GG,
		GG, __, __, __, __, __, __, __, __, GG,
		WW, __, __, __, __, __, __, __, __, WW,
		__, WW, T0, __, __, __, __, T0, WW, __,
		__, __, WW, __, __, __, __, WW, __, __,
		__, __, __, WW, __, __, WW, __, __, __,
		__, __, __, __, MS, MS, __, __, __, __,
		__, __, __, __, __, __, __, __, __, __,
		__, __, __, __, __, __, __, __, __, __,
		__, __, __, __, __, __, __, __, __, __,
		__, __, __, __, __, __, __, __, __, __,
		__, __, __, __, __, __, __, __, __, __,
		__, __, __, __, __, __, __, __, __, __,
		__, __, __, __, __, __, __, __, __, __,
		__, __, __, __, __, __, __, __, __, __,

		WW, WW, WW, WW, WW, WW, WW, WW, WW, WW,
		WW, __, __, __, __, __, __, __, __, WW,
		WW, __, __, __, __, __, __, __, __, WW,
		WW, T3, __, __, __, __, __, __, T2, WW,
		WW, __, __, __, __, __, __, __, __, WW,
		WW, __, __, __, __, __, __, __, __, WW,
		__, WW, T0, __, __, __, __, T0, WW, __,
		__, __, WW, __, __, __, __, WW, __, __,
		__, __, __, WW, __, __, WW, __, __, __,
		__, __, __, __, MS, MS, __, __, __, __,
		__, __, __, __, __, __, __, __, __, __,
		__, __, __, __, __, __, __, __, __, __,
		__, __, __, __, __, __, __, __, __, __,
		__, __, __, __, __, __, __, __, __, __,
		__, __, __, __, __, __, __, __, __, __,
		__, __, __, __, __, __, __, __, __, __,
		__, __, __, __, __, __, __, __, __, __,
		__, __, __, __, __, __, __, __, __, __,

		WW, WW, WW, WW, WW, WW, WW, WW, WW, WW,
		WW, S0, S0, S0, __, __, S0, S0, S0, WW,
		WW, __, __, __, __, __, __, __, __, WW,
		WW, T3, __, __, __, __, __, __, T2, WW,
		WW, __, __, __, __, __, __, __, __, WW,
		WW, __, __, __, __, __, __, __, __, WW,
		__, WW, T0, __, __, __, __, T0, WW, __,
		__, __, WW, __, __, __, __, WW, __, __,
		__, __, __, WW, __, __, WW, __, __, __,
		__, __, __, __, MS, MS, __, __, __, __,
		__, __, __, __, __, __, __, __, __, __,
		__, __, __, __, __, __, __, __, __, __,
		__, __, __, __, __, __, __, __, __, __,
		__, __, __, __, __, __, __, __, __, __,
		__, __, __, __, __, __, __, __, __, __,
		__, __, __, __, __, __, __, __, __, __,
		__, __, __, __, __, __, __, __, __, __,
		__, __, __, __, __, __, __, __, __, __,

		WW, WW, WW, WW, WW, WW, WW, WW, WW, WW,
		WW, __, __, __, __, __, __, __, __, WW,
		GG, __, __, __, __, __, __, __, __, GG,
		GG, __, __, __, __, __, __, __, __, GG,
		GG, __, __, __, __, __, __, __, __, GG,
		WW, __, __, __, __, __, __, __, __, WW,
		__, WW, T0, __, __, __, __, T0, WW, __,
		__, __, WW, __, __, __, __, WW, __, __,
		__, __, __, WW, __, __, WW, __, __, __,
		__, __, __, __, MS, MS, __, __, __, __,
		__, __, __, __, WW, WW, __, __, __, __,
		__, __, __, __, __, __, __, __, __, __,
		__, __, __, __, __, __, __, __, __, __,
		__, __, __, __, __, __, __, __, __, __,
		__, __, __, __, __, __, __, __, __, __,
		__, __, __, __, __, __, __, __, __, __,
		__, __, __, __, __, __, __, __, __, __,
		__, __, __, __, __, __, __, __, __, __,

		WW, WW, WW, WW, WW, WW, WW, WW, WW, WW,
		WW, S0, S0, S0, __, __, S0, S0, S0, WW,
		WW, __, __, __, __, __, __, __, __, WW,
		WW, T3, __, __, __, __, __, __, T2, WW,
		WW, __, __, __, __, __, __, __, __, WW,
		WW, __, __, __, __, __, __, __, __, WW,
		__, WW, T0, __, __, __, __, T0, WW, __,
		__, __, WW, __, __, __, __, WW, __, __,
		__, __, __, WW, __, __, WW, __, __, __,
		__, __, __, __, MS, MS, __, __, __, __,
		__, __, __, __, WW, WW, __, __, __, __,
		__, __, __, __, WW, WW, __, __, __, __,
		__, __, __, __, __, __, __, __, __, __,
		__, __, __, __, __, __, __, __, __, __,
		__, __, __, __, __, __, __, __, __, __,
		__, __, __, __, __, __, __, __, __, __,
		__, __, __, __, __, __, __, __, __, __,
		__, __, __, __, __, __, __, __, __, __,

		WW, WW, WW, WW, WW, WW, WW, WW, WW, WW,
		WW, BN, __, __, __, __, __, __, BN, WW,
		WW, BN, __, __, __, __, __, __, BN, WW,
		WW, C3, __, __, __, __, __, __, C1, WW,
		WW, __, __, __, __, __, __, __, __, WW,
		WW, __, __, __, __, __, __, __, __, WW,
		__, WW, T0, __, __, __, __, T0, WW, __,
		__, __, WW, __, __, __, __, WW, __, __,
		__, __, __, WW, __, __, WW, __, __, __,
		__, __, __, __, MS, MS, __, __, __, __,
		__, __, __, __, WW, WW, __, __, __, __,
		__, __, __, __, WW, WW, __, __, __, __,
		__, __, __, __, WW, WW, __, __, __, __,
		__, __, __, __, FF, FF, __, __, __, __,
		__, __, __, __, FF, FF, __, __, __, __,
		__, __, __, __, FF, FF, __, __, __, __,
		__, __, __, FF, FF, FF, FF, __, __, __,
		__, __, __, __, FF, FF, __, __, __, __,

		WW, WW, WW, WW, WW, WW, WW, WW, WW, WW,
		WW, BN, __, __, __, __, __, __, BN, WW,
		WW, BN, __, T4, __, __, T4, __, BN, WW,
		WW, C3, __, __, __, __, __, __, C1, WW,
		WW, __, __, __, T4, T4, __, __, __, WW,
		WW, __, __, __, __, __, __, __, __, WW,
		__, WW, T0, __, __, __, __, T0, WW, __,
		__, __, WW, __, __, __, __, WW, __, __,
		__, __, __, WW, __, __, WW, __, __, __,
		__, __, __, __, MS, MS, __, __, __, __,
		__, __, __, __, WW, WW, __, __, __, __,
		__, __, __, __, WW, WW, __, __, __, __,
		__, __, __, __, __, __, __, __, __, __,
		__, __, __, __, __, __, __, __, __, __,
		__, __, __, __, __, __, __, __, __, __,
		__, __, __, __, __, __, __, __, __, __,
		__, __, __, __, T5, T5, __, __, __, __,
		__, __, __, __, __, __, __, __, __, __,

		M2, WW, WW, WW, WW, WW, WW, WW, WW, M2,
		M0, WW, WW, WW, D2, D2, WW, WW, WW, M1,
		M0, WW, WW, WW, __, __, WW, WW, WW, M1,
		M0, WW, WW, WW, WW, WW, WW, WW, WW, M1,
		M0, WW, WW, WW, WW, WW, WW, WW, WW, M1,
		M0, WW, WW, WW, WW, WW, WW, WW, WW, M1,
		__, WW, WW, WW, WW, WW, WW, WW, WW, __,
		__, __, WW, WW, WW, WW, WW, WW, __, __,
		__, __, __, WW, WW, WW, WW, __, __, __,
		__, __, __, __, MN, MN, __, __, __, __,
		__, __, __, __, WW, WW, __, __, __, __,
		__, __, __, __, __, __, __, __, __, __,
		__, __, __, __, __, __, __, __, __, __,
		__, __, __, __, __, __, __, __, __, __,
		__, __, __, __, __, __, __, __, __, __,
		__, __, __, __, __, __, __, __, __, __,
		__, __, __, __, __, __, __, __, __, __,
		__, __, __, __, __, __, __, __, __, __,

		__, __, __, __, M7, M7, __, __, __, __,
		__, __, __, __, __, __, __, __, __, __,
		__, __, __, T5, __, __, T5, __, __, __,
		__, __, __, __, __, __, __, __, __, __,
		__, __, __, __, __, __, __, __, __, __,
		__, __, __, __, __, __, __, __, __, __,
		__, __, __, __, H0, H0, __, __, __, __,
		__, __, __, __, __, __, __, __, __, __,
		__, __, __, __, __, __, __, __, __, __,
		__, __, __, __, __, __, __, __, __, __,
		__, __, __, __, __, __, __, __, __, __,
		__, __, __, __, __, __, __, __, __, __,
		__, __, __, __, __, __, __, __, __, __,
		__, __, __, __, __, __, __, __, __, __,
		__, __, __, __, __, __, __, __, __, __,
		__, __, __, __, __, __, __, __, __, __,
		__, __, __, __, __, __, __, __, __, __,
		__, __, __, __, __, __, __, __, __, __
	},
	yslice_prob = {
		{ypos = 0,prob = 254},
		{ypos = 1,prob = 254},
		{ypos = 2,prob = 254},
		{ypos = 3,prob = 254},
		{ypos = 4,prob = 254},
		{ypos = 5,prob = 254},
		{ypos = 6,prob = 254},
		{ypos = 7,prob = 254},
		{ypos = 8,prob = 254},
		{ypos = 9,prob = 254},
		{ypos = 10,prob = 254},
		{ypos = 11,prob = 254},
		{ypos = 12,prob = 254},
		{ypos = 13,prob = 254},
		{ypos = 14,prob = 254},
		{ypos = 15,prob = 254},
		{ypos = 16,prob = 254},
		{ypos = 17,prob = 254}
	}
}
lib_towns.schematics["schem_ruin_church_x10_y18_z18_r000"] = le_temp_schem

le_temp_schem = {
	size = {x = 10,y = 18,z = 18},
	data = {
		M2, WW, WW, WW, WW, WW, WW, WW, WW, M3,
		__, __, WW, WW, WW, WW, WW, __, WW, M2,
		M2, WW, WW, WW, WW, WW, WW, WW, WW, M2,
		__, WW, WW, WW, GG, GG, WW, WW, __, M2,
		M2, WW, __, WW, GG, GG, WW, __, WW, M2,
		__, __, __, WW, GG, GG, WW, WW, WW, M2,
		__, __, __, GG, GG, GG, GG, WW, __, __,
		__, __, __, WW, GG, GG, __, WW, __, __,
		__, __, __, __, WW, __, __, __, __, __,
		__, __, __, __, __, __, __, __, __, __,
		__, __, __, __, __, __, __, __, __, __,
		__, __, __, __, __, __, __, __, __, __,
		__, __, __, __, __, __, __, __, __, __,
		__, __, __, __, __, __, __, __, __, __,
		__, __, __, __, __, __, __, __, __, __,
		__, __, __, __, __, __, __, __, __, __,
		__, __, __, __, __, __, __, __, __, __,
		__, __, __, __, __, __, __, __, __, MC,

		WW, WW, WW, WW, WW, WW, WW, WW, WW, WW,
		WW, M7, M7, M7, M7, M7, M7, M7, M7, WW,
		__, __, __, __, __, __, __, __, __, WW,
		WW, __, __, __, __, __, __, __, __, WW,
		WW, __, __, __, __, __, __, __, __, WW,
		WW, __, __, __, __, __, __, __, __, __,
		__, __, __, __, __, __, __, __, __, __,
		__, __, __, __, __, __, __, __, __, __,
		__, __, __, __, __, __, __, __, __, __,
		__, __, __, __, __, __, __, __, __, __,
		__, __, __, __, __, __, __, __, __, __,
		__, __, __, __, __, __, __, __, __, __,
		__, __, __, __, __, __, __, __, __, __,
		__, __, __, __, __, __, __, __, __, __,
		__, __, __, __, __, __, __, __, __, __,
		__, __, __, __, __, __, __, __, __, __,
		__, __, __, __, __, __, __, __, __, __,
		__, __, __, __, __, __, __, __, __, __,

		WW, WW, WW, WW, WW, WW, WW, WW, WW, WW,
		WW, M5, __, __, M5, M5, M5, __, M5, WW,
		WW, __, __, __, __, __, __, __, __, WW,
		WW, __, __, __, __, __, __, __, __, __,
		__, __, __, __, __, __, __, __, __, __,
		__, __, __, __, __, __, __, __, __, __,
		__, __, __, __, __, __, __, __, __, __,
		__, __, __, __, __, __, __, __, __, __,
		__, __, __, __, __, __, __, __, __, __,
		__, __, __, __, __, __, __, __, __, __,
		__, __, __, __, __, __, __, __, __, __,
		__, __, __, __, __, __, __, __, __, __,
		__, __, __, __, __, __, __, __, __, __,
		__, __, __, __, __, __, __, __, __, __,
		__, __, __, __, __, __, __, __, __, __,
		__, __, __, __, __, __, __, __, __, __,
		__, __, __, __, __, __, __, __, __, __,
		__, __, __, __, __, __, __, __, __, __,

		WW, WW, WW, WW, WW, WW, WW, WW, WW, WW,
		__, M5, M5, M5, M5, __, M5, M5, M5, WW,
		WW, __, __, __, __, __, __, __, __, WW,
		WW, __, __, __, __, __, __, __, __, WW,
		WW, __, __, __, __, __, __, __, __, WW,
		__, __, __, __, __, __, __, __, __, __,
		__, __, __, __, __, __, __, __, __, __,
		__, __, __, __, __, __, __, __, __, __,
		__, __, __, __, __, __, __, __, __, __,
		__, __, __, __, __, __, __, __, __, __,
		__, __, __, __, __, __, __, __, __, __,
		__, __, __, __, __, __, __, __, __, __,
		__, __, __, __, __, __, __, __, __, __,
		__, __, __, __, __, __, __, __, __, __,
		__, __, __, __, __, __, __, __, __, __,
		__, __, __, __, __, __, __, __, __, __,
		__, __, __, __, __, __, __, __, __, __,
		__, __, __, __, __, __, __, __, __, __,

		WW, WW, WW, WW, WW, WW, WW, WW, WW, WW,
		WW, M5, __, M5, M5, M5, M5, __, M5, __,
		WW, __, __, __, __, __, __, __, __, WW,
		__, __, __, __, __, __, __, __, __, WW,
		__, __, __, __, __, __, __, __, __, WW,
		__, __, __, __, __, __, __, __, __, WW,
		__, __, __, __, __, __, __, __, __, __,
		__, __, __, __, __, __, __, __, __, __,
		__, __, __, __, __, __, __, __, __, __,
		__, __, __, __, __, __, __, __, __, __,
		__, __, __, __, __, __, __, __, __, __,
		__, __, __, __, __, __, __, __, __, __,
		__, __, __, __, __, __, __, __, __, __,
		__, __, __, __, __, __, __, __, __, __,
		__, __, __, __, __, __, __, __, __, __,
		__, __, __, __, __, __, __, __, __, __,
		__, __, __, __, __, __, __, __, __, __,
		__, __, __, __, __, __, __, __, __, __,

		WW, WW, WW, WW, WW, WW, WW, WW, WW, WW,
		WW, FF, FF, __, FF, FF, __, FF, __, WW,
		WW, __, __, __, M5, __, __, __, __, WW,
		WW, __, __, __, __, __, __, __, __, WW,
		WW, __, __, __, __, __, __, __, __, __,
		WW, __, __, __, __, __, __, __, __, __,
		__, __, __, __, __, __, __, __, __, __,
		__, __, __, __, __, __, __, __, __, __,
		__, __, __, __, __, __, __, __, __, __,
		__, __, __, __, __, __, __, __, __, __,
		__, __, __, __, __, __, __, __, __, __,
		__, __, __, __, __, __, __, __, __, __,
		__, __, __, __, __, __, __, __, __, __,
		__, __, __, __, __, __, __, __, __, __,
		__, __, __, __, __, __, __, __, __, __,
		__, __, __, __, __, __, __, __, __, __,
		__, __, __, __, __, __, __, __, __, __,
		__, __, __, __, __, __, __, __, __, __,

		WW, WW, __, WW, WW, WW, WW, WW, WW, WW,
		WW, __, __, __, __, __, __, __, __, WW,
		GG, __, __, __, __, __, __, __, __, __,
		GG, __, __, __, __, __, __, __, __, __,
		GG, __, __, __, __, __, __, __, __, GG,
		__, __, __, __, __, __, __, __, __, __,
		__, __, __, __, __, __, __, __, __, __,
		__, __, __, __, __, __, __, __, __, __,
		__, __, __, __, __, __, __, __, __, __,
		__, __, __, __, __, __, __, __, __, __,
		__, __, __, __, __, __, __, __, __, __,
		__, __, __, __, __, __, __, __, __, __,
		__, __, __, __, __, __, __, __, __, __,
		__, __, __, __, __, __, __, __, __, __,
		__, __, __, __, __, __, __, __, __, __,
		__, __, __, __, __, __, __, __, __, __,
		__, __, __, __, __, __, __, __, __, __,
		__, __, __, __, __, __, __, __, __, __,

		WW, WW, WW, WW, WW, WW, WW, WW, WW, WW,
		WW, S0, __, S0, __, __, __, S0, __, WW,
		WW, __, __, __, __, __, __, __, __, WW,
		WW, __, __, __, __, __, __, __, __, WW,
		__, __, __, __, __, __, __, __, __, WW,
		__, __, __, __, __, __, __, __, __, WW,
		__, __, __, __, __, __, __, __, __, __,
		__, __, __, __, __, __, __, __, __, __,
		__, __, __, __, __, __, __, __, __, __,
		__, __, __, __, __, __, __, __, __, __,
		__, __, __, __, __, __, __, __, __, __,
		__, __, __, __, __, __, __, __, __, __,
		__, __, __, __, __, __, __, __, __, __,
		__, __, __, __, __, __, __, __, __, __,
		__, __, __, __, __, __, __, __, __, __,
		__, __, __, __, __, __, __, __, __, __,
		__, __, __, __, __, __, __, __, __, __,
		__, __, __, __, __, __, __, __, __, __,

		WW, WW, WW, WW, WW, WW, WW, WW, WW, WW,
		WW, __, __, __, __, __, __, __, __, WW,
		WW, __, __, __, __, __, __, __, __, WW,
		WW, __, __, __, __, __, __, __, __, WW,
		WW, __, __, __, __, __, __, __, __, __,
		__, __, __, __, __, __, __, __, __, __,
		__, __, __, __, __, __, __, __, __, __,
		__, __, __, __, __, __, __, __, __, __,
		__, __, __, __, __, __, __, __, __, __,
		__, __, __, __, __, __, __, __, __, __,
		__, __, __, __, __, __, __, __, __, __,
		__, __, __, __, __, __, __, __, __, __,
		__, __, __, __, __, __, __, __, __, __,
		__, __, __, __, __, __, __, __, __, __,
		__, __, __, __, __, __, __, __, __, __,
		__, __, __, __, __, __, __, __, __, __,
		__, __, __, __, __, __, __, __, __, __,
		__, __, __, __, __, __, __, __, __, __,

		WW, WW, WW, WW, WW, __, WW, WW, WW, WW,
		WW, S0, S0, __, __, __, __, S0, S0, WW,
		__, __, __, __, __, __, __, __, __, GG,
		__, __, __, __, __, __, __, __, __, __,
		__, __, __, __, __, __, __, __, __, __,
		WW, __, __, __, __, __, __, __, __, WW,
		__, WW, __, __, __, __, __, __, __, __,
		__, __, __, __, __, __, __, __, __, __,
		__, __, __, WW, __, __, __, __, __, __,
		__, __, __, __, __, __, __, __, __, __,
		__, __, __, __, __, __, __, __, __, __,
		__, __, __, __, __, __, __, __, __, __,
		__, __, __, __, __, __, __, __, __, __,
		__, __, __, __, __, __, __, __, __, __,
		__, __, __, __, __, __, __, __, __, __,
		__, __, __, __, __, __, __, __, __, __,
		__, __, __, __, __, __, __, __, __, __,
		__, __, __, __, __, __, __, __, __, __,

		WW, WW, WW, WW, WW, WW, WW, WW, WW, WW,
		WW, __, __, __, __, __, __, __, __, __,
		WW, __, __, __, __, __, __, __, __, WW,
		__, __, __, __, __, __, __, __, __, __,
		WW, __, __, __, __, __, __, __, __, WW,
		WW, __, __, __, __, __, __, __, __, WW,
		__, __, __, __, __, __, __, __, __, __,
		__, __, WW, __, __, __, __, __, __, __,
		__, __, __, __, __, __, WW, __, __, __,
		__, __, __, __, __, __, __, __, __, __,
		__, __, __, __, __, __, __, __, __, __,
		__, __, __, __, __, __, __, __, __, __,
		__, __, __, __, __, __, __, __, __, __,
		__, __, __, __, __, __, __, __, __, __,
		__, __, __, __, __, __, __, __, __, __,
		__, __, __, __, __, __, __, __, __, __,
		__, __, __, __, __, __, __, __, __, __,
		__, __, __, __, __, __, __, __, __, __,

		WW, __, WW, WW, __, WW, WW, WW, WW, __,
		WW, __, __, __, __, __, S0, S0, __, WW,
		WW, __, __, __, __, __, __, __, __, WW,
		WW, __, __, __, __, __, __, __, __, __,
		WW, __, __, __, __, __, __, __, __, __,
		WW, __, __, __, __, __, __, __, __, __,
		__, WW, __, __, __, __, __, __, __, __,
		__, __, WW, __, __, __, __, WW, __, __,
		__, __, __, WW, __, __, WW, __, __, __,
		__, __, __, __, __, __, __, __, __, __,
		__, __, __, __, __, __, __, __, __, __,
		__, __, __, __, __, __, __, __, __, __,
		__, __, __, __, __, __, __, __, __, __,
		__, __, __, __, __, __, __, __, __, __,
		__, __, __, __, __, __, __, __, __, __,
		__, __, __, __, __, __, __, __, __, __,
		__, __, __, __, __, __, __, __, __, __,
		__, __, __, __, __, __, __, __, __, __,

		WW, WW, WW, WW, WW, WW, WW, WW, WW, WW,
		WW, __, __, __, __, __, __, __, __, WW,
		__, __, __, __, __, __, __, __, __, GG,
		__, __, __, __, __, __, __, __, __, __,
		__, __, __, __, __, __, __, __, __, GG,
		WW, __, __, __, __, __, __, __, __, WW,
		__, __, __, __, __, __, __, __, WW, __,
		__, __, WW, __, __, __, __, WW, __, __,
		__, __, __, WW, __, __, WW, __, __, __,
		__, __, __, __, MS, MS, __, __, __, __,
		__, __, __, __, WW, WW, __, __, __, __,
		__, __, __, __, __, __, __, __, __, __,
		__, __, __, __, __, __, __, __, __, __,
		__, __, __, __, __, __, __, __, __, __,
		__, __, __, __, __, __, __, __, __, __,
		__, __, __, __, __, __, __, __, __, __,
		__, __, __, __, __, __, __, __, __, __,
		__, __, __, __, __, __, __, __, __, __,

		WW, WW, WW, WW, WW, WW, WW, WW, WW, WW,
		WW, __, S0, S0, __, __, S0, __, S0, WW,
		WW, __, __, __, __, __, __, __, __, WW,
		WW, __, __, __, __, __, __, __, __, WW,
		WW, __, __, __, __, __, __, __, __, WW,
		WW, __, __, __, __, __, __, __, __, WW,
		__, WW, __, __, __, __, __, __, WW, __,
		__, __, __, __, __, __, __, WW, __, __,
		__, __, __, WW, __, __, __, __, __, __,
		__, __, __, __, MS, MS, __, __, __, __,
		__, __, __, __, WW, WW, __, __, __, __,
		__, __, __, __, WW, WW, __, __, __, __,
		__, __, __, __, __, __, __, __, __, __,
		__, __, __, __, __, __, __, __, __, __,
		__, __, __, __, __, __, __, __, __, __,
		__, __, __, __, __, __, __, __, __, __,
		__, __, __, __, __, __, __, __, __, __,
		__, __, __, __, __, __, __, __, __, __,

		WW, WW, WW, WW, WW, WW, WW, WW, WW, WW,
		WW, __, __, __, __, __, __, __, __, WW,
		__, __, __, __, __, __, __, __, __, WW,
		WW, __, __, __, __, __, __, __, __, __,
		WW, __, __, __, __, __, __, __, __, WW,
		__, __, __, __, __, __, __, __, __, WW,
		__, WW, __, __, __, __, __, __, WW, __,
		__, __, WW, __, __, __, __, WW, __, __,
		__, __, __, WW, __, __, WW, __, __, __,
		__, __, __, __, __, MS, __, __, __, __,
		__, __, __, __, WW, WW, __, __, __, __,
		__, __, __, __, WW, WW, __, __, __, __,
		__, __, __, __, WW, WW, __, __, __, __,
		__, __, __, __, FF, FF, __, __, __, __,
		__, __, __, __, FF, FF, __, __, __, __,
		__, __, __, __, FF, FF, __, __, __, __,
		__, __, __, FF, FF, FF, FF, __, __, __,
		__, __, __, __, FF, FF, __, __, __, __,

		WW, WW, WW, WW, WW, WW, WW, WW, WW, WW,
		WW, __, __, __, __, __, __, __, __, WW,
		__, __, __, __, __, __, __, __, __, __,
		__, __, __, __, __, __, __, __, __, WW,
		WW, __, __, __, __, __, __, __, __, WW,
		WW, __, __, __, __, __, __, __, __, __,
		__, WW, __, __, __, __, __, __, __, __,
		__, __, WW, __, __, __, __, __, __, __,
		__, __, __, WW, __, __, WW, __, __, __,
		__, __, __, __, MS, MS, __, __, __, __,
		__, __, __, __, WW, WW, __, __, __, __,
		__, __, __, __, WW, WW, __, __, __, __,
		__, __, __, __, __, __, __, __, __, __,
		__, __, __, __, __, __, __, __, __, __,
		__, __, __, __, __, __, __, __, __, __,
		__, __, __, __, __, __, __, __, __, __,
		__, __, __, __, __, __, __, __, __, __,
		__, __, __, __, __, __, __, __, __, __,

		M2, WW, __, WW, WW, WW, WW, WW, WW, __,
		M0, WW, WW, WW, __, D2, WW, WW, WW, __,
		__, WW, WW, WW, __, __, WW, WW, __, __,
		M0, WW, __, WW, WW, WW, WW, WW, WW, __,
		M0, WW, __, WW, WW, WW, __, WW, WW, __,
		M0, WW, __, WW, __, WW, __, WW, WW, __,
		__, WW, WW, WW, WW, WW, WW, WW, WW, __,
		__, __, WW, WW, WW, WW, WW, WW, __, __,
		__, __, __, WW, WW, WW, WW, __, __, __,
		__, __, __, __, MN, MN, __, __, __, __,
		__, __, __, __, WW, WW, __, __, __, __,
		__, __, __, __, __, __, __, __, __, __,
		__, __, __, __, __, __, __, __, __, __,
		__, __, __, __, __, __, __, __, __, __,
		__, __, __, __, __, __, __, __, __, __,
		__, __, __, __, __, __, __, __, __, __,
		__, __, __, __, __, __, __, __, __, __,
		__, __, __, __, __, __, __, __, __, __,

		__, __, __, __, M7, M7, __, __, __, __,
		__, __, __, __, __, __, __, __, __, __,
		__, __, __, __, __, __, __, __, __, __,
		__, __, __, __, __, __, __, __, __, __,
		__, __, __, __, __, __, __, __, __, __,
		__, __, __, __, __, __, __, __, __, __,
		__, __, __, __, __, __, __, __, __, __,
		__, __, __, __, __, __, __, __, __, __,
		__, __, __, __, __, __, __, __, __, __,
		__, __, __, __, __, __, __, __, __, __,
		__, __, __, __, __, __, __, __, __, __,
		__, __, __, __, __, __, __, __, __, __,
		__, __, __, __, __, __, __, __, __, __,
		__, __, __, __, __, __, __, __, __, __,
		__, __, __, __, __, __, __, __, __, __,
		__, __, __, __, __, __, __, __, __, __,
		__, __, __, __, __, __, __, __, __, __,
		__, __, __, __, __, __, __, __, __, __
	},
	yslice_prob = {
		{ypos = 0,prob = 254},
		{ypos = 1,prob = 254},
		{ypos = 2,prob = 254},
		{ypos = 3,prob = 254},
		{ypos = 4,prob = 254},
		{ypos = 5,prob = 254},
		{ypos = 6,prob = 254},
		{ypos = 7,prob = 254},
		{ypos = 8,prob = 254},
		{ypos = 9,prob = 254},
		{ypos = 10,prob = 254},
		{ypos = 11,prob = 254},
		{ypos = 12,prob = 254},
		{ypos = 13,prob = 254},
		{ypos = 14,prob = 254},
		{ypos = 15,prob = 254},
		{ypos = 16,prob = 254},
		{ypos = 17,prob = 254}
	}
}
lib_towns.schematics["schem_ruin_church_old_x10_y18_z18_r000"] = le_temp_schem

le_temp_schem = {
	size = {x = 4,y = 11,z = 4},
	data = {
		DD, DD, DD, DD,
		CC, CC, CC, CC,
		CC, CC, CC, CC,
		CC, CC, CC, CC,
		CC, CC, CC, CC,
		CC, CC, CC, CC,
		CC, CC, CC, CC,
		CC, CC, CC, CC,
		CC, CC, CC, CC,
		FF, FF, FF, FF,
		T1, __, __, T1,

		DD, DD, DD, DD,
		CC, L5, __, CC,
		CC, L5, __, CC,
		CC, L5, __, CC,
		CC, L5, CC, CC,
		CC, L5, __, CC,
		GG, L5, T5, GG,
		CC, L5, __, CC,
		CC, L5, CC, CC,
		FF, __, __, FF,
		__, __, __, __,

		DD, DD, DD, DD,
		CC, __, __, CC,
		CC, T4, __, CC,
		CC, __, __, CC,
		CC, CC, CC, CC,
		CC, __, __, CC,
		GG, __, __, GG,
		CC, __, __, CC,
		CC, CC, CC, CC,
		FF, __, __, FF,
		__, __, __, __,

		DD, DD, DD, DD,
		CC, CC, D2, CC,
		CC, CC, __, CC,
		CC, CC, CC, CC,
		CC, CC, CC, CC,
		CC, CC, CC, CC,
		CC, GG, GG, CC,
		CC, CC, CC, CC,
		CC, CC, CC, CC,
		FF, FF, FF, FF,
		T1, __, __, T1
	},
	yslice_prob = {
		{ypos = 0,prob = 254},
		{ypos = 1,prob = 254},
		{ypos = 2,prob = 254},
		{ypos = 3,prob = 254},
		{ypos = 4,prob = 254},
		{ypos = 5,prob = 254},
		{ypos = 6,prob = 254},
		{ypos = 7,prob = 254},
		{ypos = 8,prob = 254},
		{ypos = 9,prob = 254}
	}
}
lib_towns.schematics["schem_ruin_watchtower_x4_y10_z4_r000"] = le_temp_schem

le_temp_schem = {
	size = {x = 4,y = 10,z = 4},
	data = {
		DD, DD, DD, DD,
		MC, MC, MC, __,
		__, MC, MC, MC,
		MC, MC, MC, MC,
		MC, __, MC, MC,
		MC, MC, MC, MC,
		MC, MC, MC, __,
		MC, MC, MC, MC,
		__, MC, MC, MC,
		__, FF, FF, FF,

		DD, DD, DD, DD,
		MC, L5, __, MC,
		MC, L5, __, MC,
		MC, L5, __, MC,
		__, __, MC, MC,
		MC, L5, __, MC,
		__, L5, __, __,
		MC, __, __, MC,
		MC, L5, MC, MC,
		FF, __, __, FF,

		DD, DD, DD, DD,
		MC, __, __, MC,
		MC, __, __, MC,
		MC, __, __, __,
		MC, MC, MC, MC,
		MC, __, __, MC,
		GG, __, __, __,
		MC, __, __, __,
		MC, MC, MC, MC,
		FF, __, __, FF,

		DD, DD, DD, DD,
		MC, MC, D2, __,
		__, MC, __, MC,
		__, MC, MC, MC,
		MC, MC, __, MC,
		MC, MC, MC, MC,
		__, __, __, MC,
		__, MC, MC, MC,
		MC, MC, MC, MC,
		FF, FF, FF, FF
	},
	yslice_prob = {
		{ypos = 0,prob = 254},
		{ypos = 1,prob = 254},
		{ypos = 2,prob = 254},
		{ypos = 3,prob = 254},
		{ypos = 4,prob = 254},
		{ypos = 5,prob = 254},
		{ypos = 6,prob = 254},
		{ypos = 7,prob = 254},
		{ypos = 8,prob = 254}
	}
}
lib_towns.schematics["schem_ruin_watchtower_old_x4_y9_z4_r000"] = le_temp_schem

le_temp_schem = {
	size = {x = 4,y = 10,z = 4},
	data = {
		DD, DD, DD, DD,
		__, __, MC, __,
		__, __, __, __,
		__, __, __, __,
		__, __, __, __,
		__, __, __, __,
		CC, __, CC, __,
		__, __, FF, __,
		__, __, WW, __,
		__, __, __, __,

		DD, DD, DD, DD,
		CC, __, __, __,
		__, MC, CC, __,
		__, CC, MC, __,
		__, __, MC, __,
		__, MC, CC, __,
		CC, CC, __, CC,
		FF, T0, __, __,
		WW, __, __, WW,
		__, __, __, __,

		DD, DD, DD, DD,
		CC, __, __, __,
		__, CC, __, __,
		__, __, MC, __,
		__, __, __, __,
		__, CC, __, __,
		CC, MC, __, CC,
		FF, __, __, __,
		WW, __, __, WW,
		__, WW, WW, __,

		DD, DD, DD, DD,
		__, MC, MC, __,
		__, __, __, __,
		__, __, __, __,
		__, __, __, __,
		__, __, __, __,
		CC, __, __, CC,
		__, __, __, FF,
		__, WW, WW, WW,
		__, __, __, __
	},
	yslice_prob = {
		{ypos = 0,prob = 254},
		{ypos = 1,prob = 254},
		{ypos = 2,prob = 254},
		{ypos = 3,prob = 254},
		{ypos = 4,prob = 254},
		{ypos = 5,prob = 254},
		{ypos = 6,prob = 254},
		{ypos = 7,prob = 254},
		{ypos = 8,prob = 254}
	}
}
lib_towns.schematics["schem_ruin_watchtower_ruin_x4_y9_z4_r000"] = le_temp_schem

le_temp_schem = {
	size = {x = 4,y = 10,z = 4},
	data = {
		DD, DD, DD, DD,
		__, CC, CC, __,
		__, __, __, __,
		__, __, __, __,
		__, __, __, __,
		__, __, __, __,
		CC, CC, CC, CC,
		FF, FF, FF, FF,
		WW, WW, WW, WW,
		__, __, __, __,

		DD, DD, DD, DD,
		CC, __, __, CC,
		__, CC, CC, __,
		__, CC, CC, __,
		__, CC, CC, __,
		__, CC, CC, __,
		CC, CC, CC, CC,
		FF, T0, T0, FF,
		WW, WW, WW, WW,
		__, WW, WW, __,

		DD, DD, DD, DD,
		CC, __, __, CC,
		__, CC, CC, __,
		__, CC, CC, __,
		__, CC, CC, __,
		__, CC, CC, __,
		CC, CC, CC, CC,
		FF, T0, T0, FF,
		WW, WW, WW, WW,
		__, WW, WW, __,

		DD, DD, DD, DD,
		__, CC, CC, __,
		__, __, __, __,
		__, __, __, __,
		__, __, __, __,
		__, __, __, __,
		CC, CC, CC, CC,
		FF, FF, FF, FF,
		WW, WW, WW, WW,
		__, __, __, __
	},
	yslice_prob = {
		{ypos = 0,prob = 254},
		{ypos = 1,prob = 254},
		{ypos = 2,prob = 254},
		{ypos = 3,prob = 254},
		{ypos = 4,prob = 254},
		{ypos = 5,prob = 254},
		{ypos = 6,prob = 254},
		{ypos = 7,prob = 254},
		{ypos = 8,prob = 254}
	}
}
lib_towns.schematics["schem_ruin_watchtower2_x4_y9_z4_r000"] = le_temp_schem

le_temp_schem = {
	size = {x = 8,y = 5,z = 6},
	data = {
		M0, WW, WW, __, __, WW, WW, M0,
		M0, GG, M0, __, __, M0, GG, M0,
		M0, WW, WW, WW, WW, WW, WW, M0,
		WW, WW, WW, WW, WW, WW, WW, WW,
		__, __, __, __, __, __, __, __,

		WW, __, __, __, __, __, __, WW,
		WW, __, __, __, __, __, __, WW,
		WW, __, __, __, __, __, __, WW,
		WW, __, __, __, __, __, __, WW,
		__, WW, WW, WW, WW, WW, WW, __,

		WW, __, __, __, __, __, __, WW,
		GG, __, __, __, __, __, __, GG,
		WW, __, __, __, __, __, __, WW,
		WW, __, __, __, __, __, __, WW,
		__, WW, WW, WW, WW, WW, WW, __,

		WW, __, __, __, __, __, __, WW,
		GG, __, __, __, __, __, __, GG,
		WW, __, __, __, __, __, __, WW,
		WW, __, __, __, __, __, __, WW,
		__, WW, WW, WW, WW, WW, WW, __,

		WW, __, __, __, __, __, __, WW,
		WW, __, __, __, __, __, __, WW,
		WW, __, __, __, __, __, __, WW,
		WW, __, __, __, __, __, __, WW,
		__, WW, WW, WW, WW, WW, WW, __,

		M0, WW, WW, WW, WW, WW, WW, M0,
		M0, WW, GG, WW, WW, GG, WW, M0,
		M0, WW, WW, WW, WW, WW, WW, M0,
		WW, WW, WW, WW, WW, WW, WW, WW,
		__, __, __, __, __, __, __, __
	},
	yslice_prob = {
		{ypos = 0,prob = 254},
		{ypos = 1,prob = 254},
		{ypos = 2,prob = 254},
		{ypos = 3,prob = 254},
		{ypos = 4,prob = 254}
	}
}
lib_towns.schematics["schem_ruin_wooden_house_x8_y5_z6_r000"] = le_temp_schem
	
		
		
		
		
		
		
		