

--Air, Lava, and Water constants used throughout schematics
		local __ = {name = "air", param2 = 0, prob = 0}
		local wt = {name = "lib_materials:liquid_water_river_source", param2 = 0, prob = 254}
		local lv = {name = "lib_materials:liquid_lava_source", param2 = 0, prob = 254}
		local lf = {name = "lib_materials:liquid_lava_flowing", param2 = 0, prob = 254}
		
--Node Definitions
		local M0 = {name = "lib_materials:stone", param2 = 0, prob = 254}
		local M1 = {name = "lib_materials:stone_cobble", param2 = 0, prob = 254}
		local M2 = {name = "lib_materials:stone_brick", param2 = 0, prob = 254}
		local M3 = {name = "lib_materials:stone_block", param2 = 0, prob = 254}
		local M4 = {name = "lib_materials:stone_stucco", param2 = 0, prob = 254}
		local M5 = {name = "stairs:slab_stonebrick", param2 = 3, prob = 254}
		local M6 = {name = "stairs:stair_cobble", param2 = 0, prob = 254}
		local M7 = {name = "stairs:slab_stonebrick", param2 = 0, prob = 254}
		local M8 = {name = "", param2 = 0, prob = 254}
		local M9 = {name = "", param2 = 0, prob = 254}
		local MX = {name = "", param2 = 4, prob = 254}
		local MZ = {name = "", param2 = 8, prob = 254}

		local N0 = {name = "lib_materials:stone_sand", param2 = 0, prob = 254}
		local N1 = {name = "lib_materials:sand", param2 = 0, prob = 254}
		local N2 = {name = "lib_materials:stone_gravel", param2 = 0, prob = 254}
		local N3 = {name = "lib_materials:stone_cobble_mossy", param2 = 0, prob = 254}
		local N4 = {name = "lib_materials:stone_brick_mossy", param2 = 0, prob = 254}
		local N5 = {name = "lib_materials:stone_tile", param2 = 0, prob = 254}
		local N6 = {name = "lib_materials:stone_tile_with_dirt", param2 = 0, prob = 254}
		local N7 = {name = "lib_materials:stone_tile_mossy", param2 = 0, prob = 254}
		local N8 = {name = "lib_materials:stone_tile_crumbled", param2 = 0, prob = 254}
		local N9 = {name = "lib_ecology:tree_default_wood", param2 = 0, prob = 254}
		local NY = {name = "lib_ecology:tree_default_trunk", param2 = 0, prob = 254}
		local NZ = {name = "lib_ecology:tree_default_trunk", param2 = 4, prob = 254}
		local NX = {name = "lib_ecology:tree_default_trunk", param2 = 8, prob = 254}

		local S0 = {name = "lib_materials:stone_cobble_stairs", param2 = 0, prob = 254}
		local S1 = {name = "lib_materials:stone_cobble_stairs", param2 = 1, prob = 254}
		local S2 = {name = "lib_materials:stone_cobble_stairs", param2 = 2, prob = 254}
		local S3 = {name = "lib_materials:stone_cobble_stairs", param2 = 3, prob = 254}
		local S5 = {name = "lib_materials:stone_cobble_stairs", param2 = 20, prob = 254}
		local S6 = {name = "lib_materials:stone_cobble_stairs", param2 = 21, prob = 254}
		local S7 = {name = "lib_materials:stone_cobble_stairs", param2 = 22, prob = 254}
		local S8 = {name = "lib_materials:stone_cobble_stairs", param2 = 23, prob = 254}
		local SN = {name = "lib_materials:stone_cobble_stairs", param2 = 4, prob = 254}
		local SE = {name = "lib_materials:stone_cobble_stairs", param2 = 8, prob = 254}
		local SW = {name = "lib_materials:stone_cobble_stairs", param2 = 12, prob = 254}
		local SS = {name = "lib_materials:stone_cobble_stairs", param2 = 16, prob = 254}
		
		local Q0 = {name = "lib_ecology:tree_default_wood_slab", param2 = 0, prob = 254}
		local Q1 = {name = "lib_ecology:tree_default_wood_slab", param2 = 1, prob = 254}
		local Q2 = {name = "lib_ecology:tree_default_wood_slab", param2 = 2, prob = 254}
		local Q3 = {name = "lib_ecology:tree_default_wood_slab", param2 = 3, prob = 254}
		local Q5 = {name = "lib_ecology:tree_default_wood_slab", param2 = 20, prob = 254}
		local Q6 = {name = "lib_ecology:tree_default_wood_slab", param2 = 21, prob = 254}
		local Q7 = {name = "lib_ecology:tree_default_wood_slab", param2 = 22, prob = 254}
		local Q8 = {name = "lib_ecology:tree_default_wood_slab", param2 = 23, prob = 254}
		local QN = {name = "lib_ecology:tree_default_wood_slab", param2 = 4, prob = 254}
		local QE = {name = "lib_ecology:tree_default_wood_slab", param2 = 8, prob = 254}
		local QW = {name = "lib_ecology:tree_default_wood_slab", param2 = 12, prob = 254}
		local QS = {name = "lib_ecology:tree_default_wood_slab", param2 = 16, prob = 254}
		
		local O0 = {name = "lib_materials:stone_stairs_outer", param2 = 0, prob = 254}
		local O1 = {name = "lib_materials:stone_stairs_outer", param2 = 1, prob = 254}
		local O2 = {name = "lib_materials:stone_stairs_outer", param2 = 2, prob = 254}
		local O3 = {name = "lib_materials:stone_stairs_outer", param2 = 3, prob = 254}
		local O5 = {name = "lib_materials:stone_stairs_inner", param2 = 0, prob = 254}
		local O6 = {name = "lib_materials:stone_stairs_inner", param2 = 1, prob = 254}
		local O7 = {name = "lib_materials:stone_stairs_inner", param2 = 2, prob = 254}
		local O8 = {name = "lib_materials:stone_stairs_inner", param2 = 3, prob = 254}

		local JW = {name = "lib_ecology:tree_jungle_01_wood", param2 = 0, prob = 254}
		local PW = {name = "lib_ecology:tree_pine_01_wood", param2 = 0, prob = 254}
		

		local DD = {name = "lib_materials:dirt", param2 = 0, prob = 254}
		local DG = {name = "lib_materials:dirt_with_grass", param2 = 0, prob = 254}
		local GR = {name = "lib_materials:dirt_with_grass", param2 = 0, prob = 254}
		local G1 = {name = "lib_materials:glass", param2 = 0, prob = 254}

		local FF = {name = "lib_materials:dirt_with_soil_wet", param2 = 0, prob = 254}
		local CC = {name = "lib_ecology:plant_corn_5", param2 = 0, prob = 254}
		
		
		local F0 = {name = "lib_forge:furnace", param2 = 0, prob = 254}
		local F1 = {name = "lib_forge:furnace", param2 = 1, prob = 254}
		local F2 = {name = "lib_forge:furnace", param2 = 2, prob = 254}
		local F3 = {name = "lib_forge:furnace", param2 = 3, prob = 254}

		local C0 = {name = "lib_chests:chest", param2 = 0, prob = 254}
		local C1 = {name = "lib_chests:chest", param2 = 1, prob = 254}
		local C2 = {name = "lib_chests:chest", param2 = 2, prob = 254}
		local C3 = {name = "lib_chests:chest", param2 = 3, prob = 254}

		local L0 = {name = "default:ladder_wood", param2 = 0, prob = 254}
		local L1 = {name = "default:ladder_wood", param2 = 1, prob = 254}
		local L2 = {name = "default:ladder_wood", param2 = 2, prob = 254}
		local L3 = {name = "default:ladder_wood", param2 = 3, prob = 254}
		local L4 = {name = "default:ladder_wood", param2 = 4, prob = 254}
		local L5 = {name = "default:ladder_wood", param2 = 5, prob = 254}

		local DR = {name = "lib_ecology:tree_default_wood_door_centered_300_height_150_width_right", param2 = 1, prob = 254}
		local DL = {name = "lib_ecology:tree_default_wood_door_centered_300_height_150_width", param2 = 1, prob = 254}
		local D0 = {name = "lib_ecology:tree_default_wood_door_centered_with_window", param2 = 0, prob = 254}
		local D1 = {name = "lib_ecology:tree_default_wood_door_centered_with_window", param2 = 1, prob = 254}
		local D2 = {name = "lib_ecology:tree_default_wood_door_centered_with_window", param2 = 2, prob = 254}
		local D3 = {name = "lib_ecology:tree_default_wood_door_centered_with_window", param2 = 3, prob = 254}
		local D5 = {name = "lib_ecology:tree_default_wood_trapdoor_with_window", param2 = 0, prob = 254}
		local D6 = {name = "lib_ecology:tree_default_wood_trapdoor_with_window", param2 = 1, prob = 254}
		local D7 = {name = "lib_ecology:tree_default_wood_trapdoor_with_window", param2 = 2, prob = 254}
		local D8 = {name = "lib_ecology:tree_default_wood_trapdoor_with_window", param2 = 3, prob = 254}

		local TC = {name = "torch:torch_ceiling", param2 = 0, prob = 254}
		local TT = {name = "torch:torch", param2 = 1, prob = 254}
		local T1 = {name = "torch:torch_wall", param2 = 1, prob = 254}
		local T2 = {name = "torch:torch_wall", param2 = 2, prob = 254}
		local T3 = {name = "torch:torch_wall", param2 = 3, prob = 254}
		local T4 = {name = "torch:torch_wall", param2 = 4, prob = 254}
		local T5 = {name = "torch:torch_wall", param2 = 5, prob = 254}
		local T6 = {name = "decoblocks:lantern_wall", param2 = 2, prob = 254}
		local T7 = {name = "decoblocks:lantern_wall", param2 = 3, prob = 254}
		local T8 = {name = "decoblocks:lantern_wall", param2 = 4, prob = 254}
		local T9 = {name = "decoblocks:lantern_wall", param2 = 5, prob = 254}
		local T0 = {name = "decoblocks:lantern_ceiling", param2 = 0, prob = 254}

		local A0 = {name = "lib_tools:anvil", param2 = 0, prob = 254}
		local A1 = {name = "lib_tools:anvil", param2 = 1, prob = 254}
		local A2 = {name = "lib_tools:anvil", param2 = 2, prob = 254}
		local A3 = {name = "lib_tools:anvil", param2 = 3, prob = 254}
		local AA = {name = "decoblocks:altar", param2 = 2, prob = 254}

		local B0 = {name = "beds:bed_bottom", param2 = 0, prob = 254}
		local B1 = {name = "beds:bed_bottom", param2 = 1, prob = 254}
		local B2 = {name = "beds:bed_bottom", param2 = 2, prob = 254}
		local B3 = {name = "beds:bed_bottom", param2 = 3, prob = 254}
		local B5 = {name = "beds:bed_top", param2 = 0, prob = 254}
		local B6 = {name = "beds:bed_top", param2 = 1, prob = 254}
		local B7 = {name = "beds:bed_top", param2 = 2, prob = 254}
		local B8 = {name = "beds:bed_top", param2 = 3, prob = 254}
		local BN = {name = "lib_books:bookshelf", param2 = 0, prob = 254}
		local BE = {name = "lib_books:bookshelf", param2 = 1, prob = 254}
		local BS = {name = "lib_books:bookshelf", param2 = 2, prob = 254}
		local BW = {name = "lib_books:bookshelf", param2 = 3, prob = 254}

		local RB = {name = "lib_tools:ropebox", param2 = 3, prob = 254}
		local RP = {name = "lib_tools:box_rope", param2 = 0, prob = 254}

		local R1 = {name = "cottages:roof_wood", param2 = 1, prob = 254}
		local R3 = {name = "cottages:roof_wood", param2 = 3, prob = 254}
		local R5 = {name = "cottages:roof_connector_wood", param2 = 1, prob = 254}
		local R7 = {name = "cottages:roof_connector_wood", param2 = 3, prob = 254}

		local X0 = {name = "xpanes:bar_flat", param2 = 0, prob = 254}
		local X1 = {name = "xpanes:bar_flat", param2 = 1, prob = 254}
		local X2 = {name = "xpanes:bar_flat", param2 = 2, prob = 254}
		local X3 = {name = "xpanes:bar_flat", param2 = 3, prob = 254}
		local X5 = {name = "xpanes:framed_pane_flat", param2 = 0, prob = 254}
		local X6 = {name = "xpanes:framed_pane_flat", param2 = 1, prob = 254}
		local X7 = {name = "xpanes:framed_pane_flat", param2 = 2, prob = 254}
		local X8 = {name = "xpanes:framed_pane_flat", param2 = 3, prob = 254}

		local Z1 = {name = "lib_tools:cauldron_empty", param2 = 0, prob = 254}
		local Z2 = {name = "lib_ecology:tree_default_wood_table_basic_01", param2 = 0, prob = 254}
		local Z3 = {name = "lib_materials:metal_steel_block", param2 = 0, prob = 254}
		local Z4 = {name = "xpanes:bar_flat", param2 = 1, prob = 254}
		local Z5 = {name = "mg_villages:mob_workplace_marker", param2 = 0, prob = 254}
		local Z6 = {name = "cottages:shelf", param2 = 1, prob = 254}
		local Z7 = {name = "cottages:shelf", param2 = 3, prob = 254}
		local Z8 = {name = "cottages:table", param2 = 2, prob = 254}

		local I0 = {name = "air",param2 = 0,prob = 254}
		local I1 = {name = "air",param2 = 1,prob = 254}
		local I2 = {name = "air",param2 = 2,prob = 254}
		local I3 = {name = "air",param2 = 3,prob = 254}
		local I4 = {name = "",param2 = 0,prob = 254}
		local I5 = {name = "lib_tools:draft_table",param2 = 0,prob = 254}
		local I6 = {name = "decoblocks:vase",param2 = 0,prob = 254}
		local I7 = {name = "air",param2 = 0,prob = 254}
		local I8 = {name = "",param2 = 0,prob = 254}
		local I9 = {name = "",param2 = 0,prob = 254}

		local II = {name = "lib_ecology:tree_default_wood_fence",param2 = 0,prob = 254}

		local le_temp_schem
		
--Cow Shed 1 Schematic
	le_temp_schem = {
	size = {x = 16,y = 10,z = 18},
	yslice_prob = {
		{
			ypos = 0,
			prob = 254
		},
		{
			ypos = 1,
			prob = 254
		},
		{
			ypos = 2,
			prob = 254
		},
		{
			ypos = 3,
			prob = 254
		},
		{
			ypos = 4,
			prob = 254
		},
		{
			ypos = 5,
			prob = 254
		},
		{
			ypos = 6,
			prob = 254
		},
		{
			ypos = 7,
			prob = 254
		},
		{
			ypos = 8,
			prob = 254
		},
		{
			ypos = 9,
			prob = 254
		}
	},
	data = {
		{
			param2 = 0,
			name = "default:dirt_with_grass",
			prob = 254
		},
		{
			param2 = 0,
			name = "default:dirt_with_grass",
			prob = 254
		},
		{
			param2 = 0,
			name = "default:dirt_with_grass",
			prob = 254
		},
		{
			param2 = 0,
			name = "default:dirt_with_grass",
			prob = 254
		},
		{
			param2 = 0,
			name = "default:dirt_with_grass",
			prob = 254
		},
		{
			param2 = 0,
			name = "default:dirt_with_grass",
			prob = 254
		},
		{
			param2 = 0,
			name = "default:dirt_with_grass",
			prob = 254
		},
		{
			param2 = 0,
			name = "default:dirt_with_grass",
			prob = 254
		},
		{
			param2 = 0,
			name = "default:dirt_with_grass",
			prob = 254
		},
		{
			param2 = 0,
			name = "default:dirt_with_grass",
			prob = 254
		},
		{
			param2 = 0,
			name = "default:dirt_with_grass",
			prob = 254
		},
		{
			param2 = 0,
			name = "default:dirt_with_grass",
			prob = 254
		},
		{
			param2 = 0,
			name = "default:dirt_with_grass",
			prob = 254
		},
		{
			param2 = 0,
			name = "default:dirt_with_grass",
			prob = 254
		},
		{
			param2 = 0,
			name = "default:dirt_with_grass",
			prob = 254
		},
		{
			param2 = 0,
			name = "default:dirt_with_grass",
			prob = 254
		},
		{
			param2 = 0,
			name = "air",
			prob = 254
		},
		{
			param2 = 0,
			name = "air",
			prob = 254
		},
		{
			param2 = 0,
			name = "air",
			prob = 254
		},
		{
			param2 = 0,
			name = "air",
			prob = 254
		},
		{
			param2 = 0,
			name = "air",
			prob = 254
		},
		{
			param2 = 0,
			name = "air",
			prob = 254
		},
		{
			param2 = 0,
			name = "air",
			prob = 254
		},
		{
			param2 = 0,
			name = "air",
			prob = 254
		},
		{
			param2 = 0,
			name = "air",
			prob = 254
		},
		{
			param2 = 0,
			name = "air",
			prob = 254
		},
		{
			param2 = 0,
			name = "air",
			prob = 254
		},
		{
			param2 = 0,
			name = "air",
			prob = 254
		},
		{
			param2 = 0,
			name = "air",
			prob = 254
		},
		{
			param2 = 0,
			name = "air",
			prob = 254
		},
		{
			param2 = 0,
			name = "air",
			prob = 254
		},
		{
			param2 = 0,
			name = "air",
			prob = 254
		},
		{
			param2 = 0,
			name = "air",
			prob = 254
		},
		{
			param2 = 0,
			name = "air",
			prob = 254
		},
		{
			param2 = 0,
			name = "air",
			prob = 254
		},
		{
			param2 = 0,
			name = "air",
			prob = 254
		},
		{
			param2 = 0,
			name = "air",
			prob = 254
		},
		{
			param2 = 0,
			name = "air",
			prob = 254
		},
		{
			param2 = 0,
			name = "air",
			prob = 254
		},
		{
			param2 = 0,
			name = "air",
			prob = 254
		},
		{
			param2 = 0,
			name = "air",
			prob = 254
		},
		{
			param2 = 0,
			name = "air",
			prob = 254
		},
		{
			param2 = 0,
			name = "air",
			prob = 254
		},
		{
			param2 = 0,
			name = "air",
			prob = 254
		},
		{
			param2 = 0,
			name = "air",
			prob = 254
		},
		{
			param2 = 0,
			name = "air",
			prob = 254
		},
		{
			param2 = 0,
			name = "air",
			prob = 254
		},
		{
			param2 = 0,
			name = "air",
			prob = 254
		},
		{
			param2 = 0,
			name = "air",
			prob = 254
		},
		{
			param2 = 0,
			name = "air",
			prob = 254
		},
		{
			param2 = 0,
			name = "air",
			prob = 254
		},
		{
			param2 = 0,
			name = "air",
			prob = 254
		},
		{
			param2 = 0,
			name = "air",
			prob = 254
		},
		{
			param2 = 0,
			name = "air",
			prob = 254
		},
		{
			param2 = 0,
			name = "air",
			prob = 254
		},
		{
			param2 = 0,
			name = "air",
			prob = 254
		},
		{
			param2 = 0,
			name = "air",
			prob = 254
		},
		{
			param2 = 0,
			name = "air",
			prob = 254
		},
		{
			param2 = 0,
			name = "air",
			prob = 254
		},
		{
			param2 = 0,
			name = "air",
			prob = 254
		},
		{
			param2 = 0,
			name = "air",
			prob = 254
		},
		{
			param2 = 0,
			name = "air",
			prob = 254
		},
		{
			param2 = 0,
			name = "air",
			prob = 254
		},
		{
			param2 = 0,
			name = "air",
			prob = 254
		},
		{
			param2 = 0,
			name = "air",
			prob = 254
		},
		{
			param2 = 0,
			name = "air",
			prob = 254
		},
		{
			param2 = 0,
			name = "air",
			prob = 254
		},
		{
			param2 = 0,
			name = "air",
			prob = 254
		},
		{
			param2 = 0,
			name = "air",
			prob = 254
		},
		{
			param2 = 0,
			name = "air",
			prob = 254
		},
		{
			param2 = 0,
			name = "air",
			prob = 254
		},
		{
			param2 = 0,
			name = "air",
			prob = 254
		},
		{
			param2 = 0,
			name = "air",
			prob = 254
		},
		{
			param2 = 0,
			name = "air",
			prob = 254
		},
		{
			param2 = 0,
			name = "air",
			prob = 254
		},
		{
			param2 = 0,
			name = "air",
			prob = 254
		},
		{
			param2 = 0,
			name = "air",
			prob = 254
		},
		{
			param2 = 0,
			name = "air",
			prob = 254
		},
		{
			param2 = 0,
			name = "air",
			prob = 254
		},
		{
			param2 = 0,
			name = "air",
			prob = 254
		},
		{
			param2 = 0,
			name = "air",
			prob = 254
		},
		{
			param2 = 0,
			name = "air",
			prob = 254
		},
		{
			param2 = 0,
			name = "air",
			prob = 254
		},
		{
			param2 = 0,
			name = "air",
			prob = 254
		},
		{
			param2 = 0,
			name = "air",
			prob = 254
		},
		{
			param2 = 0,
			name = "air",
			prob = 254
		},
		{
			param2 = 0,
			name = "air",
			prob = 254
		},
		{
			param2 = 0,
			name = "air",
			prob = 254
		},
		{
			param2 = 0,
			name = "air",
			prob = 254
		},
		{
			param2 = 0,
			name = "air",
			prob = 254
		},
		{
			param2 = 0,
			name = "air",
			prob = 254
		},
		{
			param2 = 0,
			name = "air",
			prob = 254
		},
		{
			param2 = 0,
			name = "air",
			prob = 254
		},
		{
			param2 = 0,
			name = "air",
			prob = 254
		},
		{
			param2 = 0,
			name = "air",
			prob = 254
		},
		{
			param2 = 0,
			name = "air",
			prob = 254
		},
		{
			param2 = 0,
			name = "air",
			prob = 254
		},
		{
			param2 = 0,
			name = "air",
			prob = 254
		},
		{
			param2 = 0,
			name = "air",
			prob = 254
		},
		{
			param2 = 0,
			name = "air",
			prob = 254
		},
		{
			param2 = 0,
			name = "air",
			prob = 254
		},
		{
			param2 = 0,
			name = "air",
			prob = 254
		},
		{
			param2 = 0,
			name = "air",
			prob = 254
		},
		{
			param2 = 0,
			name = "air",
			prob = 254
		},
		{
			param2 = 0,
			name = "air",
			prob = 254
		},
		{
			param2 = 0,
			name = "air",
			prob = 254
		},
		{
			param2 = 0,
			name = "air",
			prob = 254
		},
		{
			param2 = 0,
			name = "air",
			prob = 254
		},
		{
			param2 = 0,
			name = "air",
			prob = 254
		},
		{
			param2 = 0,
			name = "air",
			prob = 254
		},
		{
			param2 = 0,
			name = "air",
			prob = 254
		},
		{
			param2 = 0,
			name = "air",
			prob = 254
		},
		{
			param2 = 0,
			name = "air",
			prob = 254
		},
		{
			param2 = 0,
			name = "air",
			prob = 254
		},
		{
			param2 = 0,
			name = "air",
			prob = 254
		},
		{
			param2 = 0,
			name = "air",
			prob = 254
		},
		{
			param2 = 0,
			name = "air",
			prob = 254
		},
		{
			param2 = 0,
			name = "air",
			prob = 254
		},
		{
			param2 = 0,
			name = "air",
			prob = 254
		},
		{
			param2 = 0,
			name = "air",
			prob = 254
		},
		{
			param2 = 0,
			name = "air",
			prob = 254
		},
		{
			param2 = 0,
			name = "air",
			prob = 254
		},
		{
			param2 = 0,
			name = "air",
			prob = 254
		},
		{
			param2 = 0,
			name = "air",
			prob = 254
		},
		{
			param2 = 0,
			name = "air",
			prob = 254
		},
		{
			param2 = 0,
			name = "air",
			prob = 254
		},
		{
			param2 = 0,
			name = "air",
			prob = 254
		},
		{
			param2 = 0,
			name = "air",
			prob = 254
		},
		{
			param2 = 0,
			name = "air",
			prob = 254
		},
		{
			param2 = 0,
			name = "air",
			prob = 254
		},
		{
			param2 = 0,
			name = "air",
			prob = 254
		},
		{
			param2 = 0,
			name = "air",
			prob = 254
		},
		{
			param2 = 0,
			name = "air",
			prob = 254
		},
		{
			param2 = 0,
			name = "air",
			prob = 254
		},
		{
			param2 = 0,
			name = "air",
			prob = 254
		},
		{
			param2 = 0,
			name = "air",
			prob = 254
		},
		{
			param2 = 0,
			name = "air",
			prob = 254
		},
		{
			param2 = 0,
			name = "air",
			prob = 254
		},
		{
			param2 = 0,
			name = "air",
			prob = 254
		},
		{
			param2 = 0,
			name = "air",
			prob = 254
		},
		{
			param2 = 0,
			name = "air",
			prob = 254
		},
		{
			param2 = 0,
			name = "air",
			prob = 254
		},
		{
			param2 = 0,
			name = "air",
			prob = 254
		},
		{
			param2 = 0,
			name = "air",
			prob = 254
		},
		{
			param2 = 0,
			name = "air",
			prob = 254
		},
		{
			param2 = 0,
			name = "air",
			prob = 254
		},
		{
			param2 = 0,
			name = "air",
			prob = 254
		},
		{
			param2 = 0,
			name = "air",
			prob = 254
		},
		{
			param2 = 0,
			name = "air",
			prob = 254
		},
		{
			param2 = 0,
			name = "air",
			prob = 254
		},
		{
			param2 = 0,
			name = "air",
			prob = 254
		},
		{
			param2 = 0,
			name = "air",
			prob = 254
		},
		{
			param2 = 0,
			name = "air",
			prob = 254
		},
		{
			param2 = 0,
			name = "air",
			prob = 254
		},
		{
			param2 = 0,
			name = "air",
			prob = 254
		},
		{
			param2 = 0,
			name = "air",
			prob = 254
		},
		{
			param2 = 0,
			name = "air",
			prob = 254
		},
		{
			param2 = 0,
			name = "air",
			prob = 254
		},
		{
			param2 = 0,
			name = "air",
			prob = 254
		},
		{
			param2 = 0,
			name = "air",
			prob = 254
		},
		{
			param2 = 0,
			name = "default:dirt_with_grass",
			prob = 254
		},
		{
			param2 = 0,
			name = "default:dirt_with_grass",
			prob = 254
		},
		{
			param2 = 0,
			name = "default:dirt_with_grass",
			prob = 254
		},
		{
			param2 = 0,
			name = "default:dirt_with_grass",
			prob = 254
		},
		{
			param2 = 0,
			name = "default:dirt_with_grass",
			prob = 254
		},
		{
			param2 = 0,
			name = "default:dirt_with_grass",
			prob = 254
		},
		{
			param2 = 0,
			name = "default:dirt_with_grass",
			prob = 254
		},
		{
			param2 = 0,
			name = "default:dirt_with_grass",
			prob = 254
		},
		{
			param2 = 0,
			name = "default:dirt_with_grass",
			prob = 254
		},
		{
			param2 = 0,
			name = "default:dirt_with_grass",
			prob = 254
		},
		{
			param2 = 0,
			name = "default:dirt_with_grass",
			prob = 254
		},
		{
			param2 = 0,
			name = "default:dirt_with_grass",
			prob = 254
		},
		{
			param2 = 0,
			name = "default:dirt_with_grass",
			prob = 254
		},
		{
			param2 = 0,
			name = "default:dirt_with_grass",
			prob = 254
		},
		{
			param2 = 0,
			name = "default:dirt_with_grass",
			prob = 254
		},
		{
			param2 = 0,
			name = "default:dirt_with_grass",
			prob = 254
		},
		{
			param2 = 0,
			name = "air",
			prob = 254
		},
		{
			param2 = 0,
			name = "air",
			prob = 254
		},
		{
			param2 = 0,
			name = "air",
			prob = 254
		},
		{
			param2 = 0,
			name = "air",
			prob = 254
		},
		{
			param2 = 0,
			name = "air",
			prob = 254
		},
		{
			param2 = 0,
			name = "air",
			prob = 254
		},
		{
			param2 = 0,
			name = "air",
			prob = 254
		},
		{
			param2 = 0,
			name = "air",
			prob = 254
		},
		{
			param2 = 0,
			name = "air",
			prob = 254
		},
		{
			param2 = 0,
			name = "air",
			prob = 254
		},
		{
			param2 = 0,
			name = "air",
			prob = 254
		},
		{
			param2 = 0,
			name = "air",
			prob = 254
		},
		{
			param2 = 0,
			name = "air",
			prob = 254
		},
		{
			param2 = 0,
			name = "air",
			prob = 254
		},
		{
			param2 = 0,
			name = "air",
			prob = 254
		},
		{
			param2 = 0,
			name = "air",
			prob = 254
		},
		{
			param2 = 0,
			name = "air",
			prob = 254
		},
		{
			param2 = 0,
			name = "air",
			prob = 254
		},
		{
			param2 = 0,
			name = "air",
			prob = 254
		},
		{
			param2 = 0,
			name = "air",
			prob = 254
		},
		{
			param2 = 0,
			name = "air",
			prob = 254
		},
		{
			param2 = 0,
			name = "air",
			prob = 254
		},
		{
			param2 = 0,
			name = "air",
			prob = 254
		},
		{
			param2 = 0,
			name = "air",
			prob = 254
		},
		{
			param2 = 0,
			name = "air",
			prob = 254
		},
		{
			param2 = 0,
			name = "air",
			prob = 254
		},
		{
			param2 = 0,
			name = "air",
			prob = 254
		},
		{
			param2 = 0,
			name = "air",
			prob = 254
		},
		{
			param2 = 0,
			name = "air",
			prob = 254
		},
		{
			param2 = 0,
			name = "air",
			prob = 254
		},
		{
			param2 = 0,
			name = "air",
			prob = 254
		},
		{
			param2 = 0,
			name = "air",
			prob = 254
		},
		{
			param2 = 0,
			name = "air",
			prob = 254
		},
		{
			param2 = 0,
			name = "air",
			prob = 254
		},
		{
			param2 = 0,
			name = "air",
			prob = 254
		},
		{
			param2 = 0,
			name = "air",
			prob = 254
		},
		{
			param2 = 0,
			name = "air",
			prob = 254
		},
		{
			param2 = 0,
			name = "air",
			prob = 254
		},
		{
			param2 = 0,
			name = "air",
			prob = 254
		},
		{
			param2 = 0,
			name = "air",
			prob = 254
		},
		{
			param2 = 0,
			name = "air",
			prob = 254
		},
		{
			param2 = 0,
			name = "air",
			prob = 254
		},
		{
			param2 = 0,
			name = "air",
			prob = 254
		},
		{
			param2 = 0,
			name = "air",
			prob = 254
		},
		{
			param2 = 0,
			name = "air",
			prob = 254
		},
		{
			param2 = 0,
			name = "air",
			prob = 254
		},
		{
			param2 = 0,
			name = "air",
			prob = 254
		},
		{
			param2 = 0,
			name = "air",
			prob = 254
		},
		{
			param2 = 0,
			name = "air",
			prob = 254
		},
		{
			param2 = 0,
			name = "air",
			prob = 254
		},
		{
			param2 = 0,
			name = "air",
			prob = 254
		},
		{
			param2 = 0,
			name = "air",
			prob = 254
		},
		{
			param2 = 0,
			name = "air",
			prob = 254
		},
		{
			param2 = 0,
			name = "air",
			prob = 254
		},
		{
			param2 = 0,
			name = "air",
			prob = 254
		},
		{
			param2 = 0,
			name = "air",
			prob = 254
		},
		{
			param2 = 0,
			name = "air",
			prob = 254
		},
		{
			param2 = 0,
			name = "air",
			prob = 254
		},
		{
			param2 = 0,
			name = "air",
			prob = 254
		},
		{
			param2 = 0,
			name = "air",
			prob = 254
		},
		{
			param2 = 0,
			name = "air",
			prob = 254
		},
		{
			param2 = 0,
			name = "air",
			prob = 254
		},
		{
			param2 = 0,
			name = "air",
			prob = 254
		},
		{
			param2 = 0,
			name = "air",
			prob = 254
		},
		{
			param2 = 0,
			name = "air",
			prob = 254
		},
		{
			param2 = 0,
			name = "air",
			prob = 254
		},
		{
			param2 = 0,
			name = "air",
			prob = 254
		},
		{
			param2 = 0,
			name = "air",
			prob = 254
		},
		{
			param2 = 0,
			name = "air",
			prob = 254
		},
		{
			param2 = 0,
			name = "air",
			prob = 254
		},
		{
			param2 = 0,
			name = "air",
			prob = 254
		},
		{
			param2 = 0,
			name = "air",
			prob = 254
		},
		{
			param2 = 0,
			name = "air",
			prob = 254
		},
		{
			param2 = 0,
			name = "air",
			prob = 254
		},
		{
			param2 = 0,
			name = "air",
			prob = 254
		},
		{
			param2 = 0,
			name = "air",
			prob = 254
		},
		{
			param2 = 0,
			name = "air",
			prob = 254
		},
		{
			param2 = 0,
			name = "air",
			prob = 254
		},
		{
			param2 = 0,
			name = "air",
			prob = 254
		},
		{
			param2 = 0,
			name = "air",
			prob = 254
		},
		{
			param2 = 0,
			name = "air",
			prob = 254
		},
		{
			param2 = 0,
			name = "air",
			prob = 254
		},
		{
			param2 = 0,
			name = "air",
			prob = 254
		},
		{
			param2 = 0,
			name = "air",
			prob = 254
		},
		{
			param2 = 0,
			name = "air",
			prob = 254
		},
		{
			param2 = 1,
			name = "cottages:roof_straw",
			prob = 254
		},
		{
			param2 = 0,
			name = "air",
			prob = 254
		},
		{
			param2 = 3,
			name = "cottages:roof_straw",
			prob = 254
		},
		{
			param2 = 0,
			name = "air",
			prob = 254
		},
		{
			param2 = 0,
			name = "air",
			prob = 254
		},
		{
			param2 = 0,
			name = "air",
			prob = 254
		},
		{
			param2 = 0,
			name = "air",
			prob = 254
		},
		{
			param2 = 0,
			name = "air",
			prob = 254
		},
		{
			param2 = 0,
			name = "air",
			prob = 254
		},
		{
			param2 = 0,
			name = "air",
			prob = 254
		},
		{
			param2 = 0,
			name = "air",
			prob = 254
		},
		{
			param2 = 0,
			name = "air",
			prob = 254
		},
		{
			param2 = 0,
			name = "air",
			prob = 254
		},
		{
			param2 = 0,
			name = "air",
			prob = 254
		},
		{
			param2 = 0,
			name = "air",
			prob = 254
		},
		{
			param2 = 0,
			name = "air",
			prob = 254
		},
		{
			param2 = 0,
			name = "air",
			prob = 254
		},
		{
			param2 = 2,
			name = "cottages:roof_flat_straw",
			prob = 254
		},
		{
			param2 = 0,
			name = "air",
			prob = 254
		},
		{
			param2 = 0,
			name = "air",
			prob = 254
		},
		{
			param2 = 0,
			name = "air",
			prob = 254
		},
		{
			param2 = 0,
			name = "air",
			prob = 254
		},
		{
			param2 = 0,
			name = "air",
			prob = 254
		},
		{
			param2 = 0,
			name = "air",
			prob = 254
		},
		{
			param2 = 0,
			name = "air",
			prob = 254
		},
		{
			param2 = 0,
			name = "air",
			prob = 254
		},
		{
			param2 = 0,
			name = "air",
			prob = 254
		},
		{
			param2 = 0,
			name = "air",
			prob = 254
		},
		{
			param2 = 0,
			name = "air",
			prob = 254
		},
		{
			param2 = 0,
			name = "air",
			prob = 254
		},
		{
			param2 = 0,
			name = "air",
			prob = 254
		},
		{
			param2 = 0,
			name = "air",
			prob = 254
		},
		{
			param2 = 0,
			name = "air",
			prob = 254
		},
		{
			param2 = 0,
			name = "air",
			prob = 254
		},
		{
			param2 = 0,
			name = "air",
			prob = 254
		},
		{
			param2 = 0,
			name = "air",
			prob = 254
		},
		{
			param2 = 0,
			name = "air",
			prob = 254
		},
		{
			param2 = 0,
			name = "air",
			prob = 254
		},
		{
			param2 = 0,
			name = "air",
			prob = 254
		},
		{
			param2 = 0,
			name = "air",
			prob = 254
		},
		{
			param2 = 0,
			name = "air",
			prob = 254
		},
		{
			param2 = 0,
			name = "air",
			prob = 254
		},
		{
			param2 = 0,
			name = "air",
			prob = 254
		},
		{
			param2 = 0,
			name = "air",
			prob = 254
		},
		{
			param2 = 0,
			name = "air",
			prob = 254
		},
		{
			param2 = 0,
			name = "air",
			prob = 254
		},
		{
			param2 = 0,
			name = "air",
			prob = 254
		},
		{
			param2 = 0,
			name = "air",
			prob = 254
		},
		{
			param2 = 0,
			name = "air",
			prob = 254
		},
		{
			param2 = 0,
			name = "air",
			prob = 254
		},
		{
			param2 = 0,
			name = "air",
			prob = 254
		},
		{
			param2 = 0,
			name = "air",
			prob = 254
		},
		{
			param2 = 0,
			name = "air",
			prob = 254
		},
		{
			param2 = 0,
			name = "air",
			prob = 254
		},
		{
			param2 = 0,
			name = "air",
			prob = 254
		},
		{
			param2 = 0,
			name = "air",
			prob = 254
		},
		{
			param2 = 0,
			name = "air",
			prob = 254
		},
		{
			param2 = 0,
			name = "air",
			prob = 254
		},
		{
			param2 = 0,
			name = "air",
			prob = 254
		},
		{
			param2 = 0,
			name = "default:dirt_with_grass",
			prob = 254
		},
		{
			param2 = 0,
			name = "default:dirt_with_grass",
			prob = 254
		},
		{
			param2 = 0,
			name = "default:dirt_with_grass",
			prob = 254
		},
		{
			param2 = 0,
			name = "default:dirt_with_grass",
			prob = 254
		},
		{
			param2 = 0,
			name = "default:dirt_with_grass",
			prob = 254
		},
		{
			param2 = 0,
			name = "default:dirt_with_grass",
			prob = 254
		},
		{
			param2 = 0,
			name = "default:dirt_with_grass",
			prob = 254
		},
		{
			param2 = 0,
			name = "default:dirt_with_grass",
			prob = 254
		},
		{
			param2 = 0,
			name = "default:dirt_with_grass",
			prob = 254
		},
		{
			param2 = 0,
			name = "default:dirt_with_grass",
			prob = 254
		},
		{
			param2 = 0,
			name = "default:dirt_with_grass",
			prob = 254
		},
		{
			param2 = 0,
			name = "default:dirt_with_grass",
			prob = 254
		},
		{
			param2 = 0,
			name = "default:dirt_with_grass",
			prob = 254
		},
		{
			param2 = 0,
			name = "default:dirt_with_grass",
			prob = 254
		},
		{
			param2 = 0,
			name = "default:dirt_with_grass",
			prob = 254
		},
		{
			param2 = 0,
			name = "default:dirt_with_grass",
			prob = 254
		},
		{
			param2 = 0,
			name = "air",
			prob = 254
		},
		{
			param2 = 0,
			name = "air",
			prob = 254
		},
		{
			param2 = 0,
			name = "air",
			prob = 254
		},
		{
			param2 = 0,
			name = "air",
			prob = 254
		},
		{
			param2 = 0,
			name = "air",
			prob = 254
		},
		{
			param2 = 0,
			name = "cottages:barrel",
			prob = 254
		},
		{
			param2 = 0,
			name = "air",
			prob = 254
		},
		{
			param2 = 0,
			name = "air",
			prob = 254
		},
		{
			param2 = 0,
			name = "air",
			prob = 254
		},
		{
			param2 = 0,
			name = "air",
			prob = 254
		},
		{
			param2 = 0,
			name = "air",
			prob = 254
		},
		{
			param2 = 0,
			name = "air",
			prob = 254
		},
		{
			param2 = 0,
			name = "air",
			prob = 254
		},
		{
			param2 = 0,
			name = "air",
			prob = 254
		},
		{
			param2 = 0,
			name = "air",
			prob = 254
		},
		{
			param2 = 0,
			name = "air",
			prob = 254
		},
		{
			param2 = 0,
			name = "air",
			prob = 254
		},
		{
			param2 = 0,
			name = "air",
			prob = 254
		},
		{
			param2 = 0,
			name = "air",
			prob = 254
		},
		{
			param2 = 0,
			name = "air",
			prob = 254
		},
		{
			param2 = 0,
			name = "air",
			prob = 254
		},
		{
			param2 = 0,
			name = "air",
			prob = 254
		},
		{
			param2 = 0,
			name = "air",
			prob = 254
		},
		{
			param2 = 0,
			name = "cottages:window_shutter_open",
			prob = 254
		},
		{
			param2 = 0,
			name = "air",
			prob = 254
		},
		{
			param2 = 0,
			name = "air",
			prob = 254
		},
		{
			param2 = 0,
			name = "air",
			prob = 254
		},
		{
			param2 = 0,
			name = "air",
			prob = 254
		},
		{
			param2 = 0,
			name = "air",
			prob = 254
		},
		{
			param2 = 0,
			name = "air",
			prob = 254
		},
		{
			param2 = 0,
			name = "air",
			prob = 254
		},
		{
			param2 = 0,
			name = "air",
			prob = 254
		},
		{
			param2 = 0,
			name = "air",
			prob = 254
		},
		{
			param2 = 0,
			name = "air",
			prob = 254
		},
		{
			param2 = 1,
			name = "cottages:roof_straw",
			prob = 254
		},
		{
			param2 = 0,
			name = "air",
			prob = 254
		},
		{
			param2 = 0,
			name = "air",
			prob = 254
		},
		{
			param2 = 4,
			name = "default:torch_wall",
			prob = 254
		},
		{
			param2 = 0,
			name = "air",
			prob = 254
		},
		{
			param2 = 4,
			name = "default:torch_wall",
			prob = 254
		},
		{
			param2 = 0,
			name = "air",
			prob = 254
		},
		{
			param2 = 0,
			name = "air",
			prob = 254
		},
		{
			param2 = 3,
			name = "cottages:roof_straw",
			prob = 254
		},
		{
			param2 = 0,
			name = "air",
			prob = 254
		},
		{
			param2 = 0,
			name = "air",
			prob = 254
		},
		{
			param2 = 0,
			name = "air",
			prob = 254
		},
		{
			param2 = 0,
			name = "air",
			prob = 254
		},
		{
			param2 = 0,
			name = "air",
			prob = 254
		},
		{
			param2 = 0,
			name = "air",
			prob = 254
		},
		{
			param2 = 0,
			name = "air",
			prob = 254
		},
		{
			param2 = 0,
			name = "air",
			prob = 254
		},
		{
			param2 = 1,
			name = "cottages:roof_straw",
			prob = 254
		},
		{
			param2 = 0,
			name = "air",
			prob = 254
		},
		{
			param2 = 10,
			name = "stairs:stair_wood",
			prob = 254
		},
		{
			param2 = 0,
			name = "air",
			prob = 254
		},
		{
			param2 = 10,
			name = "stairs:stair_wood",
			prob = 254
		},
		{
			param2 = 0,
			name = "air",
			prob = 254
		},
		{
			param2 = 3,
			name = "cottages:roof_straw",
			prob = 254
		},
		{
			param2 = 0,
			name = "air",
			prob = 254
		},
		{
			param2 = 0,
			name = "air",
			prob = 254
		},
		{
			param2 = 0,
			name = "air",
			prob = 254
		},
		{
			param2 = 0,
			name = "air",
			prob = 254
		},
		{
			param2 = 0,
			name = "air",
			prob = 254
		},
		{
			param2 = 0,
			name = "air",
			prob = 254
		},
		{
			param2 = 0,
			name = "air",
			prob = 254
		},
		{
			param2 = 0,
			name = "air",
			prob = 254
		},
		{
			param2 = 0,
			name = "air",
			prob = 254
		},
		{
			param2 = 0,
			name = "air",
			prob = 254
		},
		{
			param2 = 1,
			name = "cottages:roof_straw",
			prob = 254
		},
		{
			param2 = 0,
			name = "air",
			prob = 254
		},
		{
			param2 = 0,
			name = "air",
			prob = 254
		},
		{
			param2 = 0,
			name = "air",
			prob = 254
		},
		{
			param2 = 3,
			name = "cottages:roof_straw",
			prob = 254
		},
		{
			param2 = 0,
			name = "air",
			prob = 254
		},
		{
			param2 = 0,
			name = "air",
			prob = 254
		},
		{
			param2 = 0,
			name = "air",
			prob = 254
		},
		{
			param2 = 0,
			name = "air",
			prob = 254
		},
		{
			param2 = 0,
			name = "air",
			prob = 254
		},
		{
			param2 = 0,
			name = "air",
			prob = 254
		},
		{
			param2 = 0,
			name = "air",
			prob = 254
		},
		{
			param2 = 0,
			name = "air",
			prob = 254
		},
		{
			param2 = 0,
			name = "air",
			prob = 254
		},
		{
			param2 = 0,
			name = "air",
			prob = 254
		},
		{
			param2 = 0,
			name = "air",
			prob = 254
		},
		{
			param2 = 0,
			name = "air",
			prob = 254
		},
		{
			param2 = 1,
			name = "cottages:roof_straw",
			prob = 254
		},
		{
			param2 = 0,
			name = "air",
			prob = 254
		},
		{
			param2 = 3,
			name = "cottages:roof_straw",
			prob = 254
		},
		{
			param2 = 0,
			name = "air",
			prob = 254
		},
		{
			param2 = 0,
			name = "air",
			prob = 254
		},
		{
			param2 = 0,
			name = "air",
			prob = 254
		},
		{
			param2 = 0,
			name = "air",
			prob = 254
		},
		{
			param2 = 0,
			name = "air",
			prob = 254
		},
		{
			param2 = 0,
			name = "air",
			prob = 254
		},
		{
			param2 = 0,
			name = "air",
			prob = 254
		},
		{
			param2 = 0,
			name = "air",
			prob = 254
		},
		{
			param2 = 0,
			name = "air",
			prob = 254
		},
		{
			param2 = 0,
			name = "air",
			prob = 254
		},
		{
			param2 = 0,
			name = "air",
			prob = 254
		},
		{
			param2 = 0,
			name = "air",
			prob = 254
		},
		{
			param2 = 0,
			name = "air",
			prob = 254
		},
		{
			param2 = 0,
			name = "air",
			prob = 254
		},
		{
			param2 = 2,
			name = "cottages:roof_flat_straw",
			prob = 254
		},
		{
			param2 = 0,
			name = "air",
			prob = 254
		},
		{
			param2 = 0,
			name = "air",
			prob = 254
		},
		{
			param2 = 0,
			name = "air",
			prob = 254
		},
		{
			param2 = 0,
			name = "air",
			prob = 254
		},
		{
			param2 = 0,
			name = "air",
			prob = 254
		},
		{
			param2 = 0,
			name = "air",
			prob = 254
		},
		{
			param2 = 0,
			name = "air",
			prob = 254
		},
		{
			param2 = 0,
			name = "air",
			prob = 254
		},
		{
			param2 = 0,
			name = "air",
			prob = 254
		},
		{
			param2 = 0,
			name = "air",
			prob = 254
		},
		{
			param2 = 0,
			name = "air",
			prob = 254
		},
		{
			param2 = 0,
			name = "air",
			prob = 254
		},
		{
			param2 = 0,
			name = "air",
			prob = 254
		},
		{
			param2 = 0,
			name = "air",
			prob = 254
		},
		{
			param2 = 0,
			name = "air",
			prob = 254
		},
		{
			param2 = 0,
			name = "air",
			prob = 254
		},
		{
			param2 = 0,
			name = "air",
			prob = 254
		},
		{
			param2 = 0,
			name = "air",
			prob = 254
		},
		{
			param2 = 0,
			name = "air",
			prob = 254
		},
		{
			param2 = 0,
			name = "air",
			prob = 254
		},
		{
			param2 = 0,
			name = "air",
			prob = 254
		},
		{
			param2 = 0,
			name = "air",
			prob = 254
		},
		{
			param2 = 0,
			name = "air",
			prob = 254
		},
		{
			param2 = 0,
			name = "air",
			prob = 254
		},
		{
			param2 = 0,
			name = "air",
			prob = 254
		},
		{
			param2 = 0,
			name = "air",
			prob = 254
		},
		{
			param2 = 0,
			name = "air",
			prob = 254
		},
		{
			param2 = 0,
			name = "air",
			prob = 254
		},
		{
			param2 = 0,
			name = "air",
			prob = 254
		},
		{
			param2 = 0,
			name = "air",
			prob = 254
		},
		{
			param2 = 0,
			name = "air",
			prob = 254
		},
		{
			param2 = 0,
			name = "air",
			prob = 254
		},
		{
			param2 = 0,
			name = "air",
			prob = 254
		},
		{
			param2 = 0,
			name = "air",
			prob = 254
		},
		{
			param2 = 0,
			name = "air",
			prob = 254
		},
		{
			param2 = 0,
			name = "air",
			prob = 254
		},
		{
			param2 = 0,
			name = "air",
			prob = 254
		},
		{
			param2 = 0,
			name = "air",
			prob = 254
		},
		{
			param2 = 0,
			name = "air",
			prob = 254
		},
		{
			param2 = 0,
			name = "air",
			prob = 254
		},
		{
			param2 = 0,
			name = "air",
			prob = 254
		},
		{
			param2 = 0,
			name = "default:dirt_with_grass",
			prob = 254
		},
		{
			param2 = 0,
			name = "default:dirt_with_grass",
			prob = 254
		},
		{
			param2 = 0,
			name = "default:cobble",
			prob = 254
		},
		{
			param2 = 0,
			name = "default:cobble",
			prob = 254
		},
		{
			param2 = 0,
			name = "default:cobble",
			prob = 254
		},
		{
			param2 = 0,
			name = "default:cobble",
			prob = 254
		},
		{
			param2 = 0,
			name = "default:cobble",
			prob = 254
		},
		{
			param2 = 0,
			name = "default:cobble",
			prob = 254
		},
		{
			param2 = 0,
			name = "default:cobble",
			prob = 254
		},
		{
			param2 = 1,
			name = "default:tree",
			prob = 254
		},
		{
			param2 = 0,
			name = "default:dirt_with_grass",
			prob = 254
		},
		{
			param2 = 0,
			name = "default:dirt_with_grass",
			prob = 254
		},
		{
			param2 = 0,
			name = "default:dirt_with_grass",
			prob = 254
		},
		{
			param2 = 0,
			name = "default:dirt_with_grass",
			prob = 254
		},
		{
			param2 = 0,
			name = "default:dirt_with_grass",
			prob = 254
		},
		{
			param2 = 0,
			name = "default:dirt_with_grass",
			prob = 254
		},
		{
			param2 = 0,
			name = "air",
			prob = 254
		},
		{
			param2 = 0,
			name = "air",
			prob = 254
		},
		{
			param2 = 0,
			name = "air",
			prob = 254
		},
		{
			param2 = 1,
			name = "default:tree",
			prob = 254
		},
		{
			param2 = 1,
			name = "default:wood",
			prob = 254
		},
		{
			param2 = 1,
			name = "default:wood",
			prob = 254
		},
		{
			param2 = 0,
			name = "default:tree",
			prob = 254
		},
		{
			param2 = 1,
			name = "default:wood",
			prob = 254
		},
		{
			param2 = 1,
			name = "default:wood",
			prob = 254
		},
		{
			param2 = 1,
			name = "default:tree",
			prob = 254
		},
		{
			param2 = 0,
			name = "air",
			prob = 254
		},
		{
			param2 = 0,
			name = "air",
			prob = 254
		},
		{
			param2 = 0,
			name = "air",
			prob = 254
		},
		{
			param2 = 0,
			name = "air",
			prob = 254
		},
		{
			param2 = 0,
			name = "air",
			prob = 254
		},
		{
			param2 = 0,
			name = "air",
			prob = 254
		},
		{
			param2 = 0,
			name = "air",
			prob = 254
		},
		{
			param2 = 0,
			name = "air",
			prob = 254
		},
		{
			param2 = 0,
			name = "air",
			prob = 254
		},
		{
			param2 = 1,
			name = "default:tree",
			prob = 254
		},
		{
			param2 = 1,
			name = "default:wood",
			prob = 254
		},
		{
			param2 = 1,
			name = "default:wood",
			prob = 254
		},
		{
			param2 = 0,
			name = "default:tree",
			prob = 254
		},
		{
			param2 = 0,
			name = "default:fence_wood",
			prob = 254
		},
		{
			param2 = 1,
			name = "default:wood",
			prob = 254
		},
		{
			param2 = 1,
			name = "default:tree",
			prob = 254
		},
		{
			param2 = 0,
			name = "air",
			prob = 254
		},
		{
			param2 = 0,
			name = "air",
			prob = 254
		},
		{
			param2 = 0,
			name = "air",
			prob = 254
		},
		{
			param2 = 0,
			name = "air",
			prob = 254
		},
		{
			param2 = 0,
			name = "air",
			prob = 254
		},
		{
			param2 = 0,
			name = "air",
			prob = 254
		},
		{
			param2 = 0,
			name = "air",
			prob = 254
		},
		{
			param2 = 0,
			name = "air",
			prob = 254
		},
		{
			param2 = 1,
			name = "cottages:roof_straw",
			prob = 254
		},
		{
			param2 = 1,
			name = "default:tree",
			prob = 254
		},
		{
			param2 = 1,
			name = "default:wood",
			prob = 254
		},
		{
			param2 = 12,
			name = "default:tree",
			prob = 254
		},
		{
			param2 = 12,
			name = "default:tree",
			prob = 254
		},
		{
			param2 = 12,
			name = "default:tree",
			prob = 254
		},
		{
			param2 = 1,
			name = "default:wood",
			prob = 254
		},
		{
			param2 = 1,
			name = "default:tree",
			prob = 254
		},
		{
			param2 = 3,
			name = "cottages:roof_straw",
			prob = 254
		},
		{
			param2 = 0,
			name = "air",
			prob = 254
		},
		{
			param2 = 0,
			name = "air",
			prob = 254
		},
		{
			param2 = 0,
			name = "air",
			prob = 254
		},
		{
			param2 = 0,
			name = "air",
			prob = 254
		},
		{
			param2 = 0,
			name = "air",
			prob = 254
		},
		{
			param2 = 0,
			name = "air",
			prob = 254
		},
		{
			param2 = 0,
			name = "air",
			prob = 254
		},
		{
			param2 = 0,
			name = "air",
			prob = 254
		},
		{
			param2 = 1,
			name = "cottages:roof_connector_straw",
			prob = 254
		},
		{
			param2 = 1,
			name = "default:wood",
			prob = 254
		},
		{
			param2 = 7,
			name = "default:tree",
			prob = 254
		},
		{
			param2 = 1,
			name = "default:wood",
			prob = 254
		},
		{
			param2 = 7,
			name = "default:tree",
			prob = 254
		},
		{
			param2 = 1,
			name = "default:wood",
			prob = 254
		},
		{
			param2 = 3,
			name = "cottages:roof_connector_straw",
			prob = 254
		},
		{
			param2 = 0,
			name = "air",
			prob = 254
		},
		{
			param2 = 0,
			name = "air",
			prob = 254
		},
		{
			param2 = 0,
			name = "air",
			prob = 254
		},
		{
			param2 = 0,
			name = "air",
			prob = 254
		},
		{
			param2 = 0,
			name = "air",
			prob = 254
		},
		{
			param2 = 0,
			name = "air",
			prob = 254
		},
		{
			param2 = 0,
			name = "air",
			prob = 254
		},
		{
			param2 = 0,
			name = "air",
			prob = 254
		},
		{
			param2 = 0,
			name = "air",
			prob = 254
		},
		{
			param2 = 0,
			name = "air",
			prob = 254
		},
		{
			param2 = 1,
			name = "cottages:roof_connector_straw",
			prob = 254
		},
		{
			param2 = 1,
			name = "default:wood",
			prob = 254
		},
		{
			param2 = 0,
			name = "default:fence_wood",
			prob = 254
		},
		{
			param2 = 1,
			name = "default:wood",
			prob = 254
		},
		{
			param2 = 3,
			name = "cottages:roof_connector_straw",
			prob = 254
		},
		{
			param2 = 0,
			name = "air",
			prob = 254
		},
		{
			param2 = 0,
			name = "air",
			prob = 254
		},
		{
			param2 = 0,
			name = "air",
			prob = 254
		},
		{
			param2 = 0,
			name = "air",
			prob = 254
		},
		{
			param2 = 0,
			name = "air",
			prob = 254
		},
		{
			param2 = 0,
			name = "air",
			prob = 254
		},
		{
			param2 = 0,
			name = "air",
			prob = 254
		},
		{
			param2 = 0,
			name = "air",
			prob = 254
		},
		{
			param2 = 0,
			name = "air",
			prob = 254
		},
		{
			param2 = 0,
			name = "air",
			prob = 254
		},
		{
			param2 = 0,
			name = "air",
			prob = 254
		},
		{
			param2 = 0,
			name = "air",
			prob = 254
		},
		{
			param2 = 1,
			name = "cottages:roof_connector_straw",
			prob = 254
		},
		{
			param2 = 0,
			name = "default:fence_wood",
			prob = 254
		},
		{
			param2 = 3,
			name = "cottages:roof_connector_straw",
			prob = 254
		},
		{
			param2 = 0,
			name = "air",
			prob = 254
		},
		{
			param2 = 0,
			name = "air",
			prob = 254
		},
		{
			param2 = 0,
			name = "air",
			prob = 254
		},
		{
			param2 = 0,
			name = "air",
			prob = 254
		},
		{
			param2 = 0,
			name = "air",
			prob = 254
		},
		{
			param2 = 0,
			name = "air",
			prob = 254
		},
		{
			param2 = 0,
			name = "air",
			prob = 254
		},
		{
			param2 = 0,
			name = "air",
			prob = 254
		},
		{
			param2 = 0,
			name = "air",
			prob = 254
		},
		{
			param2 = 0,
			name = "air",
			prob = 254
		},
		{
			param2 = 0,
			name = "air",
			prob = 254
		},
		{
			param2 = 0,
			name = "air",
			prob = 254
		},
		{
			param2 = 0,
			name = "air",
			prob = 254
		},
		{
			param2 = 0,
			name = "air",
			prob = 254
		},
		{
			param2 = 2,
			name = "cottages:roof_flat_straw",
			prob = 254
		},
		{
			param2 = 0,
			name = "air",
			prob = 254
		},
		{
			param2 = 0,
			name = "air",
			prob = 254
		},
		{
			param2 = 0,
			name = "air",
			prob = 254
		},
		{
			param2 = 0,
			name = "air",
			prob = 254
		},
		{
			param2 = 0,
			name = "air",
			prob = 254
		},
		{
			param2 = 0,
			name = "air",
			prob = 254
		},
		{
			param2 = 0,
			name = "air",
			prob = 254
		},
		{
			param2 = 0,
			name = "air",
			prob = 254
		},
		{
			param2 = 0,
			name = "air",
			prob = 254
		},
		{
			param2 = 0,
			name = "air",
			prob = 254
		},
		{
			param2 = 0,
			name = "air",
			prob = 254
		},
		{
			param2 = 0,
			name = "air",
			prob = 254
		},
		{
			param2 = 0,
			name = "air",
			prob = 254
		},
		{
			param2 = 0,
			name = "air",
			prob = 254
		},
		{
			param2 = 0,
			name = "air",
			prob = 254
		},
		{
			param2 = 0,
			name = "air",
			prob = 254
		},
		{
			param2 = 0,
			name = "air",
			prob = 254
		},
		{
			param2 = 0,
			name = "air",
			prob = 254
		},
		{
			param2 = 0,
			name = "air",
			prob = 254
		},
		{
			param2 = 0,
			name = "air",
			prob = 254
		},
		{
			param2 = 0,
			name = "air",
			prob = 254
		},
		{
			param2 = 0,
			name = "air",
			prob = 254
		},
		{
			param2 = 0,
			name = "air",
			prob = 254
		},
		{
			param2 = 0,
			name = "air",
			prob = 254
		},
		{
			param2 = 0,
			name = "air",
			prob = 254
		},
		{
			param2 = 0,
			name = "air",
			prob = 254
		},
		{
			param2 = 0,
			name = "air",
			prob = 254
		},
		{
			param2 = 0,
			name = "air",
			prob = 254
		},
		{
			param2 = 0,
			name = "air",
			prob = 254
		},
		{
			param2 = 0,
			name = "air",
			prob = 254
		},
		{
			param2 = 0,
			name = "air",
			prob = 254
		},
		{
			param2 = 0,
			name = "air",
			prob = 254
		},
		{
			param2 = 0,
			name = "air",
			prob = 254
		},
		{
			param2 = 0,
			name = "air",
			prob = 254
		},
		{
			param2 = 0,
			name = "air",
			prob = 254
		},
		{
			param2 = 0,
			name = "air",
			prob = 254
		},
		{
			param2 = 0,
			name = "air",
			prob = 254
		},
		{
			param2 = 0,
			name = "air",
			prob = 254
		},
		{
			param2 = 0,
			name = "air",
			prob = 254
		},
		{
			param2 = 0,
			name = "air",
			prob = 254
		},
		{
			param2 = 0,
			name = "air",
			prob = 254
		},
		{
			param2 = 0,
			name = "default:dirt_with_grass",
			prob = 254
		},
		{
			param2 = 0,
			name = "default:dirt_with_grass",
			prob = 254
		},
		{
			param2 = 0,
			name = "default:cobble",
			prob = 254
		},
		{
			param2 = 0,
			name = "default:wood",
			prob = 254
		},
		{
			param2 = 0,
			name = "default:wood",
			prob = 254
		},
		{
			param2 = 0,
			name = "farming:straw",
			prob = 254
		},
		{
			param2 = 0,
			name = "farming:straw",
			prob = 254
		},
		{
			param2 = 0,
			name = "farming:straw",
			prob = 254
		},
		{
			param2 = 0,
			name = "farming:straw",
			prob = 254
		},
		{
			param2 = 0,
			name = "farming:straw",
			prob = 254
		},
		{
			param2 = 0,
			name = "default:dirt_with_grass",
			prob = 254
		},
		{
			param2 = 0,
			name = "default:dirt_with_grass",
			prob = 254
		},
		{
			param2 = 0,
			name = "default:dirt_with_grass",
			prob = 254
		},
		{
			param2 = 0,
			name = "default:dirt_with_grass",
			prob = 254
		},
		{
			param2 = 0,
			name = "default:dirt_with_grass",
			prob = 254
		},
		{
			param2 = 0,
			name = "default:dirt_with_grass",
			prob = 254
		},
		{
			param2 = 0,
			name = "air",
			prob = 254
		},
		{
			param2 = 0,
			name = "air",
			prob = 254
		},
		{
			param2 = 0,
			name = "air",
			prob = 254
		},
		{
			param2 = 1,
			name = "doors:door_wood_a",
			prob = 254
		},
		{
			param2 = 0,
			name = "air",
			prob = 254
		},
		{
			param2 = 0,
			name = "default:fence_wood",
			prob = 254
		},
		{
			param2 = 0,
			name = "air",
			prob = 254
		},
		{
			param2 = 0,
			name = "air",
			prob = 254
		},
		{
			param2 = 0,
			name = "air",
			prob = 254
		},
		{
			param2 = 0,
			name = "air",
			prob = 254
		},
		{
			param2 = 1,
			name = "default:wood",
			prob = 254
		},
		{
			param2 = 0,
			name = "default:fence_wood",
			prob = 254
		},
		{
			param2 = 0,
			name = "default:fence_wood",
			prob = 254
		},
		{
			param2 = 0,
			name = "default:fence_wood",
			prob = 254
		},
		{
			param2 = 0,
			name = "default:fence_wood",
			prob = 254
		},
		{
			param2 = 0,
			name = "default:fence_wood",
			prob = 254
		},
		{
			param2 = 0,
			name = "air",
			prob = 254
		},
		{
			param2 = 0,
			name = "air",
			prob = 254
		},
		{
			param2 = 0,
			name = "air",
			prob = 254
		},
		{
			param2 = 0,
			name = "doors:hidden",
			prob = 254
		},
		{
			param2 = 0,
			name = "air",
			prob = 254
		},
		{
			param2 = 0,
			name = "default:fence_wood",
			prob = 254
		},
		{
			param2 = 0,
			name = "air",
			prob = 254
		},
		{
			param2 = 0,
			name = "air",
			prob = 254
		},
		{
			param2 = 0,
			name = "air",
			prob = 254
		},
		{
			param2 = 0,
			name = "air",
			prob = 254
		},
		{
			param2 = 1,
			name = "default:wood",
			prob = 254
		},
		{
			param2 = 0,
			name = "default:fence_wood",
			prob = 254
		},
		{
			param2 = 0,
			name = "air",
			prob = 254
		},
		{
			param2 = 0,
			name = "air",
			prob = 254
		},
		{
			param2 = 0,
			name = "air",
			prob = 254
		},
		{
			param2 = 0,
			name = "air",
			prob = 254
		},
		{
			param2 = 0,
			name = "air",
			prob = 254
		},
		{
			param2 = 0,
			name = "air",
			prob = 254
		},
		{
			param2 = 1,
			name = "cottages:roof_straw",
			prob = 254
		},
		{
			param2 = 1,
			name = "default:wood",
			prob = 254
		},
		{
			param2 = 5,
			name = "default:torch_wall",
			prob = 254
		},
		{
			param2 = 0,
			name = "air",
			prob = 254
		},
		{
			param2 = 0,
			name = "air",
			prob = 254
		},
		{
			param2 = 0,
			name = "air",
			prob = 254
		},
		{
			param2 = 0,
			name = "air",
			prob = 254
		},
		{
			param2 = 0,
			name = "default:wood",
			prob = 254
		},
		{
			param2 = 3,
			name = "cottages:roof_connector_straw",
			prob = 254
		},
		{
			param2 = 3,
			name = "cottages:roof_flat_straw",
			prob = 254
		},
		{
			param2 = 0,
			name = "air",
			prob = 254
		},
		{
			param2 = 0,
			name = "air",
			prob = 254
		},
		{
			param2 = 0,
			name = "air",
			prob = 254
		},
		{
			param2 = 0,
			name = "air",
			prob = 254
		},
		{
			param2 = 0,
			name = "air",
			prob = 254
		},
		{
			param2 = 0,
			name = "air",
			prob = 254
		},
		{
			param2 = 0,
			name = "air",
			prob = 254
		},
		{
			param2 = 1,
			name = "cottages:roof_connector_straw",
			prob = 254
		},
		{
			param2 = 1,
			name = "default:wood",
			prob = 254
		},
		{
			param2 = 7,
			name = "default:tree",
			prob = 254
		},
		{
			param2 = 1,
			name = "default:wood",
			prob = 254
		},
		{
			param2 = 7,
			name = "default:tree",
			prob = 254
		},
		{
			param2 = 1,
			name = "default:wood",
			prob = 254
		},
		{
			param2 = 3,
			name = "cottages:roof_connector_straw",
			prob = 254
		},
		{
			param2 = 0,
			name = "air",
			prob = 254
		},
		{
			param2 = 0,
			name = "air",
			prob = 254
		},
		{
			param2 = 0,
			name = "air",
			prob = 254
		},
		{
			param2 = 0,
			name = "air",
			prob = 254
		},
		{
			param2 = 0,
			name = "air",
			prob = 254
		},
		{
			param2 = 0,
			name = "air",
			prob = 254
		},
		{
			param2 = 0,
			name = "air",
			prob = 254
		},
		{
			param2 = 0,
			name = "air",
			prob = 254
		},
		{
			param2 = 0,
			name = "air",
			prob = 254
		},
		{
			param2 = 0,
			name = "air",
			prob = 254
		},
		{
			param2 = 1,
			name = "cottages:roof_connector_straw",
			prob = 254
		},
		{
			param2 = 0,
			name = "cottages:barrel",
			prob = 254
		},
		{
			param2 = 0,
			name = "air",
			prob = 254
		},
		{
			param2 = 0,
			name = "cottages:straw_bale",
			prob = 254
		},
		{
			param2 = 3,
			name = "cottages:roof_connector_straw",
			prob = 254
		},
		{
			param2 = 0,
			name = "air",
			prob = 254
		},
		{
			param2 = 0,
			name = "air",
			prob = 254
		},
		{
			param2 = 0,
			name = "air",
			prob = 254
		},
		{
			param2 = 0,
			name = "air",
			prob = 254
		},
		{
			param2 = 0,
			name = "air",
			prob = 254
		},
		{
			param2 = 0,
			name = "air",
			prob = 254
		},
		{
			param2 = 0,
			name = "air",
			prob = 254
		},
		{
			param2 = 0,
			name = "air",
			prob = 254
		},
		{
			param2 = 0,
			name = "air",
			prob = 254
		},
		{
			param2 = 0,
			name = "air",
			prob = 254
		},
		{
			param2 = 0,
			name = "air",
			prob = 254
		},
		{
			param2 = 0,
			name = "air",
			prob = 254
		},
		{
			param2 = 1,
			name = "cottages:roof_straw",
			prob = 254
		},
		{
			param2 = 0,
			name = "air",
			prob = 254
		},
		{
			param2 = 3,
			name = "cottages:roof_straw",
			prob = 254
		},
		{
			param2 = 0,
			name = "air",
			prob = 254
		},
		{
			param2 = 0,
			name = "air",
			prob = 254
		},
		{
			param2 = 0,
			name = "air",
			prob = 254
		},
		{
			param2 = 0,
			name = "air",
			prob = 254
		},
		{
			param2 = 0,
			name = "air",
			prob = 254
		},
		{
			param2 = 0,
			name = "air",
			prob = 254
		},
		{
			param2 = 0,
			name = "air",
			prob = 254
		},
		{
			param2 = 0,
			name = "air",
			prob = 254
		},
		{
			param2 = 0,
			name = "air",
			prob = 254
		},
		{
			param2 = 0,
			name = "air",
			prob = 254
		},
		{
			param2 = 0,
			name = "air",
			prob = 254
		},
		{
			param2 = 0,
			name = "air",
			prob = 254
		},
		{
			param2 = 0,
			name = "air",
			prob = 254
		},
		{
			param2 = 0,
			name = "air",
			prob = 254
		},
		{
			param2 = 2,
			name = "cottages:roof_flat_straw",
			prob = 254
		},
		{
			param2 = 0,
			name = "air",
			prob = 254
		},
		{
			param2 = 0,
			name = "air",
			prob = 254
		},
		{
			param2 = 0,
			name = "air",
			prob = 254
		},
		{
			param2 = 0,
			name = "air",
			prob = 254
		},
		{
			param2 = 0,
			name = "air",
			prob = 254
		},
		{
			param2 = 0,
			name = "air",
			prob = 254
		},
		{
			param2 = 0,
			name = "air",
			prob = 254
		},
		{
			param2 = 0,
			name = "air",
			prob = 254
		},
		{
			param2 = 0,
			name = "air",
			prob = 254
		},
		{
			param2 = 0,
			name = "air",
			prob = 254
		},
		{
			param2 = 0,
			name = "air",
			prob = 254
		},
		{
			param2 = 0,
			name = "air",
			prob = 254
		},
		{
			param2 = 0,
			name = "air",
			prob = 254
		},
		{
			param2 = 0,
			name = "air",
			prob = 254
		},
		{
			param2 = 0,
			name = "air",
			prob = 254
		},
		{
			param2 = 0,
			name = "air",
			prob = 254
		},
		{
			param2 = 0,
			name = "air",
			prob = 254
		},
		{
			param2 = 0,
			name = "air",
			prob = 254
		},
		{
			param2 = 0,
			name = "air",
			prob = 254
		},
		{
			param2 = 0,
			name = "air",
			prob = 254
		},
		{
			param2 = 0,
			name = "air",
			prob = 254
		},
		{
			param2 = 0,
			name = "air",
			prob = 254
		},
		{
			param2 = 0,
			name = "air",
			prob = 254
		},
		{
			param2 = 0,
			name = "air",
			prob = 254
		},
		{
			param2 = 0,
			name = "air",
			prob = 254
		},
		{
			param2 = 0,
			name = "air",
			prob = 254
		},
		{
			param2 = 0,
			name = "air",
			prob = 254
		},
		{
			param2 = 0,
			name = "air",
			prob = 254
		},
		{
			param2 = 0,
			name = "air",
			prob = 254
		},
		{
			param2 = 0,
			name = "air",
			prob = 254
		},
		{
			param2 = 0,
			name = "air",
			prob = 254
		},
		{
			param2 = 0,
			name = "air",
			prob = 254
		},
		{
			param2 = 0,
			name = "air",
			prob = 254
		},
		{
			param2 = 0,
			name = "air",
			prob = 254
		},
		{
			param2 = 0,
			name = "air",
			prob = 254
		},
		{
			param2 = 0,
			name = "air",
			prob = 254
		},
		{
			param2 = 0,
			name = "air",
			prob = 254
		},
		{
			param2 = 0,
			name = "air",
			prob = 254
		},
		{
			param2 = 0,
			name = "air",
			prob = 254
		},
		{
			param2 = 0,
			name = "air",
			prob = 254
		},
		{
			param2 = 0,
			name = "air",
			prob = 254
		},
		{
			param2 = 0,
			name = "default:dirt_with_grass",
			prob = 254
		},
		{
			param2 = 0,
			name = "default:dirt_with_grass",
			prob = 254
		},
		{
			param2 = 0,
			name = "default:cobble",
			prob = 254
		},
		{
			param2 = 0,
			name = "default:cobble",
			prob = 254
		},
		{
			param2 = 0,
			name = "default:wood",
			prob = 254
		},
		{
			param2 = 0,
			name = "farming:straw",
			prob = 254
		},
		{
			param2 = 0,
			name = "farming:straw",
			prob = 254
		},
		{
			param2 = 0,
			name = "farming:straw",
			prob = 254
		},
		{
			param2 = 0,
			name = "farming:straw",
			prob = 254
		},
		{
			param2 = 0,
			name = "farming:straw",
			prob = 254
		},
		{
			param2 = 0,
			name = "default:wood",
			prob = 254
		},
		{
			param2 = 0,
			name = "default:dirt_with_grass",
			prob = 254
		},
		{
			param2 = 0,
			name = "default:dirt_with_grass",
			prob = 254
		},
		{
			param2 = 0,
			name = "default:dirt_with_grass",
			prob = 254
		},
		{
			param2 = 0,
			name = "default:dirt_with_grass",
			prob = 254
		},
		{
			param2 = 0,
			name = "default:dirt_with_grass",
			prob = 254
		},
		{
			param2 = 0,
			name = "air",
			prob = 254
		},
		{
			param2 = 0,
			name = "air",
			prob = 254
		},
		{
			param2 = 0,
			name = "air",
			prob = 254
		},
		{
			param2 = 1,
			name = "default:wood",
			prob = 254
		},
		{
			param2 = 0,
			name = "air",
			prob = 254
		},
		{
			param2 = 1,
			name = "cottages:gate_closed",
			prob = 254
		},
		{
			param2 = 0,
			name = "air",
			prob = 254
		},
		{
			param2 = 0,
			name = "air",
			prob = 254
		},
		{
			param2 = 0,
			name = "air",
			prob = 254
		},
		{
			param2 = 0,
			name = "air",
			prob = 254
		},
		{
			param2 = 1,
			name = "doors:door_wood_b",
			prob = 254
		},
		{
			param2 = 0,
			name = "air",
			prob = 254
		},
		{
			param2 = 0,
			name = "air",
			prob = 254
		},
		{
			param2 = 0,
			name = "air",
			prob = 254
		},
		{
			param2 = 0,
			name = "air",
			prob = 254
		},
		{
			param2 = 0,
			name = "default:fence_wood",
			prob = 254
		},
		{
			param2 = 0,
			name = "air",
			prob = 254
		},
		{
			param2 = 0,
			name = "air",
			prob = 254
		},
		{
			param2 = 0,
			name = "air",
			prob = 254
		},
		{
			param2 = 1,
			name = "default:wood",
			prob = 254
		},
		{
			param2 = 0,
			name = "air",
			prob = 254
		},
		{
			param2 = 0,
			name = "air",
			prob = 254
		},
		{
			param2 = 0,
			name = "air",
			prob = 254
		},
		{
			param2 = 0,
			name = "air",
			prob = 254
		},
		{
			param2 = 0,
			name = "air",
			prob = 254
		},
		{
			param2 = 0,
			name = "air",
			prob = 254
		},
		{
			param2 = 0,
			name = "doors:hidden",
			prob = 254
		},
		{
			param2 = 0,
			name = "air",
			prob = 254
		},
		{
			param2 = 0,
			name = "air",
			prob = 254
		},
		{
			param2 = 0,
			name = "air",
			prob = 254
		},
		{
			param2 = 0,
			name = "air",
			prob = 254
		},
		{
			param2 = 0,
			name = "air",
			prob = 254
		},
		{
			param2 = 0,
			name = "air",
			prob = 254
		},
		{
			param2 = 0,
			name = "air",
			prob = 254
		},
		{
			param2 = 1,
			name = "cottages:roof_straw",
			prob = 254
		},
		{
			param2 = 1,
			name = "default:wood",
			prob = 254
		},
		{
			param2 = 0,
			name = "air",
			prob = 254
		},
		{
			param2 = 0,
			name = "air",
			prob = 254
		},
		{
			param2 = 0,
			name = "air",
			prob = 254
		},
		{
			param2 = 0,
			name = "air",
			prob = 254
		},
		{
			param2 = 0,
			name = "air",
			prob = 254
		},
		{
			param2 = 0,
			name = "default:wood",
			prob = 254
		},
		{
			param2 = 3,
			name = "cottages:roof_straw",
			prob = 254
		},
		{
			param2 = 3,
			name = "cottages:roof_flat_straw",
			prob = 254
		},
		{
			param2 = 0,
			name = "air",
			prob = 254
		},
		{
			param2 = 0,
			name = "air",
			prob = 254
		},
		{
			param2 = 0,
			name = "air",
			prob = 254
		},
		{
			param2 = 0,
			name = "air",
			prob = 254
		},
		{
			param2 = 0,
			name = "air",
			prob = 254
		},
		{
			param2 = 0,
			name = "air",
			prob = 254
		},
		{
			param2 = 0,
			name = "air",
			prob = 254
		},
		{
			param2 = 1,
			name = "cottages:roof_connector_straw",
			prob = 254
		},
		{
			param2 = 1,
			name = "default:wood",
			prob = 254
		},
		{
			param2 = 7,
			name = "default:tree",
			prob = 254
		},
		{
			param2 = 1,
			name = "default:wood",
			prob = 254
		},
		{
			param2 = 7,
			name = "default:tree",
			prob = 254
		},
		{
			param2 = 1,
			name = "default:wood",
			prob = 254
		},
		{
			param2 = 3,
			name = "cottages:roof_connector_straw",
			prob = 254
		},
		{
			param2 = 0,
			name = "air",
			prob = 254
		},
		{
			param2 = 0,
			name = "air",
			prob = 254
		},
		{
			param2 = 0,
			name = "air",
			prob = 254
		},
		{
			param2 = 0,
			name = "air",
			prob = 254
		},
		{
			param2 = 0,
			name = "air",
			prob = 254
		},
		{
			param2 = 0,
			name = "air",
			prob = 254
		},
		{
			param2 = 0,
			name = "air",
			prob = 254
		},
		{
			param2 = 0,
			name = "air",
			prob = 254
		},
		{
			param2 = 0,
			name = "air",
			prob = 254
		},
		{
			param2 = 0,
			name = "air",
			prob = 254
		},
		{
			param2 = 1,
			name = "cottages:roof_connector_straw",
			prob = 254
		},
		{
			param2 = 0,
			name = "air",
			prob = 254
		},
		{
			param2 = 0,
			name = "air",
			prob = 254
		},
		{
			param2 = 0,
			name = "cottages:straw_bale",
			prob = 254
		},
		{
			param2 = 3,
			name = "cottages:roof_connector_straw",
			prob = 254
		},
		{
			param2 = 0,
			name = "air",
			prob = 254
		},
		{
			param2 = 0,
			name = "air",
			prob = 254
		},
		{
			param2 = 0,
			name = "air",
			prob = 254
		},
		{
			param2 = 0,
			name = "air",
			prob = 254
		},
		{
			param2 = 0,
			name = "air",
			prob = 254
		},
		{
			param2 = 0,
			name = "air",
			prob = 254
		},
		{
			param2 = 0,
			name = "air",
			prob = 254
		},
		{
			param2 = 0,
			name = "air",
			prob = 254
		},
		{
			param2 = 0,
			name = "air",
			prob = 254
		},
		{
			param2 = 0,
			name = "air",
			prob = 254
		},
		{
			param2 = 0,
			name = "air",
			prob = 254
		},
		{
			param2 = 0,
			name = "air",
			prob = 254
		},
		{
			param2 = 1,
			name = "cottages:roof_straw",
			prob = 254
		},
		{
			param2 = 0,
			name = "air",
			prob = 254
		},
		{
			param2 = 3,
			name = "cottages:roof_straw",
			prob = 254
		},
		{
			param2 = 0,
			name = "air",
			prob = 254
		},
		{
			param2 = 0,
			name = "air",
			prob = 254
		},
		{
			param2 = 0,
			name = "air",
			prob = 254
		},
		{
			param2 = 0,
			name = "air",
			prob = 254
		},
		{
			param2 = 0,
			name = "air",
			prob = 254
		},
		{
			param2 = 0,
			name = "air",
			prob = 254
		},
		{
			param2 = 0,
			name = "air",
			prob = 254
		},
		{
			param2 = 0,
			name = "air",
			prob = 254
		},
		{
			param2 = 0,
			name = "air",
			prob = 254
		},
		{
			param2 = 0,
			name = "air",
			prob = 254
		},
		{
			param2 = 0,
			name = "air",
			prob = 254
		},
		{
			param2 = 0,
			name = "air",
			prob = 254
		},
		{
			param2 = 0,
			name = "air",
			prob = 254
		},
		{
			param2 = 0,
			name = "air",
			prob = 254
		},
		{
			param2 = 2,
			name = "cottages:roof_flat_straw",
			prob = 254
		},
		{
			param2 = 0,
			name = "air",
			prob = 254
		},
		{
			param2 = 0,
			name = "air",
			prob = 254
		},
		{
			param2 = 0,
			name = "air",
			prob = 254
		},
		{
			param2 = 0,
			name = "air",
			prob = 254
		},
		{
			param2 = 0,
			name = "air",
			prob = 254
		},
		{
			param2 = 0,
			name = "air",
			prob = 254
		},
		{
			param2 = 0,
			name = "air",
			prob = 254
		},
		{
			param2 = 0,
			name = "air",
			prob = 254
		},
		{
			param2 = 0,
			name = "air",
			prob = 254
		},
		{
			param2 = 0,
			name = "air",
			prob = 254
		},
		{
			param2 = 0,
			name = "air",
			prob = 254
		},
		{
			param2 = 0,
			name = "air",
			prob = 254
		},
		{
			param2 = 0,
			name = "air",
			prob = 254
		},
		{
			param2 = 0,
			name = "air",
			prob = 254
		},
		{
			param2 = 0,
			name = "air",
			prob = 254
		},
		{
			param2 = 0,
			name = "air",
			prob = 254
		},
		{
			param2 = 0,
			name = "air",
			prob = 254
		},
		{
			param2 = 0,
			name = "air",
			prob = 254
		},
		{
			param2 = 0,
			name = "air",
			prob = 254
		},
		{
			param2 = 0,
			name = "air",
			prob = 254
		},
		{
			param2 = 0,
			name = "air",
			prob = 254
		},
		{
			param2 = 0,
			name = "air",
			prob = 254
		},
		{
			param2 = 0,
			name = "air",
			prob = 254
		},
		{
			param2 = 0,
			name = "air",
			prob = 254
		},
		{
			param2 = 0,
			name = "air",
			prob = 254
		},
		{
			param2 = 0,
			name = "air",
			prob = 254
		},
		{
			param2 = 0,
			name = "air",
			prob = 254
		},
		{
			param2 = 0,
			name = "air",
			prob = 254
		},
		{
			param2 = 0,
			name = "air",
			prob = 254
		},
		{
			param2 = 0,
			name = "air",
			prob = 254
		},
		{
			param2 = 0,
			name = "air",
			prob = 254
		},
		{
			param2 = 0,
			name = "air",
			prob = 254
		},
		{
			param2 = 0,
			name = "air",
			prob = 254
		},
		{
			param2 = 0,
			name = "air",
			prob = 254
		},
		{
			param2 = 0,
			name = "air",
			prob = 254
		},
		{
			param2 = 0,
			name = "air",
			prob = 254
		},
		{
			param2 = 0,
			name = "air",
			prob = 254
		},
		{
			param2 = 0,
			name = "air",
			prob = 254
		},
		{
			param2 = 0,
			name = "air",
			prob = 254
		},
		{
			param2 = 0,
			name = "air",
			prob = 254
		},
		{
			param2 = 0,
			name = "air",
			prob = 254
		},
		{
			param2 = 0,
			name = "default:dirt_with_grass",
			prob = 254
		},
		{
			param2 = 0,
			name = "default:dirt_with_grass",
			prob = 254
		},
		{
			param2 = 0,
			name = "default:dirt_with_grass",
			prob = 254
		},
		{
			param2 = 0,
			name = "default:cobble",
			prob = 254
		},
		{
			param2 = 0,
			name = "default:wood",
			prob = 254
		},
		{
			param2 = 0,
			name = "farming:straw",
			prob = 254
		},
		{
			param2 = 0,
			name = "farming:straw",
			prob = 254
		},
		{
			param2 = 0,
			name = "farming:straw",
			prob = 254
		},
		{
			param2 = 0,
			name = "farming:straw",
			prob = 254
		},
		{
			param2 = 0,
			name = "farming:straw",
			prob = 254
		},
		{
			param2 = 0,
			name = "default:wood",
			prob = 254
		},
		{
			param2 = 0,
			name = "default:dirt_with_grass",
			prob = 254
		},
		{
			param2 = 0,
			name = "default:dirt_with_grass",
			prob = 254
		},
		{
			param2 = 0,
			name = "default:dirt_with_grass",
			prob = 254
		},
		{
			param2 = 0,
			name = "default:dirt_with_grass",
			prob = 254
		},
		{
			param2 = 0,
			name = "default:dirt_with_grass",
			prob = 254
		},
		{
			param2 = 0,
			name = "air",
			prob = 254
		},
		{
			param2 = 0,
			name = "air",
			prob = 254
		},
		{
			param2 = 0,
			name = "cottages:straw_bale",
			prob = 254
		},
		{
			param2 = 1,
			name = "default:wood",
			prob = 254
		},
		{
			param2 = 0,
			name = "air",
			prob = 254
		},
		{
			param2 = 0,
			name = "default:fence_wood",
			prob = 254
		},
		{
			param2 = 0,
			name = "air",
			prob = 254
		},
		{
			param2 = 0,
			name = "air",
			prob = 254
		},
		{
			param2 = 0,
			name = "air",
			prob = 254
		},
		{
			param2 = 0,
			name = "air",
			prob = 254
		},
		{
			param2 = 1,
			name = "doors:door_wood_a",
			prob = 254
		},
		{
			param2 = 0,
			name = "air",
			prob = 254
		},
		{
			param2 = 0,
			name = "air",
			prob = 254
		},
		{
			param2 = 0,
			name = "air",
			prob = 254
		},
		{
			param2 = 0,
			name = "air",
			prob = 254
		},
		{
			param2 = 0,
			name = "default:fence_wood",
			prob = 254
		},
		{
			param2 = 0,
			name = "air",
			prob = 254
		},
		{
			param2 = 0,
			name = "air",
			prob = 254
		},
		{
			param2 = 0,
			name = "air",
			prob = 254
		},
		{
			param2 = 1,
			name = "default:wood",
			prob = 254
		},
		{
			param2 = 0,
			name = "air",
			prob = 254
		},
		{
			param2 = 0,
			name = "air",
			prob = 254
		},
		{
			param2 = 0,
			name = "air",
			prob = 254
		},
		{
			param2 = 0,
			name = "air",
			prob = 254
		},
		{
			param2 = 0,
			name = "air",
			prob = 254
		},
		{
			param2 = 0,
			name = "air",
			prob = 254
		},
		{
			param2 = 1,
			name = "doors:hidden",
			prob = 254
		},
		{
			param2 = 0,
			name = "air",
			prob = 254
		},
		{
			param2 = 0,
			name = "air",
			prob = 254
		},
		{
			param2 = 0,
			name = "air",
			prob = 254
		},
		{
			param2 = 0,
			name = "air",
			prob = 254
		},
		{
			param2 = 0,
			name = "air",
			prob = 254
		},
		{
			param2 = 0,
			name = "air",
			prob = 254
		},
		{
			param2 = 0,
			name = "air",
			prob = 254
		},
		{
			param2 = 1,
			name = "cottages:roof_straw",
			prob = 254
		},
		{
			param2 = 1,
			name = "default:wood",
			prob = 254
		},
		{
			param2 = 0,
			name = "air",
			prob = 254
		},
		{
			param2 = 0,
			name = "air",
			prob = 254
		},
		{
			param2 = 0,
			name = "air",
			prob = 254
		},
		{
			param2 = 0,
			name = "air",
			prob = 254
		},
		{
			param2 = 0,
			name = "air",
			prob = 254
		},
		{
			param2 = 0,
			name = "default:wood",
			prob = 254
		},
		{
			param2 = 3,
			name = "cottages:roof_straw",
			prob = 254
		},
		{
			param2 = 3,
			name = "cottages:roof_flat_straw",
			prob = 254
		},
		{
			param2 = 0,
			name = "air",
			prob = 254
		},
		{
			param2 = 0,
			name = "air",
			prob = 254
		},
		{
			param2 = 0,
			name = "air",
			prob = 254
		},
		{
			param2 = 0,
			name = "air",
			prob = 254
		},
		{
			param2 = 0,
			name = "air",
			prob = 254
		},
		{
			param2 = 0,
			name = "air",
			prob = 254
		},
		{
			param2 = 0,
			name = "air",
			prob = 254
		},
		{
			param2 = 1,
			name = "cottages:roof_connector_straw",
			prob = 254
		},
		{
			param2 = 1,
			name = "default:wood",
			prob = 254
		},
		{
			param2 = 7,
			name = "default:tree",
			prob = 254
		},
		{
			param2 = 1,
			name = "default:wood",
			prob = 254
		},
		{
			param2 = 7,
			name = "default:tree",
			prob = 254
		},
		{
			param2 = 1,
			name = "default:wood",
			prob = 254
		},
		{
			param2 = 3,
			name = "cottages:roof_connector_straw",
			prob = 254
		},
		{
			param2 = 0,
			name = "air",
			prob = 254
		},
		{
			param2 = 0,
			name = "air",
			prob = 254
		},
		{
			param2 = 0,
			name = "air",
			prob = 254
		},
		{
			param2 = 0,
			name = "air",
			prob = 254
		},
		{
			param2 = 0,
			name = "air",
			prob = 254
		},
		{
			param2 = 0,
			name = "air",
			prob = 254
		},
		{
			param2 = 0,
			name = "air",
			prob = 254
		},
		{
			param2 = 0,
			name = "air",
			prob = 254
		},
		{
			param2 = 0,
			name = "air",
			prob = 254
		},
		{
			param2 = 0,
			name = "air",
			prob = 254
		},
		{
			param2 = 1,
			name = "cottages:roof_connector_straw",
			prob = 254
		},
		{
			param2 = 3,
			name = "cottages:shelf",
			prob = 254
		},
		{
			param2 = 0,
			name = "air",
			prob = 254
		},
		{
			param2 = 0,
			name = "cottages:straw_bale",
			prob = 254
		},
		{
			param2 = 3,
			name = "cottages:roof_connector_straw",
			prob = 254
		},
		{
			param2 = 0,
			name = "air",
			prob = 254
		},
		{
			param2 = 0,
			name = "air",
			prob = 254
		},
		{
			param2 = 0,
			name = "air",
			prob = 254
		},
		{
			param2 = 0,
			name = "air",
			prob = 254
		},
		{
			param2 = 0,
			name = "air",
			prob = 254
		},
		{
			param2 = 0,
			name = "air",
			prob = 254
		},
		{
			param2 = 0,
			name = "air",
			prob = 254
		},
		{
			param2 = 0,
			name = "air",
			prob = 254
		},
		{
			param2 = 0,
			name = "air",
			prob = 254
		},
		{
			param2 = 0,
			name = "air",
			prob = 254
		},
		{
			param2 = 0,
			name = "air",
			prob = 254
		},
		{
			param2 = 0,
			name = "air",
			prob = 254
		},
		{
			param2 = 1,
			name = "cottages:roof_straw",
			prob = 254
		},
		{
			param2 = 0,
			name = "air",
			prob = 254
		},
		{
			param2 = 3,
			name = "cottages:roof_straw",
			prob = 254
		},
		{
			param2 = 0,
			name = "air",
			prob = 254
		},
		{
			param2 = 0,
			name = "air",
			prob = 254
		},
		{
			param2 = 0,
			name = "air",
			prob = 254
		},
		{
			param2 = 0,
			name = "air",
			prob = 254
		},
		{
			param2 = 0,
			name = "air",
			prob = 254
		},
		{
			param2 = 0,
			name = "air",
			prob = 254
		},
		{
			param2 = 0,
			name = "air",
			prob = 254
		},
		{
			param2 = 0,
			name = "air",
			prob = 254
		},
		{
			param2 = 0,
			name = "air",
			prob = 254
		},
		{
			param2 = 0,
			name = "air",
			prob = 254
		},
		{
			param2 = 0,
			name = "air",
			prob = 254
		},
		{
			param2 = 0,
			name = "air",
			prob = 254
		},
		{
			param2 = 0,
			name = "air",
			prob = 254
		},
		{
			param2 = 0,
			name = "air",
			prob = 254
		},
		{
			param2 = 2,
			name = "cottages:roof_flat_straw",
			prob = 254
		},
		{
			param2 = 0,
			name = "air",
			prob = 254
		},
		{
			param2 = 0,
			name = "air",
			prob = 254
		},
		{
			param2 = 0,
			name = "air",
			prob = 254
		},
		{
			param2 = 0,
			name = "air",
			prob = 254
		},
		{
			param2 = 0,
			name = "air",
			prob = 254
		},
		{
			param2 = 0,
			name = "air",
			prob = 254
		},
		{
			param2 = 0,
			name = "air",
			prob = 254
		},
		{
			param2 = 0,
			name = "air",
			prob = 254
		},
		{
			param2 = 0,
			name = "air",
			prob = 254
		},
		{
			param2 = 0,
			name = "air",
			prob = 254
		},
		{
			param2 = 0,
			name = "air",
			prob = 254
		},
		{
			param2 = 0,
			name = "air",
			prob = 254
		},
		{
			param2 = 0,
			name = "air",
			prob = 254
		},
		{
			param2 = 0,
			name = "air",
			prob = 254
		},
		{
			param2 = 0,
			name = "air",
			prob = 254
		},
		{
			param2 = 0,
			name = "air",
			prob = 254
		},
		{
			param2 = 0,
			name = "air",
			prob = 254
		},
		{
			param2 = 0,
			name = "air",
			prob = 254
		},
		{
			param2 = 0,
			name = "air",
			prob = 254
		},
		{
			param2 = 0,
			name = "air",
			prob = 254
		},
		{
			param2 = 0,
			name = "air",
			prob = 254
		},
		{
			param2 = 0,
			name = "air",
			prob = 254
		},
		{
			param2 = 0,
			name = "air",
			prob = 254
		},
		{
			param2 = 0,
			name = "air",
			prob = 254
		},
		{
			param2 = 0,
			name = "air",
			prob = 254
		},
		{
			param2 = 0,
			name = "air",
			prob = 254
		},
		{
			param2 = 0,
			name = "air",
			prob = 254
		},
		{
			param2 = 0,
			name = "air",
			prob = 254
		},
		{
			param2 = 0,
			name = "air",
			prob = 254
		},
		{
			param2 = 0,
			name = "air",
			prob = 254
		},
		{
			param2 = 0,
			name = "air",
			prob = 254
		},
		{
			param2 = 0,
			name = "air",
			prob = 254
		},
		{
			param2 = 0,
			name = "air",
			prob = 254
		},
		{
			param2 = 0,
			name = "air",
			prob = 254
		},
		{
			param2 = 0,
			name = "air",
			prob = 254
		},
		{
			param2 = 0,
			name = "air",
			prob = 254
		},
		{
			param2 = 0,
			name = "air",
			prob = 254
		},
		{
			param2 = 0,
			name = "air",
			prob = 254
		},
		{
			param2 = 0,
			name = "air",
			prob = 254
		},
		{
			param2 = 0,
			name = "air",
			prob = 254
		},
		{
			param2 = 0,
			name = "air",
			prob = 254
		},
		{
			param2 = 0,
			name = "default:dirt_with_grass",
			prob = 254
		},
		{
			param2 = 0,
			name = "default:dirt_with_grass",
			prob = 254
		},
		{
			param2 = 0,
			name = "default:dirt_with_grass",
			prob = 254
		},
		{
			param2 = 0,
			name = "default:cobble",
			prob = 254
		},
		{
			param2 = 0,
			name = "default:wood",
			prob = 254
		},
		{
			param2 = 0,
			name = "farming:straw",
			prob = 254
		},
		{
			param2 = 0,
			name = "farming:straw",
			prob = 254
		},
		{
			param2 = 0,
			name = "farming:straw",
			prob = 254
		},
		{
			param2 = 0,
			name = "farming:straw",
			prob = 254
		},
		{
			param2 = 0,
			name = "farming:straw",
			prob = 254
		},
		{
			param2 = 0,
			name = "default:dirt_with_grass",
			prob = 254
		},
		{
			param2 = 0,
			name = "default:dirt_with_grass",
			prob = 254
		},
		{
			param2 = 0,
			name = "default:dirt_with_grass",
			prob = 254
		},
		{
			param2 = 0,
			name = "default:dirt_with_grass",
			prob = 254
		},
		{
			param2 = 0,
			name = "default:dirt_with_grass",
			prob = 254
		},
		{
			param2 = 0,
			name = "default:dirt_with_grass",
			prob = 254
		},
		{
			param2 = 0,
			name = "air",
			prob = 254
		},
		{
			param2 = 0,
			name = "air",
			prob = 254
		},
		{
			param2 = 0,
			name = "cottages:straw_bale",
			prob = 254
		},
		{
			param2 = 1,
			name = "default:wood",
			prob = 254
		},
		{
			param2 = 0,
			name = "air",
			prob = 254
		},
		{
			param2 = 0,
			name = "default:fence_wood",
			prob = 254
		},
		{
			param2 = 0,
			name = "air",
			prob = 254
		},
		{
			param2 = 0,
			name = "air",
			prob = 254
		},
		{
			param2 = 0,
			name = "air",
			prob = 254
		},
		{
			param2 = 0,
			name = "air",
			prob = 254
		},
		{
			param2 = 1,
			name = "default:wood",
			prob = 254
		},
		{
			param2 = 0,
			name = "default:fence_wood",
			prob = 254
		},
		{
			param2 = 0,
			name = "air",
			prob = 254
		},
		{
			param2 = 0,
			name = "air",
			prob = 254
		},
		{
			param2 = 0,
			name = "air",
			prob = 254
		},
		{
			param2 = 0,
			name = "default:fence_wood",
			prob = 254
		},
		{
			param2 = 0,
			name = "air",
			prob = 254
		},
		{
			param2 = 0,
			name = "air",
			prob = 254
		},
		{
			param2 = 0,
			name = "cottages:straw_bale",
			prob = 254
		},
		{
			param2 = 1,
			name = "default:wood",
			prob = 254
		},
		{
			param2 = 0,
			name = "air",
			prob = 254
		},
		{
			param2 = 0,
			name = "air",
			prob = 254
		},
		{
			param2 = 0,
			name = "air",
			prob = 254
		},
		{
			param2 = 0,
			name = "air",
			prob = 254
		},
		{
			param2 = 0,
			name = "air",
			prob = 254
		},
		{
			param2 = 0,
			name = "air",
			prob = 254
		},
		{
			param2 = 1,
			name = "default:wood",
			prob = 254
		},
		{
			param2 = 0,
			name = "default:fence_wood",
			prob = 254
		},
		{
			param2 = 0,
			name = "air",
			prob = 254
		},
		{
			param2 = 0,
			name = "air",
			prob = 254
		},
		{
			param2 = 0,
			name = "air",
			prob = 254
		},
		{
			param2 = 0,
			name = "air",
			prob = 254
		},
		{
			param2 = 0,
			name = "air",
			prob = 254
		},
		{
			param2 = 0,
			name = "air",
			prob = 254
		},
		{
			param2 = 1,
			name = "cottages:roof_straw",
			prob = 254
		},
		{
			param2 = 1,
			name = "default:wood",
			prob = 254
		},
		{
			param2 = 0,
			name = "air",
			prob = 254
		},
		{
			param2 = 0,
			name = "air",
			prob = 254
		},
		{
			param2 = 0,
			name = "air",
			prob = 254
		},
		{
			param2 = 0,
			name = "air",
			prob = 254
		},
		{
			param2 = 0,
			name = "air",
			prob = 254
		},
		{
			param2 = 0,
			name = "default:wood",
			prob = 254
		},
		{
			param2 = 3,
			name = "cottages:roof_connector_straw",
			prob = 254
		},
		{
			param2 = 3,
			name = "cottages:roof_flat_straw",
			prob = 254
		},
		{
			param2 = 0,
			name = "air",
			prob = 254
		},
		{
			param2 = 0,
			name = "air",
			prob = 254
		},
		{
			param2 = 0,
			name = "air",
			prob = 254
		},
		{
			param2 = 0,
			name = "air",
			prob = 254
		},
		{
			param2 = 0,
			name = "air",
			prob = 254
		},
		{
			param2 = 0,
			name = "air",
			prob = 254
		},
		{
			param2 = 0,
			name = "air",
			prob = 254
		},
		{
			param2 = 1,
			name = "cottages:roof_connector_straw",
			prob = 254
		},
		{
			param2 = 1,
			name = "default:wood",
			prob = 254
		},
		{
			param2 = 7,
			name = "default:tree",
			prob = 254
		},
		{
			param2 = 1,
			name = "default:wood",
			prob = 254
		},
		{
			param2 = 7,
			name = "default:tree",
			prob = 254
		},
		{
			param2 = 1,
			name = "default:wood",
			prob = 254
		},
		{
			param2 = 3,
			name = "cottages:roof_connector_straw",
			prob = 254
		},
		{
			param2 = 0,
			name = "air",
			prob = 254
		},
		{
			param2 = 0,
			name = "air",
			prob = 254
		},
		{
			param2 = 0,
			name = "air",
			prob = 254
		},
		{
			param2 = 0,
			name = "air",
			prob = 254
		},
		{
			param2 = 0,
			name = "air",
			prob = 254
		},
		{
			param2 = 0,
			name = "air",
			prob = 254
		},
		{
			param2 = 0,
			name = "air",
			prob = 254
		},
		{
			param2 = 0,
			name = "air",
			prob = 254
		},
		{
			param2 = 0,
			name = "air",
			prob = 254
		},
		{
			param2 = 0,
			name = "air",
			prob = 254
		},
		{
			param2 = 1,
			name = "cottages:roof_connector_straw",
			prob = 254
		},
		{
			param2 = 0,
			name = "cottages:straw_bale",
			prob = 254
		},
		{
			param2 = 0,
			name = "air",
			prob = 254
		},
		{
			param2 = 0,
			name = "cottages:straw_bale",
			prob = 254
		},
		{
			param2 = 3,
			name = "cottages:roof_connector_straw",
			prob = 254
		},
		{
			param2 = 0,
			name = "air",
			prob = 254
		},
		{
			param2 = 0,
			name = "air",
			prob = 254
		},
		{
			param2 = 0,
			name = "air",
			prob = 254
		},
		{
			param2 = 0,
			name = "air",
			prob = 254
		},
		{
			param2 = 0,
			name = "air",
			prob = 254
		},
		{
			param2 = 0,
			name = "air",
			prob = 254
		},
		{
			param2 = 0,
			name = "air",
			prob = 254
		},
		{
			param2 = 0,
			name = "air",
			prob = 254
		},
		{
			param2 = 0,
			name = "air",
			prob = 254
		},
		{
			param2 = 0,
			name = "air",
			prob = 254
		},
		{
			param2 = 0,
			name = "air",
			prob = 254
		},
		{
			param2 = 0,
			name = "air",
			prob = 254
		},
		{
			param2 = 1,
			name = "cottages:roof_straw",
			prob = 254
		},
		{
			param2 = 0,
			name = "air",
			prob = 254
		},
		{
			param2 = 3,
			name = "cottages:roof_straw",
			prob = 254
		},
		{
			param2 = 0,
			name = "air",
			prob = 254
		},
		{
			param2 = 0,
			name = "air",
			prob = 254
		},
		{
			param2 = 0,
			name = "air",
			prob = 254
		},
		{
			param2 = 0,
			name = "air",
			prob = 254
		},
		{
			param2 = 0,
			name = "air",
			prob = 254
		},
		{
			param2 = 0,
			name = "air",
			prob = 254
		},
		{
			param2 = 0,
			name = "air",
			prob = 254
		},
		{
			param2 = 0,
			name = "air",
			prob = 254
		},
		{
			param2 = 0,
			name = "air",
			prob = 254
		},
		{
			param2 = 0,
			name = "air",
			prob = 254
		},
		{
			param2 = 0,
			name = "air",
			prob = 254
		},
		{
			param2 = 0,
			name = "air",
			prob = 254
		},
		{
			param2 = 0,
			name = "air",
			prob = 254
		},
		{
			param2 = 0,
			name = "air",
			prob = 254
		},
		{
			param2 = 2,
			name = "cottages:roof_flat_straw",
			prob = 254
		},
		{
			param2 = 0,
			name = "air",
			prob = 254
		},
		{
			param2 = 0,
			name = "air",
			prob = 254
		},
		{
			param2 = 0,
			name = "air",
			prob = 254
		},
		{
			param2 = 0,
			name = "air",
			prob = 254
		},
		{
			param2 = 0,
			name = "air",
			prob = 254
		},
		{
			param2 = 0,
			name = "air",
			prob = 254
		},
		{
			param2 = 0,
			name = "air",
			prob = 254
		},
		{
			param2 = 0,
			name = "air",
			prob = 254
		},
		{
			param2 = 0,
			name = "air",
			prob = 254
		},
		{
			param2 = 0,
			name = "air",
			prob = 254
		},
		{
			param2 = 0,
			name = "air",
			prob = 254
		},
		{
			param2 = 0,
			name = "air",
			prob = 254
		},
		{
			param2 = 0,
			name = "air",
			prob = 254
		},
		{
			param2 = 0,
			name = "air",
			prob = 254
		},
		{
			param2 = 0,
			name = "air",
			prob = 254
		},
		{
			param2 = 0,
			name = "air",
			prob = 254
		},
		{
			param2 = 0,
			name = "air",
			prob = 254
		},
		{
			param2 = 0,
			name = "air",
			prob = 254
		},
		{
			param2 = 0,
			name = "air",
			prob = 254
		},
		{
			param2 = 0,
			name = "air",
			prob = 254
		},
		{
			param2 = 0,
			name = "air",
			prob = 254
		},
		{
			param2 = 0,
			name = "air",
			prob = 254
		},
		{
			param2 = 0,
			name = "air",
			prob = 254
		},
		{
			param2 = 0,
			name = "air",
			prob = 254
		},
		{
			param2 = 0,
			name = "air",
			prob = 254
		},
		{
			param2 = 0,
			name = "air",
			prob = 254
		},
		{
			param2 = 0,
			name = "air",
			prob = 254
		},
		{
			param2 = 0,
			name = "air",
			prob = 254
		},
		{
			param2 = 0,
			name = "air",
			prob = 254
		},
		{
			param2 = 0,
			name = "air",
			prob = 254
		},
		{
			param2 = 0,
			name = "air",
			prob = 254
		},
		{
			param2 = 0,
			name = "air",
			prob = 254
		},
		{
			param2 = 0,
			name = "air",
			prob = 254
		},
		{
			param2 = 0,
			name = "air",
			prob = 254
		},
		{
			param2 = 0,
			name = "air",
			prob = 254
		},
		{
			param2 = 0,
			name = "air",
			prob = 254
		},
		{
			param2 = 0,
			name = "air",
			prob = 254
		},
		{
			param2 = 0,
			name = "air",
			prob = 254
		},
		{
			param2 = 0,
			name = "air",
			prob = 254
		},
		{
			param2 = 0,
			name = "air",
			prob = 254
		},
		{
			param2 = 0,
			name = "air",
			prob = 254
		},
		{
			param2 = 0,
			name = "default:dirt_with_grass",
			prob = 254
		},
		{
			param2 = 0,
			name = "default:dirt_with_grass",
			prob = 254
		},
		{
			param2 = 0,
			name = "default:dirt_with_grass",
			prob = 254
		},
		{
			param2 = 0,
			name = "default:cobble",
			prob = 254
		},
		{
			param2 = 0,
			name = "default:wood",
			prob = 254
		},
		{
			param2 = 0,
			name = "default:wood",
			prob = 254
		},
		{
			param2 = 0,
			name = "default:cobble",
			prob = 254
		},
		{
			param2 = 0,
			name = "default:cobble",
			prob = 254
		},
		{
			param2 = 0,
			name = "default:cobble",
			prob = 254
		},
		{
			param2 = 0,
			name = "default:cobble",
			prob = 254
		},
		{
			param2 = 0,
			name = "default:dirt_with_grass",
			prob = 254
		},
		{
			param2 = 0,
			name = "default:dirt_with_grass",
			prob = 254
		},
		{
			param2 = 0,
			name = "default:dirt_with_grass",
			prob = 254
		},
		{
			param2 = 0,
			name = "default:dirt_with_grass",
			prob = 254
		},
		{
			param2 = 0,
			name = "default:dirt_with_grass",
			prob = 254
		},
		{
			param2 = 0,
			name = "default:dirt_with_grass",
			prob = 254
		},
		{
			param2 = 0,
			name = "air",
			prob = 254
		},
		{
			param2 = 0,
			name = "air",
			prob = 254
		},
		{
			param2 = 0,
			name = "cottages:straw_bale",
			prob = 254
		},
		{
			param2 = 1,
			name = "default:wood",
			prob = 254
		},
		{
			param2 = 0,
			name = "air",
			prob = 254
		},
		{
			param2 = 0,
			name = "default:fence_wood",
			prob = 254
		},
		{
			param2 = 0,
			name = "default:tree",
			prob = 254
		},
		{
			param2 = 2,
			name = "default:chest",
			prob = 254
		},
		{
			param2 = 1,
			name = "default:wood",
			prob = 254
		},
		{
			param2 = 1,
			name = "default:wood",
			prob = 254
		},
		{
			param2 = 3,
			name = "cottages:washing",
			prob = 254
		},
		{
			param2 = 0,
			name = "air",
			prob = 254
		},
		{
			param2 = 0,
			name = "air",
			prob = 254
		},
		{
			param2 = 0,
			name = "air",
			prob = 254
		},
		{
			param2 = 0,
			name = "air",
			prob = 254
		},
		{
			param2 = 0,
			name = "default:fence_wood",
			prob = 254
		},
		{
			param2 = 0,
			name = "air",
			prob = 254
		},
		{
			param2 = 0,
			name = "air",
			prob = 254
		},
		{
			param2 = 0,
			name = "air",
			prob = 254
		},
		{
			param2 = 1,
			name = "default:wood",
			prob = 254
		},
		{
			param2 = 0,
			name = "air",
			prob = 254
		},
		{
			param2 = 0,
			name = "default:fence_wood",
			prob = 254
		},
		{
			param2 = 0,
			name = "default:tree",
			prob = 254
		},
		{
			param2 = 1,
			name = "default:wood",
			prob = 254
		},
		{
			param2 = 1,
			name = "default:wood",
			prob = 254
		},
		{
			param2 = 1,
			name = "default:wood",
			prob = 254
		},
		{
			param2 = 0,
			name = "air",
			prob = 254
		},
		{
			param2 = 0,
			name = "air",
			prob = 254
		},
		{
			param2 = 0,
			name = "air",
			prob = 254
		},
		{
			param2 = 0,
			name = "air",
			prob = 254
		},
		{
			param2 = 0,
			name = "air",
			prob = 254
		},
		{
			param2 = 0,
			name = "air",
			prob = 254
		},
		{
			param2 = 0,
			name = "air",
			prob = 254
		},
		{
			param2 = 0,
			name = "air",
			prob = 254
		},
		{
			param2 = 1,
			name = "cottages:roof_straw",
			prob = 254
		},
		{
			param2 = 1,
			name = "default:wood",
			prob = 254
		},
		{
			param2 = 0,
			name = "default:wood",
			prob = 254
		},
		{
			param2 = 12,
			name = "default:tree",
			prob = 254
		},
		{
			param2 = 12,
			name = "default:tree",
			prob = 254
		},
		{
			param2 = 12,
			name = "default:tree",
			prob = 254
		},
		{
			param2 = 1,
			name = "default:wood",
			prob = 254
		},
		{
			param2 = 1,
			name = "default:wood",
			prob = 254
		},
		{
			param2 = 3,
			name = "cottages:roof_straw",
			prob = 254
		},
		{
			param2 = 0,
			name = "air",
			prob = 254
		},
		{
			param2 = 0,
			name = "air",
			prob = 254
		},
		{
			param2 = 0,
			name = "air",
			prob = 254
		},
		{
			param2 = 0,
			name = "air",
			prob = 254
		},
		{
			param2 = 0,
			name = "air",
			prob = 254
		},
		{
			param2 = 0,
			name = "air",
			prob = 254
		},
		{
			param2 = 0,
			name = "air",
			prob = 254
		},
		{
			param2 = 0,
			name = "air",
			prob = 254
		},
		{
			param2 = 1,
			name = "cottages:roof_connector_straw",
			prob = 254
		},
		{
			param2 = 1,
			name = "default:wood",
			prob = 254
		},
		{
			param2 = 7,
			name = "default:tree",
			prob = 254
		},
		{
			param2 = 0,
			name = "default:tree",
			prob = 254
		},
		{
			param2 = 7,
			name = "default:tree",
			prob = 254
		},
		{
			param2 = 1,
			name = "default:wood",
			prob = 254
		},
		{
			param2 = 3,
			name = "cottages:roof_connector_straw",
			prob = 254
		},
		{
			param2 = 0,
			name = "air",
			prob = 254
		},
		{
			param2 = 0,
			name = "air",
			prob = 254
		},
		{
			param2 = 0,
			name = "air",
			prob = 254
		},
		{
			param2 = 0,
			name = "air",
			prob = 254
		},
		{
			param2 = 0,
			name = "air",
			prob = 254
		},
		{
			param2 = 0,
			name = "air",
			prob = 254
		},
		{
			param2 = 0,
			name = "air",
			prob = 254
		},
		{
			param2 = 0,
			name = "air",
			prob = 254
		},
		{
			param2 = 0,
			name = "air",
			prob = 254
		},
		{
			param2 = 0,
			name = "air",
			prob = 254
		},
		{
			param2 = 1,
			name = "cottages:roof_connector_straw",
			prob = 254
		},
		{
			param2 = 0,
			name = "default:fence_wood",
			prob = 254
		},
		{
			param2 = 0,
			name = "air",
			prob = 254
		},
		{
			param2 = 0,
			name = "default:fence_wood",
			prob = 254
		},
		{
			param2 = 3,
			name = "cottages:roof_connector_straw",
			prob = 254
		},
		{
			param2 = 0,
			name = "air",
			prob = 254
		},
		{
			param2 = 0,
			name = "air",
			prob = 254
		},
		{
			param2 = 0,
			name = "air",
			prob = 254
		},
		{
			param2 = 0,
			name = "air",
			prob = 254
		},
		{
			param2 = 0,
			name = "air",
			prob = 254
		},
		{
			param2 = 0,
			name = "air",
			prob = 254
		},
		{
			param2 = 0,
			name = "air",
			prob = 254
		},
		{
			param2 = 0,
			name = "air",
			prob = 254
		},
		{
			param2 = 0,
			name = "air",
			prob = 254
		},
		{
			param2 = 0,
			name = "air",
			prob = 254
		},
		{
			param2 = 0,
			name = "air",
			prob = 254
		},
		{
			param2 = 0,
			name = "air",
			prob = 254
		},
		{
			param2 = 1,
			name = "cottages:roof_connector_straw",
			prob = 254
		},
		{
			param2 = 0,
			name = "air",
			prob = 254
		},
		{
			param2 = 3,
			name = "cottages:roof_connector_straw",
			prob = 254
		},
		{
			param2 = 0,
			name = "air",
			prob = 254
		},
		{
			param2 = 0,
			name = "air",
			prob = 254
		},
		{
			param2 = 0,
			name = "air",
			prob = 254
		},
		{
			param2 = 0,
			name = "air",
			prob = 254
		},
		{
			param2 = 0,
			name = "air",
			prob = 254
		},
		{
			param2 = 0,
			name = "air",
			prob = 254
		},
		{
			param2 = 0,
			name = "air",
			prob = 254
		},
		{
			param2 = 0,
			name = "air",
			prob = 254
		},
		{
			param2 = 0,
			name = "air",
			prob = 254
		},
		{
			param2 = 0,
			name = "air",
			prob = 254
		},
		{
			param2 = 0,
			name = "air",
			prob = 254
		},
		{
			param2 = 0,
			name = "air",
			prob = 254
		},
		{
			param2 = 0,
			name = "air",
			prob = 254
		},
		{
			param2 = 0,
			name = "air",
			prob = 254
		},
		{
			param2 = 2,
			name = "cottages:roof_flat_straw",
			prob = 254
		},
		{
			param2 = 0,
			name = "air",
			prob = 254
		},
		{
			param2 = 0,
			name = "air",
			prob = 254
		},
		{
			param2 = 0,
			name = "air",
			prob = 254
		},
		{
			param2 = 0,
			name = "air",
			prob = 254
		},
		{
			param2 = 0,
			name = "air",
			prob = 254
		},
		{
			param2 = 0,
			name = "air",
			prob = 254
		},
		{
			param2 = 0,
			name = "air",
			prob = 254
		},
		{
			param2 = 0,
			name = "air",
			prob = 254
		},
		{
			param2 = 0,
			name = "air",
			prob = 254
		},
		{
			param2 = 0,
			name = "air",
			prob = 254
		},
		{
			param2 = 0,
			name = "air",
			prob = 254
		},
		{
			param2 = 0,
			name = "air",
			prob = 254
		},
		{
			param2 = 0,
			name = "air",
			prob = 254
		},
		{
			param2 = 0,
			name = "air",
			prob = 254
		},
		{
			param2 = 0,
			name = "air",
			prob = 254
		},
		{
			param2 = 0,
			name = "air",
			prob = 254
		},
		{
			param2 = 0,
			name = "air",
			prob = 254
		},
		{
			param2 = 0,
			name = "air",
			prob = 254
		},
		{
			param2 = 0,
			name = "air",
			prob = 254
		},
		{
			param2 = 0,
			name = "air",
			prob = 254
		},
		{
			param2 = 0,
			name = "air",
			prob = 254
		},
		{
			param2 = 0,
			name = "air",
			prob = 254
		},
		{
			param2 = 0,
			name = "air",
			prob = 254
		},
		{
			param2 = 0,
			name = "air",
			prob = 254
		},
		{
			param2 = 0,
			name = "air",
			prob = 254
		},
		{
			param2 = 0,
			name = "air",
			prob = 254
		},
		{
			param2 = 0,
			name = "air",
			prob = 254
		},
		{
			param2 = 0,
			name = "air",
			prob = 254
		},
		{
			param2 = 3,
			name = "air",
			prob = 254
		},
		{
			param2 = 3,
			name = "air",
			prob = 254
		},
		{
			param2 = 0,
			name = "air",
			prob = 254
		},
		{
			param2 = 0,
			name = "air",
			prob = 254
		},
		{
			param2 = 0,
			name = "air",
			prob = 254
		},
		{
			param2 = 0,
			name = "air",
			prob = 254
		},
		{
			param2 = 0,
			name = "air",
			prob = 254
		},
		{
			param2 = 0,
			name = "air",
			prob = 254
		},
		{
			param2 = 0,
			name = "air",
			prob = 254
		},
		{
			param2 = 0,
			name = "air",
			prob = 254
		},
		{
			param2 = 0,
			name = "air",
			prob = 254
		},
		{
			param2 = 0,
			name = "air",
			prob = 254
		},
		{
			param2 = 0,
			name = "air",
			prob = 254
		},
		{
			param2 = 0,
			name = "default:dirt_with_grass",
			prob = 254
		},
		{
			param2 = 0,
			name = "default:dirt_with_grass",
			prob = 254
		},
		{
			param2 = 0,
			name = "default:dirt_with_grass",
			prob = 254
		},
		{
			param2 = 0,
			name = "default:cobble",
			prob = 254
		},
		{
			param2 = 0,
			name = "default:wood",
			prob = 254
		},
		{
			param2 = 0,
			name = "default:wood",
			prob = 254
		},
		{
			param2 = 0,
			name = "default:wood",
			prob = 254
		},
		{
			param2 = 0,
			name = "default:wood",
			prob = 254
		},
		{
			param2 = 0,
			name = "default:wood",
			prob = 254
		},
		{
			param2 = 0,
			name = "default:cobble",
			prob = 254
		},
		{
			param2 = 0,
			name = "default:dirt_with_grass",
			prob = 254
		},
		{
			param2 = 0,
			name = "default:dirt_with_grass",
			prob = 254
		},
		{
			param2 = 0,
			name = "default:dirt_with_grass",
			prob = 254
		},
		{
			param2 = 0,
			name = "default:dirt_with_grass",
			prob = 254
		},
		{
			param2 = 0,
			name = "default:dirt_with_grass",
			prob = 254
		},
		{
			param2 = 0,
			name = "default:dirt_with_grass",
			prob = 254
		},
		{
			param2 = 0,
			name = "air",
			prob = 254
		},
		{
			param2 = 0,
			name = "air",
			prob = 254
		},
		{
			param2 = 0,
			name = "cottages:straw_bale",
			prob = 254
		},
		{
			param2 = 1,
			name = "default:wood",
			prob = 254
		},
		{
			param2 = 0,
			name = "air",
			prob = 254
		},
		{
			param2 = 0,
			name = "air",
			prob = 254
		},
		{
			param2 = 5,
			name = "default:ladder_wood",
			prob = 254
		},
		{
			param2 = 2,
			name = "cottages:bench",
			prob = 254
		},
		{
			param2 = 2,
			name = "cottages:bench",
			prob = 254
		},
		{
			param2 = 1,
			name = "default:wood",
			prob = 254
		},
		{
			param2 = 0,
			name = "air",
			prob = 254
		},
		{
			param2 = 0,
			name = "air",
			prob = 254
		},
		{
			param2 = 0,
			name = "air",
			prob = 254
		},
		{
			param2 = 0,
			name = "air",
			prob = 254
		},
		{
			param2 = 0,
			name = "air",
			prob = 254
		},
		{
			param2 = 0,
			name = "default:fence_wood",
			prob = 254
		},
		{
			param2 = 0,
			name = "air",
			prob = 254
		},
		{
			param2 = 0,
			name = "air",
			prob = 254
		},
		{
			param2 = 0,
			name = "air",
			prob = 254
		},
		{
			param2 = 1,
			name = "default:wood",
			prob = 254
		},
		{
			param2 = 21,
			name = "cottages:wood_flat",
			prob = 254
		},
		{
			param2 = 0,
			name = "air",
			prob = 254
		},
		{
			param2 = 5,
			name = "default:ladder_wood",
			prob = 254
		},
		{
			param2 = 0,
			name = "air",
			prob = 254
		},
		{
			param2 = 21,
			name = "cottages:wood_flat",
			prob = 254
		},
		{
			param2 = 0,
			name = "default:fence_wood",
			prob = 254
		},
		{
			param2 = 3,
			name = "cottages:window_shutter_open",
			prob = 254
		},
		{
			param2 = 0,
			name = "air",
			prob = 254
		},
		{
			param2 = 0,
			name = "air",
			prob = 254
		},
		{
			param2 = 0,
			name = "air",
			prob = 254
		},
		{
			param2 = 0,
			name = "air",
			prob = 254
		},
		{
			param2 = 0,
			name = "air",
			prob = 254
		},
		{
			param2 = 0,
			name = "air",
			prob = 254
		},
		{
			param2 = 0,
			name = "air",
			prob = 254
		},
		{
			param2 = 1,
			name = "cottages:roof_straw",
			prob = 254
		},
		{
			param2 = 1,
			name = "default:wood",
			prob = 254
		},
		{
			param2 = 3,
			name = "cottages:shelf",
			prob = 254
		},
		{
			param2 = 5,
